Workbook

Sheet Опр этажности
A1: Кадастровый номер | B1: Назначение | C1: Количество этажей | D1: В том числе подземных этажей | E1: Этажность | F1: Этажность источник | G1: датапакета | H1: Статус расчета КС | I1: LocFloor1 | J1: UndegraundLF1 | K1: LocFloorP | L1: Метод | M1: Равенство с пред значением | N1: LocFloors | O1: LocFloorP1 | P1: Sourcelocfloors2 | Q1: FlagLocFloors | R1: Sourcelocfloors | S1: OldLocfloors
A2: CADASTRALNUMBER | B2: ASSIGNATIONBUILDING | C2: FLOORS | D2: FLOORSUNDERGROUND | E2: LOCFLOORS | F2: SOURCELOCFLOORS | G2: inputpacket_id | H2: Status_KC
A3: Buildings | B3: Buildings | C3: Buildings | D3: Buildings | E3: Buildings | F3: Buildings | G3: Buildings | H3: Buildings
A4: 66:01:3601001:538 | B4: Жилой дом | C4: 1 | E4: 1 | F4: Значение определено ГБУ СО ЦГКО (допущение по среднему значению для года постройки по кад. Кварталу, материалу, назначению по данным на 01.02.2018) | G4: 24.12.2022 | H4: НЕ ГОТОВ | I4: =IFERROR(VLOOKUP(C4,'Справочник соответствий'!A$2:D$2981,2,FALSE),IF(VALUE(C4)=0,1,VLOOKUP(C4,'Справочник соответствий'!A$2:D$2981,2,FALSE))) -> 1 | J4: =IFERROR(VLOOKUP(D4,'Справочник соответствий'!A$2:D$2981,2,FALSE),IF(VALUE(D4)=0,0,VLOOKUP(D4,'Справочник соответствий'!A$2:D$2981,2,FALSE))) -> 0 | K4: =IF(B4="Многоквартирный дом",IF(I4-J4>0,I4-J4,1),I4) -> 1 | L4: =IFERROR(VLOOKUP(C4,'Справочник соответствий'!A$2:D$2981,3,FALSE),IF(VALUE(C4)=0,"ЭТАЖ НЕ ОПРЕДЕЛЕН. ПРИНЯТ ПО ДОПУЩЕНИЮ 1",VLOOKUP(C4,'Справочник соответствий'!A$2:D$2981,3,FALSE))) -> ЭТАЖ ЗАДАН ЧИСЛОМ | M4: =I4=E4 -> FALSE | N4: =IF(VALUE(E4)=0,VALUE(K4),IF(L4="ЭТАЖ НЕ ОПРЕДЕЛЕН. ПРИНЯТ ПО ДОПУЩЕНИЮ 1",VALUE(E4),VALUE(K4))) -> 1 | O4: =IF(VALUE(E4)=0,L4,IF(L4="ЭТАЖ НЕ ОПРЕДЕЛЕН. ПРИНЯТ ПО ДОПУЩЕНИЮ 1",F4,L4)) -> ЭТАЖ ЗАДАН ЧИСЛОМ | P4: =IF(B4="Многоквартирный дом",CONCATENATE("МКД_",O4),O4) -> ЭТАЖ ЗАДАН ЧИСЛОМ | Q4: =IFERROR(IF(N4>0,IF(N4=VALUE(E4),"ГОТОВ","ГОТОВ_ИЗМЕНЕН"),"НЕ ГОТОВ"),"НЕ ГОТОВ") -> ГОТОВ | R4: =IFERROR(VLOOKUP(P4,Лист1!A$1:B$20,2,FALSE),0) -> 784 | S4: =VALUE(E4) -> 1
A5: 66:48:0317001:1961 | B5: Нежилое здание | C5: 1 | E5: 1 | F5: Значение определено ГБУ СО ЦГКО (допущение по среднему значению для года постройки по кад. Кварталу, материалу, назначению по данным на 01.02.2018) | G5: 22.02.2023 | H5: НЕ ГОТОВ | I5: =IFERROR(VLOOKUP(C5,'Справочник соответствий'!A$2:D$2981,2,FALSE),IF(VALUE(C5)=0,1,VLOOKUP(C5,'Справочник соответствий'!A$2:D$2981,2,FALSE))) -> 1 | J5: =IFERROR(VLOOKUP(D5,'Справочник соответствий'!A$2:D$2981,2,FALSE),IF(VALUE(D5)=0,0,VLOOKUP(D5,'Справочник соответствий'!A$2:D$2981,2,FALSE))) -> 0 | K5: =IF(B5="Многоквартирный дом",IF(I5-J5>0,I5-J5,1),I5) -> 1 | L5: =IFERROR(VLOOKUP(C5,'Справочник соответствий'!A$2:D$2981,3,FALSE),IF(VALUE(C5)=0,"ЭТАЖ НЕ ОПРЕДЕЛЕН. ПРИНЯТ ПО ДОПУЩЕНИЮ 1",VLOOKUP(C5,'Справочник соответствий'!A$2:D$2981,3,FALSE))) -> ЭТАЖ ЗАДАН ЧИСЛОМ | M5: =I5=E5 -> FALSE | N5: =IF(VALUE(E5)=0,VALUE(K5),IF(L5="ЭТАЖ НЕ ОПРЕДЕЛЕН. ПРИНЯТ ПО ДОПУЩЕНИЮ 1",VALUE(E5),VALUE(K5))) -> 1 | O5: =IF(VALUE(E5)=0,L5,IF(L5="ЭТАЖ НЕ ОПРЕДЕЛЕН. ПРИНЯТ ПО ДОПУЩЕНИЮ 1",F5,L5)) -> ЭТАЖ ЗАДАН ЧИСЛОМ | P5: =IF(B5="Многоквартирный дом",CONCATENATE("МКД_",O5),O5) -> ЭТАЖ ЗАДАН ЧИСЛОМ | Q5: =IFERROR(IF(N5>0,IF(N5=VALUE(E5),"ГОТОВ","ГОТОВ_ИЗМЕНЕН"),"НЕ ГОТОВ"),"НЕ ГОТОВ") -> ГОТОВ | R5: =IFERROR(VLOOKUP(P5,Лист1!A$1:B$20,2,FALSE),0) -> 784 | S5: =VALUE(E5) -> 1
A6: 66:28:2901014:144 | B6: Жилой дом | C6: 1 | E6: 1 | F6: Значение определено ГБУ СО ЦГКО (допущение по среднему значению для года постройки по кад. Кварталу, материалу, назначению по данным на 01.02.2018) | G6: 24.12.2022 | H6: НЕ ГОТОВ | I6: =IFERROR(VLOOKUP(C6,'Справочник соответствий'!A$2:D$2981,2,FALSE),IF(VALUE(C6)=0,1,VLOOKUP(C6,'Справочник соответствий'!A$2:D$2981,2,FALSE))) -> 1 | J6: =IFERROR(VLOOKUP(D6,'Справочник соответствий'!A$2:D$2981,2,FALSE),IF(VALUE(D6)=0,0,VLOOKUP(D6,'Справочник соответствий'!A$2:D$2981,2,FALSE))) -> 0 | K6: =IF(B6="Многоквартирный дом",IF(I6-J6>0,I6-J6,1),I6) -> 1 | L6: =IFERROR(VLOOKUP(C6,'Справочник соответствий'!A$2:D$2981,3,FALSE),IF(VALUE(C6)=0,"ЭТАЖ НЕ ОПРЕДЕЛЕН. ПРИНЯТ ПО ДОПУЩЕНИЮ 1",VLOOKUP(C6,'Справочник соответствий'!A$2:D$2981,3,FALSE))) -> ЭТАЖ ЗАДАН ЧИСЛОМ | M6: =I6=E6 -> FALSE | N6: =IF(VALUE(E6)=0,VALUE(K6),IF(L6="ЭТАЖ НЕ ОПРЕДЕЛЕН. ПРИНЯТ ПО ДОПУЩЕНИЮ 1",VALUE(E6),VALUE(K6))) -> 1 | O6: =IF(VALUE(E6)=0,L6,IF(L6="ЭТАЖ НЕ ОПРЕДЕЛЕН. ПРИНЯТ ПО ДОПУЩЕНИЮ 1",F6,L6)) -> ЭТАЖ ЗАДАН ЧИСЛОМ | P6: =IF(B6="Многоквартирный дом",CONCATENATE("МКД_",O6),O6) -> ЭТАЖ ЗАДАН ЧИСЛОМ | Q6: =IFERROR(IF(N6>0,IF(N6=VALUE(E6),"ГОТОВ","ГОТОВ_ИЗМЕНЕН"),"НЕ ГОТОВ"),"НЕ ГОТОВ") -> ГОТОВ | R6: =IFERROR(VLOOKUP(P6,Лист1!A$1:B$20,2,FALSE),0) -> 784 | S6: =VALUE(E6) -> 1
A7: 66:52:0107001:667 | B7: Нежилое здание | C7: 1 | E7: 1 | F7: Значение определено ГБУ СО ЦГКО (допущение по среднему значению для года постройки по кад. Кварталу, материалу, назначению по данным на 01.02.2018) | G7: 26.01.2023 | H7: НЕ ГОТОВ | I7: =IFERROR(VLOOKUP(C7,'Справочник соответствий'!A$2:D$2981,2,FALSE),IF(VALUE(C7)=0,1,VLOOKUP(C7,'Справочник соответствий'!A$2:D$2981,2,FALSE))) -> 1 | J7: =IFERROR(VLOOKUP(D7,'Справочник соответствий'!A$2:D$2981,2,FALSE),IF(VALUE(D7)=0,0,VLOOKUP(D7,'Справочник соответствий'!A$2:D$2981,2,FALSE))) -> 0 | K7: =IF(B7="Многоквартирный дом",IF(I7-J7>0,I7-J7,1),I7) -> 1 | L7: =IFERROR(VLOOKUP(C7,'Справочник соответствий'!A$2:D$2981,3,FALSE),IF(VALUE(C7)=0,"ЭТАЖ НЕ ОПРЕДЕЛЕН. ПРИНЯТ ПО ДОПУЩЕНИЮ 1",VLOOKUP(C7,'Справочник соответствий'!A$2:D$2981,3,FALSE))) -> ЭТАЖ ЗАДАН ЧИСЛОМ | M7: =I7=E7 -> FALSE | N7: =IF(VALUE(E7)=0,VALUE(K7),IF(L7="ЭТАЖ НЕ ОПРЕДЕЛЕН. ПРИНЯТ ПО ДОПУЩЕНИЮ 1",VALUE(E7),VALUE(K7))) -> 1 | O7: =IF(VALUE(E7)=0,L7,IF(L7="ЭТАЖ НЕ ОПРЕДЕЛЕН. ПРИНЯТ ПО ДОПУЩЕНИЮ 1",F7,L7)) -> ЭТАЖ ЗАДАН ЧИСЛОМ | P7: =IF(B7="Многоквартирный дом",CONCATENATE("МКД_",O7),O7) -> ЭТАЖ ЗАДАН ЧИСЛОМ | Q7: =IFERROR(IF(N7>0,IF(N7=VALUE(E7),"ГОТОВ","ГОТОВ_ИЗМЕНЕН"),"НЕ ГОТОВ"),"НЕ ГОТОВ") -> ГОТОВ | R7: =IFERROR(VLOOKUP(P7,Лист1!A$1:B$20,2,FALSE),0) -> 784 | S7: =VALUE(E7) -> 1
A8: 66:52:0107005:709 | B8: Жилой дом | C8: 1 | E8: 1 | F8: Значение определено ГБУ СО ЦГКО (допущение по среднему значению для года постройки по кад. Кварталу, материалу, назначению по данным на 01.02.2018) | G8: 19.01.2023 | H8: НЕ ГОТОВ | I8: =IFERROR(VLOOKUP(C8,'Справочник соответствий'!A$2:D$2981,2,FALSE),IF(VALUE(C8)=0,1,VLOOKUP(C8,'Справочник соответствий'!A$2:D$2981,2,FALSE))) -> 1 | J8: =IFERROR(VLOOKUP(D8,'Справочник соответствий'!A$2:D$2981,2,FALSE),IF(VALUE(D8)=0,0,VLOOKUP(D8,'Справочник соответствий'!A$2:D$2981,2,FALSE))) -> 0 | K8: =IF(B8="Многоквартирный дом",IF(I8-J8>0,I8-J8,1),I8) -> 1 | L8: =IFERROR(VLOOKUP(C8,'Справочник соответствий'!A$2:D$2981,3,FALSE),IF(VALUE(C8)=0,"ЭТАЖ НЕ ОПРЕДЕЛЕН. ПРИНЯТ ПО ДОПУЩЕНИЮ 1",VLOOKUP(C8,'Справочник соответствий'!A$2:D$2981,3,FALSE))) -> ЭТАЖ ЗАДАН ЧИСЛОМ | M8: =I8=E8 -> FALSE | N8: =IF(VALUE(E8)=0,VALUE(K8),IF(L8="ЭТАЖ НЕ ОПРЕДЕЛЕН. ПРИНЯТ ПО ДОПУЩЕНИЮ 1",VALUE(E8),VALUE(K8))) -> 1 | O8: =IF(VALUE(E8)=0,L8,IF(L8="ЭТАЖ НЕ ОПРЕДЕЛЕН. ПРИНЯТ ПО ДОПУЩЕНИЮ 1",F8,L8)) -> ЭТАЖ ЗАДАН ЧИСЛОМ | P8: =IF(B8="Многоквартирный дом",CONCATENATE("МКД_",O8),O8) -> ЭТАЖ ЗАДАН ЧИСЛОМ | Q8: =IFERROR(IF(N8>0,IF(N8=VALUE(E8),"ГОТОВ","ГОТОВ_ИЗМЕНЕН"),"НЕ ГОТОВ"),"НЕ ГОТОВ") -> ГОТОВ | R8: =IFERROR(VLOOKUP(P8,Лист1!A$1:B$20,2,FALSE),0) -> 784 | S8: =VALUE(E8) -> 1
A9: 66:14:3401006:762 | B9: Жилой дом | C9: 1 | E9: 1 | F9: Значение определено ГБУ СО ЦГКО (допущение по среднему значению для года постройки по кад. Кварталу, материалу, назначению по данным на 01.02.2018) | G9: 26.01.2023 | H9: НЕ ГОТОВ | I9: =IFERROR(VLOOKUP(C9,'Справочник соответствий'!A$2:D$2981,2,FALSE),IF(VALUE(C9)=0,1,VLOOKUP(C9,'Справочник соответствий'!A$2:D$2981,2,FALSE))) -> 1 | J9: =IFERROR(VLOOKUP(D9,'Справочник соответствий'!A$2:D$2981,2,FALSE),IF(VALUE(D9)=0,0,VLOOKUP(D9,'Справочник соответствий'!A$2:D$2981,2,FALSE))) -> 0 | K9: =IF(B9="Многоквартирный дом",IF(I9-J9>0,I9-J9,1),I9) -> 1 | L9: =IFERROR(VLOOKUP(C9,'Справочник соответствий'!A$2:D$2981,3,FALSE),IF(VALUE(C9)=0,"ЭТАЖ НЕ ОПРЕДЕЛЕН. ПРИНЯТ ПО ДОПУЩЕНИЮ 1",VLOOKUP(C9,'Справочник соответствий'!A$2:D$2981,3,FALSE))) -> ЭТАЖ ЗАДАН ЧИСЛОМ | M9: =I9=E9 -> FALSE | N9: =IF(VALUE(E9)=0,VALUE(K9),IF(L9="ЭТАЖ НЕ ОПРЕДЕЛЕН. ПРИНЯТ ПО ДОПУЩЕНИЮ 1",VALUE(E9),VALUE(K9))) -> 1 | O9: =IF(VALUE(E9)=0,L9,IF(L9="ЭТАЖ НЕ ОПРЕДЕЛЕН. ПРИНЯТ ПО ДОПУЩЕНИЮ 1",F9,L9)) -> ЭТАЖ ЗАДАН ЧИСЛОМ | P9: =IF(B9="Многоквартирный дом",CONCATENATE("МКД_",O9),O9) -> ЭТАЖ ЗАДАН ЧИСЛОМ | Q9: =IFERROR(IF(N9>0,IF(N9=VALUE(E9),"ГОТОВ","ГОТОВ_ИЗМЕНЕН"),"НЕ ГОТОВ"),"НЕ ГОТОВ") -> ГОТОВ | R9: =IFERROR(VLOOKUP(P9,Лист1!A$1:B$20,2,FALSE),0) -> 784 | S9: =VALUE(E9) -> 1
A10: 66:52:0104019:140 | B10: Жилой дом | C10: 1 | D10: 0 | E10: 1 | F10: Значение определено ГБУ СО ЦГКО (допущение по среднему значению для года постройки по кад. Кварталу, материалу, назначению по данным на 01.02.2018) | G10: 31.01.2023 | H10: НЕ ГОТОВ | I10: =IFERROR(VLOOKUP(C10,'Справочник соответствий'!A$2:D$2981,2,FALSE),IF(VALUE(C10)=0,1,VLOOKUP(C10,'Справочник соответствий'!A$2:D$2981,2,FALSE))) -> 1 | J10: =IFERROR(VLOOKUP(D10,'Справочник соответствий'!A$2:D$2981,2,FALSE),IF(VALUE(D10)=0,0,VLOOKUP(D10,'Справочник соответствий'!A$2:D$2981,2,FALSE))) -> 1 | K10: =IF(B10="Многоквартирный дом",IF(I10-J10>0,I10-J10,1),I10) -> 1 | L10: =IFERROR(VLOOKUP(C10,'Справочник соответствий'!A$2:D$2981,3,FALSE),IF(VALUE(C10)=0,"ЭТАЖ НЕ ОПРЕДЕЛЕН. ПРИНЯТ ПО ДОПУЩЕНИЮ 1",VLOOKUP(C10,'Справочник соответствий'!A$2:D$2981,3,FALSE))) -> ЭТАЖ ЗАДАН ЧИСЛОМ | M10: =I10=E10 -> FALSE | N10: =IF(VALUE(E10)=0,VALUE(K10),IF(L10="ЭТАЖ НЕ ОПРЕДЕЛЕН. ПРИНЯТ ПО ДОПУЩЕНИЮ 1",VALUE(E10),VALUE(K10))) -> 1 | O10: =IF(VALUE(E10)=0,L10,IF(L10="ЭТАЖ НЕ ОПРЕДЕЛЕН. ПРИНЯТ ПО ДОПУЩЕНИЮ 1",F10,L10)) -> ЭТАЖ ЗАДАН ЧИСЛОМ | P10: =IF(B10="Многоквартирный дом",CONCATENATE("МКД_",O10),O10) -> ЭТАЖ ЗАДАН ЧИСЛОМ | Q10: =IFERROR(IF(N10>0,IF(N10=VALUE(E10),"ГОТОВ","ГОТОВ_ИЗМЕНЕН"),"НЕ ГОТОВ"),"НЕ ГОТОВ") -> ГОТОВ | R10: =IFERROR(VLOOKUP(P10,Лист1!A$1:B$20,2,FALSE),0) -> 784 | S10: =VALUE(E10) -> 1
A11: 66:07:1002009:244 | B11: Многоквартирный дом | C11: 5 | E11: 5 | F11: Министерство энергетики | G11: 28.12.2022 | H11: НЕ ГОТОВ | I11: =IFERROR(VLOOKUP(C11,'Справочник соответствий'!A$2:D$2981,2,FALSE),IF(VALUE(C11)=0,1,VLOOKUP(C11,'Справочник соответствий'!A$2:D$2981,2,FALSE))) -> 5 | J11: =IFERROR(VLOOKUP(D11,'Справочник соответствий'!A$2:D$2981,2,FALSE),IF(VALUE(D11)=0,0,VLOOKUP(D11,'Справочник соответствий'!A$2:D$2981,2,FALSE))) -> 0 | K11: =IF(B11="Многоквартирный дом",IF(I11-J11>0,I11-J11,1),I11) -> 5 | L11: =IFERROR(VLOOKUP(C11,'Справочник соответствий'!A$2:D$2981,3,FALSE),IF(VALUE(C11)=0,"ЭТАЖ НЕ ОПРЕДЕЛЕН. ПРИНЯТ ПО ДОПУЩЕНИЮ 1",VLOOKUP(C11,'Справочник соответствий'!A$2:D$2981,3,FALSE))) -> ЭТАЖ ЗАДАН ЧИСЛОМ | M11: =I11=E11 -> FALSE | N11: =IF(VALUE(E11)=0,VALUE(K11),IF(L11="ЭТАЖ НЕ ОПРЕДЕЛЕН. ПРИНЯТ ПО ДОПУЩЕНИЮ 1",VALUE(E11),VALUE(K11))) -> 5 | O11: =IF(VALUE(E11)=0,L11,IF(L11="ЭТАЖ НЕ ОПРЕДЕЛЕН. ПРИНЯТ ПО ДОПУЩЕНИЮ 1",F11,L11)) -> ЭТАЖ ЗАДАН ЧИСЛОМ | P11: =IF(B11="Многоквартирный дом",CONCATENATE("МКД_",O11),O11) -> МКД_ЭТАЖ ЗАДАН ЧИСЛОМ | Q11: =IFERROR(IF(N11>0,IF(N11=VALUE(E11),"ГОТОВ","ГОТОВ_ИЗМЕНЕН"),"НЕ ГОТОВ"),"НЕ ГОТОВ") -> ГОТОВ | R11: =IFERROR(VLOOKUP(P11,Лист1!A$1:B$20,2,FALSE),0) -> 786 | S11: =VALUE(E11) -> 5
A12: 66:36:1301014:372 | B12: Жилой дом | C12: 1 | E12: 1 | F12: Значение определено ГБУ СО ЦГКО (допущение по среднему значению для года постройки по кад. Кварталу, материалу, назначению по данным на 01.02.2018) | G12: 09.01.2023 | H12: НЕ ГОТОВ | I12: =IFERROR(VLOOKUP(C12,'Справочник соответствий'!A$2:D$2981,2,FALSE),IF(VALUE(C12)=0,1,VLOOKUP(C12,'Справочник соответствий'!A$2:D$2981,2,FALSE))) -> 1 | J12: =IFERROR(VLOOKUP(D12,'Справочник соответствий'!A$2:D$2981,2,FALSE),IF(VALUE(D12)=0,0,VLOOKUP(D12,'Справочник соответствий'!A$2:D$2981,2,FALSE))) -> 0 | K12: =IF(B12="Многоквартирный дом",IF(I12-J12>0,I12-J12,1),I12) -> 1 | L12: =IFERROR(VLOOKUP(C12,'Справочник соответствий'!A$2:D$2981,3,FALSE),IF(VALUE(C12)=0,"ЭТАЖ НЕ ОПРЕДЕЛЕН. ПРИНЯТ ПО ДОПУЩЕНИЮ 1",VLOOKUP(C12,'Справочник соответствий'!A$2:D$2981,3,FALSE))) -> ЭТАЖ ЗАДАН ЧИСЛОМ | M12: =I12=E12 -> FALSE | N12: =IF(VALUE(E12)=0,VALUE(K12),IF(L12="ЭТАЖ НЕ ОПРЕДЕЛЕН. ПРИНЯТ ПО ДОПУЩЕНИЮ 1",VALUE(E12),VALUE(K12))) -> 1 | O12: =IF(VALUE(E12)=0,L12,IF(L12="ЭТАЖ НЕ ОПРЕДЕЛЕН. ПРИНЯТ ПО ДОПУЩЕНИЮ 1",F12,L12)) -> ЭТАЖ ЗАДАН ЧИСЛОМ | P12: =IF(B12="Многоквартирный дом",CONCATENATE("МКД_",O12),O12) -> ЭТАЖ ЗАДАН ЧИСЛОМ | Q12: =IFERROR(IF(N12>0,IF(N12=VALUE(E12),"ГОТОВ","ГОТОВ_ИЗМЕНЕН"),"НЕ ГОТОВ"),"НЕ ГОТОВ") -> ГОТОВ | R12: =IFERROR(VLOOKUP(P12,Лист1!A$1:B$20,2,FALSE),0) -> 784 | S12: =VALUE(E12) -> 1
A13: 66:04:1301001:229 | B13: Нежилое здание | C13: 1 | E13: 1 | F13: Значение определено ГБУ СО ЦГКО (допущение по среднему значению для года постройки по кад. Кварталу, материалу, назначению по данным на 01.02.2018) | G13: 31.01.2023 | H13: НЕ ГОТОВ | I13: =IFERROR(VLOOKUP(C13,'Справочник соответствий'!A$2:D$2981,2,FALSE),IF(VALUE(C13)=0,1,VLOOKUP(C13,'Справочник соответствий'!A$2:D$2981,2,FALSE))) -> 1 | J13: =IFERROR(VLOOKUP(D13,'Справочник соответствий'!A$2:D$2981,2,FALSE),IF(VALUE(D13)=0,0,VLOOKUP(D13,'Справочник соответствий'!A$2:D$2981,2,FALSE))) -> 0 | K13: =IF(B13="Многоквартирный дом",IF(I13-J13>0,I13-J13,1),I13) -> 1 | L13: =IFERROR(VLOOKUP(C13,'Справочник соответствий'!A$2:D$2981,3,FALSE),IF(VALUE(C13)=0,"ЭТАЖ НЕ ОПРЕДЕЛЕН. ПРИНЯТ ПО ДОПУЩЕНИЮ 1",VLOOKUP(C13,'Справочник соответствий'!A$2:D$2981,3,FALSE))) -> ЭТАЖ ЗАДАН ЧИСЛОМ | M13: =I13=E13 -> FALSE | N13: =IF(VALUE(E13)=0,VALUE(K13),IF(L13="ЭТАЖ НЕ ОПРЕДЕЛЕН. ПРИНЯТ ПО ДОПУЩЕНИЮ 1",VALUE(E13),VALUE(K13))) -> 1 | O13: =IF(VALUE(E13)=0,L13,IF(L13="ЭТАЖ НЕ ОПРЕДЕЛЕН. ПРИНЯТ ПО ДОПУЩЕНИЮ 1",F13,L13)) -> ЭТАЖ ЗАДАН ЧИСЛОМ | P13: =IF(B13="Многоквартирный дом",CONCATENATE("МКД_",O13),O13) -> ЭТАЖ ЗАДАН ЧИСЛОМ | Q13: =IFERROR(IF(N13>0,IF(N13=VALUE(E13),"ГОТОВ","ГОТОВ_ИЗМЕНЕН"),"НЕ ГОТОВ"),"НЕ ГОТОВ") -> ГОТОВ | R13: =IFERROR(VLOOKUP(P13,Лист1!A$1:B$20,2,FALSE),0) -> 784 | S13: =VALUE(E13) -> 1
A14: 66:22:0508003:245 | B14: Жилой дом | C14: 1 | E14: 1 | F14: Значение определено ГБУ СО ЦГКО (допущение по среднему значению для года постройки по кад. Кварталу, материалу, назначению по данным на 01.02.2018) | G14: 30.01.2023 | H14: НЕ ГОТОВ | I14: =IFERROR(VLOOKUP(C14,'Справочник соответствий'!A$2:D$2981,2,FALSE),IF(VALUE(C14)=0,1,VLOOKUP(C14,'Справочник соответствий'!A$2:D$2981,2,FALSE))) -> 1 | J14: =IFERROR(VLOOKUP(D14,'Справочник соответствий'!A$2:D$2981,2,FALSE),IF(VALUE(D14)=0,0,VLOOKUP(D14,'Справочник соответствий'!A$2:D$2981,2,FALSE))) -> 0 | K14: =IF(B14="Многоквартирный дом",IF(I14-J14>0,I14-J14,1),I14) -> 1 | L14: =IFERROR(VLOOKUP(C14,'Справочник соответствий'!A$2:D$2981,3,FALSE),IF(VALUE(C14)=0,"ЭТАЖ НЕ ОПРЕДЕЛЕН. ПРИНЯТ ПО ДОПУЩЕНИЮ 1",VLOOKUP(C14,'Справочник соответствий'!A$2:D$2981,3,FALSE))) -> ЭТАЖ ЗАДАН ЧИСЛОМ | M14: =I14=E14 -> FALSE | N14: =IF(VALUE(E14)=0,VALUE(K14),IF(L14="ЭТАЖ НЕ ОПРЕДЕЛЕН. ПРИНЯТ ПО ДОПУЩЕНИЮ 1",VALUE(E14),VALUE(K14))) -> 1 | O14: =IF(VALUE(E14)=0,L14,IF(L14="ЭТАЖ НЕ ОПРЕДЕЛЕН. ПРИНЯТ ПО ДОПУЩЕНИЮ 1",F14,L14)) -> ЭТАЖ ЗАДАН ЧИСЛОМ | P14: =IF(B14="Многоквартирный дом",CONCATENATE("МКД_",O14),O14) -> ЭТАЖ ЗАДАН ЧИСЛОМ | Q14: =IFERROR(IF(N14>0,IF(N14=VALUE(E14),"ГОТОВ","ГОТОВ_ИЗМЕНЕН"),"НЕ ГОТОВ"),"НЕ ГОТОВ") -> ГОТОВ | R14: =IFERROR(VLOOKUP(P14,Лист1!A$1:B$20,2,FALSE),0) -> 784 | S14: =VALUE(E14) -> 1
A15: 66:28:2601001:601 | B15: Жилой дом | C15: 1 | E15: 1 | F15: По допущению год постановки на КУ | G15: 02.02.2023 | H15: НЕ ГОТОВ | I15: =IFERROR(VLOOKUP(C15,'Справочник соответствий'!A$2:D$2981,2,FALSE),IF(VALUE(C15)=0,1,VLOOKUP(C15,'Справочник соответствий'!A$2:D$2981,2,FALSE))) -> 1 | J15: =IFERROR(VLOOKUP(D15,'Справочник соответствий'!A$2:D$2981,2,FALSE),IF(VALUE(D15)=0,0,VLOOKUP(D15,'Справочник соответствий'!A$2:D$2981,2,FALSE))) -> 0 | K15: =IF(B15="Многоквартирный дом",IF(I15-J15>0,I15-J15,1),I15) -> 1 | L15: =IFERROR(VLOOKUP(C15,'Справочник соответствий'!A$2:D$2981,3,FALSE),IF(VALUE(C15)=0,"ЭТАЖ НЕ ОПРЕДЕЛЕН. ПРИНЯТ ПО ДОПУЩЕНИЮ 1",VLOOKUP(C15,'Справочник соответствий'!A$2:D$2981,3,FALSE))) -> ЭТАЖ ЗАДАН ЧИСЛОМ | M15: =I15=E15 -> FALSE | N15: =IF(VALUE(E15)=0,VALUE(K15),IF(L15="ЭТАЖ НЕ ОПРЕДЕЛЕН. ПРИНЯТ ПО ДОПУЩЕНИЮ 1",VALUE(E15),VALUE(K15))) -> 1 | O15: =IF(VALUE(E15)=0,L15,IF(L15="ЭТАЖ НЕ ОПРЕДЕЛЕН. ПРИНЯТ ПО ДОПУЩЕНИЮ 1",F15,L15)) -> ЭТАЖ ЗАДАН ЧИСЛОМ | P15: =IF(B15="Многоквартирный дом",CONCATENATE("МКД_",O15),O15) -> ЭТАЖ ЗАДАН ЧИСЛОМ | Q15: =IFERROR(IF(N15>0,IF(N15=VALUE(E15),"ГОТОВ","ГОТОВ_ИЗМЕНЕН"),"НЕ ГОТОВ"),"НЕ ГОТОВ") -> ГОТОВ | R15: =IFERROR(VLOOKUP(P15,Лист1!A$1:B$20,2,FALSE),0) -> 784 | S15: =VALUE(E15) -> 1
A16: 66:07:1002013:197 | B16: Многоквартирный дом | C16: 5 | E16: 5 | F16: Министерство энергетики | G16: 28.12.2022 | H16: НЕ ГОТОВ | I16: =IFERROR(VLOOKUP(C16,'Справочник соответствий'!A$2:D$2981,2,FALSE),IF(VALUE(C16)=0,1,VLOOKUP(C16,'Справочник соответствий'!A$2:D$2981,2,FALSE))) -> 5 | J16: =IFERROR(VLOOKUP(D16,'Справочник соответствий'!A$2:D$2981,2,FALSE),IF(VALUE(D16)=0,0,VLOOKUP(D16,'Справочник соответствий'!A$2:D$2981,2,FALSE))) -> 0 | K16: =IF(B16="Многоквартирный дом",IF(I16-J16>0,I16-J16,1),I16) -> 5 | L16: =IFERROR(VLOOKUP(C16,'Справочник соответствий'!A$2:D$2981,3,FALSE),IF(VALUE(C16)=0,"ЭТАЖ НЕ ОПРЕДЕЛЕН. ПРИНЯТ ПО ДОПУЩЕНИЮ 1",VLOOKUP(C16,'Справочник соответствий'!A$2:D$2981,3,FALSE))) -> ЭТАЖ ЗАДАН ЧИСЛОМ | M16: =I16=E16 -> FALSE | N16: =IF(VALUE(E16)=0,VALUE(K16),IF(L16="ЭТАЖ НЕ ОПРЕДЕЛЕН. ПРИНЯТ ПО ДОПУЩЕНИЮ 1",VALUE(E16),VALUE(K16))) -> 5 | O16: =IF(VALUE(E16)=0,L16,IF(L16="ЭТАЖ НЕ ОПРЕДЕЛЕН. ПРИНЯТ ПО ДОПУЩЕНИЮ 1",F16,L16)) -> ЭТАЖ ЗАДАН ЧИСЛОМ | P16: =IF(B16="Многоквартирный дом",CONCATENATE("МКД_",O16),O16) -> МКД_ЭТАЖ ЗАДАН ЧИСЛОМ | Q16: =IFERROR(IF(N16>0,IF(N16=VALUE(E16),"ГОТОВ","ГОТОВ_ИЗМЕНЕН"),"НЕ ГОТОВ"),"НЕ ГОТОВ") -> ГОТОВ | R16: =IFERROR(VLOOKUP(P16,Лист1!A$1:B$20,2,FALSE),0) -> 786 | S16: =VALUE(E16) -> 5
A17: 66:21:0101039:269 | B17: Нежилое здание | C17: 1 | E17: 1 | F17: Значение определено ГБУ СО ЦГКО (допущение по среднему значению для года постройки по кад. Кварталу, материалу, назначению по данным на 01.02.2018) | G17: 27.01.2023 | H17: НЕ ГОТОВ | I17: =IFERROR(VLOOKUP(C17,'Справочник соответствий'!A$2:D$2981,2,FALSE),IF(VALUE(C17)=0,1,VLOOKUP(C17,'Справочник соответствий'!A$2:D$2981,2,FALSE))) -> 1 | J17: =IFERROR(VLOOKUP(D17,'Справочник соответствий'!A$2:D$2981,2,FALSE),IF(VALUE(D17)=0,0,VLOOKUP(D17,'Справочник соответствий'!A$2:D$2981,2,FALSE))) -> 0 | K17: =IF(B17="Многоквартирный дом",IF(I17-J17>0,I17-J17,1),I17) -> 1 | L17: =IFERROR(VLOOKUP(C17,'Справочник соответствий'!A$2:D$2981,3,FALSE),IF(VALUE(C17)=0,"ЭТАЖ НЕ ОПРЕДЕЛЕН. ПРИНЯТ ПО ДОПУЩЕНИЮ 1",VLOOKUP(C17,'Справочник соответствий'!A$2:D$2981,3,FALSE))) -> ЭТАЖ ЗАДАН ЧИСЛОМ | M17: =I17=E17 -> FALSE | N17: =IF(VALUE(E17)=0,VALUE(K17),IF(L17="ЭТАЖ НЕ ОПРЕДЕЛЕН. ПРИНЯТ ПО ДОПУЩЕНИЮ 1",VALUE(E17),VALUE(K17))) -> 1 | O17: =IF(VALUE(E17)=0,L17,IF(L17="ЭТАЖ НЕ ОПРЕДЕЛЕН. ПРИНЯТ ПО ДОПУЩЕНИЮ 1",F17,L17)) -> ЭТАЖ ЗАДАН ЧИСЛОМ | P17: =IF(B17="Многоквартирный дом",CONCATENATE("МКД_",O17),O17) -> ЭТАЖ ЗАДАН ЧИСЛОМ | Q17: =IFERROR(IF(N17>0,IF(N17=VALUE(E17),"ГОТОВ","ГОТОВ_ИЗМЕНЕН"),"НЕ ГОТОВ"),"НЕ ГОТОВ") -> ГОТОВ | R17: =IFERROR(VLOOKUP(P17,Лист1!A$1:B$20,2,FALSE),0) -> 784 | S17: =VALUE(E17) -> 1
A18: 66:07:2001001:608 | B18: Многоквартирный дом | C18: 2 | E18: 2 | F18: Министерство энергетики | G18: 28.12.2022 | H18: НЕ ГОТОВ | I18: =IFERROR(VLOOKUP(C18,'Справочник соответствий'!A$2:D$2981,2,FALSE),IF(VALUE(C18)=0,1,VLOOKUP(C18,'Справочник соответствий'!A$2:D$2981,2,FALSE))) -> 2 | J18: =IFERROR(VLOOKUP(D18,'Справочник соответствий'!A$2:D$2981,2,FALSE),IF(VALUE(D18)=0,0,VLOOKUP(D18,'Справочник соответствий'!A$2:D$2981,2,FALSE))) -> 0 | K18: =IF(B18="Многоквартирный дом",IF(I18-J18>0,I18-J18,1),I18) -> 2 | L18: =IFERROR(VLOOKUP(C18,'Справочник соответствий'!A$2:D$2981,3,FALSE),IF(VALUE(C18)=0,"ЭТАЖ НЕ ОПРЕДЕЛЕН. ПРИНЯТ ПО ДОПУЩЕНИЮ 1",VLOOKUP(C18,'Справочник соответствий'!A$2:D$2981,3,FALSE))) -> ЭТАЖ ЗАДАН ЧИСЛОМ | M18: =I18=E18 -> FALSE | N18: =IF(VALUE(E18)=0,VALUE(K18),IF(L18="ЭТАЖ НЕ ОПРЕДЕЛЕН. ПРИНЯТ ПО ДОПУЩЕНИЮ 1",VALUE(E18),VALUE(K18))) -> 2 | O18: =IF(VALUE(E18)=0,L18,IF(L18="ЭТАЖ НЕ ОПРЕДЕЛЕН. ПРИНЯТ ПО ДОПУЩЕНИЮ 1",F18,L18)) -> ЭТАЖ ЗАДАН ЧИСЛОМ | P18: =IF(B18="Многоквартирный дом",CONCATENATE("МКД_",O18),O18) -> МКД_ЭТАЖ ЗАДАН ЧИСЛОМ | Q18: =IFERROR(IF(N18>0,IF(N18=VALUE(E18),"ГОТОВ","ГОТОВ_ИЗМЕНЕН"),"НЕ ГОТОВ"),"НЕ ГОТОВ") -> ГОТОВ | R18: =IFERROR(VLOOKUP(P18,Лист1!A$1:B$20,2,FALSE),0) -> 786 | S18: =VALUE(E18) -> 2
A19: 66:04:1601005:157 | B19: Жилой дом | C19: 1 | E19: 1 | F19: Значение определено ГБУ СО ЦГКО (допущение по среднему значению для года постройки по кад. Кварталу, материалу, назначению по данным на 01.02.2018) | G19: 03.02.2023 | H19: НЕ ГОТОВ | I19: =IFERROR(VLOOKUP(C19,'Справочник соответствий'!A$2:D$2981,2,FALSE),IF(VALUE(C19)=0,1,VLOOKUP(C19,'Справочник соответствий'!A$2:D$2981,2,FALSE))) -> 1 | J19: =IFERROR(VLOOKUP(D19,'Справочник соответствий'!A$2:D$2981,2,FALSE),IF(VALUE(D19)=0,0,VLOOKUP(D19,'Справочник соответствий'!A$2:D$2981,2,FALSE))) -> 0 | K19: =IF(B19="Многоквартирный дом",IF(I19-J19>0,I19-J19,1),I19) -> 1 | L19: =IFERROR(VLOOKUP(C19,'Справочник соответствий'!A$2:D$2981,3,FALSE),IF(VALUE(C19)=0,"ЭТАЖ НЕ ОПРЕДЕЛЕН. ПРИНЯТ ПО ДОПУЩЕНИЮ 1",VLOOKUP(C19,'Справочник соответствий'!A$2:D$2981,3,FALSE))) -> ЭТАЖ ЗАДАН ЧИСЛОМ | M19: =I19=E19 -> FALSE | N19: =IF(VALUE(E19)=0,VALUE(K19),IF(L19="ЭТАЖ НЕ ОПРЕДЕЛЕН. ПРИНЯТ ПО ДОПУЩЕНИЮ 1",VALUE(E19),VALUE(K19))) -> 1 | O19: =IF(VALUE(E19)=0,L19,IF(L19="ЭТАЖ НЕ ОПРЕДЕЛЕН. ПРИНЯТ ПО ДОПУЩЕНИЮ 1",F19,L19)) -> ЭТАЖ ЗАДАН ЧИСЛОМ | P19: =IF(B19="Многоквартирный дом",CONCATENATE("МКД_",O19),O19) -> ЭТАЖ ЗАДАН ЧИСЛОМ | Q19: =IFERROR(IF(N19>0,IF(N19=VALUE(E19),"ГОТОВ","ГОТОВ_ИЗМЕНЕН"),"НЕ ГОТОВ"),"НЕ ГОТОВ") -> ГОТОВ | R19: =IFERROR(VLOOKUP(P19,Лист1!A$1:B$20,2,FALSE),0) -> 784 | S19: =VALUE(E19) -> 1
A20: 66:52:0104019:404 | B20: Жилой дом | C20: 1 | E20: 1 | F20: Значение определено ГБУ СО ЦГКО (допущение по среднему значению для года постройки по кад. Кварталу, материалу, назначению по данным на 01.02.2018) | G20: 31.01.2023 | H20: НЕ ГОТОВ | I20: =IFERROR(VLOOKUP(C20,'Справочник соответствий'!A$2:D$2981,2,FALSE),IF(VALUE(C20)=0,1,VLOOKUP(C20,'Справочник соответствий'!A$2:D$2981,2,FALSE))) -> 1 | J20: =IFERROR(VLOOKUP(D20,'Справочник соответствий'!A$2:D$2981,2,FALSE),IF(VALUE(D20)=0,0,VLOOKUP(D20,'Справочник соответствий'!A$2:D$2981,2,FALSE))) -> 0 | K20: =IF(B20="Многоквартирный дом",IF(I20-J20>0,I20-J20,1),I20) -> 1 | L20: =IFERROR(VLOOKUP(C20,'Справочник соответствий'!A$2:D$2981,3,FALSE),IF(VALUE(C20)=0,"ЭТАЖ НЕ ОПРЕДЕЛЕН. ПРИНЯТ ПО ДОПУЩЕНИЮ 1",VLOOKUP(C20,'Справочник соответствий'!A$2:D$2981,3,FALSE))) -> ЭТАЖ ЗАДАН ЧИСЛОМ | M20: =I20=E20 -> FALSE | N20: =IF(VALUE(E20)=0,VALUE(K20),IF(L20="ЭТАЖ НЕ ОПРЕДЕЛЕН. ПРИНЯТ ПО ДОПУЩЕНИЮ 1",VALUE(E20),VALUE(K20))) -> 1 | O20: =IF(VALUE(E20)=0,L20,IF(L20="ЭТАЖ НЕ ОПРЕДЕЛЕН. ПРИНЯТ ПО ДОПУЩЕНИЮ 1",F20,L20)) -> ЭТАЖ ЗАДАН ЧИСЛОМ | P20: =IF(B20="Многоквартирный дом",CONCATENATE("МКД_",O20),O20) -> ЭТАЖ ЗАДАН ЧИСЛОМ | Q20: =IFERROR(IF(N20>0,IF(N20=VALUE(E20),"ГОТОВ","ГОТОВ_ИЗМЕНЕН"),"НЕ ГОТОВ"),"НЕ ГОТОВ") -> ГОТОВ | R20: =IFERROR(VLOOKUP(P20,Лист1!A$1:B$20,2,FALSE),0) -> 784 | S20: =VALUE(E20) -> 1
A21: 66:59:0000000:4779 | B21: Нежилое здание | E21: 1 | F21: Значение определено ГБУ СО ЦГКО (допущение по среднему значению для года постройки по кад. Кварталу, материалу, назначению по данным на 01.02.2018) | G21: 31.01.2023 | H21: НЕ ГОТОВ | I21: =IFERROR(VLOOKUP(C21,'Справочник соответствий'!A$2:D$2981,2,FALSE),IF(VALUE(C21)=0,1,VLOOKUP(C21,'Справочник соответствий'!A$2:D$2981,2,FALSE))) -> 1 | J21: =IFERROR(VLOOKUP(D21,'Справочник соответствий'!A$2:D$2981,2,FALSE),IF(VALUE(D21)=0,0,VLOOKUP(D21,'Справочник соответствий'!A$2:D$2981,2,FALSE))) -> 0 | K21: =IF(B21="Многоквартирный дом",IF(I21-J21>0,I21-J21,1),I21) -> 1 | L21: =IFERROR(VLOOKUP(C21,'Справочник соответствий'!A$2:D$2981,3,FALSE),IF(VALUE(C21)=0,"ЭТАЖ НЕ ОПРЕДЕЛЕН. ПРИНЯТ ПО ДОПУЩЕНИЮ 1",VLOOKUP(C21,'Справочник соответствий'!A$2:D$2981,3,FALSE))) -> ЭТАЖ НЕ ОПРЕДЕЛЕН. ПРИНЯТ ПО ДОПУЩЕНИЮ 1 | M21: =I21=E21 -> TRUE | N21: =IF(VALUE(E21)=0,VALUE(K21),IF(L21="ЭТАЖ НЕ ОПРЕДЕЛЕН. ПРИНЯТ ПО ДОПУЩЕНИЮ 1",VALUE(E21),VALUE(K21))) -> 1 | O21: =IF(VALUE(E21)=0,L21,IF(L21="ЭТАЖ НЕ ОПРЕДЕЛЕН. ПРИНЯТ ПО ДОПУЩЕНИЮ 1",F21,L21)) -> Значение определено ГБУ СО ЦГКО (допущение по среднему значению для года постройки по кад. Кварталу, материалу, назначению по данным на 01.02.2018) | P21: =IF(B21="Многоквартирный дом",CONCATENATE("МКД_",O21),O21) -> Значение определено ГБУ СО ЦГКО (допущение по среднему значению для года постройки по кад. Кварталу, материалу, назначению по данным на 01.02.2018) | Q21: =IFERROR(IF(N21>0,IF(N21=VALUE(E21),"ГОТОВ","ГОТОВ_ИЗМЕНЕН"),"НЕ ГОТОВ"),"НЕ ГОТОВ") -> ГОТОВ | R21: =IFERROR(VLOOKUP(P21,Лист1!A$1:B$20,2,FALSE),0) -> 214 | S21: =VALUE(E21) -> 1
A22: 66:52:0108001:424 | B22: Жилой дом | C22: 1 | E22: 1 | F22: Значение определено ГБУ СО ЦГКО (допущение по среднему значению для года постройки по кад. Кварталу, материалу, назначению по данным на 01.02.2018) | G22: 31.01.2023 | H22: НЕ ГОТОВ | I22: =IFERROR(VLOOKUP(C22,'Справочник соответствий'!A$2:D$2981,2,FALSE),IF(VALUE(C22)=0,1,VLOOKUP(C22,'Справочник соответствий'!A$2:D$2981,2,FALSE))) -> 1 | J22: =IFERROR(VLOOKUP(D22,'Справочник соответствий'!A$2:D$2981,2,FALSE),IF(VALUE(D22)=0,0,VLOOKUP(D22,'Справочник соответствий'!A$2:D$2981,2,FALSE))) -> 0 | K22: =IF(B22="Многоквартирный дом",IF(I22-J22>0,I22-J22,1),I22) -> 1 | L22: =IFERROR(VLOOKUP(C22,'Справочник соответствий'!A$2:D$2981,3,FALSE),IF(VALUE(C22)=0,"ЭТАЖ НЕ ОПРЕДЕЛЕН. ПРИНЯТ ПО ДОПУЩЕНИЮ 1",VLOOKUP(C22,'Справочник соответствий'!A$2:D$2981,3,FALSE))) -> ЭТАЖ ЗАДАН ЧИСЛОМ | M22: =I22=E22 -> FALSE | N22: =IF(VALUE(E22)=0,VALUE(K22),IF(L22="ЭТАЖ НЕ ОПРЕДЕЛЕН. ПРИНЯТ ПО ДОПУЩЕНИЮ 1",VALUE(E22),VALUE(K22))) -> 1 | O22: =IF(VALUE(E22)=0,L22,IF(L22="ЭТАЖ НЕ ОПРЕДЕЛЕН. ПРИНЯТ ПО ДОПУЩЕНИЮ 1",F22,L22)) -> ЭТАЖ ЗАДАН ЧИСЛОМ | P22: =IF(B22="Многоквартирный дом",CONCATENATE("МКД_",O22),O22) -> ЭТАЖ ЗАДАН ЧИСЛОМ | Q22: =IFERROR(IF(N22>0,IF(N22=VALUE(E22),"ГОТОВ","ГОТОВ_ИЗМЕНЕН"),"НЕ ГОТОВ"),"НЕ ГОТОВ") -> ГОТОВ | R22: =IFERROR(VLOOKUP(P22,Лист1!A$1:B$20,2,FALSE),0) -> 784 | S22: =VALUE(E22) -> 1
A23: 66:52:0107002:898 | B23: Жилой дом | C23: 1 | E23: 1 | F23: Значение определено ГБУ СО ЦГКО (допущение по среднему значению для года постройки по кад. Кварталу, материалу, назначению по данным на 01.02.2018) | G23: 31.01.2023 | H23: НЕ ГОТОВ | I23: =IFERROR(VLOOKUP(C23,'Справочник соответствий'!A$2:D$2981,2,FALSE),IF(VALUE(C23)=0,1,VLOOKUP(C23,'Справочник соответствий'!A$2:D$2981,2,FALSE))) -> 1 | J23: =IFERROR(VLOOKUP(D23,'Справочник соответствий'!A$2:D$2981,2,FALSE),IF(VALUE(D23)=0,0,VLOOKUP(D23,'Справочник соответствий'!A$2:D$2981,2,FALSE))) -> 0 | K23: =IF(B23="Многоквартирный дом",IF(I23-J23>0,I23-J23,1),I23) -> 1 | L23: =IFERROR(VLOOKUP(C23,'Справочник соответствий'!A$2:D$2981,3,FALSE),IF(VALUE(C23)=0,"ЭТАЖ НЕ ОПРЕДЕЛЕН. ПРИНЯТ ПО ДОПУЩЕНИЮ 1",VLOOKUP(C23,'Справочник соответствий'!A$2:D$2981,3,FALSE))) -> ЭТАЖ ЗАДАН ЧИСЛОМ | M23: =I23=E23 -> FALSE | N23: =IF(VALUE(E23)=0,VALUE(K23),IF(L23="ЭТАЖ НЕ ОПРЕДЕЛЕН. ПРИНЯТ ПО ДОПУЩЕНИЮ 1",VALUE(E23),VALUE(K23))) -> 1 | O23: =IF(VALUE(E23)=0,L23,IF(L23="ЭТАЖ НЕ ОПРЕДЕЛЕН. ПРИНЯТ ПО ДОПУЩЕНИЮ 1",F23,L23)) -> ЭТАЖ ЗАДАН ЧИСЛОМ | P23: =IF(B23="Многоквартирный дом",CONCATENATE("МКД_",O23),O23) -> ЭТАЖ ЗАДАН ЧИСЛОМ | Q23: =IFERROR(IF(N23>0,IF(N23=VALUE(E23),"ГОТОВ","ГОТОВ_ИЗМЕНЕН"),"НЕ ГОТОВ"),"НЕ ГОТОВ") -> ГОТОВ | R23: =IFERROR(VLOOKUP(P23,Лист1!A$1:B$20,2,FALSE),0) -> 784 | S23: =VALUE(E23) -> 1
A24: 66:04:0801002:175 | B24: Многоквартирный дом | C24: 1 | E24: 1 | F24: По допущению год постановки на КУ | G24: 30.01.2023 | H24: НЕ ГОТОВ | I24: =IFERROR(VLOOKUP(C24,'Справочник соответствий'!A$2:D$2981,2,FALSE),IF(VALUE(C24)=0,1,VLOOKUP(C24,'Справочник соответствий'!A$2:D$2981,2,FALSE))) -> 1 | J24: =IFERROR(VLOOKUP(D24,'Справочник соответствий'!A$2:D$2981,2,FALSE),IF(VALUE(D24)=0,0,VLOOKUP(D24,'Справочник соответствий'!A$2:D$2981,2,FALSE))) -> 0 | K24: =IF(B24="Многоквартирный дом",IF(I24-J24>0,I24-J24,1),I24) -> 1 | L24: =IFERROR(VLOOKUP(C24,'Справочник соответствий'!A$2:D$2981,3,FALSE),IF(VALUE(C24)=0,"ЭТАЖ НЕ ОПРЕДЕЛЕН. ПРИНЯТ ПО ДОПУЩЕНИЮ 1",VLOOKUP(C24,'Справочник соответствий'!A$2:D$2981,3,FALSE))) -> ЭТАЖ ЗАДАН ЧИСЛОМ | M24: =I24=E24 -> FALSE | N24: =IF(VALUE(E24)=0,VALUE(K24),IF(L24="ЭТАЖ НЕ ОПРЕДЕЛЕН. ПРИНЯТ ПО ДОПУЩЕНИЮ 1",VALUE(E24),VALUE(K24))) -> 1 | O24: =IF(VALUE(E24)=0,L24,IF(L24="ЭТАЖ НЕ ОПРЕДЕЛЕН. ПРИНЯТ ПО ДОПУЩЕНИЮ 1",F24,L24)) -> ЭТАЖ ЗАДАН ЧИСЛОМ | P24: =IF(B24="Многоквартирный дом",CONCATENATE("МКД_",O24),O24) -> МКД_ЭТАЖ ЗАДАН ЧИСЛОМ | Q24: =IFERROR(IF(N24>0,IF(N24=VALUE(E24),"ГОТОВ","ГОТОВ_ИЗМЕНЕН"),"НЕ ГОТОВ"),"НЕ ГОТОВ") -> ГОТОВ | R24: =IFERROR(VLOOKUP(P24,Лист1!A$1:B$20,2,FALSE),0) -> 786 | S24: =VALUE(E24) -> 1
A25: 66:16:0801001:480 | B25: Жилой дом | C25: 1 | E25: 1 | F25: Значение определено ГБУ СО ЦГКО (допущение по среднему значению для года постройки по кад. Кварталу, материалу, назначению по данным на 01.02.2018) | G25: 26.12.2022 | H25: НЕ ГОТОВ | I25: =IFERROR(VLOOKUP(C25,'Справочник соответствий'!A$2:D$2981,2,FALSE),IF(VALUE(C25)=0,1,VLOOKUP(C25,'Справочник соответствий'!A$2:D$2981,2,FALSE))) -> 1 | J25: =IFERROR(VLOOKUP(D25,'Справочник соответствий'!A$2:D$2981,2,FALSE),IF(VALUE(D25)=0,0,VLOOKUP(D25,'Справочник соответствий'!A$2:D$2981,2,FALSE))) -> 0 | K25: =IF(B25="Многоквартирный дом",IF(I25-J25>0,I25-J25,1),I25) -> 1 | L25: =IFERROR(VLOOKUP(C25,'Справочник соответствий'!A$2:D$2981,3,FALSE),IF(VALUE(C25)=0,"ЭТАЖ НЕ ОПРЕДЕЛЕН. ПРИНЯТ ПО ДОПУЩЕНИЮ 1",VLOOKUP(C25,'Справочник соответствий'!A$2:D$2981,3,FALSE))) -> ЭТАЖ ЗАДАН ЧИСЛОМ | M25: =I25=E25 -> FALSE | N25: =IF(VALUE(E25)=0,VALUE(K25),IF(L25="ЭТАЖ НЕ ОПРЕДЕЛЕН. ПРИНЯТ ПО ДОПУЩЕНИЮ 1",VALUE(E25),VALUE(K25))) -> 1 | O25: =IF(VALUE(E25)=0,L25,IF(L25="ЭТАЖ НЕ ОПРЕДЕЛЕН. ПРИНЯТ ПО ДОПУЩЕНИЮ 1",F25,L25)) -> ЭТАЖ ЗАДАН ЧИСЛОМ | P25: =IF(B25="Многоквартирный дом",CONCATENATE("МКД_",O25),O25) -> ЭТАЖ ЗАДАН ЧИСЛОМ | Q25: =IFERROR(IF(N25>0,IF(N25=VALUE(E25),"ГОТОВ","ГОТОВ_ИЗМЕНЕН"),"НЕ ГОТОВ"),"НЕ ГОТОВ") -> ГОТОВ | R25: =IFERROR(VLOOKUP(P25,Лист1!A$1:B$20,2,FALSE),0) -> 784 | S25: =VALUE(E25) -> 1
A26: 66:52:0107003:606 | B26: Жилой дом | C26: - | E26: 1 | F26: Значение определено ГБУ СО ЦГКО (допущение по среднему значению для года постройки по кад. Кварталу, материалу, назначению по данным на 01.02.2018) | G26: 31.01.2023 | H26: НЕ ГОТОВ | I26: =IFERROR(VLOOKUP(C26,'Справочник соответствий'!A$2:D$2981,2,FALSE),IF(VALUE(C26)=0,1,VLOOKUP(C26,'Справочник соответствий'!A$2:D$2981,2,FALSE))) -> 1 | J26: =IFERROR(VLOOKUP(D26,'Справочник соответствий'!A$2:D$2981,2,FALSE),IF(VALUE(D26)=0,0,VLOOKUP(D26,'Справочник соответствий'!A$2:D$2981,2,FALSE))) -> 0 | K26: =IF(B26="Многоквартирный дом",IF(I26-J26>0,I26-J26,1),I26) -> 1 | L26: =IFERROR(VLOOKUP(C26,'Справочник соответствий'!A$2:D$2981,3,FALSE),IF(VALUE(C26)=0,"ЭТАЖ НЕ ОПРЕДЕЛЕН. ПРИНЯТ ПО ДОПУЩЕНИЮ 1",VLOOKUP(C26,'Справочник соответствий'!A$2:D$2981,3,FALSE))) -> ЭТАЖ НЕ ОПРЕДЕЛЕН. ПРИНЯТ ПО ДОПУЩЕНИЮ 1 | M26: =I26=E26 -> FALSE | N26: =IF(VALUE(E26)=0,VALUE(K26),IF(L26="ЭТАЖ НЕ ОПРЕДЕЛЕН. ПРИНЯТ ПО ДОПУЩЕНИЮ 1",VALUE(E26),VALUE(K26))) -> 1 | O26: =IF(VALUE(E26)=0,L26,IF(L26="ЭТАЖ НЕ ОПРЕДЕЛЕН. ПРИНЯТ ПО ДОПУЩЕНИЮ 1",F26,L26)) -> Значение определено ГБУ СО ЦГКО (допущение по среднему значению для года постройки по кад. Кварталу, материалу, назначению по данным на 01.02.2018) | P26: =IF(B26="Многоквартирный дом",CONCATENATE("МКД_",O26),O26) -> Значение определено ГБУ СО ЦГКО (допущение по среднему значению для года постройки по кад. Кварталу, материалу, назначению по данным на 01.02.2018) | Q26: =IFERROR(IF(N26>0,IF(N26=VALUE(E26),"ГОТОВ","ГОТОВ_ИЗМЕНЕН"),"НЕ ГОТОВ"),"НЕ ГОТОВ") -> ГОТОВ | R26: =IFERROR(VLOOKUP(P26,Лист1!A$1:B$20,2,FALSE),0) -> 214 | S26: =VALUE(E26) -> 1
A27: 66:52:0106011:84 | B27: Жилой дом | C27: 1 | D27: 1 | E27: 1 | F27: Значение определено ГБУ СО ЦГКО (допущение по среднему значению для года постройки по кад. Кварталу, материалу, назначению по данным на 01.02.2018) | G27: 23.12.2022 | H27: НЕ ГОТОВ | I27: =IFERROR(VLOOKUP(C27,'Справочник соответствий'!A$2:D$2981,2,FALSE),IF(VALUE(C27)=0,1,VLOOKUP(C27,'Справочник соответствий'!A$2:D$2981,2,FALSE))) -> 1 | J27: =IFERROR(VLOOKUP(D27,'Справочник соответствий'!A$2:D$2981,2,FALSE),IF(VALUE(D27)=0,0,VLOOKUP(D27,'Справочник соответствий'!A$2:D$2981,2,FALSE))) -> 1 | K27: =IF(B27="Многоквартирный дом",IF(I27-J27>0,I27-J27,1),I27) -> 1 | L27: =IFERROR(VLOOKUP(C27,'Справочник соответствий'!A$2:D$2981,3,FALSE),IF(VALUE(C27)=0,"ЭТАЖ НЕ ОПРЕДЕЛЕН. ПРИНЯТ ПО ДОПУЩЕНИЮ 1",VLOOKUP(C27,'Справочник соответствий'!A$2:D$2981,3,FALSE))) -> ЭТАЖ ЗАДАН ЧИСЛОМ | M27: =I27=E27 -> FALSE | N27: =IF(VALUE(E27)=0,VALUE(K27),IF(L27="ЭТАЖ НЕ ОПРЕДЕЛЕН. ПРИНЯТ ПО ДОПУЩЕНИЮ 1",VALUE(E27),VALUE(K27))) -> 1 | O27: =IF(VALUE(E27)=0,L27,IF(L27="ЭТАЖ НЕ ОПРЕДЕЛЕН. ПРИНЯТ ПО ДОПУЩЕНИЮ 1",F27,L27)) -> ЭТАЖ ЗАДАН ЧИСЛОМ | P27: =IF(B27="Многоквартирный дом",CONCATENATE("МКД_",O27),O27) -> ЭТАЖ ЗАДАН ЧИСЛОМ | Q27: =IFERROR(IF(N27>0,IF(N27=VALUE(E27),"ГОТОВ","ГОТОВ_ИЗМЕНЕН"),"НЕ ГОТОВ"),"НЕ ГОТОВ") -> ГОТОВ | R27: =IFERROR(VLOOKUP(P27,Лист1!A$1:B$20,2,FALSE),0) -> 784 | S27: =VALUE(E27) -> 1
A28: 66:14:1801011:61 | B28: Нежилое здание | C28: 1 | D28: 0 | E28: 1 | F28: Значение определено ГБУ СО ЦГКО (допущение по среднему значению для года постройки по кад. Кварталу, материалу, назначению по данным на 01.02.2018) | G28: 19.01.2023 | H28: НЕ ГОТОВ | I28: =IFERROR(VLOOKUP(C28,'Справочник соответствий'!A$2:D$2981,2,FALSE),IF(VALUE(C28)=0,1,VLOOKUP(C28,'Справочник соответствий'!A$2:D$2981,2,FALSE))) -> 1 | J28: =IFERROR(VLOOKUP(D28,'Справочник соответствий'!A$2:D$2981,2,FALSE),IF(VALUE(D28)=0,0,VLOOKUP(D28,'Справочник соответствий'!A$2:D$2981,2,FALSE))) -> 1 | K28: =IF(B28="Многоквартирный дом",IF(I28-J28>0,I28-J28,1),I28) -> 1 | L28: =IFERROR(VLOOKUP(C28,'Справочник соответствий'!A$2:D$2981,3,FALSE),IF(VALUE(C28)=0,"ЭТАЖ НЕ ОПРЕДЕЛЕН. ПРИНЯТ ПО ДОПУЩЕНИЮ 1",VLOOKUP(C28,'Справочник соответствий'!A$2:D$2981,3,FALSE))) -> ЭТАЖ ЗАДАН ЧИСЛОМ | M28: =I28=E28 -> FALSE | N28: =IF(VALUE(E28)=0,VALUE(K28),IF(L28="ЭТАЖ НЕ ОПРЕДЕЛЕН. ПРИНЯТ ПО ДОПУЩЕНИЮ 1",VALUE(E28),VALUE(K28))) -> 1 | O28: =IF(VALUE(E28)=0,L28,IF(L28="ЭТАЖ НЕ ОПРЕДЕЛЕН. ПРИНЯТ ПО ДОПУЩЕНИЮ 1",F28,L28)) -> ЭТАЖ ЗАДАН ЧИСЛОМ | P28: =IF(B28="Многоквартирный дом",CONCATENATE("МКД_",O28),O28) -> ЭТАЖ ЗАДАН ЧИСЛОМ | Q28: =IFERROR(IF(N28>0,IF(N28=VALUE(E28),"ГОТОВ","ГОТОВ_ИЗМЕНЕН"),"НЕ ГОТОВ"),"НЕ ГОТОВ") -> ГОТОВ | R28: =IFERROR(VLOOKUP(P28,Лист1!A$1:B$20,2,FALSE),0) -> 784 | S28: =VALUE(E28) -> 1
A29: 66:06:0801002:210 | B29: Многоквартирный дом | C29: 2 | E29: 2 | F29: Значение определено ГБУ СО ЦГКО (допущение по среднему значению для года постройки по кад. Кварталу, материалу, назначению по данным на 01.02.2018) | G29: 28.12.2022 | H29: НЕ ГОТОВ | I29: =IFERROR(VLOOKUP(C29,'Справочник соответствий'!A$2:D$2981,2,FALSE),IF(VALUE(C29)=0,1,VLOOKUP(C29,'Справочник соответствий'!A$2:D$2981,2,FALSE))) -> 2 | J29: =IFERROR(VLOOKUP(D29,'Справочник соответствий'!A$2:D$2981,2,FALSE),IF(VALUE(D29)=0,0,VLOOKUP(D29,'Справочник соответствий'!A$2:D$2981,2,FALSE))) -> 0 | K29: =IF(B29="Многоквартирный дом",IF(I29-J29>0,I29-J29,1),I29) -> 2 | L29: =IFERROR(VLOOKUP(C29,'Справочник соответствий'!A$2:D$2981,3,FALSE),IF(VALUE(C29)=0,"ЭТАЖ НЕ ОПРЕДЕЛЕН. ПРИНЯТ ПО ДОПУЩЕНИЮ 1",VLOOKUP(C29,'Справочник соответствий'!A$2:D$2981,3,FALSE))) -> ЭТАЖ ЗАДАН ЧИСЛОМ | M29: =I29=E29 -> FALSE | N29: =IF(VALUE(E29)=0,VALUE(K29),IF(L29="ЭТАЖ НЕ ОПРЕДЕЛЕН. ПРИНЯТ ПО ДОПУЩЕНИЮ 1",VALUE(E29),VALUE(K29))) -> 2 | O29: =IF(VALUE(E29)=0,L29,IF(L29="ЭТАЖ НЕ ОПРЕДЕЛЕН. ПРИНЯТ ПО ДОПУЩЕНИЮ 1",F29,L29)) -> ЭТАЖ ЗАДАН ЧИСЛОМ | P29: =IF(B29="Многоквартирный дом",CONCATENATE("МКД_",O29),O29) -> МКД_ЭТАЖ ЗАДАН ЧИСЛОМ | Q29: =IFERROR(IF(N29>0,IF(N29=VALUE(E29),"ГОТОВ","ГОТОВ_ИЗМЕНЕН"),"НЕ ГОТОВ"),"НЕ ГОТОВ") -> ГОТОВ | R29: =IFERROR(VLOOKUP(P29,Лист1!A$1:B$20,2,FALSE),0) -> 786 | S29: =VALUE(E29) -> 2
A30: 66:06:4501013:3 | B30: Многоквартирный дом | C30: 2 | E30: 2 | F30: Значение определено ГБУ СО ЦГКО (допущение по среднему значению для года постройки по кад. Кварталу, материалу, назначению по данным на 01.02.2018) | G30: 28.12.2022 | H30: НЕ ГОТОВ | I30: =IFERROR(VLOOKUP(C30,'Справочник соответствий'!A$2:D$2981,2,FALSE),IF(VALUE(C30)=0,1,VLOOKUP(C30,'Справочник соответствий'!A$2:D$2981,2,FALSE))) -> 2 | J30: =IFERROR(VLOOKUP(D30,'Справочник соответствий'!A$2:D$2981,2,FALSE),IF(VALUE(D30)=0,0,VLOOKUP(D30,'Справочник соответствий'!A$2:D$2981,2,FALSE))) -> 0 | K30: =IF(B30="Многоквартирный дом",IF(I30-J30>0,I30-J30,1),I30) -> 2 | L30: =IFERROR(VLOOKUP(C30,'Справочник соответствий'!A$2:D$2981,3,FALSE),IF(VALUE(C30)=0,"ЭТАЖ НЕ ОПРЕДЕЛЕН. ПРИНЯТ ПО ДОПУЩЕНИЮ 1",VLOOKUP(C30,'Справочник соответствий'!A$2:D$2981,3,FALSE))) -> ЭТАЖ ЗАДАН ЧИСЛОМ | M30: =I30=E30 -> FALSE | N30: =IF(VALUE(E30)=0,VALUE(K30),IF(L30="ЭТАЖ НЕ ОПРЕДЕЛЕН. ПРИНЯТ ПО ДОПУЩЕНИЮ 1",VALUE(E30),VALUE(K30))) -> 2 | O30: =IF(VALUE(E30)=0,L30,IF(L30="ЭТАЖ НЕ ОПРЕДЕЛЕН. ПРИНЯТ ПО ДОПУЩЕНИЮ 1",F30,L30)) -> ЭТАЖ ЗАДАН ЧИСЛОМ | P30: =IF(B30="Многоквартирный дом",CONCATENATE("МКД_",O30),O30) -> МКД_ЭТАЖ ЗАДАН ЧИСЛОМ | Q30: =IFERROR(IF(N30>0,IF(N30=VALUE(E30),"ГОТОВ","ГОТОВ_ИЗМЕНЕН"),"НЕ ГОТОВ"),"НЕ ГОТОВ") -> ГОТОВ | R30: =IFERROR(VLOOKUP(P30,Лист1!A$1:B$20,2,FALSE),0) -> 786 | S30: =VALUE(E30) -> 2
A31: 66:52:0107006:494 | B31: Жилой дом | E31: 1 | F31: Значение определено ГБУ СО ЦГКО (допущение по среднему значению для года постройки по кад. Кварталу, материалу, назначению по данным на 01.02.2018) | G31: 17.01.2023 | H31: НЕ ГОТОВ | I31: =IFERROR(VLOOKUP(C31,'Справочник соответствий'!A$2:D$2981,2,FALSE),IF(VALUE(C31)=0,1,VLOOKUP(C31,'Справочник соответствий'!A$2:D$2981,2,FALSE))) -> 1 | J31: =IFERROR(VLOOKUP(D31,'Справочник соответствий'!A$2:D$2981,2,FALSE),IF(VALUE(D31)=0,0,VLOOKUP(D31,'Справочник соответствий'!A$2:D$2981,2,FALSE))) -> 0 | K31: =IF(B31="Многоквартирный дом",IF(I31-J31>0,I31-J31,1),I31) -> 1 | L31: =IFERROR(VLOOKUP(C31,'Справочник соответствий'!A$2:D$2981,3,FALSE),IF(VALUE(C31)=0,"ЭТАЖ НЕ ОПРЕДЕЛЕН. ПРИНЯТ ПО ДОПУЩЕНИЮ 1",VLOOKUP(C31,'Справочник соответствий'!A$2:D$2981,3,FALSE))) -> ЭТАЖ НЕ ОПРЕДЕЛЕН. ПРИНЯТ ПО ДОПУЩЕНИЮ 1 | M31: =I31=E31 -> TRUE | N31: =IF(VALUE(E31)=0,VALUE(K31),IF(L31="ЭТАЖ НЕ ОПРЕДЕЛЕН. ПРИНЯТ ПО ДОПУЩЕНИЮ 1",VALUE(E31),VALUE(K31))) -> 1 | O31: =IF(VALUE(E31)=0,L31,IF(L31="ЭТАЖ НЕ ОПРЕДЕЛЕН. ПРИНЯТ ПО ДОПУЩЕНИЮ 1",F31,L31)) -> Значение определено ГБУ СО ЦГКО (допущение по среднему значению для года постройки по кад. Кварталу, материалу, назначению по данным на 01.02.2018) | P31: =IF(B31="Многоквартирный дом",CONCATENATE("МКД_",O31),O31) -> Значение определено ГБУ СО ЦГКО (допущение по среднему значению для года постройки по кад. Кварталу, материалу, назначению по данным на 01.02.2018) | Q31: =IFERROR(IF(N31>0,IF(N31=VALUE(E31),"ГОТОВ","ГОТОВ_ИЗМЕНЕН"),"НЕ ГОТОВ"),"НЕ ГОТОВ") -> ГОТОВ | R31: =IFERROR(VLOOKUP(P31,Лист1!A$1:B$20,2,FALSE),0) -> 214 | S31: =VALUE(E31) -> 1
A32: 66:62:0201001:633 | B32: Нежилое здание | C32: 1 | E32: 1 | F32: Значение определено ГБУ СО ЦГКО (допущение по среднему значению для года постройки по кад. Кварталу, материалу, назначению по данным на 01.02.2018) | G32: 01.02.2023 | H32: НЕ ГОТОВ | I32: =IFERROR(VLOOKUP(C32,'Справочник соответствий'!A$2:D$2981,2,FALSE),IF(VALUE(C32)=0,1,VLOOKUP(C32,'Справочник соответствий'!A$2:D$2981,2,FALSE))) -> 1 | J32: =IFERROR(VLOOKUP(D32,'Справочник соответствий'!A$2:D$2981,2,FALSE),IF(VALUE(D32)=0,0,VLOOKUP(D32,'Справочник соответствий'!A$2:D$2981,2,FALSE))) -> 0 | K32: =IF(B32="Многоквартирный дом",IF(I32-J32>0,I32-J32,1),I32) -> 1 | L32: =IFERROR(VLOOKUP(C32,'Справочник соответствий'!A$2:D$2981,3,FALSE),IF(VALUE(C32)=0,"ЭТАЖ НЕ ОПРЕДЕЛЕН. ПРИНЯТ ПО ДОПУЩЕНИЮ 1",VLOOKUP(C32,'Справочник соответствий'!A$2:D$2981,3,FALSE))) -> ЭТАЖ ЗАДАН ЧИСЛОМ | M32: =I32=E32 -> FALSE | N32: =IF(VALUE(E32)=0,VALUE(K32),IF(L32="ЭТАЖ НЕ ОПРЕДЕЛЕН. ПРИНЯТ ПО ДОПУЩЕНИЮ 1",VALUE(E32),VALUE(K32))) -> 1 | O32: =IF(VALUE(E32)=0,L32,IF(L32="ЭТАЖ НЕ ОПРЕДЕЛЕН. ПРИНЯТ ПО ДОПУЩЕНИЮ 1",F32,L32)) -> ЭТАЖ ЗАДАН ЧИСЛОМ | P32: =IF(B32="Многоквартирный дом",CONCATENATE("МКД_",O32),O32) -> ЭТАЖ ЗАДАН ЧИСЛОМ | Q32: =IFERROR(IF(N32>0,IF(N32=VALUE(E32),"ГОТОВ","ГОТОВ_ИЗМЕНЕН"),"НЕ ГОТОВ"),"НЕ ГОТОВ") -> ГОТОВ | R32: =IFERROR(VLOOKUP(P32,Лист1!A$1:B$20,2,FALSE),0) -> 784 | S32: =VALUE(E32) -> 1
A33: 66:59:0201001:535 | B33: Жилой дом | C33: 2 | E33: 1 | F33: Значение определено ГБУ СО ЦГКО (допущение по среднему значению для года постройки по кад. Кварталу, материалу, назначению по данным на 01.02.2018) | G33: 20.01.2023 | H33: НЕ ГОТОВ | I33: =IFERROR(VLOOKUP(C33,'Справочник соответствий'!A$2:D$2981,2,FALSE),IF(VALUE(C33)=0,1,VLOOKUP(C33,'Справочник соответствий'!A$2:D$2981,2,FALSE))) -> 2 | J33: =IFERROR(VLOOKUP(D33,'Справочник соответствий'!A$2:D$2981,2,FALSE),IF(VALUE(D33)=0,0,VLOOKUP(D33,'Справочник соответствий'!A$2:D$2981,2,FALSE))) -> 0 | K33: =IF(B33="Многоквартирный дом",IF(I33-J33>0,I33-J33,1),I33) -> 2 | L33: =IFERROR(VLOOKUP(C33,'Справочник соответствий'!A$2:D$2981,3,FALSE),IF(VALUE(C33)=0,"ЭТАЖ НЕ ОПРЕДЕЛЕН. ПРИНЯТ ПО ДОПУЩЕНИЮ 1",VLOOKUP(C33,'Справочник соответствий'!A$2:D$2981,3,FALSE))) -> ЭТАЖ ЗАДАН ЧИСЛОМ | M33: =I33=E33 -> FALSE | N33: =IF(VALUE(E33)=0,VALUE(K33),IF(L33="ЭТАЖ НЕ ОПРЕДЕЛЕН. ПРИНЯТ ПО ДОПУЩЕНИЮ 1",VALUE(E33),VALUE(K33))) -> 2 | O33: =IF(VALUE(E33)=0,L33,IF(L33="ЭТАЖ НЕ ОПРЕДЕЛЕН. ПРИНЯТ ПО ДОПУЩЕНИЮ 1",F33,L33)) -> ЭТАЖ ЗАДАН ЧИСЛОМ | P33: =IF(B33="Многоквартирный дом",CONCATENATE("МКД_",O33),O33) -> ЭТАЖ ЗАДАН ЧИСЛОМ | Q33: =IFERROR(IF(N33>0,IF(N33=VALUE(E33),"ГОТОВ","ГОТОВ_ИЗМЕНЕН"),"НЕ ГОТОВ"),"НЕ ГОТОВ") -> ГОТОВ_ИЗМЕНЕН | R33: =IFERROR(VLOOKUP(P33,Лист1!A$1:B$20,2,FALSE),0) -> 784 | S33: =VALUE(E33) -> 1
A34: 66:52:0107004:661 | B34: Жилой дом | C34: 1 | E34: 1 | F34: Значение определено ГБУ СО ЦГКО (допущение по среднему значению для года постройки по кад. Кварталу, материалу, назначению по данным на 01.02.2018) | G34: 17.01.2023 | H34: НЕ ГОТОВ | I34: =IFERROR(VLOOKUP(C34,'Справочник соответствий'!A$2:D$2981,2,FALSE),IF(VALUE(C34)=0,1,VLOOKUP(C34,'Справочник соответствий'!A$2:D$2981,2,FALSE))) -> 1 | J34: =IFERROR(VLOOKUP(D34,'Справочник соответствий'!A$2:D$2981,2,FALSE),IF(VALUE(D34)=0,0,VLOOKUP(D34,'Справочник соответствий'!A$2:D$2981,2,FALSE))) -> 0 | K34: =IF(B34="Многоквартирный дом",IF(I34-J34>0,I34-J34,1),I34) -> 1 | L34: =IFERROR(VLOOKUP(C34,'Справочник соответствий'!A$2:D$2981,3,FALSE),IF(VALUE(C34)=0,"ЭТАЖ НЕ ОПРЕДЕЛЕН. ПРИНЯТ ПО ДОПУЩЕНИЮ 1",VLOOKUP(C34,'Справочник соответствий'!A$2:D$2981,3,FALSE))) -> ЭТАЖ ЗАДАН ЧИСЛОМ | M34: =I34=E34 -> FALSE | N34: =IF(VALUE(E34)=0,VALUE(K34),IF(L34="ЭТАЖ НЕ ОПРЕДЕЛЕН. ПРИНЯТ ПО ДОПУЩЕНИЮ 1",VALUE(E34),VALUE(K34))) -> 1 | O34: =IF(VALUE(E34)=0,L34,IF(L34="ЭТАЖ НЕ ОПРЕДЕЛЕН. ПРИНЯТ ПО ДОПУЩЕНИЮ 1",F34,L34)) -> ЭТАЖ ЗАДАН ЧИСЛОМ | P34: =IF(B34="Многоквартирный дом",CONCATENATE("МКД_",O34),O34) -> ЭТАЖ ЗАДАН ЧИСЛОМ | Q34: =IFERROR(IF(N34>0,IF(N34=VALUE(E34),"ГОТОВ","ГОТОВ_ИЗМЕНЕН"),"НЕ ГОТОВ"),"НЕ ГОТОВ") -> ГОТОВ | R34: =IFERROR(VLOOKUP(P34,Лист1!A$1:B$20,2,FALSE),0) -> 784 | S34: =VALUE(E34) -> 1
A35: 66:52:0107002:895 | B35: Жилой дом | C35: 1 | D35: 0 | E35: 1 | F35: Значение определено ГБУ СО ЦГКО (допущение по среднему значению для года постройки по кад. Кварталу, материалу, назначению по данным на 01.02.2018) | G35: 31.01.2023 | H35: НЕ ГОТОВ | I35: =IFERROR(VLOOKUP(C35,'Справочник соответствий'!A$2:D$2981,2,FALSE),IF(VALUE(C35)=0,1,VLOOKUP(C35,'Справочник соответствий'!A$2:D$2981,2,FALSE))) -> 1 | J35: =IFERROR(VLOOKUP(D35,'Справочник соответствий'!A$2:D$2981,2,FALSE),IF(VALUE(D35)=0,0,VLOOKUP(D35,'Справочник соответствий'!A$2:D$2981,2,FALSE))) -> 1 | K35: =IF(B35="Многоквартирный дом",IF(I35-J35>0,I35-J35,1),I35) -> 1 | L35: =IFERROR(VLOOKUP(C35,'Справочник соответствий'!A$2:D$2981,3,FALSE),IF(VALUE(C35)=0,"ЭТАЖ НЕ ОПРЕДЕЛЕН. ПРИНЯТ ПО ДОПУЩЕНИЮ 1",VLOOKUP(C35,'Справочник соответствий'!A$2:D$2981,3,FALSE))) -> ЭТАЖ ЗАДАН ЧИСЛОМ | M35: =I35=E35 -> FALSE | N35: =IF(VALUE(E35)=0,VALUE(K35),IF(L35="ЭТАЖ НЕ ОПРЕДЕЛЕН. ПРИНЯТ ПО ДОПУЩЕНИЮ 1",VALUE(E35),VALUE(K35))) -> 1 | O35: =IF(VALUE(E35)=0,L35,IF(L35="ЭТАЖ НЕ ОПРЕДЕЛЕН. ПРИНЯТ ПО ДОПУЩЕНИЮ 1",F35,L35)) -> ЭТАЖ ЗАДАН ЧИСЛОМ | P35: =IF(B35="Многоквартирный дом",CONCATENATE("МКД_",O35),O35) -> ЭТАЖ ЗАДАН ЧИСЛОМ | Q35: =IFERROR(IF(N35>0,IF(N35=VALUE(E35),"ГОТОВ","ГОТОВ_ИЗМЕНЕН"),"НЕ ГОТОВ"),"НЕ ГОТОВ") -> ГОТОВ | R35: =IFERROR(VLOOKUP(P35,Лист1!A$1:B$20,2,FALSE),0) -> 784 | S35: =VALUE(E35) -> 1
A36: 66:52:0107004:627 | B36: Жилой дом | C36: 1 | E36: 1 | F36: Значение определено ГБУ СО ЦГКО (допущение по среднему значению для года постройки по кад. Кварталу, материалу, назначению по данным на 01.02.2018) | G36: 17.01.2023 | H36: НЕ ГОТОВ | I36: =IFERROR(VLOOKUP(C36,'Справочник соответствий'!A$2:D$2981,2,FALSE),IF(VALUE(C36)=0,1,VLOOKUP(C36,'Справочник соответствий'!A$2:D$2981,2,FALSE))) -> 1 | J36: =IFERROR(VLOOKUP(D36,'Справочник соответствий'!A$2:D$2981,2,FALSE),IF(VALUE(D36)=0,0,VLOOKUP(D36,'Справочник соответствий'!A$2:D$2981,2,FALSE))) -> 0 | K36: =IF(B36="Многоквартирный дом",IF(I36-J36>0,I36-J36,1),I36) -> 1 | L36: =IFERROR(VLOOKUP(C36,'Справочник соответствий'!A$2:D$2981,3,FALSE),IF(VALUE(C36)=0,"ЭТАЖ НЕ ОПРЕДЕЛЕН. ПРИНЯТ ПО ДОПУЩЕНИЮ 1",VLOOKUP(C36,'Справочник соответствий'!A$2:D$2981,3,FALSE))) -> ЭТАЖ ЗАДАН ЧИСЛОМ | M36: =I36=E36 -> FALSE | N36: =IF(VALUE(E36)=0,VALUE(K36),IF(L36="ЭТАЖ НЕ ОПРЕДЕЛЕН. ПРИНЯТ ПО ДОПУЩЕНИЮ 1",VALUE(E36),VALUE(K36))) -> 1 | O36: =IF(VALUE(E36)=0,L36,IF(L36="ЭТАЖ НЕ ОПРЕДЕЛЕН. ПРИНЯТ ПО ДОПУЩЕНИЮ 1",F36,L36)) -> ЭТАЖ ЗАДАН ЧИСЛОМ | P36: =IF(B36="Многоквартирный дом",CONCATENATE("МКД_",O36),O36) -> ЭТАЖ ЗАДАН ЧИСЛОМ | Q36: =IFERROR(IF(N36>0,IF(N36=VALUE(E36),"ГОТОВ","ГОТОВ_ИЗМЕНЕН"),"НЕ ГОТОВ"),"НЕ ГОТОВ") -> ГОТОВ | R36: =IFERROR(VLOOKUP(P36,Лист1!A$1:B$20,2,FALSE),0) -> 784 | S36: =VALUE(E36) -> 1
A37: 66:04:1401003:282 | B37: Жилой дом | C37: 1 | E37: 1 | F37: Значение определено ГБУ СО ЦГКО (допущение по среднему значению для года постройки по кад. Кварталу, материалу, назначению по данным на 01.02.2018) | G37: 31.01.2023 | H37: НЕ ГОТОВ | I37: =IFERROR(VLOOKUP(C37,'Справочник соответствий'!A$2:D$2981,2,FALSE),IF(VALUE(C37)=0,1,VLOOKUP(C37,'Справочник соответствий'!A$2:D$2981,2,FALSE))) -> 1 | J37: =IFERROR(VLOOKUP(D37,'Справочник соответствий'!A$2:D$2981,2,FALSE),IF(VALUE(D37)=0,0,VLOOKUP(D37,'Справочник соответствий'!A$2:D$2981,2,FALSE))) -> 0 | K37: =IF(B37="Многоквартирный дом",IF(I37-J37>0,I37-J37,1),I37) -> 1 | L37: =IFERROR(VLOOKUP(C37,'Справочник соответствий'!A$2:D$2981,3,FALSE),IF(VALUE(C37)=0,"ЭТАЖ НЕ ОПРЕДЕЛЕН. ПРИНЯТ ПО ДОПУЩЕНИЮ 1",VLOOKUP(C37,'Справочник соответствий'!A$2:D$2981,3,FALSE))) -> ЭТАЖ ЗАДАН ЧИСЛОМ | M37: =I37=E37 -> FALSE | N37: =IF(VALUE(E37)=0,VALUE(K37),IF(L37="ЭТАЖ НЕ ОПРЕДЕЛЕН. ПРИНЯТ ПО ДОПУЩЕНИЮ 1",VALUE(E37),VALUE(K37))) -> 1 | O37: =IF(VALUE(E37)=0,L37,IF(L37="ЭТАЖ НЕ ОПРЕДЕЛЕН. ПРИНЯТ ПО ДОПУЩЕНИЮ 1",F37,L37)) -> ЭТАЖ ЗАДАН ЧИСЛОМ | P37: =IF(B37="Многоквартирный дом",CONCATENATE("МКД_",O37),O37) -> ЭТАЖ ЗАДАН ЧИСЛОМ | Q37: =IFERROR(IF(N37>0,IF(N37=VALUE(E37),"ГОТОВ","ГОТОВ_ИЗМЕНЕН"),"НЕ ГОТОВ"),"НЕ ГОТОВ") -> ГОТОВ | R37: =IFERROR(VLOOKUP(P37,Лист1!A$1:B$20,2,FALSE),0) -> 784 | S37: =VALUE(E37) -> 1
A38: 66:02:1701001:1222 | B38: Нежилое здание | C38: 1 | E38: 1 | F38: Значение определено ГБУ СО ЦГКО (допущение по среднему значению для года постройки по кад. Кварталу, материалу, назначению по данным на 01.02.2018) | G38: 21.12.2022 | H38: НЕ ГОТОВ | I38: =IFERROR(VLOOKUP(C38,'Справочник соответствий'!A$2:D$2981,2,FALSE),IF(VALUE(C38)=0,1,VLOOKUP(C38,'Справочник соответствий'!A$2:D$2981,2,FALSE))) -> 1 | J38: =IFERROR(VLOOKUP(D38,'Справочник соответствий'!A$2:D$2981,2,FALSE),IF(VALUE(D38)=0,0,VLOOKUP(D38,'Справочник соответствий'!A$2:D$2981,2,FALSE))) -> 0 | K38: =IF(B38="Многоквартирный дом",IF(I38-J38>0,I38-J38,1),I38) -> 1 | L38: =IFERROR(VLOOKUP(C38,'Справочник соответствий'!A$2:D$2981,3,FALSE),IF(VALUE(C38)=0,"ЭТАЖ НЕ ОПРЕДЕЛЕН. ПРИНЯТ ПО ДОПУЩЕНИЮ 1",VLOOKUP(C38,'Справочник соответствий'!A$2:D$2981,3,FALSE))) -> ЭТАЖ ЗАДАН ЧИСЛОМ | M38: =I38=E38 -> FALSE | N38: =IF(VALUE(E38)=0,VALUE(K38),IF(L38="ЭТАЖ НЕ ОПРЕДЕЛЕН. ПРИНЯТ ПО ДОПУЩЕНИЮ 1",VALUE(E38),VALUE(K38))) -> 1 | O38: =IF(VALUE(E38)=0,L38,IF(L38="ЭТАЖ НЕ ОПРЕДЕЛЕН. ПРИНЯТ ПО ДОПУЩЕНИЮ 1",F38,L38)) -> ЭТАЖ ЗАДАН ЧИСЛОМ | P38: =IF(B38="Многоквартирный дом",CONCATENATE("МКД_",O38),O38) -> ЭТАЖ ЗАДАН ЧИСЛОМ | Q38: =IFERROR(IF(N38>0,IF(N38=VALUE(E38),"ГОТОВ","ГОТОВ_ИЗМЕНЕН"),"НЕ ГОТОВ"),"НЕ ГОТОВ") -> ГОТОВ | R38: =IFERROR(VLOOKUP(P38,Лист1!A$1:B$20,2,FALSE),0) -> 784 | S38: =VALUE(E38) -> 1
A39: 66:01:3601001:319 | B39: Жилой дом | C39: 1 | E39: 1 | F39: Значение определено ГБУ СО ЦГКО (допущение по среднему значению для года постройки по кад. Кварталу, материалу, назначению по данным на 01.02.2018) | G39: 26.12.2022 | H39: НЕ ГОТОВ | I39: =IFERROR(VLOOKUP(C39,'Справочник соответствий'!A$2:D$2981,2,FALSE),IF(VALUE(C39)=0,1,VLOOKUP(C39,'Справочник соответствий'!A$2:D$2981,2,FALSE))) -> 1 | J39: =IFERROR(VLOOKUP(D39,'Справочник соответствий'!A$2:D$2981,2,FALSE),IF(VALUE(D39)=0,0,VLOOKUP(D39,'Справочник соответствий'!A$2:D$2981,2,FALSE))) -> 0 | K39: =IF(B39="Многоквартирный дом",IF(I39-J39>0,I39-J39,1),I39) -> 1 | L39: =IFERROR(VLOOKUP(C39,'Справочник соответствий'!A$2:D$2981,3,FALSE),IF(VALUE(C39)=0,"ЭТАЖ НЕ ОПРЕДЕЛЕН. ПРИНЯТ ПО ДОПУЩЕНИЮ 1",VLOOKUP(C39,'Справочник соответствий'!A$2:D$2981,3,FALSE))) -> ЭТАЖ ЗАДАН ЧИСЛОМ | M39: =I39=E39 -> FALSE | N39: =IF(VALUE(E39)=0,VALUE(K39),IF(L39="ЭТАЖ НЕ ОПРЕДЕЛЕН. ПРИНЯТ ПО ДОПУЩЕНИЮ 1",VALUE(E39),VALUE(K39))) -> 1 | O39: =IF(VALUE(E39)=0,L39,IF(L39="ЭТАЖ НЕ ОПРЕДЕЛЕН. ПРИНЯТ ПО ДОПУЩЕНИЮ 1",F39,L39)) -> ЭТАЖ ЗАДАН ЧИСЛОМ | P39: =IF(B39="Многоквартирный дом",CONCATENATE("МКД_",O39),O39) -> ЭТАЖ ЗАДАН ЧИСЛОМ | Q39: =IFERROR(IF(N39>0,IF(N39=VALUE(E39),"ГОТОВ","ГОТОВ_ИЗМЕНЕН"),"НЕ ГОТОВ"),"НЕ ГОТОВ") -> ГОТОВ | R39: =IFERROR(VLOOKUP(P39,Лист1!A$1:B$20,2,FALSE),0) -> 784 | S39: =VALUE(E39) -> 1
A40: 66:19:0000000:7875 | B40: Нежилое здание | C40: 1 | E40: 1 | F40: Значение определено ГБУ СО ЦГКО (допущение по среднему значению для года постройки по кад. Кварталу, материалу, назначению по данным на 01.02.2018) | G40: 17.02.2023 | H40: НЕ ГОТОВ | I40: =IFERROR(VLOOKUP(C40,'Справочник соответствий'!A$2:D$2981,2,FALSE),IF(VALUE(C40)=0,1,VLOOKUP(C40,'Справочник соответствий'!A$2:D$2981,2,FALSE))) -> 1 | J40: =IFERROR(VLOOKUP(D40,'Справочник соответствий'!A$2:D$2981,2,FALSE),IF(VALUE(D40)=0,0,VLOOKUP(D40,'Справочник соответствий'!A$2:D$2981,2,FALSE))) -> 0 | K40: =IF(B40="Многоквартирный дом",IF(I40-J40>0,I40-J40,1),I40) -> 1 | L40: =IFERROR(VLOOKUP(C40,'Справочник соответствий'!A$2:D$2981,3,FALSE),IF(VALUE(C40)=0,"ЭТАЖ НЕ ОПРЕДЕЛЕН. ПРИНЯТ ПО ДОПУЩЕНИЮ 1",VLOOKUP(C40,'Справочник соответствий'!A$2:D$2981,3,FALSE))) -> ЭТАЖ ЗАДАН ЧИСЛОМ | M40: =I40=E40 -> FALSE | N40: =IF(VALUE(E40)=0,VALUE(K40),IF(L40="ЭТАЖ НЕ ОПРЕДЕЛЕН. ПРИНЯТ ПО ДОПУЩЕНИЮ 1",VALUE(E40),VALUE(K40))) -> 1 | O40: =IF(VALUE(E40)=0,L40,IF(L40="ЭТАЖ НЕ ОПРЕДЕЛЕН. ПРИНЯТ ПО ДОПУЩЕНИЮ 1",F40,L40)) -> ЭТАЖ ЗАДАН ЧИСЛОМ | P40: =IF(B40="Многоквартирный дом",CONCATENATE("МКД_",O40),O40) -> ЭТАЖ ЗАДАН ЧИСЛОМ | Q40: =IFERROR(IF(N40>0,IF(N40=VALUE(E40),"ГОТОВ","ГОТОВ_ИЗМЕНЕН"),"НЕ ГОТОВ"),"НЕ ГОТОВ") -> ГОТОВ | R40: =IFERROR(VLOOKUP(P40,Лист1!A$1:B$20,2,FALSE),0) -> 784 | S40: =VALUE(E40) -> 1
...

Sheet Лист1
A1: ЭТАЖ ЗАДАН ЧИСЛОМ | B1: 784
A2: СПРАВОЧНИК ЭТАЖНОСТИ | B2: 785
A3: МКД_ЭТАЖ ЗАДАН ЧИСЛОМ | B3: 786
A4: МКД_СПРАВОЧНИК ЭТАЖНОСТИ | B4: 787
A5: Значение определено ГБУ СО ЦГКО(среднее значение по кад кварталу, назначению, материалу) | B5: 214
A6: ЭТАЖ НЕ ОПРЕДЕЛЕН. ПРИНЯТ ПО ДОПУЩЕНИЮ 1 | B6: 788
A7: МКД_ЭТАЖ НЕ ОПРЕДЕЛЕН. ПРИНЯТ ПО ДОПУЩЕНИЮ 1 | B7: 788
A8: Значение определено ГБУ СО ЦГКО (допущение по среднему значению для года постройки по кад. Кварталу, материалу, назначению по данным на 01.02.2018) | B8: 214

Sheet Справочник соответствий
A1: Этажность | B1: locFloor | C1: МЕТОД
A2: 1 | B2: 1 | C2: ЭТАЖ ЗАДАН ЧИСЛОМ
A3: 2 | B3: 2 | C3: ЭТАЖ ЗАДАН ЧИСЛОМ
A4: 3 | B4: 3 | C4: ЭТАЖ ЗАДАН ЧИСЛОМ
A5: 4 | B5: 4 | C5: ЭТАЖ ЗАДАН ЧИСЛОМ
A6: 5 | B6: 5 | C6: ЭТАЖ ЗАДАН ЧИСЛОМ
A7: 6 | B7: 6 | C7: ЭТАЖ ЗАДАН ЧИСЛОМ
A8: 7 | B8: 7 | C8: ЭТАЖ ЗАДАН ЧИСЛОМ
A9: 8 | B9: 8 | C9: ЭТАЖ ЗАДАН ЧИСЛОМ
A10: 9 | B10: 9 | C10: ЭТАЖ ЗАДАН ЧИСЛОМ
A11: 10 | B11: 10 | C11: ЭТАЖ ЗАДАН ЧИСЛОМ
A12: 11 | B12: 11 | C12: ЭТАЖ ЗАДАН ЧИСЛОМ
... A1018: 0-1-2 | B1018: 2 | C1018: СПРАВОЧНИК ЭТАЖНОСТИ
