Workbook

Sheet Здания
A1: Идентификатор | B1: Кадастровый номер | C1: Материал стен в расчет | D1: Источник Материал стен в расчет | E1: Флаг Материал стен в расчет | F1: Статус расчета КС | G1: Материал стен физ. | H1: Материал стен код | I1: locMaterial | J1: SourcelocMaterial1 | K1: SourcelocMaterial | L1: FlaglocMaterial | M1: OldlocMaterial
A2: ID | B2: CADASTRALNUMBER | C2: LOCMATERIAL | D2: SOURCELOCMATERIAL | E2: FLAGLOCMATERIAL | F2: STATUS_KC | G2: BUILDINGCONSTRUCTMATERIALFIZ | H2: BuildingConstructMaterialCode
A3: Buildings | B3: Buildings | C3: Buildings | D3: Buildings | E3: Buildings | F3: Buildings | G3: Buildings | H3: BuildingConstructMaterial
A4: 8060 | B4: 66:34:0502034:353 | C4: 61001005000 | D4: Сведения ЕГРН по состоянию на 01.01.2019 | E4: не готов | F4: НЕ ГОТОВ | G4: Деревянные | H4: 61001002000 | I4: =IF(LEN(H4)=11,H4,IF(LEN(H4)=0,"61001005000","61001003000")) -> 61001002000 | J4: =IF(LEN(H4)=11,"Материал по ЕГРН",IF(LEN(H4)=0,"Прочие по допущению","Смешанные по допущению")) -> Материал по ЕГРН | K4: =VLOOKUP(J4,Лист2!A$2:B$4,2,FALSE) -> 792 | L4: =IF(I4=C4,"ГОТОВ","ГОТОВ_ИЗМЕНЕН") -> ГОТОВ_ИЗМЕНЕН | M4: =C4 -> 61001005000
A5: 381226 | B5: 66:52:0108001:417 | C5: 61001005000 | D5: Сведения ЕГРН по состоянию на 01.01.2019 | E5: ГОТОВ | F5: НЕ ГОТОВ | G5: Из прочих материалов | H5: 61001005000 | I5: =IF(LEN(H5)=11,H5,IF(LEN(H5)=0,"61001005000","61001003000")) -> 61001005000 | J5: =IF(LEN(H5)=11,"Материал по ЕГРН",IF(LEN(H5)=0,"Прочие по допущению","Смешанные по допущению")) -> Материал по ЕГРН | K5: =VLOOKUP(J5,Лист2!A$2:B$4,2,FALSE) -> 792 | L5: =IF(I5=C5,"ГОТОВ","ГОТОВ_ИЗМЕНЕН") -> ГОТОВ | M5: =C5 -> 61001005000
A6: 515719 | B6: 66:52:0107003:524 | C6: 61001005000 | D6: Сведения ЕГРН по состоянию на 01.01.2019 | E6: ГОТОВ | F6: НЕ ГОТОВ | G6: Из прочих материалов | H6: 61001005000 | I6: =IF(LEN(H6)=11,H6,IF(LEN(H6)=0,"61001005000","61001003000")) -> 61001005000 | J6: =IF(LEN(H6)=11,"Материал по ЕГРН",IF(LEN(H6)=0,"Прочие по допущению","Смешанные по допущению")) -> Материал по ЕГРН | K6: =VLOOKUP(J6,Лист2!A$2:B$4,2,FALSE) -> 792 | L6: =IF(I6=C6,"ГОТОВ","ГОТОВ_ИЗМЕНЕН") -> ГОТОВ | M6: =C6 -> 61001005000
A7: 524391 | B7: 66:36:1301009:153 | C7: 61001005000 | D7: Сведения ЕГРН по состоянию на 01.01.2019 | E7: ГОТОВ | F7: НЕ ГОТОВ | G7: Из прочих материалов | H7: 61001005000 | I7: =IF(LEN(H7)=11,H7,IF(LEN(H7)=0,"61001005000","61001003000")) -> 61001005000 | J7: =IF(LEN(H7)=11,"Материал по ЕГРН",IF(LEN(H7)=0,"Прочие по допущению","Смешанные по допущению")) -> Материал по ЕГРН | K7: =VLOOKUP(J7,Лист2!A$2:B$4,2,FALSE) -> 792 | L7: =IF(I7=C7,"ГОТОВ","ГОТОВ_ИЗМЕНЕН") -> ГОТОВ | M7: =C7 -> 61001005000
A8: 534275 | B8: 66:52:0107001:265 | C8: 61001002001 | D8: Сведения ЕГРН по состоянию на 01.01.2019 | E8: ГОТОВ | F8: НЕ ГОТОВ | G8: Рубленые | H8: 61001002001 | I8: =IF(LEN(H8)=11,H8,IF(LEN(H8)=0,"61001005000","61001003000")) -> 61001002001 | J8: =IF(LEN(H8)=11,"Материал по ЕГРН",IF(LEN(H8)=0,"Прочие по допущению","Смешанные по допущению")) -> Материал по ЕГРН | K8: =VLOOKUP(J8,Лист2!A$2:B$4,2,FALSE) -> 792 | L8: =IF(I8=C8,"ГОТОВ","ГОТОВ_ИЗМЕНЕН") -> ГОТОВ | M8: =C8 -> 61001002001
A9: 765457 | B9: 66:28:2601001:274 | C9: 61001002001 | D9: Сведения ЕГРН по состоянию на 01.01.2019 | E9: ГОТОВ | F9: НЕ ГОТОВ | G9: Рубленые | H9: 61001002001 | I9: =IF(LEN(H9)=11,H9,IF(LEN(H9)=0,"61001005000","61001003000")) -> 61001002001 | J9: =IF(LEN(H9)=11,"Материал по ЕГРН",IF(LEN(H9)=0,"Прочие по допущению","Смешанные по допущению")) -> Материал по ЕГРН | K9: =VLOOKUP(J9,Лист2!A$2:B$4,2,FALSE) -> 792 | L9: =IF(I9=C9,"ГОТОВ","ГОТОВ_ИЗМЕНЕН") -> ГОТОВ | M9: =C9 -> 61001002001
A10: 241026 | B10: 66:19:0000000:7875 | C10: 61001005000 | D10: Сведения ЕГРН по состоянию на 01.01.2019 | E10: ГОТОВ | F10: НЕ ГОТОВ | G10: Из прочих материалов | H10: 61001005000 | I10: =IF(LEN(H10)=11,H10,IF(LEN(H10)=0,"61001005000","61001003000")) -> 61001005000 | J10: =IF(LEN(H10)=11,"Материал по ЕГРН",IF(LEN(H10)=0,"Прочие по допущению","Смешанные по допущению")) -> Материал по ЕГРН | K10: =VLOOKUP(J10,Лист2!A$2:B$4,2,FALSE) -> 792 | L10: =IF(I10=C10,"ГОТОВ","ГОТОВ_ИЗМЕНЕН") -> ГОТОВ | M10: =C10 -> 61001005000
A11: 340002 | B11: 66:59:0101005:1511 | C11: 61001005000 | D11: Сведения ЕГРН по состоянию на 01.01.2019 | E11: ГОТОВ | F11: НЕ ГОТОВ | G11: Из прочих материалов | H11: 61001005000 | I11: =IF(LEN(H11)=11,H11,IF(LEN(H11)=0,"61001005000","61001003000")) -> 61001005000 | J11: =IF(LEN(H11)=11,"Материал по ЕГРН",IF(LEN(H11)=0,"Прочие по допущению","Смешанные по допущению")) -> Материал по ЕГРН | K11: =VLOOKUP(J11,Лист2!A$2:B$4,2,FALSE) -> 792 | L11: =IF(I11=C11,"ГОТОВ","ГОТОВ_ИЗМЕНЕН") -> ГОТОВ | M11: =C11 -> 61001005000
A12: 591885 | B12: 66:52:0106012:227 | C12: 61001005000 | D12: Сведения ЕГРН по состоянию на 01.01.2019 | E12: ГОТОВ | F12: НЕ ГОТОВ | G12: Из прочих материалов | H12: 61001005000 | I12: =IF(LEN(H12)=11,H12,IF(LEN(H12)=0,"61001005000","61001003000")) -> 61001005000 | J12: =IF(LEN(H12)=11,"Материал по ЕГРН",IF(LEN(H12)=0,"Прочие по допущению","Смешанные по допущению")) -> Материал по ЕГРН | K12: =VLOOKUP(J12,Лист2!A$2:B$4,2,FALSE) -> 792 | L12: =IF(I12=C12,"ГОТОВ","ГОТОВ_ИЗМЕНЕН") -> ГОТОВ | M12: =C12 -> 61001005000
A13: 120134 | B13: 66:01:3601001:324 | C13: 61001002001 | D13: Сведения ЕГРН по состоянию на 01.01.2019 | E13: ГОТОВ | F13: НЕ ГОТОВ | G13: Рубленые | H13: 61001002001 | I13: =IF(LEN(H13)=11,H13,IF(LEN(H13)=0,"61001005000","61001003000")) -> 61001002001 | J13: =IF(LEN(H13)=11,"Материал по ЕГРН",IF(LEN(H13)=0,"Прочие по допущению","Смешанные по допущению")) -> Материал по ЕГРН | K13: =VLOOKUP(J13,Лист2!A$2:B$4,2,FALSE) -> 792 | L13: =IF(I13=C13,"ГОТОВ","ГОТОВ_ИЗМЕНЕН") -> ГОТОВ | M13: =C13 -> 61001002001
A14: 313806 | B14: 66:52:0106012:241 | C14: 61001005000 | D14: Сведения ЕГРН по состоянию на 01.01.2019 | E14: ГОТОВ | F14: НЕ ГОТОВ | G14: Из прочих материалов | H14: 61001005000 | I14: =IF(LEN(H14)=11,H14,IF(LEN(H14)=0,"61001005000","61001003000")) -> 61001005000 | J14: =IF(LEN(H14)=11,"Материал по ЕГРН",IF(LEN(H14)=0,"Прочие по допущению","Смешанные по допущению")) -> Материал по ЕГРН | K14: =VLOOKUP(J14,Лист2!A$2:B$4,2,FALSE) -> 792 | L14: =IF(I14=C14,"ГОТОВ","ГОТОВ_ИЗМЕНЕН") -> ГОТОВ | M14: =C14 -> 61001005000
A15: 779263 | B15: 66:41:0000000:66521 | C15: 61001005000 | D15: Сведения ЕГРН по состоянию на 01.01.2019 | E15: ГОТОВ | F15: НЕ ГОТОВ | G15: Из прочих материалов | H15: 61001005000 | I15: =IF(LEN(H15)=11,H15,IF(LEN(H15)=0,"61001005000","61001003000")) -> 61001005000 | J15: =IF(LEN(H15)=11,"Материал по ЕГРН",IF(LEN(H15)=0,"Прочие по допущению","Смешанные по допущению")) -> Материал по ЕГРН | K15: =VLOOKUP(J15,Лист2!A$2:B$4,2,FALSE) -> 792 | L15: =IF(I15=C15,"ГОТОВ","ГОТОВ_ИЗМЕНЕН") -> ГОТОВ | M15: =C15 -> 61001005000
A16: 787666 | B16: 66:50:0000000:5162 | C16: 61001005000 | D16: Сведения ЕГРН по состоянию на 01.01.2019 | E16: ГОТОВ | F16: НЕ ГОТОВ | G16: Из прочих материалов | H16: 61001005000 | I16: =IF(LEN(H16)=11,H16,IF(LEN(H16)=0,"61001005000","61001003000")) -> 61001005000 | J16: =IF(LEN(H16)=11,"Материал по ЕГРН",IF(LEN(H16)=0,"Прочие по допущению","Смешанные по допущению")) -> Материал по ЕГРН | K16: =VLOOKUP(J16,Лист2!A$2:B$4,2,FALSE) -> 792 | L16: =IF(I16=C16,"ГОТОВ","ГОТОВ_ИЗМЕНЕН") -> ГОТОВ | M16: =C16 -> 61001005000
A17: 943420 | B17: 66:25:2721002:4559 | F17: НЕ ГОТОВ | G17: Смешанные | H17: 61001003000 | I17: =IF(LEN(H17)=11,H17,IF(LEN(H17)=0,"61001005000","61001003000")) -> 61001003000 | J17: =IF(LEN(H17)=11,"Материал по ЕГРН",IF(LEN(H17)=0,"Прочие по допущению","Смешанные по допущению")) -> Материал по ЕГРН | K17: =VLOOKUP(J17,Лист2!A$2:B$4,2,FALSE) -> 792 | L17: =IF(I17=C17,"ГОТОВ","ГОТОВ_ИЗМЕНЕН") -> ГОТОВ_ИЗМЕНЕН | M17: =C17 -> 0
A18: 943432 | B18: 66:04:0501004:333 | F18: НЕ ГОТОВ | G18: Рубленые | H18: 61001002001 | I18: =IF(LEN(H18)=11,H18,IF(LEN(H18)=0,"61001005000","61001003000")) -> 61001002001 | J18: =IF(LEN(H18)=11,"Материал по ЕГРН",IF(LEN(H18)=0,"Прочие по допущению","Смешанные по допущению")) -> Материал по ЕГРН | K18: =VLOOKUP(J18,Лист2!A$2:B$4,2,FALSE) -> 792 | L18: =IF(I18=C18,"ГОТОВ","ГОТОВ_ИЗМЕНЕН") -> ГОТОВ_ИЗМЕНЕН | M18: =C18 -> 0
A19: 943444 | B19: 66:12:4801003:1405 | F19: НЕ ГОТОВ | G19: Из прочих материалов | H19: 61001005000 | I19: =IF(LEN(H19)=11,H19,IF(LEN(H19)=0,"61001005000","61001003000")) -> 61001005000 | J19: =IF(LEN(H19)=11,"Материал по ЕГРН",IF(LEN(H19)=0,"Прочие по допущению","Смешанные по допущению")) -> Материал по ЕГРН | K19: =VLOOKUP(J19,Лист2!A$2:B$4,2,FALSE) -> 792 | L19: =IF(I19=C19,"ГОТОВ","ГОТОВ_ИЗМЕНЕН") -> ГОТОВ_ИЗМЕНЕН | M19: =C19 -> 0
A20: 943456 | B20: 66:25:1201010:877 | F20: НЕ ГОТОВ | G20: Деревянные | H20: 61001002000 | I20: =IF(LEN(H20)=11,H20,IF(LEN(H20)=0,"61001005000","61001003000")) -> 61001002000 | J20: =IF(LEN(H20)=11,"Материал по ЕГРН",IF(LEN(H20)=0,"Прочие по допущению","Смешанные по допущению")) -> Материал по ЕГРН | K20: =VLOOKUP(J20,Лист2!A$2:B$4,2,FALSE) -> 792 | L20: =IF(I20=C20,"ГОТОВ","ГОТОВ_ИЗМЕНЕН") -> ГОТОВ_ИЗМЕНЕН | M20: =C20 -> 0
A21: 943468 | B21: 66:25:4201002:318 | F21: НЕ ГОТОВ | G21: Деревянные | H21: 61001002000 | I21: =IF(LEN(H21)=11,H21,IF(LEN(H21)=0,"61001005000","61001003000")) -> 61001002000 | J21: =IF(LEN(H21)=11,"Материал по ЕГРН",IF(LEN(H21)=0,"Прочие по допущению","Смешанные по допущению")) -> Материал по ЕГРН | K21: =VLOOKUP(J21,Лист2!A$2:B$4,2,FALSE) -> 792 | L21: =IF(I21=C21,"ГОТОВ","ГОТОВ_ИЗМЕНЕН") -> ГОТОВ_ИЗМЕНЕН | M21: =C21 -> 0
A22: 943480 | B22: 66:41:0614066:4363 | F22: НЕ ГОТОВ | G22: Смешанные | H22: 61001003000 | I22: =IF(LEN(H22)=11,H22,IF(LEN(H22)=0,"61001005000","61001003000")) -> 61001003000 | J22: =IF(LEN(H22)=11,"Материал по ЕГРН",IF(LEN(H22)=0,"Прочие по допущению","Смешанные по допущению")) -> Материал по ЕГРН | K22: =VLOOKUP(J22,Лист2!A$2:B$4,2,FALSE) -> 792 | L22: =IF(I22=C22,"ГОТОВ","ГОТОВ_ИЗМЕНЕН") -> ГОТОВ_ИЗМЕНЕН | M22: =C22 -> 0
A23: 943492 | B23: 66:57:0102072:530 | F23: НЕ ГОТОВ | G23: Кирпичные | H23: 61001001001 | I23: =IF(LEN(H23)=11,H23,IF(LEN(H23)=0,"61001005000","61001003000")) -> 61001001001 | J23: =IF(LEN(H23)=11,"Материал по ЕГРН",IF(LEN(H23)=0,"Прочие по допущению","Смешанные по допущению")) -> Материал по ЕГРН | K23: =VLOOKUP(J23,Лист2!A$2:B$4,2,FALSE) -> 792 | L23: =IF(I23=C23,"ГОТОВ","ГОТОВ_ИЗМЕНЕН") -> ГОТОВ_ИЗМЕНЕН | M23: =C23 -> 0
A24: 943504 | B24: 66:65:0301029:638 | F24: НЕ ГОТОВ | G24: Из мелких бетонных блоков | H24: 61001006002 | I24: =IF(LEN(H24)=11,H24,IF(LEN(H24)=0,"61001005000","61001003000")) -> 61001006002 | J24: =IF(LEN(H24)=11,"Материал по ЕГРН",IF(LEN(H24)=0,"Прочие по допущению","Смешанные по допущению")) -> Материал по ЕГРН | K24: =VLOOKUP(J24,Лист2!A$2:B$4,2,FALSE) -> 792 | L24: =IF(I24=C24,"ГОТОВ","ГОТОВ_ИЗМЕНЕН") -> ГОТОВ_ИЗМЕНЕН | M24: =C24 -> 0
A25: 943516 | B25: 66:17:0801004:427 | F25: НЕ ГОТОВ | G25: Каркасно-обшивные | H25: 61001002003 | I25: =IF(LEN(H25)=11,H25,IF(LEN(H25)=0,"61001005000","61001003000")) -> 61001002003 | J25: =IF(LEN(H25)=11,"Материал по ЕГРН",IF(LEN(H25)=0,"Прочие по допущению","Смешанные по допущению")) -> Материал по ЕГРН | K25: =VLOOKUP(J25,Лист2!A$2:B$4,2,FALSE) -> 792 | L25: =IF(I25=C25,"ГОТОВ","ГОТОВ_ИЗМЕНЕН") -> ГОТОВ_ИЗМЕНЕН | M25: =C25 -> 0
A26: 943528 | B26: 66:59:0209001:1551 | F26: НЕ ГОТОВ | G26: Из прочих материалов | H26: 61001005000 | I26: =IF(LEN(H26)=11,H26,IF(LEN(H26)=0,"61001005000","61001003000")) -> 61001005000 | J26: =IF(LEN(H26)=11,"Материал по ЕГРН",IF(LEN(H26)=0,"Прочие по допущению","Смешанные по допущению")) -> Материал по ЕГРН | K26: =VLOOKUP(J26,Лист2!A$2:B$4,2,FALSE) -> 792 | L26: =IF(I26=C26,"ГОТОВ","ГОТОВ_ИЗМЕНЕН") -> ГОТОВ_ИЗМЕНЕН | M26: =C26 -> 0
A27: 943540 | B27: 66:25:1201015:315 | F27: НЕ ГОТОВ | G27: Смешанные | H27: 61001003000 | I27: =IF(LEN(H27)=11,H27,IF(LEN(H27)=0,"61001005000","61001003000")) -> 61001003000 | J27: =IF(LEN(H27)=11,"Материал по ЕГРН",IF(LEN(H27)=0,"Прочие по допущению","Смешанные по допущению")) -> Материал по ЕГРН | K27: =VLOOKUP(J27,Лист2!A$2:B$4,2,FALSE) -> 792 | L27: =IF(I27=C27,"ГОТОВ","ГОТОВ_ИЗМЕНЕН") -> ГОТОВ_ИЗМЕНЕН | M27: =C27 -> 0
A28: 943552 | B28: 66:45:0200005:323 | F28: НЕ ГОТОВ | G28: Из прочих материалов | H28: 61001005000 | I28: =IF(LEN(H28)=11,H28,IF(LEN(H28)=0,"61001005000","61001003000")) -> 61001005000 | J28: =IF(LEN(H28)=11,"Материал по ЕГРН",IF(LEN(H28)=0,"Прочие по допущению","Смешанные по допущению")) -> Материал по ЕГРН | K28: =VLOOKUP(J28,Лист2!A$2:B$4,2,FALSE) -> 792 | L28: =IF(I28=C28,"ГОТОВ","ГОТОВ_ИЗМЕНЕН") -> ГОТОВ_ИЗМЕНЕН | M28: =C28 -> 0
... A33: 943612 | B33: 66:45:0200008:569 | F33: НЕ ГОТОВ | G33: Кирпичные | H33: 61001001001 | I33: =IF(LEN(H33)=11,H33,IF(LEN(H33)=0,"61001005000","61001003000")) -> 61001001001 | J33: =IF(LEN(H33)=11,"Материал по ЕГРН",IF(LEN(H33)=0,"Прочие по допущению","Смешанные по допущению")) -> Материал по ЕГРН | K33: =VLOOKUP(J33,Лист2!A$2:B$4,2,FALSE) -> 792 | L33: =IF(I33=C33,"ГОТОВ","ГОТОВ_ИЗМЕНЕН") -> ГОТОВ_ИЗМЕНЕН | M33: =C33 -> 0
A34: 219371 | B34: 66:42:0000000:1256 | C34: 61001005000 | D34: Сведения ЕГРН по состоянию на 01.01.2019 | E34: ГОТОВ | F34: НЕ ГОТОВ | G34: Из прочих материалов | H34: 61001005000 | I34: =IF(LEN(H34)=11,H34,IF(LEN(H34)=0,"61001005000","61001003000")) -> 61001005000 | J34: =IF(LEN(H34)=11,"Материал по ЕГРН",IF(LEN(H34)=0,"Прочие по допущению","Смешанные по допущению")) -> Материал по ЕГРН | K34: =VLOOKUP(J34,Лист2!A$2:B$4,2,FALSE) -> 792 | L34: =IF(I34=C34,"ГОТОВ","ГОТОВ_ИЗМЕНЕН") -> ГОТОВ | M34: =C34 -> 61001005000
A35: 453175 | B35: 66:52:0108001:424 | C35: 61001005000 | D35: Сведения ЕГРН по состоянию на 01.01.2019 | E35: ГОТОВ | F35: НЕ ГОТОВ | G35: Из прочих материалов | H35: 61001005000 | I35: =IF(LEN(H35)=11,H35,IF(LEN(H35)=0,"61001005000","61001003000")) -> 61001005000 | J35: =IF(LEN(H35)=11,"Материал по ЕГРН",IF(LEN(H35)=0,"Прочие по допущению","Смешанные по допущению")) -> Материал по ЕГРН | K35: =VLOOKUP(J35,Лист2!A$2:B$4,2,FALSE) -> 792 | L35: =IF(I35=C35,"ГОТОВ","ГОТОВ_ИЗМЕНЕН") -> ГОТОВ | M35: =C35 -> 61001005000
A36: 520897 | B36: 66:52:0107004:616 | C36: 61001005000 | D36: Сведения ЕГРН по состоянию на 01.01.2019 | E36: ГОТОВ | F36: НЕ ГОТОВ | G36: Из прочих материалов | H36: 61001005000 | I36: =IF(LEN(H36)=11,H36,IF(LEN(H36)=0,"61001005000","61001003000")) -> 61001005000 | J36: =IF(LEN(H36)=11,"Материал по ЕГРН",IF(LEN(H36)=0,"Прочие по допущению","Смешанные по допущению")) -> Материал по ЕГРН | K36: =VLOOKUP(J36,Лист2!A$2:B$4,2,FALSE) -> 792 | L36: =IF(I36=C36,"ГОТОВ","ГОТОВ_ИЗМЕНЕН") -> ГОТОВ | M36: =C36 -> 61001005000
A37: 527700 | B37: 66:52:0107006:466 | C37: 61001005000 | D37: Сведения ЕГРН по состоянию на 01.01.2019 | E37: ГОТОВ | F37: НЕ ГОТОВ | G37: Из прочих материалов | H37: 61001005000 | I37: =IF(LEN(H37)=11,H37,IF(LEN(H37)=0,"61001005000","61001003000")) -> 61001005000 | J37: =IF(LEN(H37)=11,"Материал по ЕГРН",IF(LEN(H37)=0,"Прочие по допущению","Смешанные по допущению")) -> Материал по ЕГРН | K37: =VLOOKUP(J37,Лист2!A$2:B$4,2,FALSE) -> 792 | L37: =IF(I37=C37,"ГОТОВ","ГОТОВ_ИЗМЕНЕН") -> ГОТОВ | M37: =C37 -> 61001005000
A38: 939125 | B38: 66:31:2301002:271 | C38: 61001005000 | D38: Материал по ЕГРН | E38: не готов | F38: НЕ ГОТОВ | G38: Деревянные | H38: 61001002000 | I38: =IF(LEN(H38)=11,H38,IF(LEN(H38)=0,"61001005000","61001003000")) -> 61001002000 | J38: =IF(LEN(H38)=11,"Материал по ЕГРН",IF(LEN(H38)=0,"Прочие по допущению","Смешанные по допущению")) -> Материал по ЕГРН | K38: =VLOOKUP(J38,Лист2!A$2:B$4,2,FALSE) -> 792 | L38: =IF(I38=C38,"ГОТОВ","ГОТОВ_ИЗМЕНЕН") -> ГОТОВ_ИЗМЕНЕН | M38: =C38 -> 61001005000
A39: 944649 | B39: 66:34:0502027:4940 | F39: НЕ ГОТОВ | G39: Деревянные | H39: 61001002000 | I39: =IF(LEN(H39)=11,H39,IF(LEN(H39)=0,"61001005000","61001003000")) -> 61001002000 | J39: =IF(LEN(H39)=11,"Материал по ЕГРН",IF(LEN(H39)=0,"Прочие по допущению","Смешанные по допущению")) -> Материал по ЕГРН | K39: =VLOOKUP(J39,Лист2!A$2:B$4,2,FALSE) -> 792 | L39: =IF(I39=C39,"ГОТОВ","ГОТОВ_ИЗМЕНЕН") -> ГОТОВ_ИЗМЕНЕН | M39: =C39 -> 0
A40: 944661 | B40: 66:41:0209114:246 | F40: НЕ ГОТОВ | G40: Деревянные | H40: 61001002000 | I40: =IF(LEN(H40)=11,H40,IF(LEN(H40)=0,"61001005000","61001003000")) -> 61001002000 | J40: =IF(LEN(H40)=11,"Материал по ЕГРН",IF(LEN(H40)=0,"Прочие по допущению","Смешанные по допущению")) -> Материал по ЕГРН | K40: =VLOOKUP(J40,Лист2!A$2:B$4,2,FALSE) -> 792 | L40: =IF(I40=C40,"ГОТОВ","ГОТОВ_ИЗМЕНЕН") -> ГОТОВ_ИЗМЕНЕН | M40: =C40 -> 0
A41: 944673 | B41: 66:41:0513005:728 | F41: НЕ ГОТОВ | G41: Деревянные | H41: 61001002000 | I41: =IF(LEN(H41)=11,H41,IF(LEN(H41)=0,"61001005000","61001003000")) -> 61001002000 | J41: =IF(LEN(H41)=11,"Материал по ЕГРН",IF(LEN(H41)=0,"Прочие по допущению","Смешанные по допущению")) -> Материал по ЕГРН | K41: =VLOOKUP(J41,Лист2!A$2:B$4,2,FALSE) -> 792 | L41: =IF(I41=C41,"ГОТОВ","ГОТОВ_ИЗМЕНЕН") -> ГОТОВ_ИЗМЕНЕН | M41: =C41 -> 0
A42: 944685 | B42: 66:45:0200058:922 | F42: НЕ ГОТОВ | G42: Кирпичные, Шлакобетонные | H42: 61001001001, 61001008000 | I42: =IF(LEN(H42)=11,H42,IF(LEN(H42)=0,"61001005000","61001003000")) -> 61001003000 | J42: =IF(LEN(H42)=11,"Материал по ЕГРН",IF(LEN(H42)=0,"Прочие по допущению","Смешанные по допущению")) -> Смешанные по допущению | K42: =VLOOKUP(J42,Лист2!A$2:B$4,2,FALSE) -> 793 | L42: =IF(I42=C42,"ГОТОВ","ГОТОВ_ИЗМЕНЕН") -> ГОТОВ_ИЗМЕНЕН | M42: =C42 -> 0
A43: 944697 | B43: 66:59:0101029:845 | F43: НЕ ГОТОВ | G43: Из прочих материалов | H43: 61001005000 | I43: =IF(LEN(H43)=11,H43,IF(LEN(H43)=0,"61001005000","61001003000")) -> 61001005000 | J43: =IF(LEN(H43)=11,"Материал по ЕГРН",IF(LEN(H43)=0,"Прочие по допущению","Смешанные по допущению")) -> Материал по ЕГРН | K43: =VLOOKUP(J43,Лист2!A$2:B$4,2,FALSE) -> 792 | L43: =IF(I43=C43,"ГОТОВ","ГОТОВ_ИЗМЕНЕН") -> ГОТОВ_ИЗМЕНЕН | M43: =C43 -> 0
A44: 944709 | B44: 66:63:0101054:2347 | F44: НЕ ГОТОВ | G44: Шлакобетонные | H44: 61001008000 | I44: =IF(LEN(H44)=11,H44,IF(LEN(H44)=0,"61001005000","61001003000")) -> 61001008000 | J44: =IF(LEN(H44)=11,"Материал по ЕГРН",IF(LEN(H44)=0,"Прочие по допущению","Смешанные по допущению")) -> Материал по ЕГРН | K44: =VLOOKUP(J44,Лист2!A$2:B$4,2,FALSE) -> 792 | L44: =IF(I44=C44,"ГОТОВ","ГОТОВ_ИЗМЕНЕН") -> ГОТОВ_ИЗМЕНЕН | M44: =C44 -> 0
...

Sheet Лист2
A1: SourcelocMaterial
A2: Материал по ЕГРН | B2: 792
A3: Смешанные по допущению | B3: 793
A4: Прочие по допущению | B4: 794
