Workbook

Sheet Помещения здания
A1: Идентификатор | B1: Идентификатор | C1: Кадастровый номер | D1: Вид объекта недвижимости | E1: КН здания или сооружения, в котором расположено помещение 2 | F1: Назначение здания, если помещение расположено в здании | G1: Назначение и вид помещения Назначение помещения (жилое, нежилое) | H1: Назначение и вид помещения Вид жилого помещения (квартира, комната) | I1: Площадь в квадратных метрах | J1: Улица Наименование | K1: Дом Значение | L1: Тип этажа(подземный/надземный) | M1: Номер этажа(для сравнения) | N1: Удельный показатель кадастровой стоимости(руб/м2) Расчетный | O1: Кадастровая стоимость Расчетная | P1: Кадастровая стоимость описание вых | Q1: Группа объекта по метод указаниям | R1: Населённый пункт | S1: Площадь(расчет) | T1: Группа для XML | U1: Год постройки/реконструкции(расчет) | V1: Материал стен для расчета | W1: Степень благоустройства | X1: Класс дома | Y1: Местоположение объекта | Z1: Этажность | AA1: Признак малогаборитности | AB1: Этаж расположения | AC1: Поправка на уторгование | AD1: Численность НП | AE1: Тип помещения | AF1: Номер заявления | AG1: Тип заявления | AH1: Статус заявления | AI1: Статус расчета КС | AJ1: Особый контроль | AK1: Наличие/Отсутствие здания-родителя | AL1: Флаг основного параметра | AM1: Дата оценки | AN1: Перечень выгрузки КС | AO1: Дата пакета | AP1: Модель старая | AQ1: Флаг родителя | AR1: Кадастровый номер | AS1: Электроснабжение | AT1: Водоснабжение | AU1: Водоотведение | AV1: Отопление | AW1: Населённый пункт | AX1: Год строительства | AY1: Этажность | AZ1: Группа объекта для расчета | BA1: Ценовая зона(Екатеринбург) | BB1: Аварийность | BC1: Материал стен в расчет | BD1: Статус расчета КС | BE1: Особый контроль | BF1: Перечень выгрузки КС | BG1: Дата пакета | BH1: Благоустройство | BI1: Дата комиссии | BJ1: Решение комиссии | BK1: Флаг Площадь в расчет | BL1: Дата оценки | BM1: Флаг Год строительства | BN1: Флаг Этажность в расчет | BO1: Флаг Материал стен в расчет | BP1: Источник кадастровой стоимости | BQ1: Материал стен в расчет | BR1: КН | BS1: Год | BT1: Площадь | BU1: Район | BV1: Тип стен | BW1: Этаж расположения | BX1: Тип дома | BY1: Степень благоустройства | BZ1: Признак малогаборитности | CA1: Поправка на уторгование | CB1: Год | CC1: Район | CD1: Тип стен | CE1: Этаж расположения | CF1: Тип дома | CG1: Степень благоустройства | CH1: Площадь | CI1: КС | CJ1: Год | CK1: Площадь | CL1: Район | CM1: Тип стен | CN1: Этаж расположения | CO1: Тип дома | CP1: Степень благоустройства | CQ1: Тип помещения (комната квартира) | CR1: Поправка на торг | CS1: Константа | CT1: УПКС, руб/м2 | CU1: КС, руб. | CX1: Описание КС
A2: ID | B2: ID | C2: CadastralNumber | D2: ObjectType | E2: ParentOKSCadNum | F2: ParentOKSAssignationBuilding | G2: AssignationCode | H2: AssignationType | I2: Area | J2: StreetName | K2: Level1Value | L2: locTypeFloorKv | M2: locNumberFloor | N2: Specific_CadastralCost | O2: CadastralCost | P2: CadastralCostDesc | Q2: LocCalc_GroupCode | R2: LocalityCode | S2: loc_Factor_110 | T2: ID_Group | U2: loc_Factor_122 | V2: loc_Factor_201 | W2: loc_Factor_202 | X2: loc_Factor_203 | Y2: loc_Factor_204 | Z2: loc_Factor_205 | AA2: loc_Factor_206 | AB2: loc_Factor_207 | AC2: loc_Factor_208 | AD2: loc_Factor_209 | AE2: locTypeFlat | AF2: Statement | AG2: Type_Statement | AH2: Status_Statement | AI2: Status_KC | AJ2: ControlSP | AK2: Orphan | AL2: FlagParamFlats | AM2: Date_KC | AN2: Upload_Scroll | AO2: inputpacket_date | AP2: ID_Group2 | AQ2: FlagParent | AR2: CadastralNumber | AS2: PresencePower | AT2: PresenceWaterSupply | AU2: PresenceWaterDisposal | AV2: PresenceHeating | AW2: LocalityCode | AX2: YearBuilt | AY2: LocFloors | AZ2: LocCalc_GroupCode | BA2: CostZone | BB2: Dilapidated | BC2: locMaterial | BD2: Status_KC | BE2: ControlSP | BF2: Upload_Scroll | BG2: inputpacket_date | BH2: Blago | BI2: Date_comm | BJ2: Sol_comm | BK2: FlagParam | BL2: Date_KC | BM2: FlagYearBuilt | BN2: FlagLocFloors | BO2: FlaglocMaterial | BP2: SourceCadastralCost
A3: Buildings | B3: Flats | C3: Flats | D3: Flats | E3: Flats | F3: Flats | G3: Flats | H3: Flats | I3: Flats | J3: Flats | K3: Flats | L3: Flats | M3: Flats | N3: Flats | O3: Flats | P3: Flats | Q3: Flats | R3: Flats | S3: Flats | T3: Flats | U3: Flats | V3: Flats | W3: Flats | X3: Flats | Y3: Flats | Z3: Flats | AA3: Flats | AB3: Flats | AC3: Flats | AD3: Flats | AE3: Flats | AF3: Flats | AG3: Flats | AH3: Flats | AI3: Flats | AJ3: Flats | AK3: Flats | AL3: Flats | AM3: Flats | AN3: Flats | AO3: Flats | AP3: Flats | AQ3: Flats | AR3: Buildings | AS3: Buildings | AT3: Buildings | AU3: Buildings | AV3: Buildings | AW3: Buildings | AX3: Buildings | AY3: Buildings | AZ3: Buildings | BA3: Buildings | BB3: Buildings | BC3: Buildings | BD3: Buildings | BE3: Buildings | BF3: Buildings | BG3: Buildings | BH3: Buildings | BI3: Buildings | BJ3: Buildings | BK3: Buildings | BL3: Buildings | BM3: Buildings | BN3: Buildings | BO3: Buildings
D4: справочник | F4: справочник | G4: справочник | H4: справочник
A5: 404069 | B5: 447553 | C5: 66:45:0200226:2520 | D5: Помещение | E5: 66:45:0200226:205 | F5: Многоквартирный дом | G5: Жилое помещение | H5: Квартира | I5: 83.7 | J5: Октябрьская | K5: 34 | L5: Средний | M5: 3 | N5: 17048.58 | O5: 930852.47 | P5: Ф8_16ст_Р_11.02.20 | Q5: 0101 | R5: 52:001:1:1:2 | S5: 54.6 | T5: 1004 | U5: 1943 | V5: Шлакоблочные | W5: Благоустроенная | Y5: УАЗ | Z5: Малоэтажный | AA5: Комната | AB5: Крайний | AC5: городской | AE5: Квартира | AI5: НЕ ГОТОВ | AK5: 0 | AL5: не готов | AO5: 26.01.2021 | AR5: 66:45:0200226:205 | AS5: Наличие | AT5: Наличие | AU5: Наличие | AV5: Наличие | AW5: 52:001:1:1:2 | AX5: 1943 | AY5: 3 | AZ5: 0101 | BA5: УАЗ | BC5: 61001008000 | BD5: ВЫГРУЖЕНА | BG5: 01.01.2019 | BH5: Благоустроенная | BK5: ГОТОВ | BL5: 01.01.2019 | BM5: ГОТОВ | BN5: ГОТОВ | BO5: ГОТОВ | BP5: =VALUE(M5) -> 3 | BQ5: =VALUE(BC5) -> 61001008000 | BR5: =C5 -> 66:45:0200226:2520 | BS5: =AX5 -> 1943 | BT5: =I5 -> 83.7 | BU5: =IF(BA5="","Ленин-Олимп",BA5) -> УАЗ | BV5: =VLOOKUP(BQ5,'[1]Справочник Мат.стен'!$A:$E,5,FALSE) -> Шлакоблочные | BW5: =IF(OR(BP5=1,BP5=AY5),"Крайний","Средний") -> Крайний | BX5: =IF(AY5<=3,"Малоэтажный",IF(AND(AY5>3,AY5<=8),"Среднеэтажный","Многоэтажный")) -> Малоэтажный | BY5: =IF(BH5="","Благоустроенная",BH5) -> Благоустроенная | BZ5: =IF(H5="комната","Комната","Квартира") -> Квартира | CA5: городской | CB5: =IF(U5="","Пустой",U5=BS5) -> TRUE | CC5: =IF(Y5="","Пустой",Y5=BU5) -> TRUE | CD5: =IF(V5="","Пустой",BV5=V5) -> TRUE | CE5: =IF(AB5="","Пустой",BW5=AB5) -> TRUE | CF5: =IF(Z5="","Пустой",BX5=Z5) -> TRUE | CG5: =IF(W5="","Пустой",BY5=W5) -> TRUE | CH5: =IF(S5="","Пустой",I5-S5) -> 29.1 | CI5: =IF(O5="","Пустой",ABS(O5-CU5)) -> 663398.17 | CJ5: =ROUND(((EXP(EXP(3.35465762+-2003.21065848/BS5))^[1]Поправки!$I$7)/[1]Поправки!$P$8),4) -> 0.9743 | CK5: =IF(ROUND(((EXP(10.72418644*BT5^-0.00840508)^[1]Поправки!$I$5)/[1]Поправки!$P$4),4)>[1]Поправки!$Q$2,[1]Поправки!$Q$2,IF(ROUND(((EXP(10.72418644*BT5^-0.00840508)^[1]Поправки!$I$5)/[1]Поправки!$P$4),4)<[1]Поправки!$Q$3,[1]Поправки!$Q$3,ROUND(((EXP(10.72418644*BT5^-0.00840508)^[1]Поправки!$I$5)/[1]Поправки!$P$4),4))) -> 0.9289 | CL5: =VLOOKUP(BU5,[1]Поправки!$B$16:$D$26,3,FALSE) -> 0.9076 | CM5: =VLOOKUP(BV5,[1]Поправки!$F$17:$H$22,3,FALSE) -> 0.8866 | CN5: =VLOOKUP(BW5,[1]Поправки!$J$19:$L$20,3,FALSE) -> 0.9885 | CO5: =VLOOKUP(BX5,[1]Поправки!$N$18:$P$20,3,FALSE) -> 0.9153 | CP5: =VLOOKUP(BY5,[1]Поправки!$J$27:$K$28,2,FALSE) -> 1 | CQ5: =VLOOKUP(BZ5,[1]Поправки!$G$27:$H$28,2,FALSE) -> 1 | CR5: 0.9439 | CS5: 30625.36 | CT5: =ROUND(PRODUCT(CJ5*CK5*CL5*CM5*CN5*CO5*CQ5*CR5*CS5*CP5),2) -> 19047.2 | CU5: =ROUND((CT5*BT5),2) -> 1594250.6 | CV5: =IF(ABS(CU5-O5)<10,"ГОТОВ","ГОТОВ ИЗМЕНЕН") -> ГОТОВ ИЗМЕНЕН | CW5: =IF(CV5="ГОТОВ","ПЕРЕСЧЕТ НЕ ТРЕБУЕТСЯ","ГОТОВ") -> ГОТОВ | CX5: Ф27_16ст_Р_09.02.21
A6: select Flats.ID Flats#ID,Flats.CadastralNumber Flats#CadastralNumber,Flats.DateCreated Flats#DateCreated,Flats.CadastralBlock Flats#CadastralBlock,Flats.ObjectType Flats#ObjectType,Flats.CadastralNumberFlat Flats#CadastralNumberFlat,Flats.CadastralNumberOKS Flats#CadastralNumberOKS,Flats.ParentOKSCadNum Flats#ParentOKSCadNum,Flats.ParentOKSObjectType Flats#ParentOKSObjectType,Flats.ParentOKSAssignationBuilding Flats#ParentOKSAssignationBuilding,Flats.ParentOKSAssignationName Flats#ParentOKSAssignationName,Flats.ExploitationCharYearBuilt Flats#ExploitationCharYearBuilt,Flats.ExploitationCharYearUsed Flats#ExploitationCharYearUsed,Flats.Floors Flats#Floors,Flats.UndergroundFloors Flats#UndergroundFloors,Flats.AssignationCode Flats#AssignationCode,Flats.AssignationType Flats#AssignationType,Flats.Area Flats#Area,Flats.PositionNumberOnPlan Flats#PositionNumberOnPlan,Flats.PositionDescription Flats#PositionDescription,Flats.AddressOrLocation Flats#AddressOrLocation,Flats.OKATO Flats#OKATO,Flats.KLADR Flats#KLADR,Flats.PostalCode Flats#PostalCode,Flats.Region Flats#Region,Flats.DistrictName Flats#DistrictName,Flats.DistrictType Flats#DistrictType,Flats.CityName Flats#CityName,Flats.CityType Flats#CityType,Flats.UrbanDistrictName Flats#UrbanDistrictName,Flats.UrbanDistrictType Flats#UrbanDistrictType,Flats.SovietVillageName Flats#SovietVillageName,Flats.SovietVillageType Flats#SovietVillageType,Flats.LocalityName Flats#LocalityName,Flats.LocalityType Flats#LocalityType,Flats.StreetName Flats#StreetName,Flats.StreetType Flats#StreetType,Flats.Level1Type Flats#Level1Type,Flats.Level1Value Flats#Level1Value,Flats.Level2Type Flats#Level2Type,Flats.Level2Value Flats#Level2Value,Flats.Level3Type Flats#Level3Type,Flats.Level3Value Flats#Level3Value,Flats.ApartmentType Flats#ApartmentType,Flats.ApartmentValue Flats#ApartmentValue,Flats.LocationOther Flats#LocationOther,Flats.LocationNote Flats#LocationNote,Flats.CostValue Flats#CostValue,Flats.CostUnit Flats#CostUnit,Flats.CostDateValuation Flats#CostDateValuation,Flats.CostDateEntering Flats#CostDateEntering,Flats.CostDateApproval Flats#CostDateApproval,Flats.CostDocNumber Flats#CostDocNumber,Flats.CostDocDate Flats#CostDocDate,Flats.CostApplicationDate Flats#CostApplicationDate,Flats.CostRevisalStatementDate Flats#CostRevisalStatementDate,Flats.CostDocName Flats#CostDocName,Flats.Name Flats#Name,Flats.AssignationSpecialType Flats#AssignationSpecialType,Flats.AssignationTotalAssets Flats#AssignationTotalAssets,Flats.AssignationAuxiliaryFlat Flats#AssignationAuxiliaryFlat,Flats.FIAS Flats#FIAS,Flats.OKTMO Flats#OKTMO,Flats.LocationRF Flats#LocationRF,Flats.PlanningElementName Flats#PlanningElementName,Flats.PlanningElementType Flats#PlanningElementType,Flats.CostApplicationLastDate Flats#CostApplicationLastDate,Flats.UnitedKN Flats#UnitedKN,Flats.FacilityKN Flats#FacilityKN,Flats.FacilityKNPurpose Flats#FacilityKNPurpose,Flats.EGROKNRegNum Flats#EGROKNRegNum,Flats.EGROKNObjCultural Flats#EGROKNObjCultural,Flats.EGROKNNameCultural Flats#EGROKNNameCultural,Flats.AssignmentEGROKNRegNum Flats#AssignmentEGROKNRegNum,Flats.AssignmentEGROKNObjCultural Flats#AssignmentEGROKNObjCultural,Flats.AssignmentEGROKNNameCultural Flats#AssignmentEGROKNNameCultural,Flats.CulturalHeritageRequirements Flats#CulturalHeritageRequirements,Flats.CodeDocumentEGROKN Flats#CodeDocumentEGROKN,Flats.DocumentNameEGROKN Flats#DocumentNameEGROKN,Flats.DocumentSeriesEGROKN Flats#DocumentSeriesEGROKN,Flats.DocumentNumberEGROKN Flats#DocumentNumberEGROKN,Flats.DocumentDateEGROKN Flats#DocumentDateEGROKN,Flats.DocumentIssueOrganEGROKN Flats#DocumentIssueOrganEGROKN,Flats.DocumentDescEGROKN Flats#DocumentDescEGROKN,Flats.OPERATORNAME Flats#OPERATORNAME,Flats.MODIFYDATE Flats#MODIFYDATE,Flats.CREATEOPERATORNAME Flats#CREATEOPERATORNAME,Flats.CREATEDATE Flats#CREATEDATE,Flats.Source_ID Flats#Source_ID,Flats.Constructions_ID Flats#Constructions_ID,Flats.locTypeFloorKv Flats#locTypeFloorKv,Flats.locNumberFloor Flats#locNumberFloor,Flats.locFloorPrim Flats#locFloorPrim,Flats.Specific_CadastralCost Flats#Specific_CadastralCost,Flats.CadastralCost Flats#CadastralCost,Flats.CadastralCostDesc Flats#CadastralCostDesc,Flats.LocCalc_GroupCode Flats#LocCalc_GroupCode,Flats.SourcelocCalc_Group Flats#SourcelocCalc_Group,Flats.locTypeUse Flats#locTypeUse,Flats.SourcelocTypeUse Flats#SourcelocTypeUse,Flats.LocalityCode Flats#LocalityCode,Flats.MO_Name Flats#MO_Name,Flats.loc_Factor_102 Flats#loc_Factor_102,Flats.loc_Factor_108 Flats#loc_Factor_108,Flats.loc_Factor_109 Flats#loc_Factor_109,Flats.loc_Factor_110 Flats#loc_Factor_110,Flats.ID_Group Flats#ID_Group,Flats.loc_Factor_122 Flats#loc_Factor_122,Flats.loc_Factor_159 Flats#loc_Factor_159,Flats.locTypeUse2 Flats#locTypeUse2,Flats.loc_VICode Flats#loc_VICode,Flats.loc_GroupName Flats#loc_GroupName,Flats.loc_VRICode Flats#loc_VRICode,Flats.loc_Factor_201 Flats#loc_Factor_201,Flats.Source_loc_Factor_201 Flats#Source_loc_Factor_201,Flats.loc_Factor_202 Flats#loc_Factor_202,Flats.Source_loc_Factor_202 Flats#Source_loc_Factor_202,Flats.Source_loc_Factor_122 Flats#Source_loc_Factor_122,Flats.loc_Factor_203 Flats#loc_Factor_203,Flats.Source_loc_Factor_203 Flats#Source_loc_Factor_203,Flats.Source_loc_Factor_102 Flats#Source_loc_Factor_102,Flats.Source_loc_Factor_110 Flats#Source_loc_Factor_110,Flats.loc_Factor_204 Flats#loc_Factor_204,Flats.Source_loc_Factor_204 Flats#Source_loc_Factor_204,Flats.Source_loc_Factor_108 Flats#Source_loc_Factor_108,Flats.Source_loc_Factor_109 Flats#Source_loc_Factor_109,Flats.loc_Factor_205 Flats#loc_Factor_205,Flats.Source_loc_Factor_205 Flats#Source_loc_Factor_205,Flats.loc_Factor_206 Flats#loc_Factor_206,Flats.Source_loc_Factor_206 Flats#Source_loc_Factor_206,Flats.loc_Factor_207 Flats#loc_Factor_207,Flats.Source_loc_Factor_207 Flats#Source_loc_Factor_207,Flats.loc_Factor_208 Flats#loc_Factor_208,Flats.Source_loc_Factor_208 Flats#Source_loc_Factor_208,Flats.loc_Factor_209 Flats#loc_Factor_209,Flats.Source_loc_Factor_209 Flats#Source_loc_Factor_209,Flats.loc_Factor_210 Flats#loc_Factor_210,Flats.Source_loc_Factor_210 Flats#Source_loc_Factor_210,Flats.Source_loc_Factor_159 Flats#Source_loc_Factor_159,Flats.locTypeFlat Flats#locTypeFlat,Flats.SourcelocTypeFlat Flats#SourcelocTypeFlat,Flats.loc_Factor_211 Flats#loc_Factor_211,Flats.loc_Factor_212 Flats#loc_Factor_212,Flats.inputpacket_id Flats#inputpacket_id,Flats.FlatLevelsFis Flats#FlatLevelsFis,Flats.FlaglocTypeFlat Flats#FlaglocTypeFlat,Flats.FlagLocCalc_GroupCode Flats#FlagLocCalc_GroupCode,Flats.FlagId_Group Flats#FlagId_Group,Flats.FlagYearBuilt Flats#FlagYearBuilt,Flats.FlagLocalityCode Flats#FlagLocalityCode,Flats.FlagLocFloors Flats#FlagLocFloors,Flats.FlagFlatLavel Flats#FlagFlatLavel,Flats.FlagCadastralCost Flats#FlagCadastralCost,Flats.SourceCadastralCost Flats#SourceCadastralCost,Flats.Status_KC Flats#Status_KC,Flats.Source_EGRN Flats#Source_EGRN,Flats.Determin_DateKCS Flats#Determin_DateKCS,Flats.Count_Floor Flats#Count_Floor,Flats.SourcelocTypeFloor Flats#SourcelocTypeFloor,Flats.ControlSP Flats#ControlSP,Flats.Orphan Flats#Orphan,Flats.FlagParamFlats Flats#FlagParamFlats,Flats.SourceLocalityCode Flats#SourceLocalityCode,Flats.Date_KC Flats#Date_KC,Flats.Upload_Scroll Flats#Upload_Scroll,Flats.Statement Flats#Statement,Flats.Type_Statement Flats#Type_Statement,Flats.Status_Statement Flats#Status_Statement,Flats.ID_Group2 Flats#ID_Group2,Flats.Date_comm Flats#Date_comm,Flats.Sol_comm Flats#Sol_comm,Flats.FlagParent Flats#FlagParent,Flats.Court Flats#Court,Flats.Date_Court Flats#Date_Court,Flats.Sol_Court Flats#Sol_Court,Flats.inputpacket_date Flats#inputpacket_date,Buildings1#ID Buildings#ID,Buildings1#CadastralNumber Buildings#CadastralNumber,Buildings1#DateCreated Buildings#DateCreated,Buildings1#CadastralBlock Buildings#CadastralBlock,Buildings1#Name Buildings#Name,Buildings1#ObjectType Buildings#ObjectType,Buildings1#AssignationBuilding Buildings#AssignationBuilding,Buildings1#ExploitationCharYearBuilt Buildings#ExploitationCharYearBuilt,Buildings1#ExploitationCharYearUsed Buildings#ExploitationCharYearUsed,Buildings1#Floors Buildings#Floors,Buildings1#FloorsUnderground Buildings#FloorsUnderground,Buildings1#Area Buildings#Area,Buildings1#AddressOrLocation Buildings#AddressOrLocation,Buildings1#OKATO Buildings#OKATO,Buildings1#KLADR Buildings#KLADR,Buildings1#PostalCode Buildings#PostalCode,Buildings1#Region Buildings#Region,Buildings1#DistrictName Buildings#DistrictName,Buildings1#DistrictType Buildings#DistrictType,Buildings1#CityName Buildings#CityName,Buildings1#CityType Buildings#CityType,Buildings1#UrbanDistrictName Buildings#UrbanDistrictName,Buildings1#UrbanDistrictType Buildings#UrbanDistrictType,Buildings1#SovietVillageName Buildings#SovietVillageName,Buildings1#SovietVillageType Buildings#SovietVillageType,Buildings1#LocalityName Buildings#LocalityName,Buildings1#LocalityType Buildings#LocalityType,Buildings1#StreetName Buildings#StreetName,Buildings1#StreetType Buildings#StreetType,Buildings1#Level1Type Buildings#Level1Type,Buildings1#Level1Value Buildings#Level1Value,Buildings1#Level2Type Buildings#Level2Type,Buildings1#Level2Value Buildings#Level2Value,Buildings1#Level3Type Buildings#Level3Type,Buildings1#Level3Value Buildings#Level3Value,Buildings1#ApartmentType Buildings#ApartmentType,Buildings1#ApartmentValue Buildings#ApartmentValue,Buildings1#LocationOther Buildings#LocationOther,Buildings1#LocationNote Buildings#LocationNote,Buildings1#CostValue Buildings#CostValue,Buildings1#CostUnit Buildings#CostUnit,Buildings1#CostDateValuation Buildings#CostDateValuation,Buildings1#CostDateEntering Buildings#CostDateEntering,Buildings1#CostDateApproval Buildings#CostDateApproval,Buildings1#CostDocNumber Buildings#CostDocNumber,Buildings1#CostDocDate Buildings#CostDocDate,Buildings1#CostApplicationDate Buildings#CostApplicationDate,Buildings1#lCostRevisalStatementDate Buildings#lCostRevisalStatementDate,Buildings1#CostDocName Buildings#CostDocName,Buildings1#FIAS Buildings#FIAS,Buildings1#OKTMO Buildings#OKTMO,Buildings1#LocationRF Buildings#LocationRF,Buildings1#PlanningElementName Buildings#PlanningElementName,Buildings1#PlanningElementType Buildings#PlanningElementType,Buildings1#CostApplicationLastDate Buildings#CostApplicationLastDate,Buildings1#UnitedKN Buildings#UnitedKN,Buildings1#FacilityKN Buildings#FacilityKN,Buildings1#FacilityKNPurpose Buildings#FacilityKNPurpose,Buildings1#EGROKNRegNum Buildings#EGROKNRegNum,Buildings1#EGROKNObjCultural Buildings#EGROKNObjCultural,Buildings1#EGROKNNameCultural Buildings#EGROKNNameCultural,Buildings1#AssignmentEGROKNRegNum Buildings#AssignmentEGROKNRegNum,Buildings1#AssignmentEGROKNObjCultural Buildings#AssignmentEGROKNObjCultural,Buildings1#AssignmentEGROKNNameCultural Buildings#AssignmentEGROKNNameCultural,Buildings1#CulturalHeritageRequirements Buildings#CulturalHeritageRequirements,Buildings1#CodeDocumentEGROKN Buildings#CodeDocumentEGROKN,Buildings1#DocumentNameEGROKN Buildings#DocumentNameEGROKN,Buildings1#DocumentSeriesEGROKN Buildings#DocumentSeriesEGROKN,Buildings1#DocumentNumberEGROKN Buildings#DocumentNumberEGROKN,Buildings1#DocumentDateEGROKN Buildings#DocumentDateEGROKN,Buildings1#DocumentIssueOrganEGROKN Buildings#DocumentIssueOrganEGROKN,Buildings1#DocumentDescEGROKN Buildings#DocumentDescEGROKN,Buildings1#OPERATORNAME Buildings#OPERATORNAME,Buildings1#MODIFYDATE Buildings#MODIFYDATE,Buildings1#CREATEOPERATORNAME Buildings#CREATEOPERATORNAME,Buildings1#CREATEDATE Buildings#CREATEDATE,Buildings1#Source_ID Buildings#Source_ID,Buildings1#PresencePower Buildings#PresencePower,Buildings1#SourcePresencePower Buildings#SourcePresencePower,Buildings1#PresenceWaterSupply Buildings#PresenceWaterSupply,Buildings1#SourcePresenceWaterSupply Buildings#SourcePresenceWaterSupply,Buildings1#PresenceWaterDisposal Buildings#PresenceWaterDisposal,Buildings1#SourcePresenceWaterDisposal Buildings#SourcePresenceWaterDisposal,Buildings1#PresenceGas Buildings#PresenceGas,Buildings1#SourcePresenceGas Buildings#SourcePresenceGas,Buildings1#PresenceHeating Buildings#PresenceHeating,Buildings1#SourcePresenceHeating Buildings#SourcePresenceHeating,Buildings1#LocalityCode Buildings#LocalityCode,Buildings1#SourceLocalityCode Buildings#SourceLocalityCode,Buildings1#YearBuilt Buildings#YearBuilt,Buildings1#SourceYearBuilt Buildings#SourceYearBuilt,Buildings1#LocFloors Buildings#LocFloors,Buildings1#SourcelocFloors Buildings#SourcelocFloors,Buildings1#LocCalc_GroupCode Buildings#LocCalc_GroupCode,Buildings1#SourcelocCalc_Group Buildings#SourcelocCalc_Group,Buildings1#locTypeUse Buildings#locTypeUse,Buildings1#SourcelocTypeUse Buildings#SourcelocTypeUse,Buildings1#CoordinateMatchingName Buildings#CoordinateMatchingName,Buildings1#CoordinateMatchingCode Buildings#CoordinateMatchingCode,Buildings1#CostZone Buildings#CostZone,Buildings1#HousingArea Buildings#HousingArea,Buildings1#Coordinate_x Buildings#Coordinate_x,Buildings1#Coordinate_y Buildings#Coordinate_y,Buildings1#Number_of_spaces Buildings#Number_of_spaces,Buildings1#Number_of_nonresidential_premises Buildings#Number_of_nonresidential_premises,Buildings1#Number_of_premises Buildings#Number_of_premises,Buildings1#Number_of_apartments Buildings#Number_of_apartments,Buildings1#Number_of_rooms Buildings#Number_of_rooms,Buildings1#Dilapidated Buildings#Dilapidated,Buildings1#SourceDilapidated Buildings#SourceDilapidated,Buildings1#locReconstructionYear Buildings#locReconstructionYear,Buildings1#SourcelocReconstructionYear Buildings#SourcelocReconstructionYear,Buildings1#Specific_CadastralCost Buildings#Specific_CadastralCost,Buildings1#CadastralCost Buildings#CadastralCost,Buildings1#CadastralCostDesc Buildings#CadastralCostDesc,Buildings1#MO_Name Buildings#MO_Name,Buildings1#locVolume Buildings#locVolume,Buildings1#SourcelocVolume Buildings#SourcelocVolume,Buildings1#LocArea Buildings#LocArea,Buildings1#SourceLocArea Buildings#SourceLocArea,Buildings1#locPhysicalWear Buildings#locPhysicalWear,Buildings1#SourcelocPhysicalWear Buildings#SourcelocPhysicalWear,Buildings1#locMaterial Buildings#locMaterial,Buildings1#SourcelocMaterial Buildings#SourcelocMaterial,Buildings1#ID_Group Buildings#ID_Group,Buildings1#loc_Factor_117 Buildings#loc_Factor_117,Buildings1#loc_Factor_118 Buildings#loc_Factor_118,Buildings1#loc_Factor_119 Buildings#loc_Factor_119,Buildings1#loc_Factor_120 Buildings#loc_Factor_120,Buildings1#loc_Factor_158 Buildings#loc_Factor_158,Buildings1#locTypeUse2 Buildings#locTypeUse2,Buildings1#loc_VICode Buildings#loc_VICode,Buildings1#loc_GroupName Buildings#loc_GroupName,Buildings1#loc_VRICode Buildings#loc_VRICode,Buildings1#Source_loc_Factor_117 Buildings#Source_loc_Factor_117,Buildings1#Source_loc_Factor_118 Buildings#Source_loc_Factor_118,Buildings1#Source_loc_Factor_119 Buildings#Source_loc_Factor_119,Buildings1#Source_loc_Factor_120 Buildings#Source_loc_Factor_120,Buildings1#source_loc_Factor_158 Buildings#source_loc_Factor_158,Buildings1#loc_Factor_180 Buildings#loc_Factor_180,Buildings1#inputpacket_id Buildings#inputpacket_id,Buildings1#Source_loc_VICode Buildings#Source_loc_VICode,Buildings1#FlagCadastralCost Buildings#FlagCadastralCost,Buildings1#FlagParam Buildings#FlagParam,Buildings1#Source_EGRN Buildings#Source_EGRN,Buildings1#Determin_DateKCS Buildings#Determin_DateKCS,Buildings1#SourceDetermin_DateKC Buildings#SourceDetermin_DateKC,Buildings1#Determin_DateKC Buildings#Determin_DateKC,Buildings1#FlagLocalityCode Buildings#FlagLocalityCode,Buildings1#FlagYearBuilt Buildings#FlagYearBuilt,Buildings1#FlagLocFloors Buildings#FlagLocFloors,Buildings1#FlaglocMaterial Buildings#FlaglocMaterial,Buildings1#FlagLocCalc_GroupCode Buildings#FlagLocCalc_GroupCode,Buildings1#SourceCadastralCost Buildings#SourceCadastralCost,Buildings1#Status_KC Buildings#Status_KC,Buildings1#locYear Buildings#locYear,Buildings1#SourcelocYear Buildings#SourcelocYear,Buildings1#BuildingConstructMaterialFiz Buildings#BuildingConstructMaterialFiz,Buildings1#ParentUchKNFiz Buildings#ParentUchKNFiz,Buildings1#FlagLocZU Buildings#FlagLocZU,Buildings1#ControlSP Buildings#ControlSP,Buildings1#Calc_base Buildings#Calc_base,Buildings1#SourceCalc_base Buildings#SourceCalc_base,Buildings1#Upload_Scroll Buildings#Upload_Scroll,Buildings1#Date_KC Buildings#Date_KC,Buildings1#LC_distance_pos Buildings#LC_distance_pos,Buildings1#LC_distance_neg Buildings#LC_distance_neg,Buildings1#Blago Buildings#Blago,Buildings1#OldYearBuilt Buildings#OldYearBuilt,Buildings1#OldLocfloors Buildings#OldLocfloors,Buildings1#OldlocMaterial Buildings#OldlocMaterial,Buildings1#OldArea Buildings#OldArea,Buildings1#Statement Buildings#Statement,Buildings1#Type_Statement Buildings#Type_Statement,Buildings1#Status_Statement Buildings#Status_Statement,Buildings1#OldLocalityCode Buildings#OldLocalityCode,Buildings1#Date_comm Buildings#Date_comm,Buildings1#Sol_comm Buildings#Sol_comm,Buildings1#FlagName Buildings#FlagName,Buildings1#FlagNazn Buildings#FlagNazn,Buildings1#Vid Buildings#Vid,Buildings1#Kontrol Buildings#Kontrol,Buildings1#Court Buildings#Court,Buildings1#Date_Court Buildings#Date_Court,Buildings1#Sol_Court Buildings#Sol_Court,Buildings1#BuildingConstructMaterialCode Buildings#BuildingConstructMaterialCode,Buildings1#inputpacket_date Buildings#inputpacket_date from (select ID, Flats.ID Flats#ID, CadastralNumber, Flats.CadastralNumber Flats#CadastralNumber, DateCreated, Flats.DateCreated Flats#DateCreated, CadastralBlock, Flats.CadastralBlock Flats#CadastralBlock, ObjectType, Flats.ObjectType Flats#ObjectType, CadastralNumberFlat, Flats.CadastralNumberFlat Flats#CadastralNumberFlat, CadastralNumberOKS, Flats.CadastralNumberOKS Flats#CadastralNumberOKS, ParentOKSCadNum, Flats.ParentOKSCadNum Flats#ParentOKSCadNum, ParentOKSObjectType, Flats.ParentOKSObjectType Flats#ParentOKSObjectType, ParentOKSAssignationBuilding, Flats.ParentOKSAssignationBuilding Flats#ParentOKSAssignationBuilding, ParentOKSAssignationName, Flats.ParentOKSAssignationName Flats#ParentOKSAssignationName, ExploitationCharYearBuilt, Flats.ExploitationCharYearBuilt Flats#ExploitationCharYearBuilt, ExploitationCharYearUsed, Flats.ExploitationCharYearUsed Flats#ExploitationCharYearUsed, Floors, Flats.Floors Flats#Floors, UndergroundFloors, Flats.UndergroundFloors Flats#UndergroundFloors, AssignationCode, Flats.AssignationCode Flats#AssignationCode, AssignationType, Flats.AssignationType Flats#AssignationType, Area, Flats.Area Flats#Area, PositionNumberOnPlan, Flats.PositionNumberOnPlan Flats#PositionNumberOnPlan, PositionDescription, Flats.PositionDescription Flats#PositionDescription, AddressOrLocation, Flats.AddressOrLocation Flats#AddressOrLocation, OKATO, Flats.OKATO Flats#OKATO, KLADR, Flats.KLADR Flats#KLADR, PostalCode, Flats.PostalCode Flats#PostalCode, Region, Flats.Region Flats#Region, DistrictName, Flats.DistrictName Flats#DistrictName, DistrictType, Flats.DistrictType Flats#DistrictType, CityName, Flats.CityName Flats#CityName, CityType, Flats.CityType Flats#CityType, UrbanDistrictName, Flats.UrbanDistrictName Flats#UrbanDistrictName, UrbanDistrictType, Flats.UrbanDistrictType Flats#UrbanDistrictType, SovietVillageName, Flats.SovietVillageName Flats#SovietVillageName, SovietVillageType, Flats.SovietVillageType Flats#SovietVillageType, LocalityName, Flats.LocalityName Flats#LocalityName, LocalityType, Flats.LocalityType Flats#LocalityType, StreetName, Flats.StreetName Flats#StreetName, StreetType, Flats.StreetType Flats#StreetType, Level1Type, Flats.Level1Type Flats#Level1Type, Level1Value, Flats.Level1Value Flats#Level1Value, Level2Type, Flats.Level2Type Flats#Level2Type, Level2Value, Flats.Level2Value Flats#Level2Value, Level3Type, Flats.Level3Type Flats#Level3Type, Level3Value, Flats.Level3Value Flats#Level3Value, ApartmentType, Flats.ApartmentType Flats#ApartmentType, ApartmentValue, Flats.ApartmentValue Flats#ApartmentValue, LocationOther, Flats.LocationOther Flats#LocationOther, LocationNote, Flats.LocationNote Flats#LocationNote, CostValue, Flats.CostValue Flats#CostValue, CostUnit, Flats.CostUnit Flats#CostUnit, CostDateValuation, Flats.CostDateValuation Flats#CostDateValuation, CostDateEntering, Flats.CostDateEntering Flats#CostDateEntering, CostDateApproval, Flats.CostDateApproval Flats#CostDateApproval, CostDocNumber, Flats.CostDocNumber Flats#CostDocNumber, CostDocDate, Flats.CostDocDate Flats#CostDocDate, CostApplicationDate, Flats.CostApplicationDate Flats#CostApplicationDate, CostRevisalStatementDate, Flats.CostRevisalStatementDate Flats#CostRevisalStatementDate, CostDocName, Flats.CostDocName Flats#CostDocName, Name, Flats.Name Flats#Name, AssignationSpecialType, Flats.AssignationSpecialType Flats#AssignationSpecialType, AssignationTotalAssets, Flats.AssignationTotalAssets Flats#AssignationTotalAssets, AssignationAuxiliaryFlat, Flats.AssignationAuxiliaryFlat Flats#AssignationAuxiliaryFlat, FIAS, Flats.FIAS Flats#FIAS, OKTMO, Flats.OKTMO Flats#OKTMO, LocationRF, Flats.LocationRF Flats#LocationRF, PlanningElementName, Flats.PlanningElementName Flats#PlanningElementName, PlanningElementType, Flats.PlanningElementType Flats#PlanningElementType, CostApplicationLastDate, Flats.CostApplicationLastDate Flats#CostApplicationLastDate, UnitedKN, Flats.UnitedKN Flats#UnitedKN, FacilityKN, Flats.FacilityKN Flats#FacilityKN, FacilityKNPurpose, Flats.FacilityKNPurpose Flats#FacilityKNPurpose, EGROKNRegNum, Flats.EGROKNRegNum Flats#EGROKNRegNum, EGROKNObjCultural, Flats.EGROKNObjCultural Flats#EGROKNObjCultural, EGROKNNameCultural, Flats.EGROKNNameCultural Flats#EGROKNNameCultural, AssignmentEGROKNRegNum, Flats.AssignmentEGROKNRegNum Flats#AssignmentEGROKNRegNum, AssignmentEGROKNObjCultural, Flats.AssignmentEGROKNObjCultural Flats#AssignmentEGROKNObjCultural, AssignmentEGROKNNameCultural, Flats.AssignmentEGROKNNameCultural Flats#AssignmentEGROKNNameCultural, CulturalHeritageRequirements, Flats.CulturalHeritageRequirements Flats#CulturalHeritageRequirements, CodeDocumentEGROKN, Flats.CodeDocumentEGROKN Flats#CodeDocumentEGROKN, DocumentNameEGROKN, Flats.DocumentNameEGROKN Flats#DocumentNameEGROKN, DocumentSeriesEGROKN, Flats.DocumentSeriesEGROKN Flats#DocumentSeriesEGROKN, DocumentNumberEGROKN, Flats.DocumentNumberEGROKN Flats#DocumentNumberEGROKN, DocumentDateEGROKN, Flats.DocumentDateEGROKN Flats#DocumentDateEGROKN, DocumentIssueOrganEGROKN, Flats.DocumentIssueOrganEGROKN Flats#DocumentIssueOrganEGROKN, DocumentDescEGROKN, Flats.DocumentDescEGROKN Flats#DocumentDescEGROKN, OPERATORNAME, Flats.OPERATORNAME Flats#OPERATORNAME, MODIFYDATE, Flats.MODIFYDATE Flats#MODIFYDATE, CREATEOPERATORNAME, Flats.CREATEOPERATORNAME Flats#CREATEOPERATORNAME, CREATEDATE, Flats.CREATEDATE Flats#CREATEDATE, Source_ID, Flats.Source_ID Flats#Source_ID, buildings_ID, Flats.buildings_ID Flats#buildings_ID, Constructions_ID, Flats.Constructions_ID Flats#Constructions_ID, locTypeFloorKv, Flats.locTypeFloorKv Flats#locTypeFloorKv, locNumberFloor, Flats.locNumberFloor Flats#locNumberFloor, locFloorPrim, Flats.locFloorPrim Flats#locFloorPrim, Specific_CadastralCost, Flats.Specific_CadastralCost Flats#Specific_CadastralCost, CadastralCost, Flats.CadastralCost Flats#CadastralCost, CadastralCostDesc, Flats.CadastralCostDesc Flats#CadastralCostDesc, LocCalc_GroupCode, Flats.LocCalc_GroupCode Flats#LocCalc_GroupCode, SourcelocCalc_Group, Flats.SourcelocCalc_Group Flats#SourcelocCalc_Group, locTypeUse, Flats.locTypeUse Flats#locTypeUse, SourcelocTypeUse, Flats.SourcelocTypeUse Flats#SourcelocTypeUse, LocalityCode, Flats.LocalityCode Flats#LocalityCode, MO_Name, Flats.MO_Name Flats#MO_Name, loc_Factor_102, Flats.loc_Factor_102 Flats#loc_Factor_102, loc_Factor_108, Flats.loc_Factor_108 Flats#loc_Factor_108, loc_Factor_109, Flats.loc_Factor_109 Flats#loc_Factor_109, loc_Factor_110, Flats.loc_Factor_110 Flats#loc_Factor_110, ID_Group, Flats.ID_Group Flats#ID_Group, loc_Factor_122, Flats.loc_Factor_122 Flats#loc_Factor_122, loc_Factor_159, Flats.loc_Factor_159 Flats#loc_Factor_159, locTypeUse2, Flats.locTypeUse2 Flats#locTypeUse2, loc_VICode, Flats.loc_VICode Flats#loc_VICode, loc_GroupName, Flats.loc_GroupName Flats#loc_GroupName, loc_VRICode, Flats.loc_VRICode Flats#loc_VRICode, loc_Factor_201, Flats.loc_Factor_201 Flats#loc_Factor_201, Source_loc_Factor_201, Flats.Source_loc_Factor_201 Flats#Source_loc_Factor_201, loc_Factor_202, Flats.loc_Factor_202 Flats#loc_Factor_202, Source_loc_Factor_202, Flats.Source_loc_Factor_202 Flats#Source_loc_Factor_202, Source_loc_Factor_122, Flats.Source_loc_Factor_122 Flats#Source_loc_Factor_122, loc_Factor_203, Flats.loc_Factor_203 Flats#loc_Factor_203, Source_loc_Factor_203, Flats.Source_loc_Factor_203 Flats#Source_loc_Factor_203, Source_loc_Factor_102, Flats.Source_loc_Factor_102 Flats#Source_loc_Factor_102, Source_loc_Factor_110, Flats.Source_loc_Factor_110 Flats#Source_loc_Factor_110, loc_Factor_204, Flats.loc_Factor_204 Flats#loc_Factor_204, Source_loc_Factor_204, Flats.Source_loc_Factor_204 Flats#Source_loc_Factor_204, Source_loc_Factor_108, Flats.Source_loc_Factor_108 Flats#Source_loc_Factor_108, Source_loc_Factor_109, Flats.Source_loc_Factor_109 Flats#Source_loc_Factor_109, loc_Factor_205, Flats.loc_Factor_205 Flats#loc_Factor_205, Source_loc_Factor_205, Flats.Source_loc_Factor_205 Flats#Source_loc_Factor_205, loc_Factor_206, Flats.loc_Factor_206 Flats#loc_Factor_206, Source_loc_Factor_206, Flats.Source_loc_Factor_206 Flats#Source_loc_Factor_206, loc_Factor_207, Flats.loc_Factor_207 Flats#loc_Factor_207, Source_loc_Factor_207, Flats.Source_loc_Factor_207 Flats#Source_loc_Factor_207, loc_Factor_208, Flats.loc_Factor_208 Flats#loc_Factor_208, Source_loc_Factor_208, Flats.Source_loc_Factor_208 Flats#Source_loc_Factor_208, loc_Factor_209, Flats.loc_Factor_209 Flats#loc_Factor_209, Source_loc_Factor_209, Flats.Source_loc_Factor_209 Flats#Source_loc_Factor_209, loc_Factor_210, Flats.loc_Factor_210 Flats#loc_Factor_210, Source_loc_Factor_210, Flats.Source_loc_Factor_210 Flats#Source_loc_Factor_210, Source_loc_Factor_159, Flats.Source_loc_Factor_159 Flats#Source_loc_Factor_159, locTypeFlat, Flats.locTypeFlat Flats#locTypeFlat, SourcelocTypeFlat, Flats.SourcelocTypeFlat Flats#SourcelocTypeFlat, loc_Factor_211, Flats.loc_Factor_211 Flats#loc_Factor_211, loc_Factor_212, Flats.loc_Factor_212 Flats#loc_Factor_212, inputpacket_id, Flats.inputpacket_id Flats#inputpacket_id, FlatLevelsFis, Flats.FlatLevelsFis Flats#FlatLevelsFis, FlaglocTypeFlat, Flats.FlaglocTypeFlat Flats#FlaglocTypeFlat, FlagLocCalc_GroupCode, Flats.FlagLocCalc_GroupCode Flats#FlagLocCalc_GroupCode, FlagId_Group, Flats.FlagId_Group Flats#FlagId_Group, FlagYearBuilt, Flats.FlagYearBuilt Flats#FlagYearBuilt, FlagLocalityCode, Flats.FlagLocalityCode Flats#FlagLocalityCode, FlagLocFloors, Flats.FlagLocFloors Flats#FlagLocFloors, FlagFlatLavel, Flats.FlagFlatLavel Flats#FlagFlatLavel, FlagCadastralCost, Flats.FlagCadastralCost Flats#FlagCadastralCost, SourceCadastralCost, Flats.SourceCadastralCost Flats#SourceCadastralCost, Status_KC, Flats.Status_KC Flats#Status_KC, Source_EGRN, Flats.Source_EGRN Flats#Source_EGRN, Determin_DateKCS, Flats.Determin_DateKCS Flats#Determin_DateKCS, Count_Floor, Flats.Count_Floor Flats#Count_Floor, SourcelocTypeFloor, Flats.SourcelocTypeFloor Flats#SourcelocTypeFloor, ControlSP, Flats.ControlSP Flats#ControlSP, Orphan, Flats.Orphan Flats#Orphan, FlagParamFlats, Flats.FlagParamFlats Flats#FlagParamFlats, SourceLocalityCode, Flats.SourceLocalityCode Flats#SourceLocalityCode, Date_KC, Flats.Date_KC Flats#Date_KC, Upload_Scroll, Flats.Upload_Scroll Flats#Upload_Scroll, Statement, Flats.Statement Flats#Statement, Type_Statement, Flats.Type_Statement Flats#Type_Statement, Status_Statement, Flats.Status_Statement Flats#Status_Statement, ID_Group2, Flats.ID_Group2 Flats#ID_Group2, Date_comm, Flats.Date_comm Flats#Date_comm, Sol_comm, Flats.Sol_comm Flats#Sol_comm, FlagParent, Flats.FlagParent Flats#FlagParent, Court, Flats.Court Flats#Court, Date_Court, Flats.Date_Court Flats#Date_Court, Sol_Court, Flats.Sol_Court Flats#Sol_Court, inputpacket_date, Flats.inputpacket_date Flats#inputpacket_date from (Select Flats.ID ID, Flats.CadastralNumber CadastralNumber, Flats.DateCreated DateCreated, Flats.CadastralBlock CadastralBlock, Flats.ObjectType ObjectType, Flats.CadastralNumberFlat CadastralNumberFlat, Flats.CadastralNumberOKS CadastralNumberOKS, Flats.ParentOKSCadNum ParentOKSCadNum, Flats.ParentOKSObjectType ParentOKSObjectType, Flats.ParentOKSAssignationBuilding ParentOKSAssignationBuilding, Flats.ParentOKSAssignationName ParentOKSAssignationName, Flats.ExploitationCharYearBuilt ExploitationCharYearBuilt, Flats.ExploitationCharYearUsed ExploitationCharYearUsed, Flats.Floors Floors, Flats.UndergroundFloors UndergroundFloors, Flats.AssignationCode AssignationCode, Flats.AssignationType AssignationType, Flats.Area Area, Flats.PositionNumberOnPlan PositionNumberOnPlan, Flats.PositionDescription PositionDescription, Flats.AddressOrLocation AddressOrLocation, Flats.OKATO OKATO, Flats.KLADR KLADR, Flats.PostalCode PostalCode, Flats.Region Region, Flats.DistrictName DistrictName, Flats.DistrictType DistrictType, Flats.CityName CityName, Flats.CityType CityType, Flats.UrbanDistrictName UrbanDistrictName, Flats.UrbanDistrictType UrbanDistrictType, Flats.SovietVillageName SovietVillageName, Flats.SovietVillageType SovietVillageType, Flats.LocalityName LocalityName, Flats.LocalityType LocalityType, Flats.StreetName StreetName, Flats.StreetType StreetType, Flats.Level1Type Level1Type, Flats.Level1Value Level1Value, Flats.Level2Type Level2Type, Flats.Level2Value Level2Value, Flats.Level3Type Level3Type, Flats.Level3Value Level3Value, Flats.ApartmentType ApartmentType, Flats.ApartmentValue ApartmentValue, Flats.LocationOther LocationOther, Flats.LocationNote LocationNote, Flats.CostValue CostValue, Flats.CostUnit CostUnit, Flats.CostDateValuation CostDateValuation, Flats.CostDateEntering CostDateEntering, Flats.CostDateApproval CostDateApproval, Flats.CostDocNumber CostDocNumber, Flats.CostDocDate CostDocDate, Flats.CostApplicationDate CostApplicationDate, Flats.CostRevisalStatementDate CostRevisalStatementDate, Flats.CostDocName CostDocName, Flats.Name Name, Flats.AssignationSpecialType AssignationSpecialType, Flats.AssignationTotalAssets AssignationTotalAssets, Flats.AssignationAuxiliaryFlat AssignationAuxiliaryFlat, Flats.FIAS FIAS, Flats.OKTMO OKTMO, Flats.LocationRF LocationRF, Flats.PlanningElementName PlanningElementName, Flats.PlanningElementType PlanningElementType, Flats.CostApplicationLastDate CostApplicationLastDate, Flats.UnitedKN UnitedKN, Flats.FacilityKN FacilityKN, Flats.FacilityKNPurpose FacilityKNPurpose, Flats.EGROKNRegNum EGROKNRegNum, Flats.EGROKNObjCultural EGROKNObjCultural, Flats.EGROKNNameCultural EGROKNNameCultural, Flats.AssignmentEGROKNRegNum AssignmentEGROKNRegNum, Flats.AssignmentEGROKNObjCultural AssignmentEGROKNObjCultural, Flats.AssignmentEGROKNNameCultural AssignmentEGROKNNameCultural, Flats.CulturalHeritageRequirements CulturalHeritageRequirements, Flats.CodeDocumentEGROKN CodeDocumentEGROKN, Flats.DocumentNameEGROKN DocumentNameEGROKN, Flats.DocumentSeriesEGROKN DocumentSeriesEGROKN, Flats.DocumentNumberEGROKN DocumentNumberEGROKN, Flats.DocumentDateEGROKN DocumentDateEGROKN, Flats.DocumentIssueOrganEGROKN DocumentIssueOrganEGROKN, Flats.DocumentDescEGROKN DocumentDescEGROKN, Flats.OPERATORNAME OPERATORNAME, Flats.MODIFYDATE MODIFYDATE, Flats.CREATEOPERATORNAME CREATEOPERATORNAME, Flats.CREATEDATE CREATEDATE, Flats.Source_ID Source_ID, Flats.buildings_ID buildings_ID, Flats.Constructions_ID Constructions_ID, Flats.locTypeFloorKv locTypeFloorKv, Flats.locNumberFloor locNumberFloor, Flats.locFloorPrim locFloorPrim, Flats.Specific_CadastralCost Specific_CadastralCost, Flats.CadastralCost CadastralCost, Flats.CadastralCostDesc CadastralCostDesc, Flats.LocCalc_GroupCode LocCalc_GroupCode, Flats.SourcelocCalc_Group SourcelocCalc_Group, Flats.locTypeUse locTypeUse, Flats.SourcelocTypeUse SourcelocTypeUse, Flats.LocalityCode LocalityCode, Flats.MO_Name MO_Name, Flats.loc_Factor_102 loc_Factor_102, Flats.loc_Factor_108 loc_Factor_108, Flats.loc_Factor_109 loc_Factor_109, Flats.loc_Factor_110 loc_Factor_110, Flats.ID_Group ID_Group, Flats.loc_Factor_122 loc_Factor_122, Flats.loc_Factor_159 loc_Factor_159, Flats.locTypeUse2 locTypeUse2, Flats.loc_VICode loc_VICode, Flats.loc_GroupName loc_GroupName, Flats.loc_VRICode loc_VRICode, Flats.loc_Factor_201 loc_Factor_201, Flats.Source_loc_Factor_201 Source_loc_Factor_201, Flats.loc_Factor_202 loc_Factor_202, Flats.Source_loc_Factor_202 Source_loc_Factor_202, Flats.Source_loc_Factor_122 Source_loc_Factor_122, Flats.loc_Factor_203 loc_Factor_203, Flats.Source_loc_Factor_203 Source_loc_Factor_203, Flats.Source_loc_Factor_102 Source_loc_Factor_102, Flats.
