Workbook

Sheet Расчет 14 сегмент
A1: Идентификатор | B1: Кадастровый номер | C1: Номер кадастрового квартала | D1: Площадь в квадратных метрах | E1: Категория земель | F1: Разрешенное использование участка Вид разрешенного использования по классификатору | G1: Вид использования участка по документу | H1: Разрешенное использование участка | I1: Удельный показатель кадастровой стоимости(руб/м2) | J1: Кадастровая стоимость (руб) | K1: Новоя модель | L1: Группа для XML | M1: Код населённого пункта | N1: Код расчета вида использования | O1: Расшифровка расчетной подгруппы | P1: Код Сегмента | Q1: Сегмент | R1: Площадь (ЦФ) | S1: Номер заявления | T1: Тип заявления | U1: Статус заявления | V1: Статус расчета | W1: Дата пакета | X1: ВРИ по правилам | Y1: Новый код сегмента | Z1: новый код сегмента
A2: ID | B2: CadastralNumber | C2: CadastralBlock | D2: Area | E2: ParcelCategory | F2: Utilization | G2: UtilizationByDoc | H2: UtilizationLandUse | I2: Specific_CadastralCost | J2: CadastralCost | K2: New_id_group | L2: ID_Group | M2: LocalityCode | N2: loc_VICode | O2: loc_GroupName | P2: loc_SgCode | Q2: Segment | R2: loc_factor_807 | S2: Statement | T2: Type_Statement | U2: Status_Statement | V2: Status_kc | W2: inputpacket_date | X2: VRICode_NEW | Y2: New_loc_SgCode | Z2: New_loc_SgCode
A3: Parcels | B3: Parcels | C3: Parcels | D3: Parcels | E3: Parcels | F3: Parcels | G3: Parcels | H3: Parcels | I3: Parcels | J3: Parcels | K3: Parcels | L3: Parcels | M3: Parcels | N3: Parcels | O3: Parcels | P3: Parcels | Q3: Parcels | R3: Parcels | S3: Parcels | T3: Parcels | U3: Parcels | V3: Parcels | W3: Parcels | X3: Parcels | Y3: Parcels | Z3: Parcels
E4: spr | F4: spr | H4: spr | AA4: НП | AB4: МО | AC4: Ср. УПКС по кварталу | AD4: Ср. УПКС по нп | AE4: Ср. упкс по мо | AF4: Ср. УПКС (сведенный) | AG4: Кадастовая стоимость | AH4: Кадастровая стоимость описание вых | AI4: Средний УПКС (ЦФ) | AJ4: Статус расчета
A5: 2444605 | B5: 66:00:0000000:1857 | C5: 66:00:0000000 | D5: 17124998 | E5: Земли сельскохозяйственного назначения | F5: Для иных видов сельскохозяйственного использования | G5: под сельскохозяйственное производство | I5: 3.38 | J5: 57882493 | K5: 8010 | L5: 8010 | M5: 07:000:0:0:0 | N5: 01:998 | O5: Сельскохозяйственное производство | P5: 1.2 | Q5: 1. СЕГМЕНТ "Сельскохозяйственное использование" | R5: 17124998 | W5: 01.01.2020 | AA5: =VLOOKUP(M:M,'справочник нп'!H:I,2,0) -> Белоярский городской округ | AB5: =VLOOKUP(M:M,'справочник нп'!H:P,9,0) -> Белоярский городской округ | AC5: =IFERROR(VLOOKUP(C:C,'ср.УПКС по кварталу '!A:B,2,0),"") | AD5: =IFERROR(VLOOKUP(M:M,'ср. упкс по нп'!A:B,2,0),"") | AE5: =IFERROR(VLOOKUP(AB:AB,'ср.упкс по МО'!A:B,2,0),"") -> 303.20637 | AF5: =ROUND(IF(AC5<>"",AC5,IF(AD5<>"",AD5,AE5)),2) -> 303.21 | AG5: =ROUND((AF5*D5),2) -> 5.1924706e+09 | AH5: =IF((AG5=J5),"","10 модель, 16 статья") -> 10 модель, 16 статья | AI5: =IF((AG5=J5),"",AF5) -> 303.21 | AJ5: =IF(AH5="","пересчет не требуется","готово") -> готово
A6: Select ID,Source_ID,CadastralNumber,DateCreated,CadastralBlock,Name,ObjectType,Area,AreaUnit,AreaInaccuracy,LocationinBounds,LocationPlaced,ElaborationReferenceMark,ElaborationDistance,ElaborationDirection,AddressOrLocation,FIAS,OKATO,KLADR,OKTMO,PostalCode,AddressRF,Region,DistrictName,DistrictType,CityName,CityType,UrbanDistrictName,UrbanDistrictType,SovietVillageName,SovietVillageType,LocalityName,LocalityType,PlanningElementName,PlanningElementType,StreetName,StreetType,Level1Type,Level1Value,Level2Type,Level2Value,Level3Type,Level3Value,ApartmentType,ApartmentValue,AddressOther,AddressNote,ParcelCategory,Utilization,UtilizationByDoc,UtilizationLandUse,UtilizationТхт,CostValue,CostUnit,CostDateValuation,CostDateEntering,CostDateApproval,CostDocNumber,CostDocDate,CostApplicationDate,CostRevisalStatementDate,CostApplicationLastDate,CostDocName,FacilityKN,FacilityKNPurpose,SurveyProjectNum,DecisionCodeDocument,DecisionName,DecisionSeries,DecisionNumber,DecisionDate,DecisionIssueOrgan,DecisionDesc,HiredHouseUse,HouseActBuilding,HouseActDevelopment,BuildingContractName,DevelopContractName,OwnerDecision,SupportContractName,CodeDocument,DocHiredHouseName,DocHiredHouseSeries,DocHiredHouseNumber,DocHiredHouseDate,DocHiredHouseIssueOrgan,DocHiredHouseDesc,LimitedRightNumber,CREATEOPERATORNAME,CREATEDATE,OPERATORNAME,MODIFYDATE,MI_STYLE,Specific_CadastralCost,CadastralCost,CadastralCostDesc,MO_Name,ID_Group,LocalityCode,locTypeUse2,loc_VICode,loc_GroupName,loc_VRICode,Sourse_loc_VICode,locTypeUse,inputpacket_id,loc_SgCode,VIP_Sp,Quant_Kontur,Quant_Point,Sum_Square,Sum_Perim,Proc_Diff_Square,Pr_Diff,Source_Sum_Square,SourceLocalityCode,Upload_Scroll,Date_KC,Segment,FlagLocalityCode,DistanceToRoad,DistanceToCMO,СМО,PresenceGas,SourcePresenceGas,PresenceHeating,SourcePresenceHeating,PresencePower,SourcePresencePower,PresenceWaterDisposal,SourcePresenceWaterDisposal,PresenceWaterSupply,SourcePresenceWaterSupply,DistanceToEKB,DistanceToRoadEKB,CCoordX,CCoordY,DistanceToMetro,DistanceToStationEKB,CostZone,DistanceToRRStation,costzone2,Textloc_VICode,act_sign,MaxFloor,Enc_squre,Enc_proc,Adm_rn_EKB,forestry,InfluenceZone_IGS,loc_factor_801,loc_factor_802,loc_factor_803,loc_factor_804,loc_factor_806,loc_factor_807,loc_factor_8071,loc_factor_809,loc_factor_8091,loc_factor_810,loc_factor_8101,loc_factor_811,loc_factor_8111,loc_factor_812,loc_factor_8121,loc_factor_813,loc_factor_814,loc_factor_815,loc_factor_816,loc_factor_8161,loc_factor_817,loc_factor_818,loc_factor_819,loc_factor_820,loc_factor_8201,loc_factor_821,loc_factor_822,loc_factor_823,loc_factor_8231,loc_factor_824,loc_factor_825,loc_factor_826,loc_factor_827,loc_factor_828,loc_factor_829,loc_factor_830,loc_factor_831,loc_factor_832,loc_factor_833,loc_factor_8331,loc_factor_835,loc_factor_836,loc_factor_837,loc_factor_838,Statement,Type_Statement,Status_Statement,DistanceToVZC,VRI_IGS,Cot_name,DistanceToZTB,PowerLines,loc_factor_839,KodMO,loc_factor_840,loc_factor_841,presence_entrance,loc_factor_8371,ControlSP,Sp_flag,loc_VRICode540,Status_kc,Date_comm,Sol_comm,Flag_LocalityCode,Flag_VRI,Flag_Location,FlagParam,Flag_VRIoldspr,Flag_VRInewspr,Flag_Category,OldLocalityCode,Flag_VRI_All,VRICode_NEW,PraviloVRI,New_id_group,New_loc_SgCode,New_Segment,Old_Utlbydoc,VRICode_OLD,PraviloVRI_old,Court,Date_Court,Sol_Court,(select (case count(*) when 0 then 0 else 1 end) from GEO.docboxes b where b.obj_id=PARCELS.ID and b.table_id=265) Attachment,(select sign(Count(*)) from PARCELS g where (not GEOM_OBJ is null) and (PARCELS.ID = g.ID)) GeometryExists,((select DatePacket from inputpacket where id=Parcels.inputpacket_id) ) [inputpacket_date] From PARCELS where status_kc='НЕ ГОТОВ'

Sheet справочник нп
A1: Идентификатор | B1: CadastralNumber | C1: MO_Type | D1: MO_Locality | E1: Road | F1: Road_Distance | G1: Descript | H1: Код НП | I1: Наименование НП | J1: Префикс НП | K1: MO | L1: Change_zak | M1: Old_Code | N1: New_Code | O1: Управленческий округ | P1: Полное наименование МО | Q1: Код МО
A2: 1 | B2: 66:01:3902006 | C2: Район | D2: Алапаевский | F2: 0 | G2: 0 жителей | H2: 49:018:2:5:6 | I2: Грязнуха | J2: д | K2: Алапаевское | O2: Восточный управленческий округ | P2: Муниципальное образование Алапаевское | Q2: =MID(H2,1,2) -> 49
A3: 2 | B3: 66:04:0101010 | C3: Район | D3: Ачитский | F3: 0 | G3: нежилой | H3: 00:002:0:0:0 | I3: Верх-Бисертский Ут | J3: б.н.п. | K3: Ачитский | L3: б.н.п. | N3: 05:000:0:0:0 | O3: Западный управленческий округ | P3: Ачитский городской округ | Q3: =MID(H3,1,2) -> 00
A4: 3 | B4: 66:05:0102002 | C4: Район | D4: Байкаловский | F4: 0 | G4: нет населения | H4: 06:038:2:5:6 | I4: Лукина | J4: д | K4: Байкаловский | O4: Восточный управленческий округ | P4: Байкаловский муниципальный район | Q4: =MID(H4,1,2) -> 06
A5: 4 | B5: 66:05:0402004 | C5: Район | D5: Байкаловский | F5: 0 | G5: нежилой | H5: 00:003:0:0:0 | I5: Орлова | J5: б.н.п. | K5: Байкаловский | L5: б.н.п. | N5: 06:000:0:0:0 | O5: Восточный управленческий округ | P5: Байкаловский муниципальный район | Q5: =MID(H5,1,2) -> 00
A6: 5 | B6: 66:05:0404005 | C6: Район | D6: Байкаловский | F6: 0 | G6: нежилой | H6: 06:015:2:5:6 | I6: Занина | J6: д | K6: Байкаловский | O6: Восточный управленческий округ | P6: Байкаловский муниципальный район | Q6: =MID(H6,1,2) -> 06
A7: 6 | B7: 66:08:0101006 | C7: Район | D7: Верхнесалдинский | F7: 0 | G7: нет жителей | H7: 10:009:2:5:6 | I7: Кокшарово | J7: д | K7: Верхнесалдинский | O7: Горнозаводской управленческий округ | P7: Верхнесалдинский городской округ | Q7: =MID(H7,1,2) -> 10
A8: 7 | B8: 66:09:2002005 | C8: Район | D8: Верхотурский | F8: 0 | G8: нет жителей | H8: 22:044:2:5:6 | I8: Шумкова | J8: д | K8: Верхотурский | O8: Северный управленческий округ | P8: Городской округ Верхотурский | Q8: =MID(H8,1,2) -> 22
A9: 8 | B9: 66:10:0101003 | C9: Район | D9: Гаринский | F9: 0 | G9: по реке | H9: 12:013:2:5:6 | I9: Кондратьева | J9: д | K9: Гаринский | O9: Северный управленческий округ | P9: Гаринский городской округ | Q9: =MID(H9,1,2) -> 12
A10: 9 | B10: 66:10:0102005 | C10: Район | D10: Гаринский | F10: 0 | G10: только по реке | H10: 12:012:2:3:6 | I10: Киня | J10: п | K10: Гаринский | O10: Северный управленческий округ | P10: Гаринский городской округ | Q10: =MID(H10,1,2) -> 12
A11: 10 | B11: 66:10:0102008 | C11: Район | D11: Гаринский | F11: 0 | G11: только по реке | H11: 12:005:2:5:6 | I11: Векшина | J11: д | K11: Гаринский | O11: Северный управленческий округ | P11: Гаринский городской округ | Q11: =MID(H11,1,2) -> 12
A12: 11 | B12: 66:10:0102011 | C12: Район | D12: Гаринский | F12: 0 | G12: только по реке | H12: 12:030:2:5:6 | I12: Пантелеева | J12: д | K12: Гаринский | O12: Северный управленческий округ | P12: Гаринский городской округ | Q12: =MID(H12,1,2) -> 12
A13: 12 | B13: 66:10:0102012 | C13: Район | D13: Гаринский | F13: 0 | G13: только по реке | H13: 12:011:2:5:6 | I13: Каргаева | J13: д | K13: Гаринский | O13: Северный управленческий округ | P13: Гаринский городской округ | Q13: =MID(H13,1,2) -> 12
A14: 13 | B14: 66:10:0201001 | C14: Район | D14: Гаринский | F14: 0 | G14: только по реке | H14: 12:042:2:5:6 | I14: Шантальская | J14: д | K14: Гаринский | O14: Северный управленческий округ | P14: Гаринский городской округ | Q14: =MID(H14,1,2) -> 12
A15: 14 | B15: 66:10:0301001 | C15: Район | D15: Гаринский | F15: 0 | G15: только по реке | H15: 12:029:2:3:6 | I15: Новый Вагиль | J15: п | K15: Гаринский | O15: Северный управленческий округ | P15: Гаринский городской округ | Q15: =MID(H15,1,2) -> 12
A16: 15 | B16: 66:10:0401001 | C16: Район | D16: Гаринский | F16: 0 | G16: только по реке | H16: 12:019:2:3:6 | I16: Ликино | J16: п | K16: Гаринский | O16: Северный управленческий округ | P16: Гаринский городской округ | Q16: =MID(H16,1,2) -> 12
A17: 16 | B17: 66:10:0501001 | C17: Район | D17: Гаринский | F17: 0 | G17: только по реке | H17: 12:008:2:4:6 | I17: Еремино | J17: с | K17: Гаринский | O17: Северный управленческий округ | P17: Гаринский городской округ | Q17: =MID(H17,1,2) -> 12
... A29: 28 | B29: 66:19:0101003 | C29: город | D29: Нижний Тагил | F29: 0 | G29: только по реке | H29: 14:011:2:5:6 | I29: Заречная | J29: д | K29: Нижний Тагил | O29: Горнозаводской управленческий округ | P29: Город Нижний Тагил | Q29: =MID(H29,1,2) -> 14
A30: 29 | B30: 66:22:0107001 | C30: Район | D30: Режевский | F30: 0 | G30: это не село, это плотина | H30: 00:004:0:0:0 | I30: Черемисское | J30: б.н.п. | K30: Режевской | L30: б.н.п. | N30: 62:000:0:0:0 | O30: Восточный управленческий округ | P30: Режевской городской округ | Q30: =MID(H30,1,2) -> 00
A31: 30 | B31: 66:23:0501005 | C31: город | D31: Серов | F31: 0 | G31: только по реке | H31: 64:030:2:3:6 | I31: Танковичи | J31: п | K31: Серов | O31: Северный управленческий округ | P31: Серовский городской округ | Q31: =MID(H31,1,2) -> 64
A32: 31 | B32: 66:23:0501006 | C32: город | D32: Серов | F32: 0 | G32: только по реке | H32: 64:029:2:5:6 | I32: Масловка | J32: д | K32: Серов | O32: Северный управленческий округ | P32: Серовский городской округ | Q32: =MID(H32,1,2) -> 64
A33: 32 | B33: 66:23:2404004 | C33: Район | D33: Серовский | F33: 0 | G33: нет жителей | H33: 66:024:2:3:6 | I33: Чары | J33: п | K33: Сосьвинский | O33: Северный управленческий округ | P33: Сосьвинский городской округ | Q33: =MID(H33,1,2) -> 66
A34: 33 | B34: 66:23:2404008 | C34: Район | D34: Серовский | F34: 0 | G34: нет жителей | H34: 66:020:2:5:6 | I34: Тюменская | J34: д | K34: Сосьвинский | O34: Северный управленческий округ | P34: Сосьвинский городской округ | Q34: =MID(H34,1,2) -> 66
A35: 34 | B35: 66:24:0804002 | C35: Район | D35: Слободо-Туринский | F35: 0 | G35: нежилой НП | H35: 00:005:0:0:0 | I35: Кадцина | J35: б.н.п. | K35: Слободо-Туринский | L35: б.н.п. | N35: 65:000:0:0:0 | O35: Восточный управленческий округ | P35: Слободо-Туринский муниципальный район | Q35: =MID(H35,1,2) -> 00
A36: 35 | B36: 66:26:0101002 | C36: Район | D36: Таборинский | F36: 0 | G36: нежилой НП | H36: 00:006:0:0:0 | I36: Гришино | J36: б.н.п. | K36: Таборинский | L36: б.н.п. | N36: 68:000:0:0:0 | O36: Восточный управленческий округ | P36: Таборинский муниципальный район | Q36: =MID(H36,1,2) -> 00
A37: 36 | B37: 66:26:0102002 | C37: Район | D37: Таборинский | F37: 0 | G37: нежилой НП | H37: 00:007:0:0:0 | I37: Кошня | J37: б.н.п. | K37: Таборинский | L37: б.н.п. | N37: 68:000:0:0:0 | O37: Восточный управленческий округ | P37: Таборинский муниципальный район | Q37: =MID(H37,1,2) -> 00
A38: 37 | B38: 66:26:0301001 | C38: Район | D38: Таборинский | F38: 0 | G38: речное сообщение | H38: 68:033:2:3:6 | I38: Якшино | J38: п | K38: Таборинский | O38: Восточный управленческий округ | P38: Таборинский муниципальный район | Q38: =MID(H38,1,2) -> 68
A39: 38 | B39: 66:26:0401001 | C39: Район | D39: Таборинский | F39: 0 | G39: речное сообщение | H39: 68:028:2:5:6 | I39: Чернавская | J39: д | K39: Таборинский | O39: Восточный управленческий округ | P39: Таборинский муниципальный район | Q39: =MID(H39,1,2) -> 68
A40: 39 | B40: 66:26:0802002 | C40: Район | D40: Таборинский | F40: 0 | G40: нежилой НП | H40: 00:008:0:0:0 | I40: Шишино | J40: б.н.п. | K40: Таборинский | L40: б.н.п. | N40: 68:000:0:0:0 | O40: Восточный управленческий округ | P40: Таборинский муниципальный район | Q40: =MID(H40,1,2) -> 00
A41: 40 | B41: 66:26:0803008 | C41: Район | D41: Таборинский | F41: 0 | G41: нежилой НП | H41: 00:009:0:0:0 | I41: Петровская | J41: б.н.п. | K41: Таборинский | L41: б.н.п. | N41: 68:000:0:0:0 | O41: Восточный управленческий округ | P41: Таборинский муниципальный район | Q41: =MID(H41,1,2) -> 00
A42: 41 | B42: 66:27:0102017 | C42: Район | D42: Тавдинский | F42: 0 | G42: нежилой НП | H42: 00:010:0:0:0 | I42: Сергино | J42: б.н.п. | K42: Тавдинский | L42: б.н.п. | N42: 69:000:0:0:0 | O42: Восточный управленческий округ | P42: Тавдинский городской округ | Q42: =MID(H42,1,2) -> 00
A43: 42 | B43: 66:31:0101011 | C43: Район | D43: Шалинский | F43: 0 | G43: только ж/д путем | H43: 73:005:2:3:6 | I43: Глухарь | J43: п | K43: Шалинский | O43: Западный управленческий округ | P43: Шалинский городской округ | Q43: =MID(H43,1,2) -> 73
A44: 43 | B44: 66:43:0201007 | C44: город | D44: Ивдель | F44: 0 | G44: только речное сообщение | H44: 38:025:2:3:6 | I44: Хандыбина Юрта | J44: п | K44: Ивдель | O44: Северный управленческий округ | P44: Ивдельский городской округ | Q44: =MID(H44,1,2) -> 38
A45: 44 | B45: 66:43:0201008 | C45: город | D45: Ивдель | F45: 0 | G45: автозимник | H45: 38:030:2:3:6 | I45: Юрта Курикова | J45: п | K45: Ивдель | O45: Северный управленческий округ | P45: Ивдельский городской округ | Q45: =MID(H45,1,2) -> 38
A46: 45 | B46: 66:43:0201009 | C46: город | D46: Ивдель | F46: 0 | G46: нежилой НП | H46: 00:011:0:0:0 | I46: Верхний Пелым | J46: б.н.п. | K46: Ивдель | L46: б.н.п. | N46: 38:000:0:0:0 | O46: Северный управленческий округ | P46: Ивдельский городской округ | Q46: =MID(H46,1,2) -> 00
A47: 46 | B47: 66:43:0201018 | C47: город | D47: Ивдель | F47: 0 | G47: нежилой НП | H47: 00:012:0:0:0 | I47: Третий Северный | J47: б.н.п. | K47: Ивдель | L47: б.н.п. | N47: 38:000:0:0:0 | O47: Северный управленческий округ | P47: Ивдельский городской округ | Q47: =MID(H47,1,2) -> 00
A48: 47 | B48: 66:43:0301002 | C48: город | D48: Ивдель | F48: 0 | G48: нежилой НП | H48: 00:013:0:0:0 | I48: Юрта Пеликова | J48: б.н.п. | K48: Ивдель | L48: б.н.п. | N48: 38:000:0:0:0 | O48: Северный управленческий округ | P48: Ивдельский городской округ | Q48: =MID(H48,1,2) -> 00
A49: 48 | B49: 66:43:0301007 | C49: город | D49: Ивдель | F49: 0 | G49: нежилой НП | H49: 00:015:0:0:0 | I49: Бор | J49: б.н.п. | K49: Ивдель | L49: б.н.п. | N49: 38:000:0:0:0 | O49: Северный управленческий округ | P49: Ивдельский городской округ | Q49: =MID(H49,1,2) -> 00
A50: 49 | B50: 66:43:0301010 | C50: город | D50: Ивдель | F50: 0 | G50: нежилой НП | H50: 00:016:0:0:0 | I50: Новошипичный | J50: б.н.п. | K50: Ивдель | L50: б.н.п. | N50: 38:000:0:0:0 | O50: Северный управленческий округ | P50: Ивдельский городской округ | Q50: =MID(H50,1,2) -> 00
A51: 50 | B51: 66:43:0301017 | C51: город | D51: Ивдель | F51: 0 | G51: нежилой НП | H51: 00:017:0:0:0 | I51: Улымсос | J51: б.н.п. | K51: Ивдель | L51: б.н.п. | N51: 38:000:0:0:0 | O51: Северный управленческий округ | P51: Ивдельский городской округ | Q51: =MID(H51,1,2) -> 00
...

Sheet ср.упкс по МО
A1: МО | B1: ср УПКС
A2: Арамильский городской округ | B2: 948.73396
A3: Артемовский городской округ | B3: 284.56947
A4: Артинский городской округ | B4: 155.292
A5: Асбестовский городской округ | B5: 372.69116
A6: Ачитский городской округ | B6: 129.08845
A7: Байкаловский муниципальный район | B7: 167.29563
A8: Белоярский городской округ | B8: 303.20637
A9: Березовский городской округ | B9: 676.41801
A10: Бисертский городской округ | B10: 239.06644
A11: Верхнесалдинский городской округ | B11: 338.7198
A12: Волчанский городской округ | B12: 281.42478
A13: Гаринский городской округ | B13: 98.349216
... A74: Шалинский городской округ | B74: 168.96776

Sheet ср. упкс по нп
A1: LOCALITYCODE | B1: ср УПКС
A2: 01:001:1:1:4 | B2: 1032.3995
A3: 01:002:2:3:5 | B3: 657.9575
A4: 01:003:2:3:5 | B4: 628.3592
A5: 02:001:1:1:4 | B5: 346.37436
A6: 02:002:2:4:6 | B6: 163.50138
A7: 02:003:2:3:6 | B7: 58.440667
A8: 02:004:2:3:6 | B8: 44.476915
A9: 02:005:2:4:6 | B9: 166.6876
A10: 02:006:2:4:6 | B10: 155.78807
A11: 02:007:2:3:6 | B11: 3.49
A12: 02:008:2:3:6 | B12: 332.72133
A13: 02:009:2:5:6 | B13: 154.05729
... A1820: 73:039:2:5:6 | B1820: 145.95067

Sheet ср.УПКС по кварталу 
A1: Квартал | B1: ср УПКС
A2: 66:30:1203001 | B2: 174.48877
A3: 66:20:3801001 | B3: 171.41031
A4: 66:22:1909008 | B4: 517.61109
A5: 66:35:0219011 | B5: 286.41489
A6: 66:02:2301020 | B6: 184.534
A7: 66:16:2601039 | B7: 228.15429
A8: 66:47:0406004 | B8: 49.2576
A9: 66:02:1701018 | B9: 383.17461
A10: 66:41:0503018 | B10: 608.06
A11: 66:01:5601001 | B11: 207.54203
A12: 66:07:1407004 | B12: 64.264722
A13: 66:59:0209002 | B13: 338.52109
... A15271: 66:12:3919002 | B15271: 3.6108333
