Workbook

Sheet Объекты оценки
A1: Идентификатор | B1: Кадастровый номер | C1: Вид объекта недвижимости | D1: Площадь в квадратных метрах | E1: Адрес (местоположение) Иное | F1: Адрес (местоположение) Неформализованное описание | G1: Категория земель | H1: Разрешенное использование участка Вид разрешенного использования по классификатору | I1: Вид использования участка по документу | J1: Разрешенное использование участка | K1: Разрешенное использование (текстовое описание) | L1: Кадастровая стоимость | M1: Дата определения кадастровой стоимости | N1: Удельный показатель кадастровой стоимости(руб/м2) | O1: Кадастровая стоимость (руб) | P1: Кадастровая стоимость описание вых | Q1: Группа для XML | R1: Код населённого пункта | S1: Код расчета вида использования | T1: Расшифровка расчетной подгруппы | U1: Сегмент | V1: Расстояние до дороги | W1: Расстояние до центра МО | X1: Наличие отопления | Y1: Наличие электроснабжения | Z1: Наличие водоотведения | AA1: Расстояние до метро | AB1: Расстояние до остановки общественного транспорта | AC1: Ценовой пояс ЕКБ | AD1: Признак актуальности | AE1: Дата пакета | AF1: Ценовой пояс (ЦФ) | AG1: Теплоснабжение (ЦФ) | AH1: Водоотведение (ЦФ) | AI1: Электроснабжение (ЦФ) | AJ1: Отношение ВРИ к сегменту (ЦФ) | AK1: Площадь (ЦФ) | AL1: Поправка на площадь (ЦФ) | AM1: Расстояние до метро (ЦФ) | AN1: Расстояние до остановок (ЦФ) | AO1: Расстояние до дороги (ЦФ) | AP1: Расстояние до административного центра МО (ЦФ) | AQ1: Номер заявления | AR1: Тип заявления | AS1: Статус заявления | AT1: Площадь обременений (ЦФ) | AU1: Особый контроль | AV1: Дата комиссии | AW1: Решение комиссии | AX1: Статус расчета | AY1: НЕ Используется | AZ1: Флаг ВРИ по документу | BA1: Флаг Местоположения (координат) | BB1: Флаг площади | BC1: Флаг ВРИ старый спр | BD1: Флаг ВРИ новый спр | BE1: Флаг Категории ЗУ | BF1: Старый код НП | BG1: Флаг переопределения ФРИ | BH1: ВРИ по правилам | BI1: Правило | BJ1: Новоя модель | BK1: Новый сегмент | BL1: Дата оценки | BO1: ОПРЕДЕЛЕНИЕ ЦФ В РАМКАХ СТАТЬИ 16 | BZ1: х1 | CA1: х2 | CB1: х3 | CC1: х4 | CD1: х5 | CE1: х6 | CF1: х7 | CG1: х8 | CH1: х9 | CI1: х10 | CJ1: x11 | CM1: МЕЖЕВАНИЕ | CO1: ИТОГ | CS1: 8003 | CT1: ТОРГ | CW1: СРАВНЕНИЕ РЕЗУЛЬТАТОВ 16СТ С ДАННЫМИ НА 01012020 В СЛУЧАЕ НАЛИЧИЯ ПРЕДЫДУЩИХ РАСЧЕТОВ НА 01012020 | DJ1: Ф5 | DK1: =CONCATENATE("М",RIGHT(CS1,1)) -> М3 | DL1: 02032021 | DM1: Мухамедьярова | DO1: ДАННЫЕ ДЛЯ ЗАГРУЗКИ В БАЗУ | EV1: КОНТРОЛЬНАЯ ПРОВЕРКА | EW1: ГОТОВО | EX1: ПЕРЕСЧЕТ НЕ ТРЕБУЕТСЯ | EY1: СТОПЛИСТ
A2: ID | B2: CadastralNumber | C2: ObjectType | D2: Area | E2: AddressOther | F2: AddressNote | G2: ParcelCategory | H2: Utilization | I2: UtilizationByDoc | J2: UtilizationLandUse | K2: UtilizationТхт | L2: CostValue | M2: CostDateValuation | N2: Specific_CadastralCost | O2: CadastralCost | P2: CadastralCostDesc | Q2: ID_Group | R2: LocalityCode | S2: loc_VICode | T2: loc_GroupName | U2: Segment | V2: DistanceToRoad | W2: DistanceToCMO | X2: PresenceHeating | Y2: PresencePower | Z2: PresenceWaterDisposal | AA2: DistanceToMetro | AB2: DistanceToStationEKB | AC2: CostZone | AD2: act_sign | AE2: inputpacket_date | AF2: loc_factor_801 | AG2: loc_factor_802 | AH2: loc_factor_803 | AI2: loc_factor_804 | AJ2: loc_factor_806 | AK2: loc_factor_807 | AL2: loc_factor_8071 | AM2: loc_factor_809 | AN2: loc_factor_810 | AO2: loc_factor_811 | AP2: loc_factor_812 | AQ2: Statement | AR2: Type_Statement | AS2: Status_Statement | AT2: loc_factor_839 | AU2: ControlSP | AV2: Date_comm | AW2: Sol_comm | AX2: Status_kc | AY2: Flag_LocalityCode | AZ2: Flag_VRI | BA2: Flag_Location | BB2: FlagParam | BC2: Flag_VRIoldspr | BD2: Flag_VRInewspr | BE2: Flag_Category | BF2: OldLocalityCode | BG2: Flag_VRI_All | BH2: VRICode_NEW | BI2: PraviloVRI | BJ2: New_id_group | BK2: New_Segment | BL2: Date_KC | BO2: loc_factor_801 | BP2: loc_factor_804 | BQ2: loc_factor_802 | BR2: loc_factor_803 | BS2: loc_factor_806 | BT2: loc_factor_807 | BU2: loc_factor_809 | BV2: loc_factor_810 | BW2: loc_factor_811 | BX2: loc_factor_812 | CE2: loc_factor_8071 | CF2: loc_factor_8091 | CG2: loc_factor_8101 | CH2: loc_factor_8111 | CI2: loc_factor_8121 | CJ2: loc_factor_839 | CO2: Specific_CadastralCost | CP2: CadastralCost | CQ2: CadastralCostDesc | CR2: CadastralNumber | CS2: id_group | CT2: loc_factor_827 | CU2: МЕЖЕВАНИЕ | DJ2: ОПИСАНИЕ КС | DO2: Кадастровый номер | DP2: Ценовой пояс | DQ2: Электроснабжение | DR2: Теплоснабжение | DS2: Водоотведение | DT2: Отношение ВРИ к сегменту | DU2: Общая площадь, м2 | DV2: Расстояние до метро, км | DW2: Расстояние до остановок, км | DX2: Расстояние до дорог, км | DY2: Расстояние до центра, км | DZ2: Общая площадь, поправочный коэффициент | EA2: Расстояние до метро, поправочный коэффициент | EB2: Расстояние до остановок, поправочный коэффициент | EC2: Расстояние до дорог, поправочный коэффициент | ED2: Расстояние до центра, поправочный коэффициент | EE2: Площадь обременений | EF2: УПКС, руб/м2 | EG2: КС, руб. | EH2: Описание КС | EI2: Группа xml | EJ2: Уторгование | EK2: Статус расчета | EL2: Сегмент | EM2: Код сегмента | EN2: ВРИ | EO2: Расшифровка расчетной подгруппы | EP2: Вид использования учтенный при ТЕКУЩЕМ расчете в рамках 16 статьи для загрузки в базу (в базе название колонки "ВРИ по документу старое") | EQ2: ИЗМЕНЕНИЕ КС | ER2: ИЗМЕНЕНИЕ, руб. | ES2: Старый/Новый объект | EW2: =IF(EW3="ОТСУТСТВУЮТ","-",EW3=ГОТОВ!AD1) -> FALSE | EX2: =IF(EX3="ОТСУТСТВУЮТ","-",EX3='ПЕРЕСЧЕТ НЕ ТРЕБУЕТСЯ'!I1) -> - | EY2: =IF(EY3="ОТСУТСТВУЮТ","-",EY3=СТОПЛИСТ!D1) -> -
A3: PARCELS | B3: PARCELS | C3: PARCELS | D3: PARCELS | E3: PARCELS | F3: PARCELS | G3: PARCELS | H3: PARCELS | I3: PARCELS | J3: PARCELS | K3: PARCELS | L3: PARCELS | M3: PARCELS | N3: PARCELS | O3: PARCELS | P3: PARCELS | Q3: PARCELS | R3: PARCELS | S3: PARCELS | T3: PARCELS | U3: PARCELS | V3: PARCELS | W3: PARCELS | X3: PARCELS | Y3: PARCELS | Z3: PARCELS | AA3: PARCELS | AB3: PARCELS | AC3: PARCELS | AD3: PARCELS | AE3: PARCELS | AF3: PARCELS | AG3: PARCELS | AH3: PARCELS | AI3: PARCELS | AJ3: PARCELS | AK3: PARCELS | AL3: PARCELS | AM3: PARCELS | AN3: PARCELS | AO3: PARCELS | AP3: PARCELS | AQ3: PARCELS | AR3: PARCELS | AS3: PARCELS | AT3: PARCELS | AU3: PARCELS | AV3: PARCELS | AW3: PARCELS | AX3: PARCELS | AY3: PARCELS | AZ3: PARCELS | BA3: PARCELS | BB3: PARCELS | BC3: PARCELS | BD3: PARCELS | BE3: PARCELS | BF3: PARCELS | BG3: PARCELS | BH3: PARCELS | BI3: PARCELS | BJ3: PARCELS | BK3: PARCELS | BL3: PARCELS | BM3: Объекты МУГИСО | BN3: Наличие/отсутствие коммуникаций по допущению | BO3: Ценовой пояс | BP3: Электроснабжение | BQ3: Теплоснабжение | BR3: Водоотведение | BS3: Отношение ВРИ к сегменту | BT3: Общая площадь, м2 | BU3: Расстояние до метро, км | BV3: Расстояние до остановок, км | BW3: Расстояние до дорог, км | BX3: Расстояние до центра, км | BY3: Константа | BZ3: Ценовой пояс, поправочный коэффициент | CA3: Электроснабжение, поправочный коэффициент | CB3: Теплоснабжение, поправочный коэффициент | CC3: Водоотведение, поправочный коэффициент | CD3: Отношение к сегменту, поправочный коэффициент | CE3: Общая площадь, поправочный коэффициент | CF3: Расстояние до метро, поправочный коэффициент | CG3: Расстояние до остановок, поправочный коэффициент | CH3: Расстояние до дорог, поправочный коэффициент | CI3: Расстояние до центра, поправочный коэффициент | CJ3: Площадь обременений | CK3: УПКС, руб/м2 | CL3: УПКС с учетом поправки на уторгование, руб/м2 на 2020 | CM3: УПКС по межеванию | CN3: УПКС с учетом поправки на уторгование И ОБРЕМЕНЕНИЕ, руб/м2 на 2020 | CO3: УПКС с учетом поправки на уторгование И ОБРЕМЕНЕНИЕ И МЕЖЕВАНИЕ, руб/м2 на 2020 | CP3: КС, руб. на 2020 | CQ3: Описание КС | CR3: КН | CS3: Группа хмл | CT3: 0.75 | CU3: 0.12 | CV3: 13117.78 | CW3: Ценовой пояс | CX3: Электроснабжение | CY3: Теплоснабжение | CZ3: Водоотведение | DA3: Отношение ВРИ к сегменту | DB3: Общая площадь, м2 | DC3: Расстояние до метро, км | DD3: Расстояние до остановок, км | DE3: Расстояние до дорог, км | DF3: Расстояние до центра, км | DG3: УПКС с учетом поправки на уторгование И ОБРЕМЕНЕНИЕ И МЕЖЕВАНИЕ, руб/м2 на 2020 | DH3: КС, руб. на 2020 | DI3: ОБЯЗАТЕЛЬНАЯ ПРОВЕРКА | DJ3: Файл | DK3: Модель | DL3: Дата | DM3: Ответственный | DN3: Графика | DO3: CadastralNumber | DP3: loc_factor_801 | DQ3: loc_factor_804 | DR3: loc_factor_802 | DS3: loc_factor_803 | DT3: loc_factor_806 | DU3: loc_factor_807 | DV3: loc_factor_809 | DW3: loc_factor_810 | DX3: loc_factor_811 | DY3: loc_factor_812 | DZ3: loc_factor_8071 | EA3: loc_factor_8091 | EB3: loc_factor_8101 | EC3: loc_factor_8111 | ED3: loc_factor_8121 | EE3: loc_factor_839 | EF3: Specific_CadastralCost | EG3: CadastralCost | EH3: CadastralCostDesc | EI3: id_group | EJ3: loc_factor_827 | EK3: Status_kc | EL3: Segment | EM3: loc_SgCode | EN3: loc_VICode | EO3: loc_GroupName | EP3: Old_Utlbydoc | EW3: =IF(AND(ГОТОВ!AD1=1,COUNTIF(EK:EK,"ГОТОВ")=0),"ОТСУТСТВУЮТ",COUNTIF(EK:EK,"ГОТОВ")+1) -> 8 | EX3: =IF(AND('ПЕРЕСЧЕТ НЕ ТРЕБУЕТСЯ'!I1=1,COUNTIF(EK:EK,"ПЕРЕСЧЕТ НЕ ТРЕБУЕТСЯ")=0),"ОТСУТСТВУЮТ",COUNTIF(EK:EK,"ПЕРЕСЧЕТ НЕ ТРЕБУЕТСЯ")+1) -> ОТСУТСТВУЮТ | EY3: =IF(AND(СТОПЛИСТ!D1=1,COUNTIF(EK:EK,"СТОПЛИСТ")=0),"ОТСУТСТВУЮТ",COUNTIF(EK:EK,"СТОПЛИСТ")+1) -> ОТСУТСТВУЮТ
A4: 2775523 | B4: 66:41:0313010:15828 | C4: Земельный участок | D4: 4367 | F4: Свердловская область, г. Екатеринбург | G4: Земли населенных пунктов | H4: Для иных видов использования, характерных для населенных пунктов | I4: Дошкольное, начальное и среднее общее образование | R4: 47:004:1:1:1 | V4: 0.01 | W4: 12.86 | AA4: 7.43 | AB4: 0.87 | AC4: пояс 3 | AE4: 2021-09-28 | AX4: НЕ ГОТОВ | BH4: 03:051 | BI4: Правило0 | BJ4: 8003 | BK4: 3. СЕГМЕНТ "Общественное использование" | BM4: =IFERROR(VLOOKUP(B4,'Объекты МУГИСО'!$A:$B,2,FALSE),"") | BN4: =IFERROR(VLOOKUP(BH4,'Коды без коммуникаций'!$C:$C,1,FALSE),"") | BO4: =IF(B4="","",IF(AC4="","Пояс 2",AC4)) -> пояс 3 | BP4: =IF(B4="","",IF(OR(Y4="отсутствие",Y4="отсутствие электроснабжения"),"Отсутствие электроснабжения","Наличие электроснабжения")) -> Наличие электроснабжения | BQ4: =IF(A4="","",IF(OR(BN4<>"",X4="",X4="Отсутствие"),"Отсутствие теплоснабжения","Наличие теплоснабжения")) -> Отсутствие теплоснабжения | BR4: =IF(A4="","",IF(OR(BN4<>"",Z4="",Z4="Отсутствие"),"Отсутствие водоотведения","Наличие водоотведения")) -> Отсутствие водоотведения | BS4: =IF(B4="","",BK4) -> 3. СЕГМЕНТ "Общественное использование" | BT4: =IF(B4="","",D4) -> 4367 | BU4: =IF(B4="","",IF(AA4="",VLOOKUP(BO4,Поправки!$AJ$1:$AK$6,2,FALSE),AA4)) -> 7.43 | BV4: =IF(B4="","",IF(AB4="",Поправки!$AO$2,AB4)) -> 0.87 | BW4: =IF(B4="","",IF(BM4=1,0.0001,IF(V4="",Поправки!$AP$2,V4))) -> 0.01 | BX4: =IF(B4="","",IF(W4<=0,VLOOKUP(BO4,Поправки!$AJ$1:$AL$6,3,FALSE),W4)) -> 12.86 | BY4: =IF(B4="","",Поправки!$K$21) -> 12012.337 | BZ4: =IF(B4="","",VLOOKUP(BO4,Поправки!$B$40:$D$52,3,FALSE)) -> 0.6496 | CA4: =IF(B4="","",VLOOKUP(BP4,Поправки!$B$40:$D$52,3,FALSE)) -> 1.127 | CB4: =IF(B4="","",VLOOKUP(BQ4,Поправки!$B$40:$D$52,3,FALSE)) -> 1 | CC4: =IF(B4="","",VLOOKUP(BR4,Поправки!$B$40:$D$52,3,FALSE)) -> 1 | CD4: =IF(B4="","",VLOOKUP(BS4,Поправки!$B$40:$D$52,3,FALSE)) -> 1 | CE4: =IF(B4="","",IF(BT4<Поправки!$I$11,Поправки!$L$11,ROUND((EXP(11.27070473*LN(BT4)^-0.08418488)^Поправки!$G$1)/Поправки!$K$10,4))) -> 1.0526 | CF4: =IF(B4="","",IF(BU4<Поправки!$N$11,Поправки!$Q$11,IF(BU4>Поправки!$N$12,Поправки!$Q$12,ROUND((EXP(9.57779229*0.98667563^LN(BU4))^Поправки!$G$2)/Поправки!$P$10,4)))) -> 0.9883 | CG4: =IF(B4="","",IF(BV4>Поправки!$S$12,Поправки!$V$12,IF(BV4<Поправки!$S$11,Поправки!$V$11,ROUND((EXP(9.3057995*0.99085691^LN(BV4))^Поправки!$G$3)/Поправки!$U$10,4)))) -> 0.9977 | CH4: =IF(B4="","",IF(BW4<Поправки!$X$11,Поправки!$AA$11,IF(BW4>Поправки!$X$12,Поправки!$AA$12,ROUND((EXP(9.23088404*0.99320482^LN(BW4))^Поправки!$G$4)/Поправки!$Z$10,4)))) -> 1.0411 | CI4: =IF(B4="","",IF(BX4<Поправки!$AC$11,Поправки!$AF$11,IF(BX4>Поправки!$AC$12,Поправки!$AF$12,ROUND((EXP(9.93943263-0.30296633*LN(BX4))^Поправки!$G$5)/Поправки!$AE$10,4)))) -> 0.7817 | CJ4: =IF(B4="","",AT4) -> 0 | CK4: =IF(B4="","",PRODUCT(BY4:CI4)) -> 7428.1752 | CL4: =IF(B4="","",ROUND(CK4*$CT$3,2)) -> 5571.13 | CM4: =IF(B4="","",ROUND(IF(51178*D4^-0.982<$CU$3,$CU$3,IF(51178*D4^-0.982>$CV$3,$CV$3,51178*D4^-0.982)),2)) -> 13.63 | CN4: =IF(B4="","",ROUND((CL4*(D4-CJ4))/D4,2)) -> 5571.13 | CO4: =IF(B4="","",IF(CJ4=0,CL4,IF(CN4<CM4,CM4,CN4))) -> 5571.13 | CP4: =IF(B4="","",ROUND(CO4*D4,2)) -> 24329125 | CQ4: =IF(B4="","",CONCATENATE("СТ16_",DJ4,"_",DK4,"_",DL4,"_",DM4,"_",DN4,"_",ES4)) -> СТ16_Ф5_М3_02032021_Мухамедьярова_Графика по ПКК_Новый | CR4: =IF(B4="","",B4) -> 66:41:0313010:15828 | CS4: =IF(B4="","",$CS$1) -> 8003 | CT4: =IF(B4="","","Наличие уторгования") -> Наличие уторгования | CW4: =IF(A4="","",IF(AF4="","Отсутствуют предыдущие значения",BO4=AF4)) -> Отсутствуют предыдущие значения | CX4: =IF(A4="","",IF(AI4="","Отсутствуют предыдущие значения",BP4=AI4)) -> Отсутствуют предыдущие значения | CY4: =IF(A4="","",IF(AG4="","Отсутствуют предыдущие значения",BQ4=AG4)) -> Отсутствуют предыдущие значения | CZ4: =IF(A4="","",IF(AH4="","Отсутствуют предыдущие значения",AH4=BR4)) -> Отсутствуют предыдущие значения | DA4: =IF(A4="","",IF(U4="","Отсутствуют предыдущие значения",BS4=U4)) -> Отсутствуют предыдущие значения | DB4: =IF(A4="","",IF(AK4="","Отсутствуют предыдущие значения",BT4=AK4)) -> Отсутствуют предыдущие значения | DC4: =IF(A4="","",IF(AM4="","Отсутствуют предыдущие значения",AM4=BU4)) -> Отсутствуют предыдущие значения | DD4: =IF(A4="","",IF(AN4="","Отсутствуют предыдущие значения",AN4=BV4)) -> Отсутствуют предыдущие значения | DE4: =IF(A4="","",IF(AO4="","Отсутствуют предыдущие значения",BW4=AO4)) -> Отсутствуют предыдущие значения | DF4: =IF(A4="","",IF(AP4="","Отсутствуют предыдущие значения",AP4=BX4)) -> Отсутствуют предыдущие значения | DG4: =IF(A4="","",IF(N4="","Отсутствуют предыдущие значения",CO4=N4)) -> Отсутствуют предыдущие значения | DH4: =IF(A4="","",IF(O4="","Отсутствуют предыдущие значения",CP4=O4)) -> Отсутствуют предыдущие значения | DI4: =IF(B4="","",IF(MID(BH4,3,1)<>":","ОШИБКА В ФОРМАТЕ КОДА НП",IF(AW4<>"","ОСПАРИВАНИЕ",IF(AQ4="","",AQ4)))) | DJ4: =IF(B4="","",$DJ$1) -> Ф5 | DK4: =IF(B4="","",$DK$1) -> М3 | DL4: =IF(B4="","",$DL$1) -> 02032021 | DM4: =IF(B4="","",$DM$1) -> Мухамедьярова | DN4: =IF(B4="","",IF(O4="","Графика по ПКК","Графика на 01012020")) -> Графика по ПКК | DO4: =IF(B4="","",B4) -> 66:41:0313010:15828 | DP4: =IF(B4="","",BO4) -> пояс 3 | DQ4: =IF(B4="","",BP4) -> Наличие электроснабжения | DR4: =IF(B4="","",BQ4) -> Отсутствие теплоснабжения | DS4: =IF(B4="","",BR4) -> Отсутствие водоотведения | DT4: =IF(B4="","",BS4) -> 3. СЕГМЕНТ "Общественное использование" | DU4: =IF(B4="","",BT4) -> 4367 | DV4: =IF(B4="","",BU4) -> 7.43 | DW4: =IF(B4="","",BV4) -> 0.87 | DX4: =IF(B4="","",BW4) -> 0.01 | DY4: =IF(B4="","",BX4) -> 12.86 | DZ4: =IF(B4="","",CE4) -> 1.0526 | EA4: =IF(B4="","",CF4) -> 0.9883 | EB4: =IF(B4="","",CG4) -> 0.9977 | EC4: =IF(B4="","",CH4) -> 1.0411 | ED4: =IF(B4="","",CI4) -> 0.7817 | EE4: =IF(B4="","",CJ4) -> 0 | EF4: =IF(B4="","",CO4) -> 5571.13 | EG4: =IF(B4="","",CP4) -> 24329125 | EH4: =IF(B4="","",CQ4) -> СТ16_Ф5_М3_02032021_Мухамедьярова_Графика по ПКК_Новый | EI4: =IF(B4="","",CS4) -> 8003 | EJ4: =IF(B4="","",CT4) -> Наличие уторгования | EK4: =IF(B4="","",IF(OR(AU4<>"",AW4<>"",EG4<0),"СТОПЛИСТ",IF(OR(EQ4="Отсутствует значения предыдущих расчетов",EQ4="Осуществлен пересчет"),"ГОТОВ","ПЕРЕСЧЕТ НЕ ТРЕБУЕТСЯ"))) -> ГОТОВ | EL4: =IF(B4="","",DT4) -> 3. СЕГМЕНТ "Общественное использование" | EM4: =IF(B4="","",VLOOKUP(EL4,'Сегмент ВРИ'!$B:$C,2,FALSE)) -> 3 | EN4: =IF(B4="","",BH4) -> 03:051 | EO4: =IF(B4="","",VLOOKUP(EN4,'Сегмент ВРИ'!$A:$E,4,FALSE)) -> Дошкольное, начальное и среднее общее образование. Размещение ОКС, предназначенных для просвещения, дошкольного, начального и среднего общего образования (детские ясли, детские сады, школы, лицеи, гимназии, художественные, музыкальные школы, образовательные кружки и иные организации, осуществляющие деятельность по воспитанию, образованию и просвещению) | EP4: =IF(B4="","",IF(OR(I4="",I4="-",I4="."),J4,I4)) -> Дошкольное, начальное и среднее общее образование | EQ4: =IF(B4="","",IF(O4="","Отсутствует значения предыдущих расчетов",IF(O4=CP4,"Значения КС не изменилось","Осуществлен пересчет"))) -> Отсутствует значения предыдущих расчетов | ER4: =IF(O4="","-",O4-CP4) -> - | ES4: =IF(B4="","-",IF(O4="","Новый","Измененный")) -> Новый
A5: 2776124 | B5: 66:41:0704045:38 | C5: Земельный участок | D5: 8218 | F5: обл. Свердловская, г. Екатеринбург, ул. Студенческая, дом 51 | G5: Земли населенных пунктов | H5: Для размещения объектов среднего профессионального и высшего профессионального образования | I5: Земли, занятые НИИ и проектными институтами | K5: Для размещения объектов среднего профессионального и высшего профессионального образования | L5: 98842899 | M5: 2010-01-01 00:00:00.0000000 | R5: 47:004:1:1:1 | V5: 0.02 | W5: 5.32 | AA5: 4.04 | AB5: 0.29 | AC5: пояс 1 | AE5: 2021-11-17 | AX5: НЕ ГОТОВ | BH5: 03:092 | BI5: Правило0 | BJ5: 8003 | BK5: 3. СЕГМЕНТ "Общественное использование" | BM5: =IFERROR(VLOOKUP(B5,'Объекты МУГИСО'!$A:$B,2,FALSE),"") | BN5: =IFERROR(VLOOKUP(BH5,'Коды без коммуникаций'!$C:$C,1,FALSE),"") | BO5: =IF(B5="","",IF(AC5="","Пояс 2",AC5)) -> пояс 1 | BP5: =IF(B5="","",IF(OR(Y5="отсутствие",Y5="отсутствие электроснабжения"),"Отсутствие электроснабжения","Наличие электроснабжения")) -> Наличие электроснабжения | BQ5: =IF(A5="","",IF(OR(BN5<>"",X5="",X5="Отсутствие"),"Отсутствие теплоснабжения","Наличие теплоснабжения")) -> Отсутствие теплоснабжения | BR5: =IF(A5="","",IF(OR(BN5<>"",Z5="",Z5="Отсутствие"),"Отсутствие водоотведения","Наличие водоотведения")) -> Отсутствие водоотведения | BS5: =IF(B5="","",BK5) -> 3. СЕГМЕНТ "Общественное использование" | BT5: =IF(B5="","",D5) -> 8218 | BU5: =IF(B5="","",IF(AA5="",VLOOKUP(BO5,Поправки!$AJ$1:$AK$6,2,FALSE),AA5)) -> 4.04 | BV5: =IF(B5="","",IF(AB5="",Поправки!$AO$2,AB5)) -> 0.29 | BW5: =IF(B5="","",IF(BM5=1,0.0001,IF(V5="",Поправки!$AP$2,V5))) -> 0.02 | BX5: =IF(B5="","",IF(W5<=0,VLOOKUP(BO5,Поправки!$AJ$1:$AL$6,3,FALSE),W5)) -> 5.32 | BY5: =IF(B5="","",Поправки!$K$21) -> 12012.337 | BZ5: =IF(B5="","",VLOOKUP(BO5,Поправки!$B$40:$D$52,3,FALSE)) -> 0.8294 | CA5: =IF(B5="","",VLOOKUP(BP5,Поправки!$B$40:$D$52,3,FALSE)) -> 1.127 | CB5: =IF(B5="","",VLOOKUP(BQ5,Поправки!$B$40:$D$52,3,FALSE)) -> 1 | CC5: =IF(B5="","",VLOOKUP(BR5,Поправки!$B$40:$D$52,3,FALSE)) -> 1 | CD5: =IF(B5="","",VLOOKUP(BS5,Поправки!$B$40:$D$52,3,FALSE)) -> 1 | CE5: =IF(B5="","",IF(BT5<Поправки!$I$11,Поправки!$L$11,ROUND((EXP(11.27070473*LN(BT5)^-0.08418488)^Поправки!$G$1)/Поправки!$K$10,4))) -> 1.0117 | CF5: =IF(B5="","",IF(BU5<Поправки!$N$11,Поправки!$Q$11,IF(BU5>Поправки!$N$12,Поправки!$Q$12,ROUND((EXP(9.57779229*0.98667563^LN(BU5))^Поправки!$G$2)/Поправки!$P$10,4)))) -> 0.9918 | CG5: =IF(B5="","",IF(BV5>Поправки!$S$12,Поправки!$V$12,IF(BV5<Поправки!$S$11,Поправки!$V$11,ROUND((EXP(9.3057995*0.99085691^LN(BV5))^Поправки!$G$3)/Поправки!$U$10,4)))) -> 1.0023 | CH5: =IF(B5="","",IF(BW5<Поправки!$X$11,Поправки!$AA$11,IF(BW5>Поправки!$X$12,Поправки!$AA$12,ROUND((EXP(9.23088404*0.99320482^LN(BW5))^Поправки!$G$4)/Поправки!$Z$10,4)))) -> 1.0332 | CI5: =IF(B5="","",IF(BX5<Поправки!$AC$11,Поправки!$AF$11,IF(BX5>Поправки!$AC$12,Поправки!$AF$12,ROUND((EXP(9.93943263-0.30296633*LN(BX5))^Поправки!$G$5)/Поправки!$AE$10,4)))) -> 0.8512 | CJ5: =IF(B5="","",AT5) -> 0 | CK5: =IF(B5="","",PRODUCT(BY5:CI5)) -> 9931.2762 | CL5: =IF(B5="","",ROUND(CK5*$CT$3,2)) -> 7448.46 | CM5: =IF(B5="","",ROUND(IF(51178*D5^-0.982<$CU$3,$CU$3,IF(51178*D5^-0.982>$CV$3,$CV$3,51178*D5^-0.982)),2)) -> 7.32 | CN5: =IF(B5="","",ROUND((CL5*(D5-CJ5))/D5,2)) -> 7448.46 | CO5: =IF(B5="","",IF(CJ5=0,CL5,IF(CN5<CM5,CM5,CN5))) -> 7448.46 | CP5: =IF(B5="","",ROUND(CO5*D5,2)) -> 61211444 | CQ5: =IF(B5="","",CONCATENATE("СТ16_",DJ5,"_",DK5,"_",DL5,"_",DM5,"_",DN5,"_",ES5)) -> СТ16_Ф5_М3_02032021_Мухамедьярова_Графика по ПКК_Новый | CR5: =IF(B5="","",B5) -> 66:41:0704045:38 | CS5: =IF(B5="","",$CS$1) -> 8003 | CT5: =IF(B5="","","Наличие уторгования") -> Наличие уторгования | CW5: =IF(A5="","",IF(AF5="","Отсутствуют предыдущие значения",BO5=AF5)) -> Отсутствуют предыдущие значения | CX5: =IF(A5="","",IF(AI5="","Отсутствуют предыдущие значения",BP5=AI5)) -> Отсутствуют предыдущие значения | CY5: =IF(A5="","",IF(AG5="","Отсутствуют предыдущие значения",BQ5=AG5)) -> Отсутствуют предыдущие значения | CZ5: =IF(A5="","",IF(AH5="","Отсутствуют предыдущие значения",AH5=BR5)) -> Отсутствуют предыдущие значения | DA5: =IF(A5="","",IF(U5="","Отсутствуют предыдущие значения",BS5=U5)) -> Отсутствуют предыдущие значения | DB5: =IF(A5="","",IF(AK5="","Отсутствуют предыдущие значения",BT5=AK5)) -> Отсутствуют предыдущие значения | DC5: =IF(A5="","",IF(AM5="","Отсутствуют предыдущие значения",AM5=BU5)) -> Отсутствуют предыдущие значения | DD5: =IF(A5="","",IF(AN5="","Отсутствуют предыдущие значения",AN5=BV5)) -> Отсутствуют предыдущие значения | DE5: =IF(A5="","",IF(AO5="","Отсутствуют предыдущие значения",BW5=AO5)) -> Отсутствуют предыдущие значения | DF5: =IF(A5="","",IF(AP5="","Отсутствуют предыдущие значения",AP5=BX5)) -> Отсутствуют предыдущие значения | DG5: =IF(A5="","",IF(N5="","Отсутствуют предыдущие значения",CO5=N5)) -> Отсутствуют предыдущие значения | DH5: =IF(A5="","",IF(O5="","Отсутствуют предыдущие значения",CP5=O5)) -> Отсутствуют предыдущие значения | DI5: =IF(B5="","",IF(MID(BH5,3,1)<>":","ОШИБКА В ФОРМАТЕ КОДА НП",IF(AW5<>"","ОСПАРИВАНИЕ",IF(AQ5="","",AQ5)))) | DJ5: =IF(B5="","",$DJ$1) -> Ф5 | DK5: =IF(B5="","",$DK$1) -> М3 | DL5: =IF(B5="","",$DL$1) -> 02032021 | DM5: =IF(B5="","",$DM$1) -> Мухамедьярова | DN5: =IF(B5="","",IF(O5="","Графика по ПКК","Графика на 01012020")) -> Графика по ПКК | DO5: =IF(B5="","",B5) -> 66:41:0704045:38 | DP5: =IF(B5="","",BO5) -> пояс 1 | DQ5: =IF(B5="","",BP5) -> Наличие электроснабжения | DR5: =IF(B5="","",BQ5) -> Отсутствие теплоснабжения | DS5: =IF(B5="","",BR5) -> Отсутствие водоотведения | DT5: =IF(B5="","",BS5) -> 3. СЕГМЕНТ "Общественное использование" | DU5: =IF(B5="","",BT5) -> 8218 | DV5: =IF(B5="","",BU5) -> 4.04 | DW5: =IF(B5="","",BV5) -> 0.29 | DX5: =IF(B5="","",BW5) -> 0.02 | DY5: =IF(B5="","",BX5) -> 5.32 | DZ5: =IF(B5="","",CE5) -> 1.0117 | EA5: =IF(B5="","",CF5) -> 0.9918 | EB5: =IF(B5="","",CG5) -> 1.0023 | EC5: =IF(B5="","",CH5) -> 1.0332 | ED5: =IF(B5="","",CI5) -> 0.8512 | EE5: =IF(B5="","",CJ5) -> 0 | EF5: =IF(B5="","",CO5) -> 7448.46 | EG5: =IF(B5="","",CP5) -> 61211444 | EH5: =IF(B5="","",CQ5) -> СТ16_Ф5_М3_02032021_Мухамедьярова_Графика по ПКК_Новый | EI5: =IF(B5="","",CS5) -> 8003 | EJ5: =IF(B5="","",CT5) -> Наличие уторгования | EK5: =IF(B5="","",IF(OR(AU5<>"",AW5<>"",EG5<0),"СТОПЛИСТ",IF(OR(EQ5="Отсутствует значения предыдущих расчетов",EQ5="Осуществлен пересчет"),"ГОТОВ","ПЕРЕСЧЕТ НЕ ТРЕБУЕТСЯ"))) -> ГОТОВ | EL5: =IF(B5="","",DT5) -> 3. СЕГМЕНТ "Общественное использование" | EM5: =IF(B5="","",VLOOKUP(EL5,'Сегмент ВРИ'!$B:$C,2,FALSE)) -> 3 | EN5: =IF(B5="","",BH5) -> 03:092 | EO5: =IF(B5="","",VLOOKUP(EN5,'Сегмент ВРИ'!$A:$E,4,FALSE)) -> Обеспечение научной деятельности. Размещение ОКС для размещения организаций, осуществляющих научные изыскания, исследования и разработки (научно-исследовательские институты, проектные институты, научные центры, опытно-конструкторские центры, государственные академии наук, в том числе отраслевые) - административных зданий научно-исследовательских организаций | EP5: =IF(B5="","",IF(OR(I5="",I5="-",I5="."),J5,I5)) -> Земли, занятые НИИ и проектными институтами | EQ5: =IF(B5="","",IF(O5="","Отсутствует значения предыдущих расчетов",IF(O5=CP5,"Значения КС не изменилось","Осуществлен пересчет"))) -> Отсутствует значения предыдущих расчетов | ER5: =IF(O5="","-",O5-CP5) -> - | ES5: =IF(B5="","-",IF(O5="","Новый","Измененный")) -> Новый
A6: 2775535 | B6: 66:41:0313010:15840 | C6: Земельный участок | D6: 10150 | F6: Свердловская область, г. Екатеринбург | G6: Земли населенных пунктов | H6: Для иных видов использования, характерных для населенных пунктов | I6: Дошкольное, начальное и среднее общее образование | R6: 47:004:1:1:1 | V6: 0.26 | W6: 11.96 | AA6: 6.82 | AB6: 0.55 | AC6: пояс 3 | AE6: 2021-09-28 | AX6: НЕ ГОТОВ | BH6: 03:051 | BI6: Правило0 | BJ6: 8003 | BK6: 3. СЕГМЕНТ "Общественное использование" | BM6: =IFERROR(VLOOKUP(B6,'Объекты МУГИСО'!$A:$B,2,FALSE),"") | BN6: =IFERROR(VLOOKUP(BH6,'Коды без коммуникаций'!$C:$C,1,FALSE),"") | BO6: =IF(B6="","",IF(AC6="","Пояс 2",AC6)) -> пояс 3 | BP6: =IF(B6="","",IF(OR(Y6="отсутствие",Y6="отсутствие электроснабжения"),"Отсутствие электроснабжения","Наличие электроснабжения")) -> Наличие электроснабжения | BQ6: =IF(A6="","",IF(OR(BN6<>"",X6="",X6="Отсутствие"),"Отсутствие теплоснабжения","Наличие теплоснабжения")) -> Отсутствие теплоснабжения | BR6: =IF(A6="","",IF(OR(BN6<>"",Z6="",Z6="Отсутствие"),"Отсутствие водоотведения","Наличие водоотведения")) -> Отсутствие водоотведения | BS6: =IF(B6="","",BK6) -> 3. СЕГМЕНТ "Общественное использование" | BT6: =IF(B6="","",D6) -> 10150 | BU6: =IF(B6="","",IF(AA6="",VLOOKUP(BO6,Поправки!$AJ$1:$AK$6,2,FALSE),AA6)) -> 6.82 | BV6: =IF(B6="","",IF(AB6="",Поправки!$AO$2,AB6)) -> 0.55 | BW6: =IF(B6="","",IF(BM6=1,0.0001,IF(V6="",Поправки!$AP$2,V6))) -> 0.26 | BX6: =IF(B6="","",IF(W6<=0,VLOOKUP(BO6,Поправки!$AJ$1:$AL$6,3,FALSE),W6)) -> 11.96 | BY6: =IF(B6="","",Поправки!$K$21) -> 12012.337 | BZ6: =IF(B6="","",VLOOKUP(BO6,Поправки!$B$40:$D$52,3,FALSE)) -> 0.6496 | CA6: =IF(B6="","",VLOOKUP(BP6,Поправки!$B$40:$D$52,3,FALSE)) -> 1.127 | CB6: =IF(B6="","",VLOOKUP(BQ6,Поправки!$B$40:$D$52,3,FALSE)) -> 1 | CC6: =IF(B6="","",VLOOKUP(BR6,Поправки!$B$40:$D$52,3,FALSE)) -> 1 | CD6: =IF(B6="","",VLOOKUP(BS6,Поправки!$B$40:$D$52,3,FALSE)) -> 1 | CE6: =IF(B6="","",IF(BT6<Поправки!$I$11,Поправки!$L$11,ROUND((EXP(11.27070473*LN(BT6)^-0.08418488)^Поправки!$G$1)/Поправки!$K$10,4))) -> 0.9991 | CF6: =IF(B6="","",IF(BU6<Поправки!$N$11,Поправки!$Q$11,IF(BU6>Поправки!$N$12,Поправки!$Q$12,ROUND((EXP(9.57779229*0.98667563^LN(BU6))^Поправки!$G$2)/Поправки!$P$10,4)))) -> 0.9887 | CG6: =IF(B6="","",IF(BV6>Поправки!$S$12,Поправки!$V$12,IF(BV6<Поправки!$S$11,Поправки!$V$11,ROUND((EXP(9.3057995*0.99085691^LN(BV6))^Поправки!$G$3)/Поправки!$U$10,4)))) -> 0.9996 | CH6: =IF(B6="","",IF(BW6<Поправки!$X$11,Поправки!$AA$11,IF(BW6>Поправки!$X$12,Поправки!$AA$12,ROUND((EXP(9.23088404*0.99320482^LN(BW6))^Поправки!$G$4)/Поправки!$Z$10,4)))) -> 1.0047 | CI6: =IF(B6="","",IF(BX6<Поправки!$AC$11,Поправки!$AF$11,IF(BX6>Поправки!$AC$12,Поправки!$AF$12,ROUND((EXP(9.93943263-0.30296633*LN(BX6))^Поправки!$G$5)/Поправки!$AE$10,4)))) -> 0.7872 | CJ6: =IF(B6="","",AT6) -> 0 | CK6: =IF(B6="","",PRODUCT(BY6:CI6)) -> 6867.8164 | CL6: =IF(B6="","",ROUND(CK6*$CT$3,2)) -> 5150.86 | CM6: =IF(B6="","",ROUND(IF(51178*D6^-0.982<$CU$3,$CU$3,IF(51178*D6^-0.982>$CV$3,$CV$3,51178*D6^-0.982)),2)) -> 5.95 | CN6: =IF(B6="","",ROUND((CL6*(D6-CJ6))/D6,2)) -> 5150.86 | CO6: =IF(B6="","",IF(CJ6=0,CL6,IF(CN6<CM6,CM6,CN6))) -> 5150.86 | CP6: =IF(B6="","",ROUND(CO6*D6,2)) -> 52281229 | CQ6: =IF(B6="","",CONCATENATE("СТ16_",DJ6,"_",DK6,"_",DL6,"_",DM6,"_",DN6,"_",ES6)) -> СТ16_Ф5_М3_02032021_Мухамедьярова_Графика по ПКК_Новый | CR6: =IF(B6="","",B6) -> 66:41:0313010:15840 | CS6: =IF(B6="","",$CS$1) -> 8003 | CT6: =IF(B6="","","Наличие уторгования") -> Наличие уторгования | CW6: =IF(A6="","",IF(AF6="","Отсутствуют предыдущие значения",BO6=AF6)) -> Отсутствуют предыдущие значения | CX6: =IF(A6="","",IF(AI6="","Отсутствуют предыдущие значения",BP6=AI6)) -> Отсутствуют предыдущие значения | CY6: =IF(A6="","",IF(AG6="","Отсутствуют предыдущие значения",BQ6=AG6)) -> Отсутствуют предыдущие значения | CZ6: =IF(A6="","",IF(AH6="","Отсутствуют предыдущие значения",AH6=BR6)) -> Отсутствуют предыдущие значения | DA6: =IF(A6="","",IF(U6="","Отсутствуют предыдущие значения",BS6=U6)) -> Отсутствуют предыдущие значения | DB6: =IF(A6="","",IF(AK6="","Отсутствуют предыдущие значения",BT6=AK6)) -> Отсутствуют предыдущие значения | DC6: =IF(A6="","",IF(AM6="","Отсутствуют предыдущие значения",AM6=BU6)) -> Отсутствуют предыдущие значения | DD6: =IF(A6="","",IF(AN6="","Отсутствуют предыдущие значения",AN6=BV6)) -> Отсутствуют предыдущие значения | DE6: =IF(A6="","",IF(AO6="","Отсутствуют предыдущие значения",BW6=AO6)) -> Отсутствуют предыдущие значения | DF6: =IF(A6="","",IF(AP6="","Отсутствуют предыдущие значения",AP6=BX6)) -> Отсутствуют предыдущие значения | DG6: =IF(A6="","",IF(N6="","Отсутствуют предыдущие значения",CO6=N6)) -> Отсутствуют предыдущие значения | DH6: =IF(A6="","",IF(O6="","Отсутствуют предыдущие значения",CP6=O6)) -> Отсутствуют предыдущие значения | DI6: =IF(B6="","",IF(MID(BH6,3,1)<>":","ОШИБКА В ФОРМАТЕ КОДА НП",IF(AW6<>"","ОСПАРИВАНИЕ",IF(AQ6="","",AQ6)))) | DJ6: =IF(B6="","",$DJ$1) -> Ф5 | DK6: =IF(B6="","",$DK$1) -> М3 | DL6: =IF(B6="","",$DL$1) -> 02032021 | DM6: =IF(B6="","",$DM$1) -> Мухамедьярова | DN6: =IF(B6="","",IF(O6="","Графика по ПКК","Графика на 01012020")) -> Графика по ПКК | DO6: =IF(B6="","",B6) -> 66:41:0313010:15840 | DP6: =IF(B6="","",BO6) -> пояс 3 | DQ6: =IF(B6="","",BP6) -> Наличие электроснабжения | DR6: =IF(B6="","",BQ6) -> Отсутствие теплоснабжения | DS6: =IF(B6="","",BR6) -> Отсутствие водоотведения | DT6: =IF(B6="","",BS6) -> 3. СЕГМЕНТ "Общественное использование" | DU6: =IF(B6="","",BT6) -> 10150 | DV6: =IF(B6="","",BU6) -> 6.82 | DW6: =IF(B6="","",BV6) -> 0.55 | DX6: =IF(B6="","",BW6) -> 0.26 | DY6: =IF(B6="","",BX6) -> 11.96 | DZ6: =IF(B6="","",CE6) -> 0.9991 | EA6: =IF(B6="","",CF6) -> 0.9887 | EB6: =IF(B6="","",CG6) -> 0.9996 | EC6: =IF(B6="","",CH6) -> 1.0047 | ED6: =IF(B6="","",CI6) -> 0.7872 | EE6: =IF(B6="","",CJ6) -> 0 | EF6: =IF(B6="","",CO6) -> 5150.86 | EG6: =IF(B6="","",CP6) -> 52281229 | EH6: =IF(B6="","",CQ6) -> СТ16_Ф5_М3_02032021_Мухамедьярова_Графика по ПКК_Новый | EI6: =IF(B6="","",CS6) -> 8003 | EJ6: =IF(B6="","",CT6) -> Наличие уторгования | EK6: =IF(B6="","",IF(OR(AU6<>"",AW6<>"",EG6<0),"СТОПЛИСТ",IF(OR(EQ6="Отсутствует значения предыдущих расчетов",EQ6="Осуществлен пересчет"),"ГОТОВ","ПЕРЕСЧЕТ НЕ ТРЕБУЕТСЯ"))) -> ГОТОВ | EL6: =IF(B6="","",DT6) -> 3. СЕГМЕНТ "Общественное использование" | EM6: =IF(B6="","",VLOOKUP(EL6,'Сегмент ВРИ'!$B:$C,2,FALSE)) -> 3 | EN6: =IF(B6="","",BH6) -> 03:051 | EO6: =IF(B6="","",VLOOKUP(EN6,'Сегмент ВРИ'!$A:$E,4,FALSE)) -> Дошкольное, начальное и среднее общее образование. Размещение ОКС, предназначенных для просвещения, дошкольного, начального и среднего общего образования (детские ясли, детские сады, школы, лицеи, гимназии, художественные, музыкальные школы, образовательные кружки и иные организации, осуществляющие деятельность по воспитанию, образованию и просвещению) | EP6: =IF(B6="","",IF(OR(I6="",I6="-",I6="."),J6,I6)) -> Дошкольное, начальное и среднее общее образование | EQ6: =IF(B6="","",IF(O6="","Отсутствует значения предыдущих расчетов",IF(O6=CP6,"Значения КС не изменилось","Осуществлен пересчет"))) -> Отсутствует значения предыдущих расчетов | ER6: =IF(O6="","-",O6-CP6) -> - | ES6: =IF(B6="","-",IF(O6="","Новый","Измененный")) -> Новый
A7: 2775531 | B7: 66:41:0313010:15836 | C7: Земельный участок | D7: 7879 | F7: Свердловская область, г. Екатеринбург | G7: Земли населенных пунктов | H7: Для иных видов использования, характерных для населенных пунктов | I7: Дошкольное, начальное и среднее общее образование | R7: 47:004:1:1:1 | V7: 0.04 | W7: 12.84 | AA7: 7.38 | AB7: 0.75 | AC7: пояс 3 | AE7: 2021-09-28 | AX7: НЕ ГОТОВ | BH7: 03:051 | BI7: Правило0 | BJ7: 8003 | BK7: 3. СЕГМЕНТ "Общественное использование" | BM7: =IFERROR(VLOOKUP(B7,'Объекты МУГИСО'!$A:$B,2,FALSE),"") | BN7: =IFERROR(VLOOKUP(BH7,'Коды без коммуникаций'!$C:$C,1,FALSE),"") | BO7: =IF(B7="","",IF(AC7="","Пояс 2",AC7)) -> пояс 3 | BP7: =IF(B7="","",IF(OR(Y7="отсутствие",Y7="отсутствие электроснабжения"),"Отсутствие электроснабжения","Наличие электроснабжения")) -> Наличие электроснабжения | BQ7: =IF(A7="","",IF(OR(BN7<>"",X7="",X7="Отсутствие"),"Отсутствие теплоснабжения","Наличие теплоснабжения")) -> Отсутствие теплоснабжения | BR7: =IF(A7="","",IF(OR(BN7<>"",Z7="",Z7="Отсутствие"),"Отсутствие водоотведения","Наличие водоотведения")) -> Отсутствие водоотведения | BS7: =IF(B7="","",BK7) -> 3. СЕГМЕНТ "Общественное использование" | BT7: =IF(B7="","",D7) -> 7879 | BU7: =IF(B7="","",IF(AA7="",VLOOKUP(BO7,Поправки!$AJ$1:$AK$6,2,FALSE),AA7)) -> 7.38 | BV7: =IF(B7="","",IF(AB7="",Поправки!$AO$2,AB7)) -> 0.75 | BW7: =IF(B7="","",IF(BM7=1,0.0001,IF(V7="",Поправки!$AP$2,V7))) -> 0.04 | BX7: =IF(B7="","",IF(W7<=0,VLOOKUP(BO7,Поправки!$AJ$1:$AL$6,3,FALSE),W7)) -> 12.84 | BY7: =IF(B7="","",Поправки!$K$21) -> 12012.337 | BZ7: =IF(B7="","",VLOOKUP(BO7,Поправки!$B$40:$D$52,3,FALSE)) -> 0.6496 | CA7: =IF(B7="","",VLOOKUP(BP7,Поправки!$B$40:$D$52,3,FALSE)) -> 1.127 | CB7: =IF(B7="","",VLOOKUP(BQ7,Поправки!$B$40:$D$52,3,FALSE)) -> 1 | CC7: =IF(B7="","",VLOOKUP(BR7,Поправки!$B$40:$D$52,3,FALSE)) -> 1 | CD7: =IF(B7="","",VLOOKUP(BS7,Поправки!$B$40:$D$52,3,FALSE)) -> 1 | CE7: =IF(B7="","",IF(BT7<Поправки!$I$11,Поправки!$L$11,ROUND((EXP(11.27070473*LN(BT7)^-0.08418488)^Поправки!$G$1)/Поправки!$K$10,4))) -> 1.0143 | CF7: =IF(B7="","",IF(BU7<Поправки!$N$11,Поправки!$Q$11,IF(BU7>Поправки!$N$12,Поправки!$Q$12,ROUND((EXP(9.57779229*0.98667563^LN(BU7))^Поправки!$G$2)/Поправки!$P$10,4)))) -> 0.9883 | CG7: =IF(B7="","",IF(BV7>Поправки!$S$12,Поправки!$V$12,IF(BV7<Поправки!$S$11,Поправки!$V$11,ROUND((EXP(9.3057995*0.99085691^LN(BV7))^Поправки!$G$3)/Поправки!$U$10,4)))) -> 0.9983 | CH7: =IF(B7="","",IF(BW7<Поправки!$X$11,Поправки!$AA$11,IF(BW7>Поправки!$X$12,Поправки!$AA$12,ROUND((EXP(9.23088404*0.99320482^LN(BW7))^Поправки!$G$4)/Поправки!$Z$10,4)))) -> 1.0254 | CI7: =IF(B7="","",IF(BX7<Поправки!$AC$11,Поправки!$AF$11,IF(BX7>Поправки!$AC$12,Поправки!$AF$12,ROUND((EXP(9.93943263-0.30296633*LN(BX7))^Поправки!$G$5)/Поправки!$AE$10,4)))) -> 0.7818 | CJ7: =IF(B7="","",AT7) -> 0 | CK7: =IF(B7="","",PRODUCT(BY7:CI7)) -> 7055.0926 | CL7: =IF(B7="","",ROUND(CK7*$CT$3,2)) -> 5291.32 | CM7: =IF(B7="","",ROUND(IF(51178*D7^-0.982<$CU$3,$CU$3,IF(51178*D7^-0.982>$CV$3,$CV$3,51178*D7^-0.982)),2)) -> 7.63 | CN7: =IF(B7="","",ROUND((CL7*(D7-CJ7))/D7,2)) -> 5291.32 | CO7: =IF(B7="","",IF(CJ7=0,CL7,IF(CN7<CM7,CM7,CN7))) -> 5291.32 | CP7: =IF(B7="","",ROUND(CO7*D7,2)) -> 41690310 | CQ7: =IF(B7="","",CONCATENATE("СТ16_",DJ7,"_",DK7,"_",DL7,"_",DM7,"_",DN7,"_",ES7)) -> СТ16_Ф5_М3_02032021_Мухамедьярова_Графика по ПКК_Новый | CR7: =IF(B7="","",B7) -> 66:41:0313010:15836 | CS7: =IF(B7="","",$CS$1) -> 8003 | CT7: =IF(B7="","","Наличие уторгования") -> Наличие уторгования | CW7: =IF(A7="","",IF(AF7="","Отсутствуют предыдущие значения",BO7=AF7)) -> Отсутствуют предыдущие значения | CX7: =IF(A7="","",IF(AI7="","Отсутствуют предыдущие значения",BP7=AI7)) -> Отсутствуют предыдущие значения | CY7: =IF(A7="","",IF(AG7="","Отсутствуют предыдущие значения",BQ7=AG7)) -> Отсутствуют предыдущие значения | CZ7: =IF(A7="","",IF(AH7="","Отсутствуют предыдущие значения",AH7=BR7)) -> Отсутствуют предыдущие значения | DA7: =IF(A7="","",IF(U7="","Отсутствуют предыдущие значения",BS7=U7)) -> Отсутствуют предыдущие значения | DB7: =IF(A7="","",IF(AK7="","Отсутствуют предыдущие значения",BT7=AK7)) -> Отсутствуют предыдущие значения | DC7: =IF(A7="","",IF(AM7="","Отсутствуют предыдущие значения",AM7=BU7)) -> Отсутствуют предыдущие значения | DD7: =IF(A7="","",IF(AN7="","Отсутствуют предыдущие значения",AN7=BV7)) -> Отсутствуют предыдущие значения | DE7: =IF(A7="","",IF(AO7="","Отсутствуют предыдущие значения",BW7=AO7)) -> Отсутствуют предыдущие значения | DF7: =IF(A7="","",IF(AP7="","Отсутствуют предыдущие значения",AP7=BX7)) -> Отсутствуют предыдущие значения | DG7: =IF(A7="","",IF(N7="","Отсутствуют предыдущие значения",CO7=N7)) -> Отсутствуют предыдущие значения | DH7: =IF(A7="","",IF(O7="","Отсутствуют предыдущие значения",CP7=O7)) -> Отсутствуют предыдущие значения | DI7: =IF(B7="","",IF(MID(BH7,3,1)<>":","ОШИБКА В ФОРМАТЕ КОДА НП",IF(AW7<>"","ОСПАРИВАНИЕ",IF(AQ7="","",AQ7)))) | DJ7: =IF(B7="","",$DJ$1) -> Ф5 | DK7: =IF(B7="","",$DK$1) -> М3 | DL7: =IF(B7="","",$DL$1) -> 02032021 | DM7: =IF(B7="","",$DM$1) -> Мухамедьярова | DN7: =IF(B7="","",IF(O7="","Графика по ПКК","Графика на 01012020")) -> Графика по ПКК | DO7: =IF(B7="","",B7) -> 66:41:0313010:15836 | DP7: =IF(B7="","",BO7) -> пояс 3 | DQ7: =IF(B7="","",BP7) -> Наличие электроснабжения | DR7: =IF(B7="","",BQ7) -> Отсутствие теплоснабжения | DS7: =IF(B7="","",BR7) -> Отсутствие водоотведения | DT7: =IF(B7="","",BS7) -> 3. СЕГМЕНТ "Общественное использование" | DU7: =IF(B7="","",BT7) -> 7879 | DV7: =IF(B7="","",BU7) -> 7.38 | DW7: =IF(B7="","",BV7) -> 0.75 | DX7: =IF(B7="","",BW7) -> 0.04 | DY7: =IF(B7="","",BX7) -> 12.84 | DZ7: =IF(B7="","",CE7) -> 1.0143 | EA7: =IF(B7="","",CF7) -> 0.9883 | EB7: =IF(B7="","",CG7) -> 0.9983 | EC7: =IF(B7="","",CH7) -> 1.0254 | ED7: =IF(B7="","",CI7) -> 0.7818 | EE7: =IF(B7="","",CJ7) -> 0 | EF7: =IF(B7="","",CO7) -> 5291.32 | EG7: =IF(B7="","",CP7) -> 41690310 | EH7: =IF(B7="","",CQ7) -> СТ16_Ф5_М3_02032021_Мухамедьярова_Графика по ПКК_Новый | EI7: =IF(B7="","",CS7) -> 8003 | EJ7: =IF(B7="","",CT7) -> Наличие уторгования | EK7: =IF(B7="","",IF(OR(AU7<>"",AW7<>"",EG7<0),"СТОПЛИСТ",IF(OR(EQ7="Отсутствует значения предыдущих расчетов",EQ7="Осуществлен пересчет"),"ГОТОВ","ПЕРЕСЧЕТ НЕ ТРЕБУЕТСЯ"))) -> ГОТОВ | EL7: =IF(B7="","",DT7) -> 3. СЕГМЕНТ "Общественное использование" | EM7: =IF(B7="","",VLOOKUP(EL7,'Сегмент ВРИ'!$B:$C,2,FALSE)) -> 3 | EN7: =IF(B7="","",BH7) -> 03:051 | EO7: =IF(B7="","",VLOOKUP(EN7,'Сегмент ВРИ'!$A:$E,4,FALSE)) -> Дошкольное, начальное и среднее общее образование. Размещение ОКС, предназначенных для просвещения, дошкольного, начального и среднего общего образования (детские ясли, детские сады, школы, лицеи, гимназии, художественные, музыкальные школы, образовательные кружки и иные организации, осуществляющие деятельность по воспитанию, образованию и просвещению) | EP7: =IF(B7="","",IF(OR(I7="",I7="-",I7="."),J7,I7)) -> Дошкольное, начальное и среднее общее образование | EQ7: =IF(B7="","",IF(O7="","Отсутствует значения предыдущих расчетов",IF(O7=CP7,"Значения КС не изменилось","Осуществлен пересчет"))) -> Отсутствует значения предыдущих расчетов | ER7: =IF(O7="","-",O7-CP7) -> - | ES7: =IF(B7="","-",IF(O7="","Новый","Измененный")) -> Новый
A8: 2775452 | B8: 66:41:0313010:15757 | C8: Земельный участок | D8: 8992 | F8: Свердловская область, г. Екатеринбург | G8: Земли населенных пунктов | H8: Для иных видов использования, характерных для населенных пунктов | I8: спорт | R8: 47:004:1:1:1 | V8: 0.03 | W8: 13.22 | AA8: 7.34 | AB8: 0.99 | AC8: пояс 3 | AE8: 2021-09-28 | AX8: НЕ ГОТОВ | BH8: 05:010 | BI8: Правило0 | BJ8: 8003 | BK8: 3. СЕГМЕНТ "Общественное использование" | BM8: =IFERROR(VLOOKUP(B8,'Объекты МУГИСО'!$A:$B,2,FALSE),"") | BN8: =IFERROR(VLOOKUP(BH8,'Коды без коммуникаций'!$C:$C,1,FALSE),"") | BO8: =IF(B8="","",IF(AC8="","Пояс 2",AC8)) -> пояс 3 | BP8: =IF(B8="","",IF(OR(Y8="отсутствие",Y8="отсутствие электроснабжения"),"Отсутствие электроснабжения","Наличие электроснабжения")) -> Наличие электроснабжения | BQ8: =IF(A8="","",IF(OR(BN8<>"",X8="",X8="Отсутствие"),"Отсутствие теплоснабжения","Наличие теплоснабжения")) -> Отсутствие теплоснабжения | BR8: =IF(A8="","",IF(OR(BN8<>"",Z8="",Z8="Отсутствие"),"Отсутствие водоотведения","Наличие водоотведения")) -> Отсутствие водоотведения | BS8: =IF(B8="","",BK8) -> 3. СЕГМЕНТ "Общественное использование" | BT8: =IF(B8="","",D8) -> 8992 | BU8: =IF(B8="","",IF(AA8="",VLOOKUP(BO8,Поправки!$AJ$1:$AK$6,2,FALSE),AA8)) -> 7.34 | BV8: =IF(B8="","",IF(AB8="",Поправки!$AO$2,AB8)) -> 0.99 | BW8: =IF(B8="","",IF(BM8=1,0.0001,IF(V8="",Поправки!$AP$2,V8))) -> 0.03 | BX8: =IF(B8="","",IF(W8<=0,VLOOKUP(BO8,Поправки!$AJ$1:$AL$6,3,FALSE),W8)) -> 13.22 | BY8: =IF(B8="","",Поправки!$K$21) -> 12012.337 | BZ8: =IF(B8="","",VLOOKUP(BO8,Поправки!$B$40:$D$52,3,FALSE)) -> 0.6496 | CA8: =IF(B8="","",VLOOKUP(BP8,Поправки!$B$40:$D$52,3,FALSE)) -> 1.127 | CB8: =IF(B8="","",VLOOKUP(BQ8,Поправки!$B$40:$D$52,3,FALSE)) -> 1 | CC8: =IF(B8="","",VLOOKUP(BR8,Поправки!$B$40:$D$52,3,FALSE)) -> 1 | CD8: =IF(B8="","",VLOOKUP(BS8,Поправки!$B$40:$D$52,3,FALSE)) -> 1 | CE8: =IF(B8="","",IF(BT8<Поправки!$I$11,Поправки!$L$11,ROUND((EXP(11.27070473*LN(BT8)^-0.08418488)^Поправки!$G$1)/Поправки!$K$10,4))) -> 1.0063 | CF8: =IF(B8="","",IF(BU8<Поправки!$N$11,Поправки!$Q$11,IF(BU8>Поправки!$N$12,Поправки!$Q$12,ROUND((EXP(9.57779229*0.98667563^LN(BU8))^Поправки!$G$2)/Поправки!$P$10,4)))) -> 0.9883 | CG8: =IF(B8="","",IF(BV8>Поправки!$S$12,Поправки!$V$12,IF(BV8<Поправки!$S$11,Поправки!$V$11,ROUND((EXP(9.3057995*0.99085691^LN(BV8))^Поправки!$G$3)/Поправки!$U$10,4)))) -> 0.9972 | CH8: =IF(B8="","",IF(BW8<Поправки!$X$11,Поправки!$AA$11,IF(BW8>Поправки!$X$12,Поправки!$AA$12,ROUND((EXP(9.23088404*0.99320482^LN(BW8))^Поправки!$G$4)/Поправки!$Z$10,4)))) -> 1.0286 | CI8: =IF(B8="","",IF(BX8<Поправки!$AC$11,Поправки!$AF$11,IF(BX8>Поправки!$AC$12,Поправки!$AF$12,ROUND((EXP(9.93943263-0.30296633*LN(BX8))^Поправки!$G$5)/Поправки!$AE$10,4)))) -> 0.7797 | CJ8: =IF(B8="","",AT8) -> 0 | CK8: =IF(B8="","",PRODUCT(BY8:CI8)) -> 6994.7152 | CL8: =IF(B8="","",ROUND(CK8*$CT$3,2)) -> 5246.04 | CM8: =IF(B8="","",ROUND(IF(51178*D8^-0.982<$CU$3,$CU$3,IF(51178*D8^-0.982>$CV$3,$CV$3,51178*D8^-0.982)),2)) -> 6.7 | CN8: =IF(B8="","",ROUND((CL8*(D8-CJ8))/D8,2)) -> 5246.04 | CO8: =IF(B8="","",IF(CJ8=0,CL8,IF(CN8<CM8,CM8,CN8))) -> 5246.04 | CP8: =IF(B8="","",ROUND(CO8*D8,2)) -> 47172392 | CQ8: =IF(B8="","",CONCATENATE("СТ16_",DJ8,"_",DK8,"_",DL8,"_",DM8,"_",DN8,"_",ES8)) -> СТ16_Ф5_М3_02032021_Мухамедьярова_Графика по ПКК_Новый | CR8: =IF(B8="","",B8) -> 66:41:0313010:15757 | CS8: =IF(B8="","",$CS$1) -> 8003 | CT8: =IF(B8="","","Наличие уторгования") -> Наличие уторгования | CW8: =IF(A8="","",IF(AF8="","Отсутствуют предыдущие значения",BO8=AF8)) -> Отсутствуют предыдущие значения | CX8: =IF(A8="","",IF(AI8="","Отсутствуют предыдущие значения",BP8=AI8)) -> Отсутствуют предыдущие значения | CY8: =IF(A8="","",IF(AG8="","Отсутствуют предыдущие значения",BQ8=AG8)) -> Отсутствуют предыдущие значения | CZ8: =IF(A8="","",IF(AH8="","Отсутствуют предыдущие значения",AH8=BR8)) -> Отсутствуют предыдущие значения | DA8: =IF(A8="","",IF(U8="","Отсутствуют предыдущие значения",BS8=U8)) -> Отсутствуют предыдущие значения | DB8: =IF(A8="","",IF(AK8="","Отсутствуют предыдущие значения",BT8=AK8)) -> Отсутствуют предыдущие значения | DC8: =IF(A8="","",IF(AM8="","Отсутствуют предыдущие значения",AM8=BU8)) -> Отсутствуют предыдущие значения | DD8: =IF(A8="","",IF(AN8="","Отсутствуют предыдущие значения",AN8=BV8)) -> Отсутствуют предыдущие значения | DE8: =IF(A8="","",IF(AO8="","Отсутствуют предыдущие значения",BW8=AO8)) -> Отсутствуют предыдущие значения | DF8: =IF(A8="","",IF(AP8="","Отсутствуют предыдущие значения",AP8=BX8)) -> Отсутствуют предыдущие значения | DG8: =IF(A8="","",IF(N8="","Отсутствуют предыдущие значения",CO8=N8)) -> Отсутствуют предыдущие значения | DH8: =IF(A8="","",IF(O8="","Отсутствуют предыдущие значения",CP8=O8)) -> Отсутствуют предыдущие значения | DI8: =IF(B8="","",IF(MID(BH8,3,1)<>":","ОШИБКА В ФОРМАТЕ КОДА НП",IF(AW8<>"","ОСПАРИВАНИЕ",IF(AQ8="","",AQ8)))) | DJ8: =IF(B8="","",$DJ$1) -> Ф5 | DK8: =IF(B8="","",$DK$1) -> М3 | DL8: =IF(B8="","",$DL$1) -> 02032021 | DM8: =IF(B8="","",$DM$1) -> Мухамедьярова | DN8: =IF(B8="","",IF(O8="","Графика по ПКК","Графика на 01012020")) -> Графика по ПКК | DO8: =IF(B8="","",B8) -> 66:41:0313010:15757 | DP8: =IF(B8="","",BO8) -> пояс 3 | DQ8: =IF(B8="","",BP8) -> Наличие электроснабжения | DR8: =IF(B8="","",BQ8) -> Отсутствие теплоснабжения | DS8: =IF(B8="","",BR8) -> Отсутствие водоотведения | DT8: =IF(B8="","",BS8) -> 3. СЕГМЕНТ "Общественное использование" | DU8: =IF(B8="","",BT8) -> 8992 | DV8: =IF(B8="","",BU8) -> 7.34 | DW8: =IF(B8="","",BV8) -> 0.99 | DX8: =IF(B8="","",BW8) -> 0.03 | DY8: =IF(B8="","",BX8) -> 13.22 | DZ8: =IF(B8="","",CE8) -> 1.0063 | EA8: =IF(B8="","",CF8) -> 0.9883 | EB8: =IF(B8="","",CG8) -> 0.9972 | EC8: =IF(B8="","",CH8) -> 1.0286 | ED8: =IF(B8="","",CI8) -> 0.7797 | EE8: =IF(B8="","",CJ8) -> 0 | EF8: =IF(B8="","",CO8) -> 5246.04 | EG8: =IF(B8="","",CP8) -> 47172392 | EH8: =IF(B8="","",CQ8) -> СТ16_Ф5_М3_02032021_Мухамедьярова_Графика по ПКК_Новый | EI8: =IF(B8="","",CS8) -> 8003 | EJ8: =IF(B8="","",CT8) -> Наличие уторгования | EK8: =IF(B8="","",IF(OR(AU8<>"",AW8<>"",EG8<0),"СТОПЛИСТ",IF(OR(EQ8="Отсутствует значения предыдущих расчетов",EQ8="Осуществлен пересчет"),"ГОТОВ","ПЕРЕСЧЕТ НЕ ТРЕБУЕТСЯ"))) -> ГОТОВ | EL8: =IF(B8="","",DT8) -> 3. СЕГМЕНТ "Общественное использование" | EM8: =IF(B8="","",VLOOKUP(EL8,'Сегмент ВРИ'!$B:$C,2,FALSE)) -> 3 | EN8: =IF(B8="","",BH8) -> 05:010 | EO8: =IF(B8="","",VLOOKUP(EN8,'Сегмент ВРИ'!$A:$E,4,FALSE)) -> Спорт в целом. Размещение ОКС в качестве спортивных клубов, спортивных залов, бассейнов, устройство площадок для занятия спортом и физкультурой (беговые дорожки, спортивные сооружения, теннисные корты, поля для спортивной игры, автодромы, мотодромы, трамплины, трассы и спортивные стрельбища), в том числе водным спортом (причалы и сооружения, необходимые для водных видов спорта и хранения соответствующего инвентаря) | EP8: =IF(B8="","",IF(OR(I8="",I8="-",I8="."),J8,I8)) -> спорт | EQ8: =IF(B8="","",IF(O8="","Отсутствует значения предыдущих расчетов",IF(O8=CP8,"Значения КС не изменилось","Осуществлен пересчет"))) -> Отсутствует значения предыдущих расчетов | ER8: =IF(O8="","-",O8-CP8) -> - | ES8: =IF(B8="","-",IF(O8="","Новый","Измененный")) -> Новый
A9: 2776207 | B9: 66:41:0313010:16416 | C9: Земельный участок | D9: 6738 | F9: Свердловская область, г. Екатеринбург | G9: Земли населенных пунктов | H9: Для иных видов использования, характерных для населенных пунктов | I9: Деловое управление, общественное питание | K9: Для иных видов использования, характерных для населенных пунктов | R9: 47:004:1:1:1 | V9: 0.05 | W9: 8.31 | AA9: 6.59 | AB9: 0.25 | AC9: пояс 2 | AE9: 2021-11-18 | AX9: НЕ ГОТОВ | BH9: 04:010 | BI9: ручной разбор | BJ9: 8003 | BK9: 4. СЕГМЕНТ "Предпринимательство" | BM9: =IFERROR(VLOOKUP(B9,'Объекты МУГИСО'!$A:$B,2,FALSE),"") | BN9: =IFERROR(VLOOKUP(BH9,'Коды без коммуникаций'!$C:$C,1,FALSE),"") | BO9: =IF(B9="","",IF(AC9="","Пояс 2",AC9)) -> пояс 2 | BP9: =IF(B9="","",IF(OR(Y9="отсутствие",Y9="отсутствие электроснабжения"),"Отсутствие электроснабжения","Наличие электроснабжения")) -> Наличие электроснабжения | BQ9: =IF(A9="","",IF(OR(BN9<>"",X9="",X9="Отсутствие"),"Отсутствие теплоснабжения","Наличие теплоснабжения")) -> Отсутствие теплоснабжения | BR9: =IF(A9="","",IF(OR(BN9<>"",Z9="",Z9="Отсутствие"),"Отсутствие водоотведения","Наличие водоотведения")) -> Отсутствие водоотведения | BS9: =IF(B9="","",BK9) -> 4. СЕГМЕНТ "Предпринимательство" | BT9: =IF(B9="","",D9) -> 6738 | BU9: =IF(B9="","",IF(AA9="",VLOOKUP(BO9,Поправки!$AJ$1:$AK$6,2,FALSE),AA9)) -> 6.59 | BV9: =IF(B9="","",IF(AB9="",Поправки!$AO$2,AB9)) -> 0.25 | BW9: =IF(B9="","",IF(BM9=1,0.0001,IF(V9="",Поправки!$AP$2,V9))) -> 0.05 | BX9: =IF(B9="","",IF(W9<=0,VLOOKUP(BO9,Поправки!$AJ$1:$AL$6,3,FALSE),W9)) -> 8.31 | BY9: =IF(B9="","",Поправки!$K$21) -> 12012.337 | BZ9: =IF(B9="","",VLOOKUP(BO9,Поправки!$B$40:$D$52,3,FALSE)) -> 0.7074 | CA9: =IF(B9="","",VLOOKUP(BP9,Поправки!$B$40:$D$52,3,FALSE)) -> 1.127 | CB9: =IF(B9="","",VLOOKUP(BQ9,Поправки!$B$40:$D$52,3,FALSE)) -> 1 | CC9: =IF(B9="","",VLOOKUP(BR9,Поправки!$B$40:$D$52,3,FALSE)) -> 1 | CD9: =IF(B9="","",VLOOKUP(BS9,Поправки!$B$40:$D$52,3,FALSE)) -> 1.0955 | CE9: =IF(B9="","",IF(BT9<Поправки!$I$11,Поправки!$L$11,ROUND((EXP(11.27070473*LN(BT9)^-0.08418488)^Поправки!$G$1)/Поправки!$K$10,4))) -> 1.024 | CF9: =IF(B9="","",IF(BU9<Поправки!$N$11,Поправки!$Q$11,IF(BU9>Поправки!$N$12,Поправки!$Q$12,ROUND((EXP(9.57779229*0.98667563^LN(BU9))^Поправки!$G$2)/Поправки!$P$10,4)))) -> 0.9889 | CG9: =IF(B9="","",IF(BV9>Поправки!$S$12,Поправки!$V$12,IF(BV9<Поправки!$S$11,Поправки!$V$11,ROUND((EXP(9.3057995*0.99085691^LN(BV9))^Поправки!$G$3)/Поправки!$U$10,4)))) -> 1.0029 | CH9: =IF(B9="","",IF(BW9<Поправки!$X$11,Поправки!$AA$11,IF(BW9>Поправки!$X$12,Поправки!$AA$12,ROUND((EXP(9.23088404*0.99320482^LN(BW9))^Поправки!$G$4)/Поправки!$Z$10,4)))) -> 1.0229 | CI9: =IF(B9="","",IF(BX9<Поправки!$AC$11,Поправки!$AF$11,IF(BX9>Поправки!$AC$12,Поправки!$AF$12,ROUND((EXP(9.93943263-0.30296633*LN(BX9))^Поправки!$G$5)/Поправки!$AE$10,4)))) -> 0.8153 | CJ9: =IF(B9="","",AT9) -> 0 | CK9: =IF(B9="","",PRODUCT(BY9:CI9)) -> 8885.6551 | CL9: =IF(B9="","",ROUND(CK9*$CT$3,2)) -> 6664.24 | CM9: =IF(B9="","",ROUND(IF(51178*D9^-0.982<$CU$3,$CU$3,IF(51178*D9^-0.982>$CV$3,$CV$3,51178*D9^-0.982)),2)) -> 8.9 | CN9: =IF(B9="","",ROUND((CL9*(D9-CJ9))/D9,2)) -> 6664.24 | CO9: =IF(B9="","",IF(CJ9=0,CL9,IF(CN9<CM9,CM9,CN9))) -> 6664.24 | CP9: =IF(B9="","",ROUND(CO9*D9,2)) -> 44903649 | CQ9: =IF(B9="","",CONCATENATE("СТ16_",DJ9,"_",DK9,"_",DL9,"_",DM9,"_",DN9,"_",ES9)) -> СТ16_Ф5_М3_02032021_Мухамедьярова_Графика по ПКК_Новый | CR9: =IF(B9="","",B9) -> 66:41:0313010:16416 | CS9: =IF(B9="","",$CS$1) -> 8003 | CT9: =IF(B9="","","Наличие уторгования") -> Наличие уторгования | CW9: =IF(A9="","",IF(AF9="","Отсутствуют предыдущие значения",BO9=AF9)) -> Отсутствуют предыдущие значения | CX9: =IF(A9="","",IF(AI9="","Отсутствуют предыдущие значения",BP9=AI9)) -> Отсутствуют предыдущие значения | CY9: =IF(A9="","",IF(AG9="","Отсутствуют предыдущие значения",BQ9=AG9)) -> Отсутствуют предыдущие значения | CZ9: =IF(A9="","",IF(AH9="","Отсутствуют предыдущие значения",AH9=BR9)) -> Отсутствуют предыдущие значения | DA9: =IF(A9="","",IF(U9="","Отсутствуют предыдущие значения",BS9=U9)) -> Отсутствуют предыдущие значения | DB9: =IF(A9="","",IF(AK9="","Отсутствуют предыдущие значения",BT9=AK9)) -> Отсутствуют предыдущие значения | DC9: =IF(A9="","",IF(AM9="","Отсутствуют предыдущие значения",AM9=BU9)) -> Отсутствуют предыдущие значения | DD9: =IF(A9="","",IF(AN9="","Отсутствуют предыдущие значения",AN9=BV9)) -> Отсутствуют предыдущие значения | DE9: =IF(A9="","",IF(AO9="","Отсутствуют предыдущие значения",BW9=AO9)) -> Отсутствуют предыдущие значения | DF9: =IF(A9="","",IF(AP9="","Отсутствуют предыдущие значения",AP9=BX9)) -> Отсутствуют предыдущие значения | DG9: =IF(A9="","",IF(N9="","Отсутствуют предыдущие значения",CO9=N9)) -> Отсутствуют предыдущие значения | DH9: =IF(A9="","",IF(O9="","Отсутствуют предыдущие значения",CP9=O9)) -> Отсутствуют предыдущие значения | DI9: =IF(B9="","",IF(MID(BH9,3,1)<>":","ОШИБКА В ФОРМАТЕ КОДА НП",IF(AW9<>"","ОСПАРИВАНИЕ",IF(AQ9="","",AQ9)))) | DJ9: =IF(B9="","",$DJ$1) -> Ф5 | DK9: =IF(B9="","",$DK$1) -> М3 | DL9: =IF(B9="","",$DL$1) -> 02032021 | DM9: =IF(B9="","",$DM$1) -> Мухамедьярова | DN9: =IF(B9="","",IF(O9="","Графика по ПКК","Графика на 01012020")) -> Графика по ПКК | DO9: =IF(B9="","",B9) -> 66:41:0313010:16416 | DP9: =IF(B9="","",BO9) -> пояс 2 | DQ9: =IF(B9="","",BP9) -> Наличие электроснабжения | DR9: =IF(B9="","",BQ9) -> Отсутствие теплоснабжения | DS9: =IF(B9="","",BR9) -> Отсутствие водоотведения | DT9: =IF(B9="","",BS9) -> 4. СЕГМЕНТ "Предпринимательство" | DU9: =IF(B9="","",BT9) -> 6738 | DV9: =IF(B9="","",BU9) -> 6.59 | DW9: =IF(B9="","",BV9) -> 0.25 | DX9: =IF(B9="","",BW9) -> 0.05 | DY9: =IF(B9="","",BX9) -> 8.31 | DZ9: =IF(B9="","",CE9) -> 1.024 | EA9: =IF(B9="","",CF9) -> 0.9889 | EB9: =IF(B9="","",CG9) -> 1.0029 | EC9: =IF(B9="","",CH9) -> 1.0229 | ED9: =IF(B9="","",CI9) -> 0.8153 | EE9: =IF(B9="","",CJ9) -> 0 | EF9: =IF(B9="","",CO9) -> 6664.24 | EG9: =IF(B9="","",CP9) -> 44903649 | EH9: =IF(B9="","",CQ9) -> СТ16_Ф5_М3_02032021_Мухамедьярова_Графика по ПКК_Новый | EI9: =IF(B9="","",CS9) -> 8003 | EJ9: =IF(B9="","",CT9) -> Наличие уторгования | EK9: =IF(B9="","",IF(OR(AU9<>"",AW9<>"",EG9<0),"СТОПЛИСТ",IF(OR(EQ9="Отсутствует значения предыдущих расчетов",EQ9="Осуществлен пересчет"),"ГОТОВ","ПЕРЕСЧЕТ НЕ ТРЕБУЕТСЯ"))) -> ГОТОВ | EL9: =IF(B9="","",DT9) -> 4. СЕГМЕНТ "Предпринимательство" | EM9: =IF(B9="","",VLOOKUP(EL9,'Сегмент ВРИ'!$B:$C,2,FALSE)) -> 4 | EN9: =IF(B9="","",BH9) -> 04:010 | EO9: =IF(B9="","",VLOOKUP(EN9,'Сегмент ВРИ'!$A:$E,4,FALSE)) -> Деловое управление. Размещение ОКС с целью размещения объектов управленческой деятельности, не связанной с государственным или муниципальным управлением и оказанием услуг, а также с целью обеспечения совершения сделок, не требующих передачи товара в момент их совершения между организациями, в том числе биржевая деятельность (за исключением банковской и страховой деятельности) | EP9: =IF(B9="","",IF(OR(I9="",I9="-",I9="."),J9,I9)) -> Деловое управление, общественное питание | EQ9: =IF(B9="","",IF(O9="","Отсутствует значения предыдущих расчетов",IF(O9=CP9,"Значения КС не изменилось","Осуществлен пересчет"))) -> Отсутствует значения предыдущих расчетов | ER9: =IF(O9="","-",O9-CP9) -> - | ES9: =IF(B9="","-",IF(O9="","Новый","Измененный")) -> Новый
A10: 2775444 | B10: 66:41:0000000:188232 | C10: Земельный участок | D10: 18060 | F10: Свердловская область. г Екатеринбург. ул Бисертская | G10: Земли населенных пунктов | H10: Для размещения культовых зданий | I10: Религиозное использование | R10: 47:004:1:1:1 | V10: 0.04 | W10: 12.72 | AA10: 6.29 | AB10: 0.15 | AC10: пояс 3 | AE10: 2021-09-13 | AX10: НЕ ГОТОВ | BH10: 03:070 | BI10: Правило0 | BJ10: 8003 | BK10: 3. СЕГМЕНТ "Общественное использование" | BM10: =IFERROR(VLOOKUP(B10,'Объекты МУГИСО'!$A:$B,2,FALSE),"") | BN10: =IFERROR(VLOOKUP(BH10,'Коды без коммуникаций'!$C:$C,1,FALSE),"") | BO10: =IF(B10="","",IF(AC10="","Пояс 2",AC10)) -> пояс 3 | BP10: =IF(B10="","",IF(OR(Y10="отсутствие",Y10="отсутствие электроснабжения"),"Отсутствие электроснабжения","Наличие электроснабжения")) -> Наличие электроснабжения | BQ10: =IF(A10="","",IF(OR(BN10<>"",X10="",X10="Отсутствие"),"Отсутствие теплоснабжения","Наличие теплоснабжения")) -> Отсутствие теплоснабжения | BR10: =IF(A10="","",IF(OR(BN10<>"",Z10="",Z10="Отсутствие"),"Отсутствие водоотведения","Наличие водоотведения")) -> Отсутствие водоотведения | BS10: =IF(B10="","",BK10) -> 3. СЕГМЕНТ "Общественное использование" | BT10: =IF(B10="","",D10) -> 18060 | BU10: =IF(B10="","",IF(AA10="",VLOOKUP(BO10,Поправки!$AJ$1:$AK$6,2,FALSE),AA10)) -> 6.29 | BV10: =IF(B10="","",IF(AB10="",Поправки!$AO$2,AB10)) -> 0.15 | BW10: =IF(B10="","",IF(BM10=1,0.0001,IF(V10="",Поправки!$AP$2,V10))) -> 0.04 | BX10: =IF(B10="","",IF(W10<=0,VLOOKUP(BO10,Поправки!$AJ$1:$AL$6,3,FALSE),W10)) -> 12.72 | BY10: =IF(B10="","",Поправки!$K$21) -> 12012.337 | BZ10: =IF(B10="","",VLOOKUP(BO10,Поправки!$B$40:$D$52,3,FALSE)) -> 0.6496 | CA10: =IF(B10="","",VLOOKUP(BP10,Поправки!$B$40:$D$52,3,FALSE)) -> 1.127 | CB10: =IF(B10="","",VLOOKUP(BQ10,Поправки!$B$40:$D$52,3,FALSE)) -> 1 | CC10: =IF(B10="","",VLOOKUP(BR10,Поправки!$B$40:$D$52,3,FALSE)) -> 1 | CD10: =IF(B10="","",VLOOKUP(BS10,Поправки!$B$40:$D$52,3,FALSE)) -> 1 | CE10: =IF(B10="","",IF(BT10<Поправки!$I$11,Поправки!$L$11,ROUND((EXP(11.27070473*LN(BT10)^-0.08418488)^Поправки!$G$1)/Поправки!$K$10,4))) -> 0.967 | CF10: =IF(B10="","",IF(BU10<Поправки!$N$11,Поправки!$Q$11,IF(BU10>Поправки!$N$12,Поправки!$Q$12,ROUND((EXP(9.57779229*0.98667563^LN(BU10))^Поправки!$G$2)/Поправки!$P$10,4)))) -> 0.9892 | CG10: =IF(B10="","",IF(BV10>Поправки!$S$12,Поправки!$V$12,IF(BV10<Поправки!$S$11,Поправки!$V$11,ROUND((EXP(9.3057995*0.99085691^LN(BV10))^Поправки!$G$3)/Поправки!$U$10,4)))) -> 1.005 | CH10: =IF(B10="","",IF(BW10<Поправки!$X$11,Поправки!$AA$11,IF(BW10>Поправки!$X$12,Поправки!$AA$12,ROUND((EXP(9.23088404*0.99320482^LN(BW10))^Поправки!$G$4)/Поправки!$Z$10,4)))) -> 1.0254 | CI10: =IF(B10="","",IF(BX10<Поправки!$AC$11,Поправки!$AF$11,IF(BX10>Поправки!$AC$12,Поправки!$AF$12,ROUND((EXP(9.93943263-0.30296633*LN(BX10))^Поправки!$G$5)/Поправки!$AE$10,4)))) -> 0.7826 | CJ10: =IF(B10="","",AT10) -> 0 | CK10: =IF(B10="","",PRODUCT(BY10:CI10)) -> 6784.3344 | CL10: =IF(B10="","",ROUND(CK10*$CT$3,2)) -> 5088.25 | CM10: =IF(B10="","",ROUND(IF(51178*D10^-0.982<$CU$3,$CU$3,IF(51178*D10^-0.982>$CV$3,$CV$3,51178*D10^-0.982)),2)) -> 3.38 | CN10: =IF(B10="","",ROUND((CL10*(D10-CJ10))/D10,2)) -> 5088.25 | CO10: =IF(B10="","",IF(CJ10=0,CL10,IF(CN10<CM10,CM10,CN10))) -> 5088.25 | CP10: =IF(B10="","",ROUND(CO10*D10,2)) -> 91893795 | CQ10: =IF(B10="","",CONCATENATE("СТ16_",DJ10,"_",DK10,"_",DL10,"_",DM10,"_",DN10,"_",ES10)) -> СТ16_Ф5_М3_02032021_Мухамедьярова_Графика по ПКК_Новый | CR10: =IF(B10="","",B10) -> 66:41:0000000:188232 | CS10: =IF(B10="","",$CS$1) -> 8003 | CT10: =IF(B10="","","Наличие уторгования") -> Наличие уторгования | CW10: =IF(A10="","",IF(AF10="","Отсутствуют предыдущие значения",BO10=AF10)) -> Отсутствуют предыдущие значения | CX10: =IF(A10="","",IF(AI10="","Отсутствуют предыдущие значения",BP10=AI10)) -> Отсутствуют предыдущие значения | CY10: =IF(A10="","",IF(AG10="","Отсутствуют предыдущие значения",BQ10=AG10)) -> Отсутствуют предыдущие значения | CZ10: =IF(A10="","",IF(AH10="","Отсутствуют предыдущие значения",AH10=BR10)) -> Отсутствуют предыдущие значения | DA10: =IF(A10="","",IF(U10="","Отсутствуют предыдущие значения",BS10=U10)) -> Отсутствуют предыдущие значения | DB10: =IF(A10="","",IF(AK10="","Отсутствуют предыдущие значения",BT10=AK10)) -> Отсутствуют предыдущие значения | DC10: =IF(A10="","",IF(AM10="","Отсутствуют предыдущие значения",AM10=BU10)) -> Отсутствуют предыдущие значения | DD10: =IF(A10="","",IF(AN10="","Отсутствуют предыдущие значения",AN10=BV10)) -> Отсутствуют предыдущие значения | DE10: =IF(A10="","",IF(AO10="","Отсутствуют предыдущие значения",BW10=AO10)) -> Отсутствуют предыдущие значения | DF10: =IF(A10="","",IF(AP10="","Отсутствуют предыдущие значения",AP10=BX10)) -> Отсутствуют предыдущие значения | DG10: =IF(A10="","",IF(N10="","Отсутствуют предыдущие значения",CO10=N10)) -> Отсутствуют предыдущие значения | DH10: =IF(A10="","",IF(O10="","Отсутствуют предыдущие значения",CP10=O10)) -> Отсутствуют предыдущие значения | DI10: =IF(B10="","",IF(MID(BH10,3,1)<>":","ОШИБКА В ФОРМАТЕ КОДА НП",IF(AW10<>"","ОСПАРИВАНИЕ",IF(AQ10="","",AQ10)))) | DJ10: =IF(B10="","",$DJ$1) -> Ф5 | DK10: =IF(B10="","",$DK$1) -> М3 | DL10: =IF(B10="","",$DL$1) -> 02032021 | DM10: =IF(B10="","",$DM$1) -> Мухамедьярова | DN10: =IF(B10="","",IF(O10="","Графика по ПКК","Графика на 01012020")) -> Графика по ПКК | DO10: =IF(B10="","",B10) -> 66:41:0000000:188232 | DP10: =IF(B10="","",BO10) -> пояс 3 | DQ10: =IF(B10="","",BP10) -> Наличие электроснабжения | DR10: =IF(B10="","",BQ10) -> Отсутствие теплоснабжения | DS10: =IF(B10="","",BR10) -> Отсутствие водоотведения | DT10: =IF(B10="","",BS10) -> 3. СЕГМЕНТ "Общественное использование" | DU10: =IF(B10="","",BT10) -> 18060 | DV10: =IF(B10="","",BU10) -> 6.29 | DW10: =IF(B10="","",BV10) -> 0.15 | DX10: =IF(B10="","",BW10) -> 0.04 | DY10: =IF(B10="","",BX10) -> 12.72 | DZ10: =IF(B10="","",CE10) -> 0.967 | EA10: =IF(B10="","",CF10) -> 0.9892 | EB10: =IF(B10="","",CG10) -> 1.005 | EC10: =IF(B10="","",CH10) -> 1.0254 | ED10: =IF(B10="","",CI10) -> 0.7826 | EE10: =IF(B10="","",CJ10) -> 0 | EF10: =IF(B10="","",CO10) -> 5088.25 | EG10: =IF(B10="","",CP10) -> 91893795 | EH10: =IF(B10="","",CQ10) -> СТ16_Ф5_М3_02032021_Мухамедьярова_Графика по ПКК_Новый | EI10: =IF(B10="","",CS10) -> 8003 | EJ10: =IF(B10="","",CT10) -> Наличие уторгования | EK10: =IF(B10="","",IF(OR(AU10<>"",AW10<>"",EG10<0),"СТОПЛИСТ",IF(OR(EQ10="Отсутствует значения предыдущих расчетов",EQ10="Осуществлен пересчет"),"ГОТОВ","ПЕРЕСЧЕТ НЕ ТРЕБУЕТСЯ"))) -> ГОТОВ | EL10: =IF(B10="","",DT10) -> 3. СЕГМЕНТ "Общественное использование" | EM10: =IF(B10="","",VLOOKUP(EL10,'Сегмент ВРИ'!$B:$C,2,FALSE)) -> 3 | EN10: =IF(B10="","",BH10) -> 03:070 | EO10: =IF(B10="","",VLOOKUP(EN10,'Сегмент ВРИ'!$A:$E,4,FALSE)) -> Религиозное использование в целом | EP10: =IF(B10="","",IF(OR(I10="",I10="-",I10="."),J10,I10)) -> Религиозное использование | EQ10: =IF(B10="","",IF(O10="","Отсутствует значения предыдущих расчетов",IF(O10=CP10,"Значения КС не изменилось","Осуществлен пересчет"))) -> Отсутствует значения предыдущих расчетов | ER10: =IF(O10="","-",O10-CP10) -> - | ES10: =IF(B10="","-",IF(O10="","Новый","Измененный")) -> Новый
