Workbook

Sheet Объекты оценки
A1: Идентификатор | B1: Кадастровый номер | C1: Вид объекта недвижимости | D1: Площадь в квадратных метрах | E1: Адрес (местоположение) Иное | F1: Адрес (местоположение) Неформализованное описание | G1: Категория земель | H1: Разрешенное использование участка Вид разрешенного использования по классификатору | I1: Вид использования участка по документу | J1: Разрешенное использование участка | K1: Разрешенное использование (текстовое описание) | L1: Кадастровая стоимость | M1: Дата определения кадастровой стоимости | N1: Удельный показатель кадастровой стоимости(руб/м2) | O1: Кадастровая стоимость (руб) | P1: Кадастровая стоимость описание вых | Q1: Группа для XML | R1: Код населённого пункта | S1: Код расчета вида использования | T1: Расшифровка расчетной подгруппы | U1: Сегмент | V1: Расстояние до дороги | W1: Расстояние до центра МО | X1: Наличие отопления | Y1: Наличие электроснабжения | Z1: Наличие водоотведения | AA1: Расстояние до метро | AB1: Расстояние до остановки общественного транспорта | AC1: Ценовой пояс ЕКБ | AD1: Признак актуальности | AE1: Дата пакета | AF1: Ценовой пояс (ЦФ) | AG1: Теплоснабжение (ЦФ) | AH1: Водоотведение (ЦФ) | AI1: Электроснабжение (ЦФ) | AJ1: Отношение ВРИ к сегменту (ЦФ) | AK1: Площадь (ЦФ) | AL1: Поправка на площадь (ЦФ) | AM1: Расстояние до метро (ЦФ) | AN1: Расстояние до остановок (ЦФ) | AO1: Расстояние до дороги (ЦФ) | AP1: Расстояние до административного центра МО (ЦФ) | AQ1: Номер заявления | AR1: Тип заявления | AS1: Статус заявления | AT1: Площадь обременений (ЦФ) | AU1: Особый контроль | AV1: Дата комиссии | AW1: Решение комиссии | AX1: Статус расчета | AY1: НЕ Используется | AZ1: Флаг ВРИ по документу | BA1: Флаг Местоположения (координат) | BB1: Флаг площади | BC1: Флаг ВРИ старый спр | BD1: Флаг ВРИ новый спр | BE1: Флаг Категории ЗУ | BF1: Старый код НП | BG1: Флаг переопределения ФРИ | BH1: ВРИ по правилам | BI1: Правило | BJ1: Новоя модель | BK1: Новый сегмент | BL1: Дата оценки | BM1: ВРИ по документу старое | BP1: ОПРЕДЕЛЕНИЕ ЦФ В РАМКАХ СТАТЬИ 16 | CA1: х1 | CB1: х2 | CC1: х3 | CD1: х4 | CE1: х5 | CF1: х6 | CG1: х7 | CH1: х8 | CI1: х9 | CJ1: х10 | CK1: x11 | CN1: МЕЖЕВАНИЕ | CP1: ИТОГ | CT1: 8003 | CU1: ТОРГ | CX1: СРАВНЕНИЕ РЕЗУЛЬТАТОВ 16СТ С ДАННЫМИ НА 01012020 В СЛУЧАЕ НАЛИЧИЯ ПРЕДЫДУЩИХ РАСЧЕТОВ НА 01012020 | DN1: Ф5 | DO1: =CONCATENATE("М",RIGHT(CT1,1)) -> М3 | DP1: 02032021 | DQ1: Мухамедьярова | DS1: ДАННЫЕ ДЛЯ ЗАГРУЗКИ В БАЗУ | FD1: КОНТРОЛЬНАЯ ПРОВЕРКА | FE1: ГОТОВО | FF1: ПЕРЕСЧЕТ НЕ ТРЕБУЕТСЯ | FG1: СТОПЛИСТ
A2: ID | B2: CadastralNumber | C2: ObjectType | D2: Area | E2: AddressOther | F2: AddressNote | G2: ParcelCategory | H2: Utilization | I2: UtilizationByDoc | J2: UtilizationLandUse | K2: UtilizationТхт | L2: CostValue | M2: CostDateValuation | N2: Specific_CadastralCost | O2: CadastralCost | P2: CadastralCostDesc | Q2: ID_Group | R2: LocalityCode | S2: loc_VICode | T2: loc_GroupName | U2: Segment | V2: DistanceToRoad | W2: DistanceToCMO | X2: PresenceHeating | Y2: PresencePower | Z2: PresenceWaterDisposal | AA2: DistanceToMetro | AB2: DistanceToStationEKB | AC2: CostZone | AD2: act_sign | AE2: inputpacket_date | AF2: loc_factor_801 | AG2: loc_factor_802 | AH2: loc_factor_803 | AI2: loc_factor_804 | AJ2: loc_factor_806 | AK2: loc_factor_807 | AL2: loc_factor_8071 | AM2: loc_factor_809 | AN2: loc_factor_810 | AO2: loc_factor_811 | AP2: loc_factor_812 | AQ2: Statement | AR2: Type_Statement | AS2: Status_Statement | AT2: loc_factor_839 | AU2: ControlSP | AV2: Date_comm | AW2: Sol_comm | AX2: Status_kc | AY2: Flag_LocalityCode | AZ2: Flag_VRI | BA2: Flag_Location | BB2: FlagParam | BC2: Flag_VRIoldspr | BD2: Flag_VRInewspr | BE2: Flag_Category | BF2: OldLocalityCode | BG2: Flag_VRI_All | BH2: VRICode_NEW | BI2: PraviloVRI | BJ2: New_id_group | BK2: New_Segment | BL2: Date_KC | BM2: Old_Utlbydoc | BP2: loc_factor_801 | BQ2: loc_factor_804 | BR2: loc_factor_802 | BS2: loc_factor_803 | BT2: loc_factor_806 | BU2: loc_factor_807 | BV2: loc_factor_809 | BW2: loc_factor_810 | BX2: loc_factor_811 | BY2: loc_factor_812 | CF2: loc_factor_8071 | CG2: loc_factor_8091 | CH2: loc_factor_8101 | CI2: loc_factor_8111 | CJ2: loc_factor_8121 | CK2: loc_factor_839 | CP2: Specific_CadastralCost | CQ2: CadastralCost | CR2: CadastralCostDesc | CS2: CadastralNumber | CT2: id_group | CU2: loc_factor_827 | CV2: МЕЖЕВАНИЕ | DN2: ОПИСАНИЕ КС | DS2: Кадастровый номер | DT2: Ценовой пояс | DU2: Электроснабжение | DV2: Теплоснабжение | DW2: Водоотведение | DX2: Отношение ВРИ к сегменту | DY2: Общая площадь, м2 | DZ2: Расстояние до метро, км | EA2: Расстояние до остановок, км | EB2: Расстояние до дорог, км | EC2: Расстояние до центра, км | ED2: Общая площадь, поправочный коэффициент | EE2: Расстояние до метро, поправочный коэффициент | EF2: Расстояние до остановок, поправочный коэффициент | EG2: Расстояние до дорог, поправочный коэффициент | EH2: Расстояние до центра, поправочный коэффициент | EI2: Площадь обременений | EJ2: УПКС, руб/м2 | EK2: КС, руб. | EL2: Описание КС | EM2: Группа xml | EN2: Уторгование | EO2: Статус расчета | EP2: Сегмент | EQ2: Код сегмента | ER2: ВРИ | ES2: Наименование вида использования | ET2: Вид использования учтенный при ТЕКУЩЕМ расчете в рамках 16 статьи для загрузки в базу (в базе название колонки "ВРИ по документу старое") | EU2: ИЗМЕНЕНИЕ КС | EV2: ИЗМЕНЕНИЕ, руб. | EW2: ИЗМЕНЕНИЕ, % | EX2: Старый/Новый объект | FE2: =IF(FE3="ОТСУТСТВУЮТ","-",FE3=ГОТОВ!$AD$1) -> FALSE | FF2: =IF(FF3="ОТСУТСТВУЮТ","-",FF3='ПЕРЕСЧЕТ НЕ ТРЕБУЕТСЯ'!I1) -> - | FG2: =IF(FG3="ОТСУТСТВУЮТ","-",FG3=СТОПЛИСТ!E1) -> -
A3: PARCELS | B3: PARCELS | C3: PARCELS | D3: PARCELS | E3: PARCELS | F3: PARCELS | G3: PARCELS | H3: PARCELS | I3: PARCELS | J3: PARCELS | K3: PARCELS | L3: PARCELS | M3: PARCELS | N3: PARCELS | O3: PARCELS | P3: PARCELS | Q3: PARCELS | R3: PARCELS | S3: PARCELS | T3: PARCELS | U3: PARCELS | V3: PARCELS | W3: PARCELS | X3: PARCELS | Y3: PARCELS | Z3: PARCELS | AA3: PARCELS | AB3: PARCELS | AC3: PARCELS | AD3: PARCELS | AE3: PARCELS | AF3: PARCELS | AG3: PARCELS | AH3: PARCELS | AI3: PARCELS | AJ3: PARCELS | AK3: PARCELS | AL3: PARCELS | AM3: PARCELS | AN3: PARCELS | AO3: PARCELS | AP3: PARCELS | AQ3: PARCELS | AR3: PARCELS | AS3: PARCELS | AT3: PARCELS | AU3: PARCELS | AV3: PARCELS | AW3: PARCELS | AX3: PARCELS | AY3: PARCELS | AZ3: PARCELS | BA3: PARCELS | BB3: PARCELS | BC3: PARCELS | BD3: PARCELS | BE3: PARCELS | BF3: PARCELS | BG3: PARCELS | BH3: PARCELS | BI3: PARCELS | BJ3: PARCELS | BK3: PARCELS | BL3: PARCELS | BM3: PARCELS | BN3: Объекты МУГИСО | BO3: Наличие/отсутствие коммуникаций по допущению | BP3: Ценовой пояс | BQ3: Электроснабжение | BR3: Теплоснабжение | BS3: Водоотведение | BT3: Отношение ВРИ к сегменту | BU3: Общая площадь, м2 | BV3: Расстояние до метро, км | BW3: Расстояние до остановок, км | BX3: Расстояние до дорог, км | BY3: Расстояние до центра, км | BZ3: Константа | CA3: Ценовой пояс, поправочный коэффициент | CB3: Электроснабжение, поправочный коэффициент | CC3: Теплоснабжение, поправочный коэффициент | CD3: Водоотведение, поправочный коэффициент | CE3: Отношение к сегменту, поправочный коэффициент | CF3: Общая площадь, поправочный коэффициент | CG3: Расстояние до метро, поправочный коэффициент | CH3: Расстояние до остановок, поправочный коэффициент | CI3: Расстояние до дорог, поправочный коэффициент | CJ3: Расстояние до центра, поправочный коэффициент | CK3: Площадь обременений | CL3: УПКС, руб/м2 | CM3: УПКС с учетом поправки на уторгование, руб/м2 на 2020 | CN3: УПКС по межеванию | CO3: УПКС с учетом поправки на уторгование И ОБРЕМЕНЕНИЕ, руб/м2 на 2020 | CP3: УПКС с учетом поправки на уторгование И ОБРЕМЕНЕНИЕ И МЕЖЕВАНИЕ, руб/м2 на 2020 | CQ3: КС, руб. на 2020 | CR3: Описание КС | CS3: КН | CT3: Группа хмл | CU3: 0.75 | CV3: 0.12 | CW3: 13117.78 | CX3: Ценовой пояс | CY3: Электроснабжение | CZ3: Теплоснабжение | DA3: Водоотведение | DB3: Отношение ВРИ к сегменту | DC3: Общая площадь, м2 | DD3: Расстояние до метро, км | DE3: Расстояние до остановок, км | DF3: Расстояние до дорог, км | DG3: Расстояние до центра, км | DH3: Код расчета вида использования | DI3: Модель | DJ3: ВРИ по документу | DK3: УПКС с учетом поправки на уторгование И ОБРЕМЕНЕНИЕ И МЕЖЕВАНИЕ, руб/м2 на 2020 | DL3: КС, руб. на 2020 | DM3: ОБЯЗАТЕЛЬНАЯ ПРОВЕРКА | DN3: Файл | DO3: Модель | DP3: Дата | DQ3: Ответственный | DR3: Графика | DS3: CadastralNumber | DT3: loc_factor_801 | DU3: loc_factor_804 | DV3: loc_factor_802 | DW3: loc_factor_803 | DX3: loc_factor_806 | DY3: loc_factor_807 | DZ3: loc_factor_809 | EA3: loc_factor_810 | EB3: loc_factor_811 | EC3: loc_factor_812 | ED3: loc_factor_8071 | EE3: loc_factor_8091 | EF3: loc_factor_8101 | EG3: loc_factor_8111 | EH3: loc_factor_8121 | EI3: loc_factor_839 | EJ3: Specific_CadastralCost | EK3: CadastralCost | EL3: CadastralCostDesc | EM3: id_group | EN3: loc_factor_827 | EO3: Status_kc | EP3: Segment | EQ3: loc_SgCode | ER3: loc_VICode | ES3: loc_GroupName | ET3: Old_Utlbydoc | FE3: =IF(AND(ГОТОВ!AD1=1,COUNTIF(EO:EO,"ГОТОВ")=0),"ОТСУТСТВУЮТ",COUNTIF(EO:EO,"ГОТОВ")+1) -> 3 | FF3: =IF(AND('ПЕРЕСЧЕТ НЕ ТРЕБУЕТСЯ'!I1=1,COUNTIF(EO:EO,"ПЕРЕСЧЕТ НЕ ТРЕБУЕТСЯ")=0),"ОТСУТСТВУЮТ",COUNTIF(EO:EO,"ПЕРЕСЧЕТ НЕ ТРЕБУЕТСЯ")+1) -> ОТСУТСТВУЮТ | FG3: =IF(AND(СТОПЛИСТ!E1=1,COUNTIF(EO:EO,"СТОПЛИСТ")=0),"ОТСУТСТВУЮТ",COUNTIF(EO:EO,"СТОПЛИСТ")+1) -> ОТСУТСТВУЮТ
A4: 2768610 | B4: 66:41:0000000:187027 | C4: Земельный участок | D4: 6567 | E4: Российская Федерация, Свердловская область, город Екатеринбург | F4: Российская Федерация, Свердловская область, город Екатеринбург | G4: Земли населенных пунктов | H4: Для иных видов использования, характерных для населенных пунктов | I4: Общественное управление (код 3.8), деловое управление (код 4.1), магазины (код 4.4), банковская и страховая деятельность (код 4.5), культурное развитие (код 3.6), обеспечение научной деятельности (код 3.9), общественное питание (код 4.6), среднеэтажная жилая застройка (код 2.5), многоэтажная жилая застройка (высотная застройка) (код 2.6), бытовое обслуживание (код 3.3), социальное обслуживание (код 3.2), историко-культурная деятельность (код 9.3), здравоохранение (код 3.4), образование и просвещение (код 9.3), объекты торговли (торговые центры, торгово-развлекательные центры (комплексы)) (код 4.2), гостиничное обслуживание (код 4.7), развлечения (код 4.8), хранение автотранспорта (код 2.7.1), служебные гаражи (код 4.9), выставочно-ярмарочная деятельность (код 4.10), спорт (код 5.1), коммунальное обслуживание (код 3.1), внеуличный транспорт (код 7.6) | J4: Общественное управление | K4: Для иных видов использования, характерных для населенных пунктов | L4: 9482616.7 | M4: 2021-07-29 00:00:00.0000000 | N4: 1443.98 | O4: 9482616.7 | P4: СТ16_Ф29_М6_02082021_Мухамедьярова_Графика по ПКК_Новый | Q4: 8006 | R4: 47:004:1:1:1 | S4: 02:071 | T4: Объекты гаражного назначения. Размещение отдельно стоящих и пристроенных одноэтажных гаражей надземных, предназначенных для хранения личного автотранспорта граждан (в том числе в квартальной жилой застройке) | U4: 7. СЕГМЕНТ "Транспорт" | V4: 0 | W4: 4.45 | AA4: 1.9 | AB4: 0.18 | AC4: пояс 1 | AE4: 2021-11-16 | AF4: пояс 1 | AH4: отсутствие водоотведения | AI4: наличие электроснабжения | AJ4: 7. СЕГМЕНТ "Транспорт" | AK4: 6567 | AO4: 0 | AT4: 0 | AX4: НЕ ГОТОВ | AY4: ГОТОВ | AZ4: не готов | BA4: ГОТОВ | BB4: ГОТОВ | BC4: не готов | BD4: не готов | BE4: ГОТОВ | BG4: не готов | BH4: 03:080 | BI4: 540СПР | BJ4: 8003 | BK4: 3. СЕГМЕНТ "Общественное использование" | BL4: 2021-07-29 | BM4: Хранение автотранспорта | BN4: =IFERROR(VLOOKUP(B4,'Объекты МУГИСО'!$A:$B,2,FALSE),"") | BO4: =IFERROR(VLOOKUP(BH4,'Коды без коммуникаций'!$C:$C,1,FALSE),"") | BP4: =IF(B4="","",IF(AF4<>"",AF4,IF(AC4<>"",AC4,"Пояс 2"))) -> пояс 1 | BQ4: =IF(B4="","",IF(AI4<>"",AI4,IF(OR(Y4="отсутствие",Y4="Отсутствие электроснабжения"),"Отсутствие электроснабжения","Наличие электроснабжения"))) -> наличие электроснабжения | BR4: =IF(B4="","",IF(AG4<>"",AG4,IF(OR(BO4<>"",X4="",X4="Отсутствие"),"Отсутствие теплоснабжения","Наличие теплоснабжения"))) -> Отсутствие теплоснабжения | BS4: =IF(B4="","",IF(AH4<>"",AH4,IF(OR(BO4<>"",Z4="",Z4="Отсутствие"),"Отсутствие водоотведения","Наличие водоотведения"))) -> отсутствие водоотведения | BT4: =IF(B4="","",BK4) -> 3. СЕГМЕНТ "Общественное использование" | BU4: =IF(B4="","",D4) -> 6567 | BV4: =IF(B4="","",IF(AM4<>"",AM4,IF(AA4="",VLOOKUP(BP4,Поправки!$AJ$1:$AK$6,2,FALSE),AA4))) -> 1.9 | BW4: =IF(B4="","",IF(AN4<>"",AN4,IF(AB4="",Поправки!$AO$2,AB4))) -> 0.18 | BX4: =IF(B4="","",IF(AO4<>"",AO4,IF(BN4=1,0.0001,IF(V4="",Поправки!$AP$2,V4)))) -> 0 | BY4: =IF(B4="","",IF(AP4<>"",AP4,IF(OR(W4<=0,W4=""),VLOOKUP(BP4,Поправки!$AJ$1:$AL$6,3,FALSE),W4))) -> 4.45 | BZ4: =IF(B4="","",Поправки!$K$21) -> 12012.337 | CA4: =IF(B4="","",VLOOKUP(BP4,Поправки!$B$40:$D$52,3,FALSE)) -> 0.8294 | CB4: =IF(B4="","",VLOOKUP(BQ4,Поправки!$B$40:$D$52,3,FALSE)) -> 1.127 | CC4: =IF(B4="","",VLOOKUP(BR4,Поправки!$B$40:$D$52,3,FALSE)) -> 1 | CD4: =IF(B4="","",VLOOKUP(BS4,Поправки!$B$40:$D$52,3,FALSE)) -> 1 | CE4: =IF(B4="","",VLOOKUP(BT4,Поправки!$B$40:$D$52,3,FALSE)) -> 1 | CF4: =IF(B4="","",IF(BU4<Поправки!$I$11,Поправки!$L$11,ROUND((EXP(11.27070473*LN(BU4)^-0.08418488)^Поправки!$G$1)/Поправки!$K$10,4))) -> 1.0257 | CG4: =IF(B4="","",IF(BV4<Поправки!$N$11,Поправки!$Q$11,IF(BV4>Поправки!$N$12,Поправки!$Q$12,ROUND((EXP(9.57779229*0.98667563^LN(BV4))^Поправки!$G$2)/Поправки!$P$10,4)))) -> 0.9962 | CH4: =IF(B4="","",IF(BW4>Поправки!$S$12,Поправки!$V$12,IF(BW4<Поправки!$S$11,Поправки!$V$11,ROUND((EXP(9.3057995*0.99085691^LN(BW4))^Поправки!$G$3)/Поправки!$U$10,4)))) -> 1.0042 | CI4: =IF(B4="","",IF(BX4<Поправки!$X$11,Поправки!$AA$11,IF(BX4>Поправки!$X$12,Поправки!$AA$12,ROUND((EXP(9.23088404*0.99320482^LN(BX4))^Поправки!$G$4)/Поправки!$Z$10,4)))) -> 1.0965 | CJ4: =IF(B4="","",IF(BY4<Поправки!$AC$11,Поправки!$AF$11,IF(BY4>Поправки!$AC$12,Поправки!$AF$12,ROUND((EXP(9.93943263-0.30296633*LN(BY4))^Поправки!$G$5)/Поправки!$AE$10,4)))) -> 0.8659 | CK4: =IF(B4="","",AT4) -> 0 | CL4: =IF(B4="","",PRODUCT(BZ4:CJ4)) -> 10939.033 | CM4: =IF(B4="","",ROUND(CL4*$CU$3,2)) -> 8204.28 | CN4: =IF(B4="","",ROUND(IF(51178*D4^-0.982<$CV$3,$CV$3,IF(51178*D4^-0.982>$CW$3,$CW$3,51178*D4^-0.982)),2)) -> 9.13 | CO4: =IF(B4="","",ROUND((CM4*(D4-CK4))/D4,2)) -> 8204.28 | CP4: =IF(B4="","",IF(CK4=0,CM4,IF(CO4<CN4,CN4,CO4))) -> 8204.28 | CQ4: =IF(B4="","",ROUND(CP4*D4,2)) -> 53877507 | CR4: =IF(B4="","",CONCATENATE("СТ16_",DN4,"_",DO4,"_",DP4,"_",DQ4,"_",DR4,"_",EX4)) -> СТ16_Ф5_М3_02032021_Мухамедьярова_Графика на 01012020_Измененный | CS4: =IF(B4="","",B4) -> 66:41:0000000:187027 | CT4: =IF(B4="","",$CT$1) -> 8003 | CU4: =IF(B4="","","Наличие уторгования") -> Наличие уторгования | CX4: =IF(A4="","",IF(AF4="","Отсутствуют предыдущие значения",BP4=AF4)) -> TRUE | CY4: =IF(A4="","",IF(AI4="","Отсутствуют предыдущие значения",BQ4=AI4)) -> TRUE | CZ4: =IF(A4="","",IF(AG4="","Отсутствуют предыдущие значения",BR4=AG4)) -> Отсутствуют предыдущие значения | DA4: =IF(A4="","",IF(AH4="","Отсутствуют предыдущие значения",AH4=BS4)) -> TRUE | DB4: =IF(A4="","",IF(U4="","Отсутствуют предыдущие значения",BT4=U4)) -> FALSE | DC4: =IF(A4="","",IF(AK4="","Отсутствуют предыдущие значения",BU4=AK4)) -> TRUE | DD4: =IF(A4="","",IF(AM4="","Отсутствуют предыдущие значения",AM4=BV4)) -> Отсутствуют предыдущие значения | DE4: =IF(A4="","",IF(AN4="","Отсутствуют предыдущие значения",AN4=BW4)) -> Отсутствуют предыдущие значения | DF4: =IF(A4="","",IF(AO4="","Отсутствуют предыдущие значения",BX4=AO4)) -> TRUE | DG4: =IF(A4="","",IF(AP4="","Отсутствуют предыдущие значения",AP4=BY4)) -> Отсутствуют предыдущие значения | DH4: =IF(A4="","",IF(OR(MID(S4,3,1)<>":",MID(BH4,3,1)<>":"),"ОШИБКА В ФОРМАТЕ",IF(S4="","Отсутствуют предыдущие значения",BH4=S4))) -> FALSE | DI4: =IF(B4="","",Q4=BJ4) -> FALSE | DJ4: =IF(A4="","",IF(AF4="","Отсутствуют предыдущие значения",BM4=I4)) -> FALSE | DK4: =IF(A4="","",IF(N4="","Отсутствуют предыдущие значения",CP4=N4)) -> FALSE | DL4: =IF(A4="","",IF(O4="","Отсутствуют предыдущие значения",CQ4=O4)) -> FALSE | DM4: =IF(B4="","",IF(AW4<>"","ОСПАРИВАНИЕ",IF(AQ4="","",AQ4))) | DN4: =IF(B4="","",$DN$1) -> Ф5 | DO4: =IF(B4="","",$DO$1) -> М3 | DP4: =IF(B4="","",$DP$1) -> 02032021 | DQ4: =IF(B4="","",$DQ$1) -> Мухамедьярова | DR4: =IF(B4="","",IF(O4="","Графика по ПКК","Графика на 01012020")) -> Графика на 01012020 | DS4: =IF(B4="","",B4) -> 66:41:0000000:187027 | DT4: =IF(B4="","",BP4) -> пояс 1 | DU4: =IF(B4="","",BQ4) -> наличие электроснабжения | DV4: =IF(B4="","",BR4) -> Отсутствие теплоснабжения | DW4: =IF(B4="","",BS4) -> отсутствие водоотведения | DX4: =IF(B4="","",BT4) -> 3. СЕГМЕНТ "Общественное использование" | DY4: =IF(B4="","",BU4) -> 6567 | DZ4: =IF(B4="","",BV4) -> 1.9 | EA4: =IF(B4="","",BW4) -> 0.18 | EB4: =IF(B4="","",BX4) -> 0 | EC4: =IF(B4="","",BY4) -> 4.45 | ED4: =IF(B4="","",CF4) -> 1.0257 | EE4: =IF(B4="","",CG4) -> 0.9962 | EF4: =IF(B4="","",CH4) -> 1.0042 | EG4: =IF(B4="","",CI4) -> 1.0965 | EH4: =IF(B4="","",CJ4) -> 0.8659 | EI4: =IF(B4="","",CK4) -> 0 | EJ4: =IF(B4="","",CP4) -> 8204.28 | EK4: =IF(B4="","",CQ4) -> 53877507 | EL4: =IF(B4="","",CR4) -> СТ16_Ф5_М3_02032021_Мухамедьярова_Графика на 01012020_Измененный | EM4: =IF(B4="","",CT4) -> 8003 | EN4: =IF(B4="","",CU4) -> Наличие уторгования | EO4: =IF(B4="","",IF(OR(AU4<>"",AW4<>"",EK4<0),"СТОПЛИСТ",IF(AR4=21,"СТОПЛИСТ",IF(AND(DH4=TRUE,DC4=TRUE),"ПЕРЕСЧЕТ НЕ ТРЕБУЕТСЯ",IF(OR(EU4="Отсутствует значения предыдущих расчетов",EU4="Осуществлен пересчет"),"ГОТОВ","ПЕРЕСЧЕТ НЕ ТРЕБУЕТСЯ"))))) -> ГОТОВ | EP4: =IF(B4="","",DX4) -> 3. СЕГМЕНТ "Общественное использование" | EQ4: =IF(C4="","",VLOOKUP(EP4,'Сегмент ВРИ'!$B:$C,2,FALSE)) -> 3 | ER4: =IF(B4="","",BH4) -> 03:080 | ES4: =IF(ER4="","",VLOOKUP(ER4,'Сегмент ВРИ'!$A:$D,4,FALSE)) -> Общественное управление в целом | ET4: =IF(BW4="","",IF(OR(I4="",I4="-",I4="."),J4,I4)) -> Общественное управление (код 3.8), деловое управление (код 4.1), магазины (код 4.4), банковская и страховая деятельность (код 4.5), культурное развитие (код 3.6), обеспечение научной деятельности (код 3.9), общественное питание (код 4.6), среднеэтажная жилая застройка (код 2.5), многоэтажная жилая застройка (высотная застройка) (код 2.6), бытовое обслуживание (код 3.3), социальное обслуживание (код 3.2), историко-культурная деятельность (код 9.3), здравоохранение (код 3.4), образование и просвещение (код 9.3), объекты торговли (торговые центры, торгово-развлекательные центры (комплексы)) (код 4.2), гостиничное обслуживание (код 4.7), развлечения (код 4.8), хранение автотранспорта (код 2.7.1), служебные гаражи (код 4.9), выставочно-ярмарочная деятельность (код 4.10), спорт (код 5.1), коммунальное обслуживание (код 3.1), внеуличный транспорт (код 7.6) | EU4: =IF(B4="","",IF(O4="","Отсутствует значения предыдущих расчетов",IF(O4=CQ4,"Значения КС не изменилось","Осуществлен пересчет"))) -> Осуществлен пересчет | EV4: =IF(B4="","",IF(O4="","-",CQ4-O4)) -> 44394890 | EW4: =IF(B4="","",IF(O4="","Отсутствует значения предыдущих расчетов",EK4/O4-1)) -> 4.681713 | EX4: =IF(B4="","-",IF(O4="","Новый","Измененный")) -> Измененный
A5: 2738179 | B5: 66:41:0614073:123 | C5: Земельный участок | D5: 162 | F5: Российская Федерация, Свердловская область, город Екатеринбург, улица Механизаторов, 100 | G5: Земли населенных пунктов | H5: Для иных видов использования, характерных для населенных пунктов | I5: Магазины (4.4) | K5: Для иных видов использования, характерных для населенных пунктов | L5: 56086.02 | M5: 2020-08-26 00:00:00.0000000 | N5: 346.21 | O5: 56086.02 | P5: СТ16_Ф1_М8_08022021_Ахмадеева_Графика по ПКК_Новый | Q5: 8008 | R5: 47:004:1:1:1 | S5: 12:999 | T5: Иной вид использования в сегменте "Специальное, ритуальное использование, запас" | U5: 12. СЕГМЕНТ "Специальное, ритуальное использование, запас" | V5: 0.15 | W5: 22.38 | AA5: 16.23 | AB5: 0.17 | AC5: пояс 4 | AE5: 2021-11-15 | AK5: 162 | AL5: 346.20997 | AX5: НЕ ГОТОВ | AY5: ГОТОВ | AZ5: не готов | BA5: ГОТОВ | BB5: ГОТОВ | BC5: не готов | BD5: ГОТОВ | BE5: ГОТОВ | BG5: не готов | BH5: 04:040 | BI5: ручной разбор | BJ5: 8003 | BK5: 4. СЕГМЕНТ "Предпринимательство" | BL5: 2021-01-01 | BM5: специального назначения | BN5: =IFERROR(VLOOKUP(B5,'Объекты МУГИСО'!$A:$B,2,FALSE),"") | BO5: =IFERROR(VLOOKUP(BH5,'Коды без коммуникаций'!$C:$C,1,FALSE),"") | BP5: =IF(B5="","",IF(AF5<>"",AF5,IF(AC5<>"",AC5,"Пояс 2"))) -> пояс 4 | BQ5: =IF(B5="","",IF(AI5<>"",AI5,IF(OR(Y5="отсутствие",Y5="Отсутствие электроснабжения"),"Отсутствие электроснабжения","Наличие электроснабжения"))) -> Наличие электроснабжения | BR5: =IF(B5="","",IF(AG5<>"",AG5,IF(OR(BO5<>"",X5="",X5="Отсутствие"),"Отсутствие теплоснабжения","Наличие теплоснабжения"))) -> Отсутствие теплоснабжения | BS5: =IF(B5="","",IF(AH5<>"",AH5,IF(OR(BO5<>"",Z5="",Z5="Отсутствие"),"Отсутствие водоотведения","Наличие водоотведения"))) -> Отсутствие водоотведения | BT5: =IF(B5="","",BK5) -> 4. СЕГМЕНТ "Предпринимательство" | BU5: =IF(B5="","",D5) -> 162 | BV5: =IF(B5="","",IF(AM5<>"",AM5,IF(AA5="",VLOOKUP(BP5,Поправки!$AJ$1:$AK$6,2,FALSE),AA5))) -> 16.23 | BW5: =IF(B5="","",IF(AN5<>"",AN5,IF(AB5="",Поправки!$AO$2,AB5))) -> 0.17 | BX5: =IF(B5="","",IF(AO5<>"",AO5,IF(BN5=1,0.0001,IF(V5="",Поправки!$AP$2,V5)))) -> 0.15 | BY5: =IF(B5="","",IF(AP5<>"",AP5,IF(OR(W5<=0,W5=""),VLOOKUP(BP5,Поправки!$AJ$1:$AL$6,3,FALSE),W5))) -> 22.38 | BZ5: =IF(B5="","",Поправки!$K$21) -> 12012.337 | CA5: =IF(B5="","",VLOOKUP(BP5,Поправки!$B$40:$D$52,3,FALSE)) -> 0.5687 | CB5: =IF(B5="","",VLOOKUP(BQ5,Поправки!$B$40:$D$52,3,FALSE)) -> 1.127 | CC5: =IF(B5="","",VLOOKUP(BR5,Поправки!$B$40:$D$52,3,FALSE)) -> 1 | CD5: =IF(B5="","",VLOOKUP(BS5,Поправки!$B$40:$D$52,3,FALSE)) -> 1 | CE5: =IF(B5="","",VLOOKUP(BT5,Поправки!$B$40:$D$52,3,FALSE)) -> 1.0955 | CF5: =IF(B5="","",IF(BU5<Поправки!$I$11,Поправки!$L$11,ROUND((EXP(11.27070473*LN(BU5)^-0.08418488)^Поправки!$G$1)/Поправки!$K$10,4))) -> 1.303 | CG5: =IF(B5="","",IF(BV5<Поправки!$N$11,Поправки!$Q$11,IF(BV5>Поправки!$N$12,Поправки!$Q$12,ROUND((EXP(9.57779229*0.98667563^LN(BV5))^Поправки!$G$2)/Поправки!$P$10,4)))) -> 0.9838 | CH5: =IF(B5="","",IF(BW5>Поправки!$S$12,Поправки!$V$12,IF(BW5<Поправки!$S$11,Поправки!$V$11,ROUND((EXP(9.3057995*0.99085691^LN(BW5))^Поправки!$G$3)/Поправки!$U$10,4)))) -> 1.0045 | CI5: =IF(B5="","",IF(BX5<Поправки!$X$11,Поправки!$AA$11,IF(BX5>Поправки!$X$12,Поправки!$AA$12,ROUND((EXP(9.23088404*0.99320482^LN(BX5))^Поправки!$G$4)/Поправки!$Z$10,4)))) -> 1.0107 | CJ5: =IF(B5="","",IF(BY5<Поправки!$AC$11,Поправки!$AF$11,IF(BY5>Поправки!$AC$12,Поправки!$AF$12,ROUND((EXP(9.93943263-0.30296633*LN(BY5))^Поправки!$G$5)/Поправки!$AE$10,4)))) -> 0.7531 | CK5: =IF(B5="","",AT5) -> 0 | CL5: =IF(B5="","",PRODUCT(BZ5:CJ5)) -> 8266.5278 | CM5: =IF(B5="","",ROUND(CL5*$CU$3,2)) -> 6199.9 | CN5: =IF(B5="","",ROUND(IF(51178*D5^-0.982<$CV$3,$CV$3,IF(51178*D5^-0.982>$CW$3,$CW$3,51178*D5^-0.982)),2)) -> 346.21 | CO5: =IF(B5="","",ROUND((CM5*(D5-CK5))/D5,2)) -> 6199.9 | CP5: =IF(B5="","",IF(CK5=0,CM5,IF(CO5<CN5,CN5,CO5))) -> 6199.9 | CQ5: =IF(B5="","",ROUND(CP5*D5,2)) -> 1004383.8 | CR5: =IF(B5="","",CONCATENATE("СТ16_",DN5,"_",DO5,"_",DP5,"_",DQ5,"_",DR5,"_",EX5)) -> СТ16_Ф5_М3_02032021_Мухамедьярова_Графика на 01012020_Измененный | CS5: =IF(B5="","",B5) -> 66:41:0614073:123 | CT5: =IF(B5="","",$CT$1) -> 8003 | CU5: =IF(B5="","","Наличие уторгования") -> Наличие уторгования | CX5: =IF(A5="","",IF(AF5="","Отсутствуют предыдущие значения",BP5=AF5)) -> Отсутствуют предыдущие значения | CY5: =IF(A5="","",IF(AI5="","Отсутствуют предыдущие значения",BQ5=AI5)) -> Отсутствуют предыдущие значения | CZ5: =IF(A5="","",IF(AG5="","Отсутствуют предыдущие значения",BR5=AG5)) -> Отсутствуют предыдущие значения | DA5: =IF(A5="","",IF(AH5="","Отсутствуют предыдущие значения",AH5=BS5)) -> Отсутствуют предыдущие значения | DB5: =IF(A5="","",IF(U5="","Отсутствуют предыдущие значения",BT5=U5)) -> FALSE | DC5: =IF(A5="","",IF(AK5="","Отсутствуют предыдущие значения",BU5=AK5)) -> TRUE | DD5: =IF(A5="","",IF(AM5="","Отсутствуют предыдущие значения",AM5=BV5)) -> Отсутствуют предыдущие значения | DE5: =IF(A5="","",IF(AN5="","Отсутствуют предыдущие значения",AN5=BW5)) -> Отсутствуют предыдущие значения | DF5: =IF(A5="","",IF(AO5="","Отсутствуют предыдущие значения",BX5=AO5)) -> Отсутствуют предыдущие значения | DG5: =IF(A5="","",IF(AP5="","Отсутствуют предыдущие значения",AP5=BY5)) -> Отсутствуют предыдущие значения | DH5: =IF(A5="","",IF(OR(MID(S5,3,1)<>":",MID(BH5,3,1)<>":"),"ОШИБКА В ФОРМАТЕ",IF(S5="","Отсутствуют предыдущие значения",BH5=S5))) -> FALSE | DI5: =IF(B5="","",Q5=BJ5) -> FALSE | DJ5: =IF(A5="","",IF(AF5="","Отсутствуют предыдущие значения",BM5=I5)) -> Отсутствуют предыдущие значения | DK5: =IF(A5="","",IF(N5="","Отсутствуют предыдущие значения",CP5=N5)) -> FALSE | DL5: =IF(A5="","",IF(O5="","Отсутствуют предыдущие значения",CQ5=O5)) -> FALSE | DM5: =IF(B5="","",IF(AW5<>"","ОСПАРИВАНИЕ",IF(AQ5="","",AQ5))) | DN5: =IF(B5="","",$DN$1) -> Ф5 | DO5: =IF(B5="","",$DO$1) -> М3 | DP5: =IF(B5="","",$DP$1) -> 02032021 | DQ5: =IF(B5="","",$DQ$1) -> Мухамедьярова | DR5: =IF(B5="","",IF(O5="","Графика по ПКК","Графика на 01012020")) -> Графика на 01012020 | DS5: =IF(B5="","",B5) -> 66:41:0614073:123 | DT5: =IF(B5="","",BP5) -> пояс 4 | DU5: =IF(B5="","",BQ5) -> Наличие электроснабжения | DV5: =IF(B5="","",BR5) -> Отсутствие теплоснабжения | DW5: =IF(B5="","",BS5) -> Отсутствие водоотведения | DX5: =IF(B5="","",BT5) -> 4. СЕГМЕНТ "Предпринимательство" | DY5: =IF(B5="","",BU5) -> 162 | DZ5: =IF(B5="","",BV5) -> 16.23 | EA5: =IF(B5="","",BW5) -> 0.17 | EB5: =IF(B5="","",BX5) -> 0.15 | EC5: =IF(B5="","",BY5) -> 22.38 | ED5: =IF(B5="","",CF5) -> 1.303 | EE5: =IF(B5="","",CG5) -> 0.9838 | EF5: =IF(B5="","",CH5) -> 1.0045 | EG5: =IF(B5="","",CI5) -> 1.0107 | EH5: =IF(B5="","",CJ5) -> 0.7531 | EI5: =IF(B5="","",CK5) -> 0 | EJ5: =IF(B5="","",CP5) -> 6199.9 | EK5: =IF(B5="","",CQ5) -> 1004383.8 | EL5: =IF(B5="","",CR5) -> СТ16_Ф5_М3_02032021_Мухамедьярова_Графика на 01012020_Измененный | EM5: =IF(B5="","",CT5) -> 8003 | EN5: =IF(B5="","",CU5) -> Наличие уторгования | EO5: =IF(B5="","",IF(OR(AU5<>"",AW5<>"",EK5<0),"СТОПЛИСТ",IF(AR5=21,"СТОПЛИСТ",IF(AND(DH5=TRUE,DC5=TRUE),"ПЕРЕСЧЕТ НЕ ТРЕБУЕТСЯ",IF(OR(EU5="Отсутствует значения предыдущих расчетов",EU5="Осуществлен пересчет"),"ГОТОВ","ПЕРЕСЧЕТ НЕ ТРЕБУЕТСЯ"))))) -> ГОТОВ | EP5: =IF(B5="","",DX5) -> 4. СЕГМЕНТ "Предпринимательство" | EQ5: =IF(C5="","",VLOOKUP(EP5,'Сегмент ВРИ'!$B:$C,2,FALSE)) -> 4 | ER5: =IF(B5="","",BH5) -> 04:040 | ES5: =IF(ER5="","",VLOOKUP(ER5,'Сегмент ВРИ'!$A:$D,4,FALSE)) -> Магазины. Размещение ОКС, предназначенных для продажи товаров, торговая площадь которых составляет до 5 000 кв.м | ET5: =IF(BW5="","",IF(OR(I5="",I5="-",I5="."),J5,I5)) -> Магазины (4.4) | EU5: =IF(B5="","",IF(O5="","Отсутствует значения предыдущих расчетов",IF(O5=CQ5,"Значения КС не изменилось","Осуществлен пересчет"))) -> Осуществлен пересчет | EV5: =IF(B5="","",IF(O5="","-",CQ5-O5)) -> 948297.78 | EW5: =IF(B5="","",IF(O5="","Отсутствует значения предыдущих расчетов",EK5/O5-1)) -> 16.907917 | EX5: =IF(B5="","-",IF(O5="","Новый","Измененный")) -> Измененный

Sheet ПЕРЕСЧЕТ НЕ ТРЕБУЕТСЯ
A1: CadastralNumber | B1: Status_kc | C1: Segment | D1: loc_SgCode | E1: loc_VICode | F1: loc_GroupName | G1: Old_Utlbydoc | I1: =COUNTA(A:A) -> 1

Sheet ГОТОВ
A1: CadastralNumber | B1: loc_factor_801 | C1: loc_factor_804 | D1: loc_factor_802 | E1: loc_factor_803 | F1: loc_factor_806 | G1: loc_factor_807 | H1: loc_factor_809 | I1: loc_factor_810 | J1: loc_factor_811 | K1: loc_factor_812 | L1: loc_factor_8071 | M1: loc_factor_8091 | N1: loc_factor_8101 | O1: loc_factor_8111 | P1: loc_factor_8121 | Q1: loc_factor_839 | R1: Specific_CadastralCost | S1: CadastralCost | T1: CadastralCostDesc | U1: id_group | V1: loc_factor_827 | W1: Status_kc | X1: Segment | Y1: loc_SgCode | Z1: loc_VICode | AA1: loc_GroupName | AB1: Old_Utlbydoc
A2: 66:41:0000000:187027 | B2: фактор1 | L2: фактор 8071 | M2: фактор 8091
A3: 66:41:0614073:123 | B3: фактор 2 | L3: фактор 8071 | M3: фактор 8091
M4: лишний

Sheet СТОПЛИСТ
A1: CadastralNumber | B1: Status_kc | E1: =COUNTA(A:A) -> 1

Sheet Инструкция
B1: Пошаговая инструкция расчета объектов в рамках статьи 16 для модели №3 | C1: Ссылки на папки
A2: 1 | B2: Открываем рабочую область модели №3 | C2: W:\ЦГКО\Отдел массовой оценки\19. 16 Статья\8. Земельные участки
A3: 2 | B3: В рабочей области стоят фильтры - новая модель 8003, статус расчета - не готов. Фильтры не трогаем
A4: 3 | B4: Выгружаем рабочую область через "Экспорт…", английские заголовки не нужны
A5: 4 | B5: Копируем объекты построчно без шапки, вставляем в данный файл на лист "объекты оценки". Должны быть заполнены ячейки от A3 до BM3 и ниже
A6: 5 | B6: Меняем формат вставленных данных в стилях ячеек на обычный
A7: 6 | B7: Все расчетные формулы работают автоматически, ячейки защищены и не редактируются (колонки BN - CW)
A8: 7 | B8: Анализируем колонки CХ- DM, в случае, если значение не изменилось ячейка останется не закрашеной. Изменений в рамках расчета по 16 статье у объектов без графики быть не должно, за исключением смены модели, кода ВРИ, значения площади
A9: 8 | B9: Проверяем колонку "ОБЯЗАТЕЛЬНАЯ ПРОВЕРКА" и "ОСОБЫЙ КОНТРОЛЬ" (AU), в ней отражены наличия замечаний по объекту, обращений по статье 21, оспаривание
A10: 9 | B10: В случае наличия обращений по статье 21 или оспаривания ЗУ автоматически ставится в СТОПЛИСТ (статус расчета)
A11: 10 | B11: В случае наличия замечаний по объекту заходим в папку замечаний и проверяем корректно ли учтены данные при расчете по статье 16 | C11: W:\ЦГКО\Отдел по работе с обращениями\Замечания к ПОД-2020\ЗАМЕЧАНИЯ
A12: 11 | B12: Заполняем ячейки DN - DR ТОЛЬКО В ПЕРВОЙ СТРОКЕ. Пишем номер файла который указан в названии файла, номер модели - М3, дата - без точек, например 22012021 (формат ячейки с точками некорректно сцепляется), фамилия исполнителя, наличие графики заполняется автоматически
A13: 12 | B13: Проверяем колонку "Статус расчета" и изменение КС. Если в колонке "Изменение, руб." значение меньше 1 руб. необходимо проверить расчеты
A14: 13 | B14: По колонке "статус расчета" EO разносим файлы по листам. Если "пересчет не требуется" то - кадастровый номер, ври, сегмент, статус расчета, если "стоплист" то только кадастровый номер и статус расчета, если "готов" то все данные на загрузку в базу. В шапке только английские заголовки!
A15: 14 | B15: ГОТОВО, проверяем колонку "контрольная проверка" (FA) отправляем на загрузку в базу если все значения ИСТИНА
A16: 15 | B16: Важно: формулы растянуты на 10000 строк, если объектов оценки больше необходимо рассчитать их двумя файлами или растянуть ячейки
B18: Ячейки в строках 1-3 выделены цветом для удобства:
B19: Ячейки для заполнения
B20: Ячейки для анализа
B21: Ячейки не требующие редактирования

Sheet Поправки
B1: Таблица №12 | E1: площадь | F1: Степеннаяln = 11,27070473*#Перем_14^-0,08418488 | G1: 0.68773776 | I1: Площадь | N1: Расстояние до метро | S1: Расстояние до остановок | X1: Расстояние до дорог | AC1: Расстояние до центра | AJ1: Названия строк | AK1: Среднее по полю Расстояние до метро | AL1: Среднее по полю Расстояние до центра МО | AO1: Среднее по полю Расстояние до остановки общественного транспорта | AP1: Среднее по полю Расстояние до дороги
B2: Линейная регрессия | E2: метро | F2: Компаундln_ = 9,57779229*0,98667563^#Перем_16 | G2: 0.046467473 | I2: 11703 | J2: =11.27070473*LN(I2)^-0.08418488 -> 9.335867 | K2: =EXP(J2)^$G$1 -> 614.38896 | L2: =ROUND(K2/$K$10,4) -> 0.9909 | N2: 0.068 | O2: =9.57779229*0.98667563^LN(N2) -> 9.9294699 | P2: =EXP(O2)^$G$2 -> 1.5862891 | Q2: =ROUND(P2/$P$10,4) -> 1.0165 | S2: 0.011 | T2: =9.3057995*0.99085691^LN(S2) -> 9.6993757 | U2: =EXP(T2)^$G$3 -> 1.5931978 | V2: =ROUND(U2/$U$10,4) -> 1.0162 | X2: 0.0001 | Y2: =9.23088404*0.99320482^LN(X2) -> 9.8291686 | Z2: =EXP(Y2)^$G$4 -> 5.3394319 | AA2: =ROUND(Z2/$Z$10,4) -> 1.0965 | AC2: 4.3 | AD2: =9.93943263-0.30296633*LN(AC2) -> 9.4975214 | AE2: =EXP(AD2)^$G$5 -> 20.539145 | AF2: =ROUND(AE2/$AE$10,4) -> 0.8688 | AJ2: Пояс 1 | AK2: =ROUND(AM2,2) -> 3.3 | AL2: =ROUND(AN2,2) -> 4.34 | AM2: 3.3046425 | AN2: 4.3361089 | AO2: =ROUND(0.27771881219732,2) -> 0.28 | AP2: =ROUND(0.0488190916089297,2) -> 0.05
B3: Параметры модели: | E3: остановки | F3: Перем_27 = 9,30579950*0,99085691^#Перем_17 | G3: 0.048017851 | I3: 25000 | J3: =11.27070473*LN(I3)^-0.08418488 -> 9.2748335 | K3: =EXP(J3)^$G$1 -> 589.13372 | L3: =ROUND(K3/$K$10,4) -> 0.9502 | N3: 3 | O3: =9.57779229*0.98667563^LN(N3) -> 9.437682 | P3: =EXP(O3)^$G$2 -> 1.55045 | Q3: =ROUND(P3/$P$10,4) -> 0.9935 | S3: 1.5 | T3: =9.3057995*0.99085691^LN(S3) -> 9.2712068 | U3: =EXP(T3)^$G$3 -> 1.5607765 | V3: =ROUND(U3/$U$10,4) -> 0.9955 | X3: 0.07 | Y3: =9.23088404*0.99320482^LN(X3) -> 9.3997834 | Z3: =EXP(Y3)^$G$4 -> 4.9626607 | AA3: =ROUND(Z3/$Z$10,4) -> 1.0191 | AC3: 3 | AD3: =9.93943263-0.30296633*LN(AC3) -> 9.6065901 | AE3: =EXP(AD3)^$G$5 -> 21.264537 | AF3: =ROUND(AE3/$AE$10,4) -> 0.8995 | AJ3: Пояс 2 | AK3: =ROUND(AM3,2) -> 4.37 | AL3: =ROUND(AN3,2) -> 8.63 | AM3: 4.3736851 | AN3: 8.634813
B4: -2,6768265015+0,6877377564*#Степеннаяln+0,0464674726*#Компаундln_+0,0480178513*#Перем_27+0,1704232904*#Перем_28+0,3182232965*#Прямая_линия+1,0000000000*#Перем_35+1,0000000000*#Перем_36+1,0000000000*#Перем_37+1,0000000000*#Перем_38+1,0000000000*#Перем_39 | E4: дороги | F4: Перем_28 = 9,23088404*0,99320482^#Перем_18 | G4: 0.17042329 | I4: 49700 | J4: =11.27070473*LN(I4)^-0.08418488 -> 9.2237148 | K4: =EXP(J4)^$G$1 -> 568.78181 | L4: =ROUND(K4/$K$10,4) -> 0.9173 | N4: 5.932 | O4: =9.57779229*0.98667563^LN(N4) -> 9.3517684 | P4: =EXP(O4)^$G$2 -> 1.5442727 | Q4: =ROUND(P4/$P$10,4) -> 0.9896 | S4: 2.989 | T4: =9.3057995*0.99085691^LN(S4) -> 9.2126785 | U4: =EXP(T4)^$G$3 -> 1.5563962 | V4: =ROUND(U4/$U$10,4) -> 0.9927 | X4: 0.1399 | Y4: =9.23088404*0.99320482^LN(X4) -> 9.3555092 | Z4: =EXP(Y4)^$G$4 -> 4.9253565 | AA4: =ROUND(Z4/$Z$10,4) -> 1.0114 | AC4: 5.71 | AD4: =9.93943263-0.30296633*LN(AC4) -> 9.4115989 | AE4: =EXP(AD4)^$G$5 -> 19.985161 | AF4: =ROUND(AE4/$AE$10,4) -> 0.8454 | AJ4: Пояс 3 | AK4: =ROUND(AM4,2) -> 6.7 | AL4: =ROUND(AN4,2) -> 10.3 | AM4: 6.7007978 | AN4: 10.298813
B5: Параметр: | C5: Значение: | E5: центр екб | F5: Прямая_линия = 9,93943263-0,30296633*#Перем_19 | G5: 0.3182233 | I5: 74400 | J5: =11.27070473*LN(I5)^-0.08418488 -> 9.1953156 | K5: =EXP(J5)^$G$1 -> 557.7806 | L5: =ROUND(K5/$K$10,4) -> 0.8996 | N5: 8.864 | O5: =9.57779229*0.98667563^LN(N5) -> 9.301521 | P5: =EXP(O5)^$G$2 -> 1.5406712 | Q5: =ROUND(P5/$P$10,4) -> 0.9872 | S5: 4.478 | T5: =9.3057995*0.99085691^LN(S5) -> 9.1785355 | U5: =EXP(T5)^$G$3 -> 1.5538466 | V5: =ROUND(U5/$U$10,4) -> 0.9911 | X5: 0.2098 | Y5: =9.23088404*0.99320482^LN(X5) -> 9.3296957 | Z5: =EXP(Y5)^$G$4 -> 4.9037364 | AA5: =ROUND(Z5/$Z$10,4) -> 1.007 | AC5: 8.42 | AD5: =9.93943263-0.30296633*LN(AC5) -> 9.2939296 | AE5: =EXP(AD5)^$G$5 -> 19.250652 | AF5: =ROUND(AE5/$AE$10,4) -> 0.8143 | AJ5: Пояс 4 | AK5: =ROUND(AM5,2) -> 15.12 | AL5: =ROUND(AN5,2) -> 16.62 | AM5: 15.121397 | AN5: 16.622086
B6: Кол-во случаев: | C6: 498 | I6: 99100 | J6: =11.27070473*LN(I6)^-0.08418488 -> 9.1758014 | K6: =EXP(J6)^$G$1 -> 550.34483 | L6: =ROUND(K6/$K$10,4) -> 0.8876 | N6: 11.796 | O6: =9.57779229*0.98667563^LN(N6) -> 9.2659347 | P6: =EXP(O6)^$G$2 -> 1.5381256 | Q6: =ROUND(P6/$P$10,4) -> 0.9856 | S6: 5.967 | T6: =9.3057995*0.99085691^LN(S6) -> 9.1543657 | U6: =EXP(T6)^$G$3 -> 1.5520443 | V6: =ROUND(U6/$U$10,4) -> 0.9899 | X6: 0.2797 | Y6: =9.23088404*0.99320482^LN(X6) -> 9.3114208 | Z6: =EXP(Y6)^$G$4 -> 4.8884876 | AA6: =ROUND(Z6/$Z$10,4) -> 1.0039 | AC6: 11.13 | AD6: =9.93943263-0.30296633*LN(AC6) -> 9.2093916 | AE6: =EXP(AD6)^$G$5 -> 18.739675 | AF6: =ROUND(AE6/$AE$10,4) -> 0.7927 | AJ6: Центр | AK6: =ROUND(AM6,2) -> 1.06 | AL6: =ROUND(AN6,2) -> 1.7 | AM6: 1.0611547 | AN6: 1.701183
B7: Коэффициент множественной корреляции R: | C7: 0.795 | I7: 123800 | J7: =11.27070473*LN(I7)^-0.08418488 -> 9.161013 | K7: =EXP(J7)^$G$1 -> 544.7759 | L7: =ROUND(K7/$K$10,4) -> 0.8786 | N7: 14.728 | O7: =9.57779229*0.98667563^LN(N7) -> 9.238384 | P7: =EXP(O7)^$G$2 -> 1.5361578 | Q7: =ROUND(P7/$P$10,4) -> 0.9844 | S7: 7.456 | T7: =9.3057995*0.99085691^LN(S7) -> 9.1356531 | U7: =EXP(T7)^$G$3 -> 1.5506504 | V7: =ROUND(U7/$U$10,4) -> 0.989 | X7: 0.3496 | Y7: =9.23088404*0.99320482^LN(X7) -> 9.297269 | Z7: =EXP(Y7)^$G$4 -> 4.8767117 | AA7: =ROUND(Z7/$Z$10,4) -> 1.0015 | AC7: 13.84 | AD7: =9.93943263-0.30296633*LN(AC7) -> 9.1433695 | AE7: =EXP(AD7)^$G$5 -> 18.350066 | AF7: =ROUND(AE7/$AE$10,4) -> 0.7762
B8: Коэффициент детерминации R-квадрат: | C8: 0.632 | I8: 148500 | J8: =11.27070473*LN(I8)^-0.08418488 -> 9.1491483 | K8: =EXP(J8)^$G$1 -> 540.34871 | L8: =ROUND(K8/$K$10,4) -> 0.8715 | N8: 17.66 | O8: =9.57779229*0.98667563^LN(N8) -> 9.2159129 | P8: =EXP(O8)^$G$2 -> 1.5345546 | Q8: =ROUND(P8/$P$10,4) -> 0.9833 | S8: 8.945 | T8: =9.3057995*0.99085691^LN(S8) -> 9.1203874 | U8: =EXP(T8)^$G$3 -> 1.5495141 | V8: =ROUND(U8/$U$10,4) -> 0.9883 | X8: 0.4195 | Y8: =9.23088404*0.99320482^LN(X8) -> 9.2857214 | Z8: =EXP(Y8)^$G$4 -> 4.8671239 | AA8: =ROUND(Z8/$Z$10,4) -> 0.9995 | AC8: 16.55 | AD8: =9.93943263-0.30296633*LN(AC8) -> 9.0891921 | AE8: =EXP(AD8)^$G$5 -> 18.036413 | AF8: =ROUND(AE8/$AE$10,4) -> 0.7629
B9: Уточненный R-квадрат: | C9: 0.625 | I9: 173200 | J9: =11.27070473*LN(I9)^-0.08418488 -> 9.1392657 | K9: =EXP(J9)^$G$1 -> 536.68862 | L9: =ROUND(K9/$K$10,4) -> 0.8656 | N9: 20.592 | O9: =9.57779229*0.98667563^LN(N9) -> 9.1969441 | P9: =EXP(O9)^$G$2 -> 1.5332026 | Q9: =ROUND(P9/$P$10,4) -> 0.9825 | S9: 10.434 | T9: =9.3057995*0.99085691^LN(S9) -> 9.1074978 | U9: =EXP(T9)^$G$3 -> 1.5485554 | V9: =ROUND(U9/$U$10,4) -> 0.9877 | X9: 0.4894 | Y9: =9.23088404*0.99320482^LN(X9) -> 9.2759689 | Z9: =EXP(Y9)^$G$4 -> 4.8590412 | AA9: =ROUND(Z9/$Z$10,4) -> 0.9978 | AC9: 19.26 | AD9: =9.93943263-0.30296633*LN(AC9) -> 9.043249 | AE9: =EXP(AD9)^$G$5 -> 17.774636 | AF9: =ROUND(AE9/$AE$10,4) -> 0.7519
B10: СреднееY(ln оспорен уд.показ.): | C10: 9.4779835 | H10: базовое значение | I10: 10000 | J10: =11.27070473*LN(I10)^-0.08418488 -> 9.3491826 | K10: =EXP(J10)^$G$1 -> 620.04114 | L10: =ROUND(K10/$K$10,4) -> 1 | M10: базовое значение | N10: 1 | O10: =9.57779229*0.98667563^LN(N10) -> 9.5777923 | P10: =EXP(O10)^$G$2 -> 1.5605773 | Q10: =ROUND(P10/$P$10,4) -> 1 | R10: базовое значение | S10: 0.5 | T10: =9.3057995*0.99085691^LN(S10) -> 9.3652353 | U10: =EXP(T10)^$G$3 -> 1.5678394 | V10: =ROUND(U10/$U$10,4) -> 1 | W10: базовое значение | X10: 0.4 | Y10: =9.23088404*0.99320482^LN(X10) -> 9.2887355 | Z10: =EXP(Y10)^$G$4 -> 4.8696247 | AA10: =ROUND(Z10/$Z$10,4) -> 1 | AB10: базовое значение | AC10: 1 | AD10: =9.93943263-0.30296633*LN(AC10) -> 9.9394326 | AE10: =EXP(AD10)^$G$5 -> 23.640445 | AF10: =ROUND(AE10/$AE$10,4) -> 1
B11: Стандартная ошибка: | C11: 0.19512048 | H11: минимум | I11: 300 | J11: =11.27070473*LN(I11)^-0.08418488 -> 9.7340503 | K11: =EXP(J11)^$G$1 -> 807.92877 | L11: =ROUND(K11/$K$10,4) -> 1.303 | M11: минимум | N11: 0.068 | O11: =9.57779229*0.98667563^LN(N11) -> 9.9294699 | P11: =EXP(O11)^$G$2 -> 1.5862891 | Q11: =ROUND(P11/$P$10,4) -> 1.0165 | R11: минимум | S11: 0.011 | T11: =9.3057995*0.99085691^LN(S11) -> 9.6993757 | U11: =EXP(T11)^$G$3 -> 1.5931978 | V11: =ROUND(U11/$U$10,4) -> 1.0162 | W11: минимум | X11: 0.0001 | Y11: =9.23088404*0.99320482^LN(X11) -> 9.8291686 | Z11: =EXP(Y11)^$G$4 -> 5.3394319 | AA11: =ROUND(Z11/$Z$10,4) -> 1.0965 | AB11: минимум | AC11: 0.29 | AD11: =9.93943263-0.30296633*LN(AC11) -> 10.314467 | AE11: =EXP(AD11)^$G$5 -> 26.637065 | AF11: =ROUND(AE11/$AE$10,4) -> 1.1268
B12: Средняя ошибка аппроксимации(%): | C12: 1.671 | H12: максимум | I12: 170591 | J12: =11.27070473*LN(I12)^-0.08418488 -> 9.1402345 | K12: =EXP(J12)^$G$1 -> 537.04633 | L12: =ROUND(K12/$K$10,4) -> 0.8661 | M12: максимум | N12: 20.844 | O12: =9.57779229*0.98667563^LN(N12) -> 9.1954436 | P12: =EXP(O12)^$G$2 -> 1.5330957 | Q12: =ROUND(P12/$P$10,4) -> 0.9824 | R12: максимум | S12: 0.984 | T12: =9.3057995*0.99085691^LN(S12) -> 9.3071783 | U12: =EXP(T12)^$G$3 -> 1.5634747 | V12: =ROUND(U12/$U$10,4) -> 0.9972 | W12: максимум | X12: 0.497 | Y12: =9.23088404*0.99320482^LN(X12) -> 9.2749943 | Z12: =EXP(Y12)^$G$4 -> 4.8582342 | AA12: =ROUND(Z12/$Z$10,4) -> 0.9977 | AB12: максимум | AC12: 18.93 | AD12: =9.93943263-0.30296633*LN(AC12) -> 9.048485 | AE12: =EXP(AD12)^$G$5 -> 17.804277 | AF12: =ROUND(AE12/$AE$10,4) -> 0.7531
B13: Средняя ошибка аппроксимации (ln)(%): | C13: 16.065 | H13: расчетное значение | I13: =Q18 -> 10000 | J13: =11.27070473*LN(I13)^-0.08418488 -> 9.3491826 | K13: =EXP(J13)^$G$1 -> 620.04114 | L13: =ROUND(K13/$K$10,4) -> 1 | M13: расчетное значение | N13: =R18 -> 0.5 | O13: =9.57779229*0.98667563^LN(N13) -> 9.6672603 | P13: =EXP(O13)^$G$2 -> 1.5670786 | Q13: =ROUND(P13/$P$10,4) -> 1.0042 | R13: расчетное значение | S13: =S18 -> 0.5 | T13: =9.3057995*0.99085691^LN(S13) -> 9.3652353 | U13: =EXP(T13)^$G$3 -> 1.5678394 | V13: =ROUND(U13/$U$10,4) -> 1 | W13: расчетное значение | X13: =T18 -> 0.2 | Y13: =9.23088404*0.99320482^LN(X13) -> 9.3327393 | Z13: =EXP(Y13)^$G$4 -> 4.9062806 | AA13: =ROUND(Z13/$Z$10,4) -> 1.0075 | AB13: расчетное значение | AC13: =U18 -> 0.2 | AD13: =9.93943263-0.30296633*LN(AC13) -> 10.427038 | AE13: =EXP(AD13)^$G$5 -> 27.608576 | AF13: =ROUND(AE13/$AE$10,4) -> 1.1679
B14: Дисперсионный анализ:
B15: Параметр: | C15: Регрессия: | D15: Остаток: | E15: Общая:
B16: Сумма квадратов: | C16: 31.9 | D16: 18.541 | E16: 50.441
B17: Число степеней свободы: | C17: 10 | D17: 487 | E17: 497 | L17: х1 | M17: х2 | N17: х3 | O17: х4 | P17: х5 | Q17: х6 | R17: х7 | S17: х8 | T17: х9 | U17: х10 | W17: x11
B18: на 1 степень: | C18: 3.19 | D18: 0.038 | L18: Центр | M18: Отсутствие электроснабжения | N18: Отсутствие теплоснабжения | O18: Отсутствие водоотведения | P18: 4. СЕГМЕНТ "Предпринимательство" | Q18: 10000 | R18: 0.5 | S18: 0.5 | T18: 0.2 | U18: 0.2
B19: F критерий Фишера: | C19: 83.789 | K19: Константа | L19: Ценовой пояс | M19: Электричество | N19: Теплоснабжение | O19: Канализация | P19: Сегмент | Q19: Площадь | R19: Расстояние до метро | S19: Расстояние до остановок | T19: Расстояние до дорог | U19: Расстояние до центра | V19: УПКС, руб/м2 | W19: Уторгование | X19: УПКС с учетом уторгования, руб/м2 | Y19: КС, руб.
B20: Вероятность ошибки (значимость): | C20: 0 | K20: =EXP(C23) -> 0.068781085 | L20: =VLOOKUP(L18,$B:$D,3,FALSE) -> 1 | M20: =VLOOKUP(M18,$B:$D,3,FALSE) -> 1 | N20: =VLOOKUP(N18,$B:$D,3,FALSE) -> 1 | O20: =VLOOKUP(O18,$B:$D,3,FALSE) -> 1 | P20: =VLOOKUP(P18,$B:$D,3,FALSE) -> 1.0955 | Q20: =K13 -> 620.04114 | R20: =P13 -> 1.5670786 | S20: =U13 -> 1.5678394 | T20: =Z13 -> 4.9062806 | U20: =AE13 -> 27.608576 | V20: =PRODUCT(K20:U20) -> 15548.577 | W20: 0.75 | X20: =V20*W20 -> 11661.433 | Y20: =ROUND(V20*$Q$18,2) -> 1.5548577e+08
B21: Таблица коэффициентов: | K21: =ROUND(K20*K10*P10*U10*Z10*AE10,4) -> 12012.337 | L21: =VLOOKUP(L18,$B:$D,3,FALSE) -> 1 | M21: =VLOOKUP(M18,$B:$D,3,FALSE) -> 1 | N21: =VLOOKUP(N18,$B:$D,3,FALSE) -> 1 | O21: =VLOOKUP(O18,$B:$D,3,FALSE) -> 1 | P21: =VLOOKUP(P18,$B:$D,3,FALSE) -> 1.0955 | Q21: =K13/K10 -> 1 | R21: =P13/P10 -> 1.004166 | S21: =U13/U10 -> 1 | T21: =Z13/Z10 -> 1.0075274 | U21: =AE13/AE10 -> 1.1678535 | V21: =PRODUCT(K21:U21) -> 15548.577 | Y21: =ROUND(V21*$Q$18,2) -> 1.5548577e+08
B22: Переменная: | C22: Коэффициент b: | D22: Ошибка b: | E22: Beta: | F22: t-Стьюдента: | G22: Значимость: | K22: =C23 -> -2.6768265 | L22: =VLOOKUP(L18,$B:$C,2,FALSE) -> 0 | M22: =VLOOKUP(M18,$B:$C,2,FALSE) -> 0 | N22: =VLOOKUP(N18,$B:$C,2,FALSE) -> 0 | O22: =VLOOKUP(O18,$B:$C,2,FALSE) -> 0 | P22: =VLOOKUP(P18,$B:$C,2,FALSE) -> 0.091217 | Q22: =J13*G1 -> 6.4297858 | R22: =O13*G2 -> 0.44921315 | S22: =T13*G3 -> 0.44969848 | T22: =Y13*G4 -> 1.5905161 | U22: =AD13*G5 -> 3.3181264 | V22: =EXP(SUM(K22:U22)) -> 15548.672 | Y22: =ROUND(V22*$Q$18,2) -> 1.5548672e+08
B23: Константа | C23: -2.6768265 | D23: 1.911944 | F23: -1.4 | G23: 0.162
B24: Степенная(ln_площадь) | C24: 0.68773776 | D24: 0.073914075 | E24: 0.271 | F24: 9.305 | G24: 0
B25: Компаунд(ln_метро) | C25: 0.046467473 | D25: 0.082821137 | E25: 0.019 | F25: 0.561 | G25: 0.575
B26: Компаунд(ln_до остановок) | C26: 0.048017851 | D26: 0.14329813 | E26: 0.01 | F26: 0.335 | G26: 0.738
B27: Компаунд(ln_до дорог) | C27: 0.17042329 | D27: 0.123468 | E27: 0.04 | F27: 1.38 | G27: 0.168
B28: Прямая линия(ln_до центра) | C28: 0.3182233 | D28: 0.086674993 | E28: 0.214 | F28: 3.671 | G28: 0
B29: Сегмент(Альтернативная) | C29: 1 | D29: 0.20082102 | E29: 0.143 | F29: 4.98 | G29: 0
B30: Электроснабжение(Альтернативная) | C30: 1 | D30: 0.24771891 | E30: 0.115 | F30: 4.037 | G30: 0
B31: Водоотведение(Альтернативная) | C31: 1 | D31: 1.2814391 | E31: 0.027 | F31: 0.78 | G31: 0.436
B32: Теплоснабжение(Альтернативная) | C32: 1 | D32: 0.59328219 | E32: 0.06 | F32: 1.686 | G32: 0.093
B33: Ценовой пояс(Альтернативная) | C33: 1 | D33: 0.12011575 | E33: 0.461 | F33: 8.325 | G33: 0
B34: Исходные переменные
A35: площадь | B35: Степеннаяln = 11,27070473*#Перем_14^-0,08418488 | C35: 0.68773776
A36: метро | B36: Компаундln_ = 9,57779229*0,98667563^#Перем_16 | C36: 0.046467473
A37: остановки | B37: Перем_27 = 9,30579950*0,99085691^#Перем_17 | C37: 0.048017851
A38: дороги | B38: Перем_28 = 9,23088404*0,99320482^#Перем_18 | C38: 0.17042329
A39: центр екб | B39: Прямая_линия = 9,93943263-0,30296633*#Перем_19 | C39: 0.3182233
B40: 3. СЕГМЕНТ "Общественное использование" | C40: 0 | D40: =ROUND(EXP(C40)^1,4) -> 1
...

Sheet Коды без коммуникаций
A1: Наименование вида использования | B1: Код вида разрешенного использования (в соответствии с классификатором видов разрешенного использования земельных участков) | C1: Код расчета вида использования | D1: Код сегмента | E1: Сегмент
A2: Спорт. Устройство площадок для занятия спортом и физкультурой (беговые дорожки, спортивные сооружения, теннисные корты, поля для спортивной игры, автодромы, мотодромы, трамплины, трассы и спортивные стрельбища), сооружения для хранения соответствующего инвентаря | B2: 5.1 | C2: 05:012 | D2: 3 | E2: 3. СЕГМЕНТ "Общественное использование"
A3: Природно-познавательный туризм. Размещение баз и палаточных лагерей для проведения походов и экскурсий по ознакомлению с природой, пеших и конных прогулок | B3: 5.2 | C3: 05:020 | D3: 3 | E3: 3. СЕГМЕНТ "Общественное использование"
A4: Природно-познавательный туризм. Устройство троп и дорожек, размещение щитов с познавательными сведениями об окружающей природной среде, осуществление необходимых природоохранных и природовосстановительных мероприятий | B4: 5.2 | C4: 05:021 | D4: 3 | E4: 3. СЕГМЕНТ "Общественное использование"
A5: Поля для гольфа или конных прогулок. Размещение конноспортивных манежей, не предусматривающих устройство трибун | B5: 5.5 | C5: 05:051 | D5: 3 | E5: 3. СЕГМЕНТ "Общественное использование"
A6: Развлечения. Размещение ОКС, предназначенных для размещения ипподромов | B6: 4.8 | C6: 04:083 | D6: 4 | E6: 4. СЕГМЕНТ "Предпринимательство"
A7: Ярмарки, торговые выставки на открытых площадках | B7: 4.96 | C7: 04:996 | D7: 4 | E7: 4. СЕГМЕНТ "Предпринимательство"
A8: Рекламные щиты/рекламные растяжки/рекламные конструкции | B8: 4.97 | C8: 04:997 | D8: 4 | E8: 4. СЕГМЕНТ "Предпринимательство"
A9: Киоски/Ларьки/Торговые павильоны/Прицепы и Трейлеры торговые/торгово-остановочные комплексы | B9: 4.98 | C9: 04:998 | D9: 4 | E9: 4. СЕГМЕНТ "Предпринимательство"
A10: Причалы для маломерных судов. Размещение сооружений, предназначенных для причаливания, хранения и обслуживания яхт, катеров, лодок и других маломерных судов | B10: 5.4 | C10: 05:040 | D10: 6 | E10: 6. СЕГМЕНТ "Производственная деятельность"
A11: Недропользование. Осуществление геологических изысканий, добыча недр открытым (карьеры, отвалы) способом | B11: 6.1 | C11: 06:010 | D11: 6 | E11: 6. СЕГМЕНТ "Производственная деятельность"
A12: Недропользование. Осуществление геологических изысканий, добыча недр закрытым (шахты, скважины) способом | B12: 6.1 | C12: 06:011 | D12: 6 | E12: 6. СЕГМЕНТ "Производственная деятельность"
A13: Связь. Размещение объектов связи, радиовещания, телевидения, включая воздушные радиорелейные, надземные и подземные кабельные линии связи, линии радиофикации, антенные поля, усилительные пункты на кабельных линиях связи, инфраструктуры спутниковой связи и телерадиовещания, за исключением объектов связи, размещение которых предусмотрено кодом расчета вида использования 03:011, диспетчерские | B13: 6.8 | C13: 06:080 | D13: 6 | E13: 6. СЕГМЕНТ "Производственная деятельность"
... A20: Коммунальное обслуживание. Размещение ОКС в целях обеспечения физических и юридических лиц коммунальными услугами, в частности: поставка воды, тепла, электричества, газа, предоставление услуг связи (отвод канализационных стоков, водопроводы, линии электропередач, газопроводы, линии связи и прочие линейные объекты) | B20: 3.1 | C20: 03:011 | D20: 6 | E20: 6. СЕГМЕНТ "Производственная деятельность"

Sheet Объекты МУГИСО
A1: 66:41:0000000:316 | B1: 1
A2: 66:41:0301001:14 | B2: 1
A3: 66:41:0704045:17 | B3: 1
A4: 66:41:0206018:7 | B4: 1
A5: 66:41:0106155:3 | B5: 1
A6: 66:41:0503014:73 | B6: 1
A7: 66:41:0000000:347 | B7: 1
A8: 66:41:0603016:9 | B8: 1
A9: 66:41:0109051:5 | B9: 1
A10: 66:41:0504096:20 | B10: 1
A11: 66:41:0000000:662 | B11: 1
A12: 66:41:0301016:4 | B12: 1
... A262: 66:41:0403901:52 | B262: 1

Sheet Сегмент ВРИ
A1: loc_VICode | B1: Segment | C1: loc_SgCode | D1: loc_GroupName
A2: Код расчета вида использования | B2: Сегмент | C2: Код сегмента | D2: Наименование вида использования
A3: 01:010 | B3: 1. СЕГМЕНТ "Сельскохозяйственное использование" | C3: 1.1 | D3: Растениеводство в целом. Включает коды расчета вида использования 01.020-01.060
A4: 01:020 | B4: 1. СЕГМЕНТ "Сельскохозяйственное использование" | C4: 1.1 | D4: Выращивание зерновых, бобовых, кормовых, технических, масличных, эфиромасличных и иных сельскохозяйственных культур
A5: 01:030 | B5: 1. СЕГМЕНТ "Сельскохозяйственное использование" | C5: 1.1 | D5: Овощеводство в целом, связанное с производством картофеля, листовых, плодовых, луковичных и бахчевых сельскохозяйственных культур, в том числе с использованием теплиц
A6: 01:031 | B6: 1. СЕГМЕНТ "Сельскохозяйственное использование" | C6: 1.1 | D6: Овощеводство в открытом грунте
A7: 01:032 | B7: 1. СЕГМЕНТ "Сельскохозяйственное использование" | C7: 1.1 | D7: Овощеводство тепличное
A8: 01:040 | B8: 1. СЕГМЕНТ "Сельскохозяйственное использование" | C8: 1.2 | D8: Выращивание тонизирующих, лекарственных, цветочных культур в целом
A9: 01:041 | B9: 1. СЕГМЕНТ "Сельскохозяйственное использование" | C9: 1.2 | D9: Выращивание тонизирующих, лекарственных, цветочных культур. Травы
A10: 01:042 | B10: 1. СЕГМЕНТ "Сельскохозяйственное использование" | C10: 1.2 | D10: Выращивание тонизирующих, лекарственных, цветочных культур. Кустарники
A11: 01:050 | B11: 1. СЕГМЕНТ "Сельскохозяйственное использование" | C11: 1.1 | D11: Садоводство в целом - выращивание многолетних плодовых и ягодных культур, винограда и иных многолетних культур
A12: 01:051 | B12: 1. СЕГМЕНТ "Сельскохозяйственное использование" | C12: 1.1 | D12: Садоводство плодовое
... A43: 01:999 | B43: 1. СЕГМЕНТ "Сельскохозяйственное использование" | C43: 1.1 | D43: Иной вид использования в сегменте "Сельскохозяйственное использование"
A44: 02:000 | B44: 2. СЕГМЕНТ "Жилая застройка (среднеэтажная и многоэтажная)" | C44: 2 | D44: Жилая застройка (среднеэтажная и многоэтажная без уточнения этажности)
A45: 02:050 | B45: 2. СЕГМЕНТ "Жилая застройка (среднеэтажная и многоэтажная)" | C45: 2 | D45: Среднеэтажная жилая застройка в целом
A46: 02:051 | B46: 2. СЕГМЕНТ "Жилая застройка (среднеэтажная и многоэтажная)" | C46: 2 | D46: Среднеэтажная жилая застройка. Размещение жилых домов, предназначенных для разделения на квартиры, каждая из которых пригодна для постоянного проживания (жилые дома высотой не выше восьми надземных этажей, разделенных на две и более квартиры), размещение встроенных в жилой дом подземных гаражей и автостоянок
A47: 02:060 | B47: 2. СЕГМЕНТ "Жилая застройка (среднеэтажная и многоэтажная)" | C47: 2 | D47: Многоэтажная жилая застройка (высотная застройка) в целом
A48: 02:061 | B48: 2. СЕГМЕНТ "Жилая застройка (среднеэтажная и многоэтажная)" | C48: 2 | D48: Многоэтажная жилая застройка. Размещение жилых домов, предназначенных для разделения на квартиры, каждая из которых пригодна для постоянного проживания (жилые дома высотой не выше восьми надземных этажей, разделенных на две и более квартиры), размещение встроенных в жилой дом подземных гаражей и автостоянок
A49: 02:999 | B49: 2. СЕГМЕНТ "Жилая застройка (среднеэтажная и многоэтажная)" | C49: 2 | D49: Иной вид использования в сегменте "Жилая застройка (среднеэтажная и многоэтажная)"
A50: 01:143 | B50: 3. СЕГМЕНТ "Общественное использование" | C50: 3 | D50: Научное обеспечение сельского хозяйства. Размещение зданий, сооружений, оборудования, необходимых для осуществления научного обеспечения сельского хозяйства, включая размещение коллекций генетических ресурсов растений
A51: 03:010 | B51: 3. СЕГМЕНТ "Общественное использование" | C51: 3 | D51: Коммунальное обслуживание в целом
A52: 03:013 | B52: 3. СЕГМЕНТ "Общественное использование" | C52: 3 | D52: Коммунальное обслуживание. Размещение ОКС в целях обеспечения физических и юридических лиц коммунальными услугами, в частности: зданий или помещений, предназначенных для приема физических и юридических лиц в связи с предоставлением им коммунальных услуг
A53: 03:020 | B53: 3. СЕГМЕНТ "Общественное использование" | C53: 3 | D53: Социальное обслуживание в целом
A54: 03:021 | B54: 3. СЕГМЕНТ "Общественное использование" | C54: 3 | D54: Социальное обслуживание. Размещение ОКС, предназначенных для оказания гражданам социальной помощи (службы занятости населения, дома престарелых, дома ребенка, детские дома, пункты питания малоимущих граждан, пункты ночлега для бездомных граждан, службы психологической и бесплатной юридической помощи, социальные, пенсионные и иные службы, в которых осуществляется прием граждан по вопросам оказания социальной помощи и назначения социальных или пенсионных выплат)
A55: 03:022 | B55: 3. СЕГМЕНТ "Общественное использование" | C55: 3 | D55: Социальное обслуживание. Размещение ОКС для размещения отделений почты и телеграфа
... A271: 14:000 | B271: 14. СЕГМЕНТ "Иное использование" | C271: 14 | D271: Иное использование
