Workbook

Sheet Объекты
A1: &T18c5c787c48 | AW1: * | BL1: &T0
A2: &H1 | B2: cadastralNumber | C2: assignationBuilding | D2: elementsConstruct | E2: name | F2: locations | G2: areaObject | H2: exploitationChar | I2: exploitationChar | J2: exploitationChar | K2: exploitationChar | L2: floors | M2: floors | N2: floors | O2: floors | P2: mrktGroup | Q2: mrktGroup | R2: actualCost | S2: actualCost | T2: actualCost | U2: additional_55198 | V2: additional_51421 | W2: additional_55197 | X2: additional_100 | Y2: parkingSpacesCadastralNumbers | Z2: parentCadastralNumbers | AA2: flatsCadastralNumbers | AB2: dateCreated | AC2: additional_61968 | AD2: additional_57378 | AE2: additional_57960 | AF2: additional_57900 | AG2: additional_62691 | BL2: &H1 | BM2: cadastralNumber | BN2: additional_51421 | BO2: additional_55198 | BP2: additional_55197 | BQ2: additional_100 | BR2: additional_61964 | BS2: additional_57900 | BT2: mrktGroup
A3: &H1 | D3: wallMaterial | F3: note | G3: areaValue | H3: yearused | I3: yearusedText | J3: yearbuilt | K3: yearbuiltText | L3: undergroundfloors | M3: undergroundfloorsInXml | N3: floorscount | O3: floorscountInXml | P3: group | Q3: groupOfUsage | R3: fullCost | S3: costValue | T3: relevanceDate | BL3: &H1 | BT3: groupOfUsage
A4: &H2 | B4: кадастровый номер объекта | C4: назначение здания | D4: материал стен | E4: наименование объекта | F4: описание | G4: значение площади | H4: год ввода в эксплуатацию | I4: год ввода в эксплуатацию (строка) | J4: год завершения строительства | K4: год завершения строительства (строка) | L4: в т.ч. подземных | M4: в т.ч. подземных (строка загрузки) | N4: количество этажей | O4: количество этажей (строка загрузки) | P4: Код функциональной группы | Q4: Код функциональной группы (подгруппы) | R4: актуальная кадастровая стоимость | S4: актуальный УПКС | T4: дата актуальной кадастровой стоимости | U4: Материал стен в расчет | V4: Этажность в расчет | W4: Год в расчет | X4: Группа капитальности | Y4: список кадастровых номеров машино-мест | Z4: список кадастровых номеров объектов содержащих текущий | AA4: список кадастровых номеров помещений | AB4: дата создания | AC4: Первоначальная площадь | AD4: НАШ ОКТМО | AE4: Ценовые зоны по квартирам | AF4: Индивидуальный расчет | AG4: Тип территории | AH4: вид использования по документу | AI4: Код расчёта вида использования | AJ4: МС | AK4: Проверка на количество МС | AL4: Год постановки на учет | AM4: Год1 | AN4: Год2 | AO4: Тип этажности | AP4: ТипФГ | AQ4: Мин ГК по МС | AR4: Макс ГК по МС | AS4: Итоговый ГК по МС | AT4: Модель для квартир | AU4: Для опр ГК | AV4: кол пом | AW4: кол ММ | AX4: наименования не противоречит ИЖС у Не Жилых | AY4: наименования не противоречит ИЖС | AZ4: для нежилых вне садов | BA4: Площадь от 10 до 500 | BB4: Этажность меньше 4 | BC4: Справочник наименований | BD4: ФГ ИЖС | BE4: ФГ МКД | BF4: ФГ Нежилое | BG4: гаражи по адресу | BH4: сады по адресу | BI4: склады, ангары | BJ4: Без информации в наименовании | BK4: ИтогФГ1 | BL4: &H2 | BM4: кадастровый номер объекта | BN4: Этажность в расчет | BO4: Материал стен в расчет | BP4: Год в расчет | BQ4: Группа капитальности | BR4: Первоначальная площадь | BS4: Индивидуальный расчет | BT4: Код функциональной группы (подгруппы)
A5: 91607663 | B5: 66:00:0000000:60518 | C5: Нежилое | D5: Шлакобетонные | G5: 27.2 | J5: 1999 | K5: 1999 | N5: 1 | O5: 1 | P5: 0300 | Q5: 0303 | U5: Шлакобетонные | V5: 1 | W5: 1999 | X5: III | Z5: 66:44:0102023:47 | AD5: 65623420 | AG5: Отсутствует информация | AJ5: =VLOOKUP(B5,'Промежуточный параметр'!A$2:D$100000,2,FALSE) -> Шлакобетонные | AK5: =IFERROR(SEARCH(",",AJ5),0) -> 0 | AL5: =YEAR(AB5) -> 1900 | AM5: =IF(H5="",0,H5) -> 0 | AN5: =IF(J5="",0,J5) -> 1999 | AO5: =VLOOKUP(BN5,'Тип этажности'!A$2:B$101,2,FALSE) -> Малоэтажное | AP5: =IFERROR(VLOOKUP(BT5,ТипФГ!A$2:C$30,3,FALSE),IF(BT5="","не сгруппирован","Прочие")) -> Прочие | AQ5: =VLOOKUP(B5,'Промежуточный параметр'!A$2:D$100000,3,FALSE) -> 3 | AR5: =VLOOKUP(B5,'Промежуточный параметр'!A$2:D$100000,4,FALSE) -> 3 | AS5: =IF(AQ5=AR5,AQ5,IF(VALUE(AQ5)>2,AQ5,IF(VALUE(AR5)=1,"1","2"))) -> 3 | AT5: =VLOOKUP(AD5,'Спр ОКТМО'!A$2:G$1940,7,FALSE) -> 1002_М6_Квартиры области до 50 | AU5: =CONCATENATE(AP5,AO5,AS5) -> ПрочиеМалоэтажное3 | AV5: =IFERROR(VLOOKUP(B5,'Промежуточная табл 4'!A$2:C$30000,3,FALSE),0) -> 0 | AW5: =IFERROR(VLOOKUP(B5,'[1]Промежуточная табл 2'!A$2:C$30000,3,FALSE),0) -> 0 | AX5: =AND(OR(MID(E5,1,4)="жило",IFERROR(SEARCH("Дом блокирова",E5),0)>0,IFERROR(SEARCH("Садовый дом",E5),0)>0,IFERROR(SEARCH("жилой дом",E5),0)>0,IFERROR(SEARCH("Объект индивидуального жилищного строительства",E5),0)>0),IFERROR(SEARCH("нежило",E5),0)=0,IFERROR(SEARCH("многокв",E5),0)=0) -> FALSE | AY5: =OR(LEN(E5)=0,E5="дом",E5="Здание",MID(E5,1,4)="жило",IFERROR(SEARCH("жило",E5),0)>0,IFERROR(SEARCH("Объект индивидуального жилищного строительства",E5),0)>0) -> TRUE | AZ5: =AND(OR(IFERROR(SEARCH("Дом блокирова",E5),0)>0,IFERROR(SEARCH("Садовый дом",E5),0)>0,IFERROR(SEARCH("жилой дом",E5),0)>0,IFERROR(SEARCH("Объект индивидуального жилищного строительства",E5),0)>0),IFERROR(SEARCH("нежило",E5),0)=0,IFERROR(SEARCH("многокв",E5),0)=0) -> FALSE | BA5: =AND(G5>10,G5<500) -> TRUE | BB5: =BN5<4 -> TRUE | BC5: =IFERROR(VLOOKUP(E5,'СПР Наименований'!#REF!,2,FALSE),-1) -> -1 | BD5: =IF(C5="Жилое",IF(AND(BB5,AY5,BA5,AV5+AW5<5),IF(LEN(AD5)=8,VLOOKUP(AG5,'Тип территории'!A$2:C$10,2,FALSE),VLOOKUP(AG5,'Тип территории'!A$2:D$10,4,FALSE)),"Не выполнены условия ИЖС по жилым"),IF(OR(C5="Нежилое",C5="Жилое строение",C5="Садовый дом"),IF(OR(AND(VLOOKUP(AG5,'Тип территории'!A$2:C$10,1,FALSE)="Отсутствует информация",BB5,AZ5,BA5,AV5+AW5<5),AND(VLOOKUP(AG5,'Тип территории'!A$2:C$10,1,FALSE)<>"Отсутствует информация",BB5,OR(AY5,AX5),BA5,AV5+AW5<5)),VLOOKUP(AG5,'Тип территории'!A$2:C$10,3,FALSE),"Не выполнены условия ИЖС по нежилым"),"Несоответствие типа здания")) -> Не выполнены условия ИЖС по нежилым | BE5: =IF(C5="Многоквартирный дом",IF(AND(VLOOKUP(AD5,'Спр ОКТМО'!A$2:J$1940,10,FALSE)="0104",Объекты!BP5>2014,Объекты!BR5>2000),"0104","0101"),"Не МКД") -> Не МКД | BF5: =IFERROR(IF(G5<VLOOKUP(E5,'СПР Наименований'!A$2:E$50000,3,FALSE),VLOOKUP(E5,'СПР Наименований'!A$2:E$50000,4,FALSE),VLOOKUP(E5,'СПР Наименований'!A$2:E$50000,5,FALSE)),"нет в справочнике наименований") -> нет в справочнике наименований | BG5: =IF(AND(C5="Нежилое",OR(IFERROR(SEARCH("гараж",F5),0)>0,IFERROR(SEARCH("СПГК",F5),0)>0,IFERROR(SEARCH("ПГК",F5),0)>0,OR(MID(F5,1,3)="гск",IFERROR(SEARCH(" гск",F5),0)>0))),IF(G5>90,"0303","0302"),"") | BH5: =IF(AND(C5="Нежилое",OR(IFERROR(SEARCH("Коллективный сад",F5),0)>0,IFERROR(SEARCH("к/с",F5),0)>0,IFERROR(SEARCH("снт",F5),0)>0)),"СНТ","") | BI5: =IF(AND(C5="Нежилое",OR(IFERROR(SEARCH("склад",E5),0)>0,IFERROR(SEARCH("ангар",E5),0)>0,)),"склады, ангары","") | BJ5: =IF(AND(C5="Нежилое",LEN(BG5)=0,LEN(BH5)=0,G5<1000,OR(LEN(E5)=0,E5="Здание",E5="Отдельно-стоящее здание с пристроями",E5="Часть здания",E5="Здание нежилого назначения",E5="Отдельно-стоящее здание с пристроем",E5="Нежилое здание",E5="Отдельно-стоящее здание")),"0907","") -> 0907 | BK5: =IFERROR(VLOOKUP(BD5,'СПР ФГ'!B$2:C$374,1,FALSE),IFERROR(VLOOKUP(BE5,'СПР ФГ'!B$2:C$374,1,FALSE),IFERROR(VLOOKUP(BF5,'СПР ФГ'!B$2:C$374,1,FALSE),""))) | BM5: =B5 -> 66:00:0000000:60518 | BN5: =IF(O5="",1,VALUE(VLOOKUP(O5,'Соответствие этажей'!A$2:B$5000,2,FALSE))) -> 1 | BO5: =IF(AK5=0,AJ5,IF(Q5="0100","","Смешанные")) -> Шлакобетонные | BP5: =IF(AND(AM5=0,AN5=0),AL5,MAX(AM5,AN5)) -> 1999 | BQ5: =VLOOKUP(AU5,ОпределениеГК!A$2:F$61,6,FALSE) -> III | BR5: =G5 -> 27.2 | BS5: =Константы0!$A$1 -> 0 | BT5: =IF(LEN(P5)=0,BK5,P5) -> 0300

Sheet Спр ОКТМО
A1: НАШ ОКТМО | B1: Код НП | C1: Наименование МО | D1: Наименование НП | E1: Модель для квартир | F1: Численность | G1: Модель | H1: Ценовая зона
A2: 65729000106 | B2: 01:002:2:3:5 | C2: Арамильский городской округ | D2: п Арамиль | E2: 106 | F2: =VLOOKUP(B2,'[2]справочник кодов нп'!$A:$D,4,0) -> сельские населенные пункты с численностью населения более 1 000 человек; | G2: 1002_М6_Квартиры области до 50 | H2: Арамильский городской округ | I2: 0202 | J2: 0101
A3: 65729000111 | B3: 01:003:2:3:5 | C3: Арамильский городской округ | D3: п Светлый | E3: 106 | F3: =VLOOKUP(B3,'[2]справочник кодов нп'!$A:$D,4,0) -> сельские населенные пункты с численностью населения более 1 000 человек; | G3: 1002_М6_Квартиры области до 50 | H3: Арамильский городской округ | I3: 0202 | J3: 0101
A4: 65729000001 | B4: 01:001:1:1:4 | C4: Арамильский городской округ | D4: г Арамиль | E4: 106 | F4: =VLOOKUP(B4,'[2]справочник кодов нп'!$A:$D,4,0) -> городские населенные пункты с численностью населения менее 50 000 человек; | G4: 1002_М6_Квартиры области до 50 | H4: Арамильский городской округ | I4: 0202 | J4: 0104
A5: 65729000 | B5: 01:000:0:0:0 | C5: Арамильский городской округ | D5: межселенка | E5: 106 | F5: =VLOOKUP(B5,'[2]справочник кодов нп'!$A:$D,4,0) -> межселенная территория | G5: 1002_М6_Квартиры области до 50 | H5: Арамильский городской округ | I5: 0205 | J5: 0101
A6: 65703000116 | B6: 02:016:2:5:6 | C6: Артемовский городской округ | D6: д Луговая | E6: 106 | F6: =VLOOKUP(B6,'[2]справочник кодов нп'!$A:$D,4,0) -> сельские населенные пункты с численностью населения менее 1 000 человек. | G6: 1002_М6_Квартиры области до 50 | H6: Артемовский городской округ | I6: 0202 | J6: 0101
A7: 65703000126 | B7: 02:020:2:5:6 | C7: Артемовский городской округ | D7: д Налимово | E7: 106 | F7: =VLOOKUP(B7,'[2]справочник кодов нп'!$A:$D,4,0) -> сельские населенные пункты с численностью населения менее 1 000 человек. | G7: 1002_М6_Квартиры области до 50 | H7: Артемовский городской округ | I7: 0202 | J7: 0101
A8: 65703000236 | B8: 02:014:2:4:6 | C8: Артемовский городской округ | D8: с Липино | E8: 106 | F8: =VLOOKUP(B8,'[2]справочник кодов нп'!$A:$D,4,0) -> сельские населенные пункты с численностью населения менее 1 000 человек. | G8: 1002_М6_Квартиры области до 50 | H8: Артемовский городской округ | I8: 0202 | J8: 0101
A9: 65703000106 | B9: 02:009:2:5:6 | C9: Артемовский городской округ | D9: д Бучино | E9: 106 | F9: =VLOOKUP(B9,'[2]справочник кодов нп'!$A:$D,4,0) -> сельские населенные пункты с численностью населения менее 1 000 человек. | G9: 1002_М6_Квартиры области до 50 | H9: Артемовский городской округ | I9: 0202 | J9: 0101
A10: 65703000226 | B10: 02:006:2:4:6 | C10: Артемовский городской округ | D10: с Большое Трифоново | E10: 106 | F10: =VLOOKUP(B10,'[2]справочник кодов нп'!$A:$D,4,0) -> сельские населенные пункты с численностью населения менее 1 000 человек. | G10: 1002_М6_Квартиры области до 50 | H10: Артемовский городской округ | I10: 0202 | J10: 0101
A11: 65703000136 | B11: 02:003:2:3:6 | C11: Артемовский городской округ | D11: п Белый Яр | E11: 106 | F11: =VLOOKUP(B11,'[2]справочник кодов нп'!$A:$D,4,0) -> сельские населенные пункты с численностью населения менее 1 000 человек. | G11: 1002_М6_Квартиры области до 50 | H11: Артемовский городской округ | I11: 0202 | J11: 0101
A12: 65703000216 | B12: 02:002:2:4:6 | C12: Артемовский городской округ | D12: с Антоново | E12: 106 | F12: =VLOOKUP(B12,'[2]справочник кодов нп'!$A:$D,4,0) -> сельские населенные пункты с численностью населения менее 1 000 человек. | G12: 1002_М6_Квартиры области до 50 | H12: Артемовский городской округ | I12: 0202 | J12: 0101
A13: 65703000196 | B13: 02:021:2:3:6 | C13: Артемовский городской округ | D13: п Незевай | E13: 106 | F13: =VLOOKUP(B13,'[2]справочник кодов нп'!$A:$D,4,0) -> сельские населенные пункты с численностью населения менее 1 000 человек. | G13: 1002_М6_Квартиры области до 50 | H13: Артемовский городской округ | I13: 0202 | J13: 0101
... A94: 65730000111 | B94: 04:003:2:3:6 | C94: Асбестовский городской округ | D94: п Красноармейский | E94: 105 | F94: =VLOOKUP(B94,'[2]справочник кодов нп'!$A:$D,4,0) -> сельские населенные пункты с численностью населения менее 1 000 человек. | G94: 1003_М5_Квартиры области до 100 | H94: Асбестовский городской округ | I94: 0202 | J94: 0101
A95: 65730000001 | B95: 04:001:1:1:3 | C95: Асбестовский городской округ | D95: г Асбест | E95: 105 | F95: городские населенные пункты с численностью населения от 50 000 до 100 000 человек; | G95: 1003_М5_Квартиры области до 100 | H95: Асбестовский городской округ | I95: 0202 | J95: 0101
A96: 65730000106 | B96: 04:002:2:3:5 | C96: Асбестовский городской округ | D96: п Белокаменный | E96: 105 | F96: =VLOOKUP(B96,'[2]справочник кодов нп'!$A:$D,4,0) -> сельские населенные пункты с численностью населения более 1 000 человек; | G96: 1003_М5_Квартиры области до 100 | H96: Асбестовский городской округ | I96: 0202 | J96: 0101
A97: 65730000 | B97: 04:000:0:0:0 | C97: Асбестовский городской округ | D97: межселенка | E97: 105 | F97: =VLOOKUP(B97,'[2]справочник кодов нп'!$A:$D,4,0) -> межселенная территория | G97: 1003_М5_Квартиры области до 100 | H97: Асбестовский городской округ | I97: 0205 | J97: 0101
A98: 65705000326 | B98: 05:053:2:3:5 | C98: Ачитский городской округ | D98: п Уфимский | E98: 106 | F98: =VLOOKUP(B98,'[2]справочник кодов нп'!$A:$D,4,0) -> сельские населенные пункты с численностью населения более 1 000 человек; | G98: 1002_М6_Квартиры области до 50 | H98: Ачитский городской округ | I98: 0202 | J98: 0101
A99: 65705000281 | B99: 05:051:2:5:6 | C99: Ачитский городской округ | D99: д Теплый Ключ | E99: 106 | F99: =VLOOKUP(B99,'[2]справочник кодов нп'!$A:$D,4,0) -> сельские населенные пункты с численностью населения менее 1 000 человек. | G99: 1002_М6_Квартиры области до 50 | H99: Ачитский городской округ | I99: 0202 | J99: 0101
A100: 65705000106 | B100: 05:001:2:5:6 | C100: Ачитский городской округ | D100: д Алап | E100: 106 | F100: =VLOOKUP(B100,'[2]справочник кодов нп'!$A:$D,4,0) -> сельские населенные пункты с численностью населения менее 1 000 человек. | G100: 1002_М6_Квартиры области до 50 | H100: Ачитский городской округ | I100: 0202 | J100: 0101
A101: 65705000266 | B101: 05:048:2:5:6 | C101: Ачитский городской округ | D101: д Сарга | E101: 106 | F101: =VLOOKUP(B101,'[2]справочник кодов нп'!$A:$D,4,0) -> сельские населенные пункты с численностью населения менее 1 000 человек. | G101: 1002_М6_Квартиры области до 50 | H101: Ачитский городской округ | I101: 0202 | J101: 0101
A102: 65705000146 | B102: 05:015:2:5:6 | C102: Ачитский городской округ | D102: д Давыдкова | E102: 106 | F102: =VLOOKUP(B102,'[2]справочник кодов нп'!$A:$D,4,0) -> сельские населенные пункты с численностью населения менее 1 000 человек. | G102: 1002_М6_Квартиры области до 50 | H102: Ачитский городской округ | I102: 0202 | J102: 0101
A103: 65705000321 | B103: 05:046:2:3:6 | C103: Ачитский городской округ | D103: п Рябчиково | E103: 106 | F103: =VLOOKUP(B103,'[2]справочник кодов нп'!$A:$D,4,0) -> сельские населенные пункты с численностью населения менее 1 000 человек. | G103: 1002_М6_Квартиры области до 50 | H103: Ачитский городской округ | I103: 0202 | J103: 0101
A104: 65705000286 | B104: 05:052:2:5:6 | C104: Ачитский городской округ | D104: д Тюш | E104: 106 | F104: =VLOOKUP(B104,'[2]справочник кодов нп'!$A:$D,4,0) -> сельские населенные пункты с численностью населения менее 1 000 человек. | G104: 1002_М6_Квартиры области до 50 | H104: Ачитский городской округ | I104: 0202 | J104: 0101
A105: 65705000291 | B105: 05:054:2:5:6 | C105: Ачитский городской округ | D105: д Ялым | E105: 106 | F105: =VLOOKUP(B105,'[2]справочник кодов нп'!$A:$D,4,0) -> сельские населенные пункты с численностью населения менее 1 000 человек. | G105: 1002_М6_Квартиры области до 50 | H105: Ачитский городской округ | I105: 0202 | J105: 0101
A106: 65705000276 | B106: 05:050:2:5:6 | C106: Ачитский городской округ | D106: д Судницына | E106: 106 | F106: =VLOOKUP(B106,'[2]справочник кодов нп'!$A:$D,4,0) -> сельские населенные пункты с численностью населения менее 1 000 человек. | G106: 1002_М6_Квартиры области до 50 | H106: Ачитский городской округ | I106: 0202 | J106: 0101
A107: 65705000236 | B107: 05:037:2:5:6 | C107: Ачитский городской округ | D107: д Марийские Карши | E107: 106 | F107: =VLOOKUP(B107,'[2]справочник кодов нп'!$A:$D,4,0) -> сельские населенные пункты с численностью населения менее 1 000 человек. | G107: 1002_М6_Квартиры области до 50 | H107: Ачитский городской округ | I107: 0202 | J107: 0101
... A268: 65706000 | B268: 07:000:0:0:0 | C268: Белоярский городской округ | D268: межселенка | E268: 106 | F268: =VLOOKUP(B268,'[2]справочник кодов нп'!$A:$D,4,0) -> межселенная территория | G268: 1002_М6_Квартиры области до 50 | H268: Белоярский городской округ | I268: 0205 | J268: 0101
A269: 65731000001 | B269: 08:002:1:1:3 | C269: Березовский городской округ | D269: г Березовский | E269: 105 | F269: городские населенные пункты с численностью населения от 50 000 до 100 000 человек; | G269: 1003_М5_Квартиры области до 100 | H269: Березовский городской округ | I269: 0202 | J269: 0104
A270: 65731000126 | B270: 08:006:2:3:6 | C270: Березовский городской округ | D270: п Красногвардейский | E270: 105 | F270: =VLOOKUP(B270,'[2]справочник кодов нп'!$A:$D,4,0) -> сельские населенные пункты с численностью населения менее 1 000 человек. | G270: 1003_М5_Квартиры области до 100 | H270: Березовский городской округ | I270: 0202 | J270: 0101
A271: 65731000116 | B271: 08:004:2:3:5 | C271: Березовский городской округ | D271: п Кедровка | E271: 105 | F271: =VLOOKUP(B271,'[2]справочник кодов нп'!$A:$D,4,0) -> сельские населенные пункты с численностью населения более 1 000 человек; | G271: 1003_М5_Квартиры области до 100 | H271: Березовский городской округ | I271: 0202 | J271: 0101
A272: 65731000171 | B272: 08:015:2:3:6 | C272: Березовский городской округ | D272: п Сарапулка | E272: 105 | F272: =VLOOKUP(B272,'[2]справочник кодов нп'!$A:$D,4,0) -> сельские населенные пункты с численностью населения менее 1 000 человек. | G272: 1003_М5_Квартиры области до 100 | H272: Березовский городской округ | I272: 0202 | J272: 0101
A273: 65731000186 | B273: 08:018:2:3:5 | C273: Березовский городской округ | D273: п Старопышминск | E273: 105 | F273: =VLOOKUP(B273,'[2]справочник кодов нп'!$A:$D,4,0) -> сельские населенные пункты с численностью населения более 1 000 человек; | G273: 1003_М5_Квартиры области до 100 | H273: Березовский городской округ | I273: 0202 | J273: 0101
A274: 65731000111 | B274: 08:003:2:3:6 | C274: Березовский городской округ | D274: п Зеленый Дол | E274: 105 | F274: =VLOOKUP(B274,'[2]справочник кодов нп'!$A:$D,4,0) -> сельские населенные пункты с численностью населения менее 1 000 человек. | G274: 1003_М5_Квартиры области до 100 | H274: Березовский городской округ | I274: 0202 | J274: 0101
A275: 65731000106 | B275: 08:001:2:3:6 | C275: Березовский городской округ | D275: п Безречный | E275: 105 | F275: =VLOOKUP(B275,'[2]справочник кодов нп'!$A:$D,4,0) -> сельские населенные пункты с численностью населения менее 1 000 человек. | G275: 1003_М5_Квартиры области до 100 | H275: Березовский городской округ | I275: 0202 | J275: 0101
A276: 65731000181 | B276: 08:017:2:3:6 | C276: Березовский городской округ | D276: п Становая | E276: 105 | F276: =VLOOKUP(B276,'[2]справочник кодов нп'!$A:$D,4,0) -> сельские населенные пункты с численностью населения менее 1 000 человек. | G276: 1003_М5_Квартиры области до 100 | H276: Березовский городской округ | I276: 0202 | J276: 0101
A277: 65731000136 | B277: 08:008:2:3:5 | C277: Березовский городской округ | D277: п Лосиный | E277: 105 | F277: =VLOOKUP(B277,'[2]справочник кодов нп'!$A:$D,4,0) -> сельские населенные пункты с численностью населения более 1 000 человек; | G277: 1003_М5_Квартиры области до 100 | H277: Березовский городской округ | I277: 0202 | J277: 0101
A278: 65731000166 | B278: 08:013:2:3:6 | C278: Березовский городской округ | D278: п Островное | E278: 105 | F278: =VLOOKUP(B278,'[2]справочник кодов нп'!$A:$D,4,0) -> сельские населенные пункты с численностью населения менее 1 000 человек. | G278: 1003_М5_Квартиры области до 100 | H278: Березовский городской округ | I278: 0202 | J278: 0101
A279: 65731000176 | B279: 08:016:2:3:6 | C279: Березовский городской округ | D279: п Солнечный | E279: 105 | F279: =VLOOKUP(B279,'[2]справочник кодов нп'!$A:$D,4,0) -> сельские населенные пункты с численностью населения менее 1 000 человек. | G279: 1003_М5_Квартиры области до 100 | H279: Березовский городской округ | I279: 0202 | J279: 0101
A280: 65731000156 | B280: 08:011:2:3:6 | C280: Березовский городской округ | D280: п Мурзинский | E280: 105 | F280: =VLOOKUP(B280,'[2]справочник кодов нп'!$A:$D,4,0) -> сельские населенные пункты с численностью населения менее 1 000 человек. | G280: 1003_М5_Квартиры области до 100 | H280: Березовский городской округ | I280: 0202 | J280: 0101
...

Sheet СПР ФГ
A1: Группа | B1: Подгруппа | C1: Функциональная группа | D1: ОБЩАЯ
A2: 0100 | B2: 0100 | C2: Многоквартирные дома (дома средне- и многоэтажной жилой застройки) | D2: Группа 1. Многоквартирные дома (дома средне- и многоэтажной жилой застройки)
A3: 0100 | B3: 0101 | C3: Дома жилые экономичного класса (с преобладанием малогабаритных квартир) | D3: Группа 1. Многоквартирные дома (дома средне- и многоэтажной жилой застройки)
A4: 0100 | B4: 0102 | C4: Дома жилые со встроенными нежилыми помещениями | D4: Группа 1. Многоквартирные дома (дома средне- и многоэтажной жилой застройки)
A5: 0100 | B5: 0103 | C5: Дома жилые повышенной комфортности (дома с небольшим количеством малогабаритных квартир, дома класса комфорт) | D5: Группа 1. Многоквартирные дома (дома средне- и многоэтажной жилой застройки)
A6: 0100 | B6: 0104 | C6: Дома жилые повышенной комфортности со встроенными нежилыми помещениями | D6: Группа 1. Многоквартирные дома (дома средне- и многоэтажной жилой застройки)
A7: 0100 | B7: 0105 | C7: Дома бизнес-класса и выше (дома с повышенными габаритами квартир, уровнем отделки и обслуживания, как правило, расположены в престижных районах застройки) | D7: Группа 1. Многоквартирные дома (дома средне- и многоэтажной жилой застройки)
A8: 0100 | B8: 0106 | C8: Дома бизнес-класса и выше со встроенными нежилыми помещениями | D8: Группа 1. Многоквартирные дома (дома средне- и многоэтажной жилой застройки)
A9: 0200 | B9: 0200 | C9: Дома малоэтажной жилой застройки, в том числе индивидуальной жилой застройки - индивидуальные, малоэтажные блокированные (таунхаусы), дачных объединений, садоводческих товариществ | D9: Группа 2. Дома малоэтажной жилой застройки, в том числе индивидуальной жилой застройки - индивидуальные, малоэтажные блокированные (таунхаусы), дачных объединений, садоводческих товариществ
A10: 0200 | B10: 0201 | C10: Дома жилые блокированной застройки (таунхаусы) | D10: Группа 2. Дома малоэтажной жилой застройки, в том числе индивидуальной жилой застройки - индивидуальные, малоэтажные блокированные (таунхаусы), дачных объединений, садоводческих товариществ
A11: 0200 | B11: 0202 | C11: Дома индивидуальные | D11: Группа 2. Дома малоэтажной жилой застройки, в том числе индивидуальной жилой застройки - индивидуальные, малоэтажные блокированные (таунхаусы), дачных объединений, садоводческих товариществ
A12: 0200 | B12: 0203 | C12: Дома индивидуальные с бытовыми пристройками | D12: Группа 2. Дома малоэтажной жилой застройки, в том числе индивидуальной жилой застройки - индивидуальные, малоэтажные блокированные (таунхаусы), дачных объединений, садоводческих товариществ
... A201: 0900 | B201: 0908_1 | C201: Бани, банные комплексы, бани-прачечные. частные/общественные, душевые средней и большой площади 50 кв.м. - 150 кв.м. | D201: Группа 9. Прочие объекты
A202: 1000 | B202: 1001 | C202: Аттракционы | D202: Сооружения
A203: 1000 | B203: 1002_1 | C203: Вышка, башня | D203: Сооружения
A204: 1000 | B204: 1002_2 | C204: Башня пожарная | D204: Сооружения
A205: 1000 | B205: 1002_3 | C205: Башня водонапорная | D205: Сооружения
A206: 1000 | B206: 1002_4 | C206: Вышка, башня радиорелейная, связи, сотовой связи | D206: Сооружения
A207: 1000 | B207: 1003_1 | C207: Мачта радиорелейная, мачта сотовой связи | D207: Сооружения
A208: 1000 | B208: 1003_2 | C208: Молниеотвод | D208: Сооружения
A209: 1000 | B209: 1003_3 | C209: Вышка сторожевая, караульная | D209: Сооружения
A210: 1000 | B210: 1003_4 | C210: Мачта прожекторная, осветительная | D210: Сооружения
A211: 1000 | B211: 1003_5 | C211: Светофорный объект | D211: Сооружения
A212: 1000 | B212: 1003_6 | C212: Опоры освещения | D212: Сооружения
A213: 1000 | B213: 1004 | C213: Беседки | D213: Сооружения
A214: 1000 | B214: 1005 | C214: Гидротехнические сооружения - набережные | D214: Сооружения
A215: 1000 | B215: 1005_1 | C215: Подпорная стенка | D215: Сооружения
A216: 1000 | B216: 1006_2 | C216: Крыльцо | D216: Сооружения
A217: 1000 | B217: 1006_3 | C217: Железнодорожная рампа | D217: Сооружения
A218: 1000 | B218: 1006_5 | C218: Эстакады ж/бетонные | D218: Сооружения
A219: 1000 | B219: 1006_6 | C219: Эстакады металлические | D219: Сооружения
A220: 1000 | B220: 1006_11 | C220: Лестница металлическая | D220: Сооружения
A221: 1000 | B221: 1006_12 | C221: Лестница ж/бетонная | D221: Сооружения
A222: 1000 | B222: 1007_1 | C222: Резервуары (наземные -подземные металлические) | D222: Сооружения
A223: 1000 | B223: 1007_2 | C223: Иловые, песковые площадки | D223: Сооружения
A224: 1000 | B224: 1007_3 | C224: Пылеуловители, циклоны | D224: Сооружения
A225: 1000 | B225: 1007_4 | C225: Мазутохранилище, битумохранилище | D225: Сооружения
A226: 1000 | B226: 1007_5 | C226: Нефтехранилище | D226: Сооружения
... A232: 1000 | B232: 1007_11 | C232: Минерализатор аэробный | D232: Сооружения
A233: 1000 | B233: 1008 | C233: Бункеры | D233: Сооружения
...

Sheet СУРС ГКО2023
A1: вид объекта учёта | B1: Код функциональной группы (подгруппы) | C1: Группа капитальности | D1: значение площади | E1: Удельная стоимость
A2: Здание | B2: 0301 | C2: I | D2: 0-1000000 | E2: 6570
A3: Здание | B3: 0302 | C3: I | D3: 0-1000000 | E3: 29000
A4: Здание | B4: 0303 | C4: I | D4: 0-401 | E4: 27300
A5: Здание | B5: 0303 | C5: I | D5: 401-1001 | E5: 25400
A6: Здание | B6: 0303 | C6: I | D6: 1001-3001 | E6: 22900
A7: Здание | B7: 0303 | C7: I | D7: 3001-1000000 | E7: 20600
A8: Здание | B8: 0304_1 | C8: I | D8: 0-801 | E8: 33900
A9: Здание | B9: 0304_1 | C9: I | D9: 801-3001 | E9: 32300
A10: Здание | B10: 0304_1 | C10: I | D10: 3001-5001 | E10: 30200
A11: Здание | B11: 0304_1 | C11: I | D11: 5001-10001 | E11: 28200
A12: Здание | B12: 0304_1 | C12: I | D12: 10001-25001 | E12: 26350
A13: Здание | B13: 0304_1 | C13: I | D13: 25001-1000000 | E13: 24500
... A2771: Здание | B2771: 0207 | C2771: V | D2771: 0-1000000 | E2771: 3800

Sheet Константы0
A1: 0 | B1: Индивидуальный расчет

Sheet СПР Наименований
A1: Наименование | B1: Правило | C1: Условие на плошадь | D1: ФГ1 | E1: ФГ2
A2: Гараж - мастерская | B2: 1 | C2: 90 | D2: 0302 | E2: 0306
A3: Гараж для грузовых машин | B3: 0 | C3: 0 | D3: 0306 | E3: 0306
A4: Гараж с мастерской | B4: 1 | C4: 90 | D4: 0302 | E4: 0306
A5: Гараж, автомастерская | B5: 1 | C5: 90 | D5: 0302 | E5: 0306
A6: Гараж, Мастерские | B6: 1 | C6: 90 | D6: 0302 | E6: 0306
A7: Гараж, назначение: нежилое. Площадь: общая 24 кв.м. Этажность: 1. Подземная этажность: 0. | B7: 1 | C7: 90 | D7: 0302 | E7: 0303
A8: Гараж-мастерская | B8: 1 | C8: 90 | D8: 0302 | E8: 0306
A9: Грузовой гараж | B9: 0 | C9: 0 | D9: 0306 | E9: 0306
A10: Здание автотранспортного цеха | B10: 0 | C10: 0 | D10: 0306 | E10: 0306
A11: Здание бокса на 20 автомашин | B11: 1 | C11: 90 | D11: 0302 | E11: 0303
A12: Здание гаража грузовых автомобилей | B12: 0 | C12: 0 | D12: 0306 | E12: 0306
A13: Здание гаража для грузовых машин | B13: 0 | C13: 0 | D13: 0306 | E13: 0306
... A395: Проходная | B395: 1 | C395: 100 | D395: 0703 | E395: 0607

Sheet Тип территории
A1: Тип территории | B1: ФГ для жилых вне НП | C1: ФГ для нежилых | D1: ФГ для жилых в НП
A2: КП | B2: 0204 | C2: 0204 | D2: 0204
A3: Таунхаусы-КП | B3: 0204 | C3: 0204 | D3: 0204
A4: Таунхаусы-КП-МКД | B4: 0204 | C4: 0204 | D4: 0204
A5: КП - гостинницы | B5: 0204 | C5: 0204 | D5: 0204
A6: Таунхаусы | B6: 0201 | C6: 0201 | D6: 0201
A7: Таунхаусы и дачи | B7: 0205 | C7: 0205 | D7: 0202
A8: Сады | B8: 0205 | C8: 0205 | D8: 0202
A9: Коттеджные_поселки | B9: 0205 | C9: 0205 | D9: 0202
A10: Отсутствует информация | B10: 0202 | C10: 0205 | D10: 0202

Sheet Тип этажности
A1: Этажность | B1: Тип
A2: 1 | B2: Малоэтажное
A3: 2 | B3: Малоэтажное
A4: 3 | B4: Малоэтажное
A5: 4 | B5: Среднеэтажное
A6: 5 | B6: Среднеэтажное
A7: 6 | B7: Среднеэтажное
A8: 7 | B8: Среднеэтажное
A9: 8 | B9: Среднеэтажное
A10: =A9+1 -> 9 | B10: Многоэтажное
A11: =A10+1 -> 10 | B11: Многоэтажное
A12: =A11+1 -> 11 | B12: Многоэтажное
A13: =A12+1 -> 12 | B13: Многоэтажное
A14: =A13+1 -> 13 | B14: Многоэтажное
A15: =A14+1 -> 14 | B15: Многоэтажное
A16: =A15+1 -> 15 | B16: Многоэтажное
A17: =A16+1 -> 16 | B17: Многоэтажное
A18: =A17+1 -> 17 | B18: Многоэтажное
A19: =A18+1 -> 18 | B19: Многоэтажное
A20: =A19+1 -> 19 | B20: Многоэтажное
A21: =A20+1 -> 20 | B21: Многоэтажное
... A100: =A99+1 -> 99 | B100: Многоэтажное
A101: 100 | B101: Многоэтажное

Sheet Соответствие этажей
A1: Этажность | B1: locFloor | C1: МЕТОД
A2: 1 | B2: 1 | C2: ЭТАЖ ЗАДАН ЧИСЛОМ
A3: 2 | B3: 2 | C3: ЭТАЖ ЗАДАН ЧИСЛОМ
A4: 3 | B4: 3 | C4: ЭТАЖ ЗАДАН ЧИСЛОМ
A5: 4 | B5: 4 | C5: ЭТАЖ ЗАДАН ЧИСЛОМ
A6: 5 | B6: 5 | C6: ЭТАЖ ЗАДАН ЧИСЛОМ
A7: 6 | B7: 6 | C7: ЭТАЖ ЗАДАН ЧИСЛОМ
A8: 7 | B8: 7 | C8: ЭТАЖ ЗАДАН ЧИСЛОМ
A9: 8 | B9: 8 | C9: ЭТАЖ ЗАДАН ЧИСЛОМ
A10: 9 | B10: 9 | C10: ЭТАЖ ЗАДАН ЧИСЛОМ
A11: 10 | B11: 10 | C11: ЭТАЖ ЗАДАН ЧИСЛОМ
A12: 11 | B12: 11 | C12: ЭТАЖ ЗАДАН ЧИСЛОМ
... A1087: литер 2А - 1 с встройкой и антресолями; 2Б - 1 | B1087: 1 | C1087: СПРАВОЧНИК ЭТАЖНОСТИ
B1088: 1 | C1088: СПРАВОЧНИК ЭТАЖНОСТИ
A1089: 1 | B1089: 1 | C1089: СПРАВОЧНИК ЭТАЖНОСТИ
A1090: 1.2 | B1090: 2 | C1090: СПРАВОЧНИК ЭТАЖНОСТИ
A1091: 1:цокольный, мансарда | B1091: 2 | C1091: СПРАВОЧНИК ЭТАЖНОСТИ
A1092: 1-2, цокольный этаж | B1092: 2 | C1092: СПРАВОЧНИК ЭТАЖНОСТИ
A1093: 5, подвал | B1093: 5 | C1093: СПРАВОЧНИК ЭТАЖНОСТИ
A1094: подземная этажность | B1094: 1 | C1094: СПРАВОЧНИК ЭТАЖНОСТИ
A1095: 1 с 2-х и 3-х этажной встройкой | B1095: 1 | C1095: СПРАВОЧНИК ЭТАЖНОСТИ
A1096: 1 с 2х этажной встройкой | B1096: 1 | C1096: СПРАВОЧНИК ЭТАЖНОСТИ
A1097: 1 с 2-х этажной встройкой | B1097: 1 | C1097: СПРАВОЧНИК ЭТАЖНОСТИ
A1098: 1 с 3-х этажной встройкой | B1098: 1 | C1098: СПРАВОЧНИК ЭТАЖНОСТИ
A1099: 1 с площадками + 1 надземная | B1099: 1 | C1099: СПРАВОЧНИК ЭТАЖНОСТИ
A1100: 12, 25 | B1100: 25 | C1100: СПРАВОЧНИК ЭТАЖНОСТИ
... A1190: 9-11-17 | B1190: 17 | C1190: СПРАВОЧНИК ЭТАЖНОСТИ

Sheet СПР МС
A1: Материал Код | B1: Основной материал | C1: Группа капитальности присвоена | D1: Возраст | E1: Возраст2
A2: 61001000000 | B2: Стены | C2: 3 | D2: 80 | E2: 48
A3: 61001001000 | B3: Каменные | C3: 1 | D3: 150 | E3: 90
A4: 61001001001 | B4: Кирпичные | C4: 1 | D4: 150 | E4: 90
A5: 61001001002 | B5: Кирпичные облегченные | C5: 3 | D5: 80 | E5: 48
A6: 61001001003 | B6: Из природного камня | C6: 1 | D6: 150 | E6: 90
A7: 61001002000 | B7: Деревянные | C7: 4 | D7: 50 | E7: 30
A8: 61001002001 | B8: Рубленые | C8: 4 | D8: 50 | E8: 30
A9: 61001002002 | B9: Каркасно-засыпные | C9: 5 | D9: 30 | E9: 18
A10: 61001002003 | B10: Каркасно-обшивные | C10: 5 | D10: 30 | E10: 18
A11: 61001002004 | B11: Сборно-щитовые | C11: 5 | D11: 30 | E11: 18
A12: 61001002005 | B12: Дощатые | C12: 5 | D12: 30 | E12: 18
A13: 61001002006 | B13: Деревянный каркас без обшивки | C13: 4 | D13: 50 | E13: 30
... A32: 61001999000 | B32: Иное | C32: 3 | D32: 80 | E32: 48

Sheet ТипФГ
A1: Подгруппа | B1: Функциональная группа | C1: ТипФГ
A2: 0402 | B2: Магазин более 250 кв.м. | C2: Бизнес и Администрация
A3: 0403_1 | B3: Торгово-сервисные комплексы | C3: Бизнес и Администрация
A4: 0403_2 | B4: Торгово-административные комплексы (Торгово-офисные) | C4: Бизнес и Администрация
A5: 0403_3 | B5: Торгово-развлекательный центр/Торгово-досуговый комплекс | C5: Бизнес и Администрация
A6: 0403_4 | B6: Торгово-складские объекты (гипермаркеты) | C6: Бизнес и Администрация
A7: 0403_6 | B7: Торгово-коммерческий многофункциональный комплекс | C7: Бизнес и Администрация
A8: 0408 | B8: Автосалоны | C8: Бизнес и Администрация
A9: 0409 | B9: Рестораны | C9: Бизнес и Администрация
A10: 0501 | B10: Гостиницы: класса 2* и ниже, ведомственные гостиницы, хостелы | C10: Бизнес и Администрация
A11: 0502 | B11: Гостиницы: класса 3* | C11: Бизнес и Администрация
A12: 0503 | B12: Гостиницы: класса 4* и выше | C12: Бизнес и Администрация
... A30: 0205 | B30: ИЖС | C30: ИЖС

Sheet ОпределениеГК
A1: сцепка | B1: ТипФГ | C1: ТИпЭтажности | D1: ГКпоМС | E1: ГК
A2: =CONCATENATE(B2,C2,D2) -> ПрочиеМалоэтажное1 | B2: Прочие | C2: Малоэтажное | D2: 1 | E2: 1 | F2: I
A3: =CONCATENATE(B3,C3,D3) -> ПрочиеСреднеэтажное1 | B3: Прочие | C3: Среднеэтажное | D3: 1 | E3: 1 | F3: I
A4: =CONCATENATE(B4,C4,D4) -> ПрочиеМногоэтажное1 | B4: Прочие | C4: Многоэтажное | D4: 1 | E4: 1 | F4: I
A5: =CONCATENATE(B5,C5,D5) -> ПрочиеМалоэтажное2 | B5: Прочие | C5: Малоэтажное | D5: 2 | E5: 2 | F5: II
A6: =CONCATENATE(B6,C6,D6) -> ПрочиеСреднеэтажное2 | B6: Прочие | C6: Среднеэтажное | D6: 2 | E6: 2 | F6: II
A7: =CONCATENATE(B7,C7,D7) -> ПрочиеМногоэтажное2 | B7: Прочие | C7: Многоэтажное | D7: 2 | E7: 2 | F7: II
A8: =CONCATENATE(B8,C8,D8) -> ПрочиеМалоэтажное3 | B8: Прочие | C8: Малоэтажное | D8: 3 | E8: 3 | F8: III
A9: =CONCATENATE(B9,C9,D9) -> ПрочиеСреднеэтажное3 | B9: Прочие | C9: Среднеэтажное | D9: 3 | E9: 3 | F9: III
A10: =CONCATENATE(B10,C10,D10) -> ПрочиеМногоэтажное3 | B10: Прочие | C10: Многоэтажное | D10: 3 | E10: 3 | F10: III
A11: =CONCATENATE(B11,C11,D11) -> ПрочиеМалоэтажное4 | B11: Прочие | C11: Малоэтажное | D11: 4 | E11: 4 | F11: IV
A12: =CONCATENATE(B12,C12,D12) -> ПрочиеСреднеэтажное4 | B12: Прочие | C12: Среднеэтажное | D12: 4 | E12: 4 | F12: IV
A13: =CONCATENATE(B13,C13,D13) -> ПрочиеМногоэтажное4 | B13: Прочие | C13: Многоэтажное | D13: 4 | E13: 4 | F13: IV
... A61: =CONCATENATE(B61,C61,D61) -> ИЖСМногоэтажное5 | B61: ИЖС | C61: Многоэтажное | D61: 5 | E61: 4 | F61: IV

Sheet Промежуточный параметр
A1: кадастровый номер объекта | B1: материал стен | C1: min | D1: max
A2: 66:00:0000000:60518 | B2: Шлакобетонные | C2: 3 | D2: 3

Sheet Промежуточная табл 1

Sheet Промежуточная табл 2
A1: кадастровый номер объекта | B1: список кадастровых номеров машино-мест | C1: количество
A2: 66:51:0106004:304

Sheet Промежуточная табл 3
A1: кадастровый номер объекта | B1: список кадастровых номеров объектов содержащих текущий
A2: 1 | B2: 2

Sheet Промежуточная табл 4
A1: кадастровый номер объекта | B1: список кадастровых номеров помещений | C1: количество
A2: 66:51:0106004:304
