Workbook

Sheet расчеты
A1: Идентификатор | B1: Кадастровый номер | C1: Номер кадастрового квартала | D1: Площадь (ЦФ) | E1: Газоснабжение (ЦФ) | F1: Электроснабжение (ЦФ) | G1: Водоотведение (ЦФ) | H1: Теплоснабжение (ЦФ) | I1: Рыночная стоимость квартиры(ЦФ) | J1: Коэффициент плотности(ЦФ) | K1: Коэффициент типовых характеристик(ЦФ) | L1: Код населённого пункта | M1: Старый код НП | N1: Удельный показатель кадастровой стоимости(руб/м2) | O1: Кадастровая стоимость (руб) | P1: Кадастровая стоимость описание вых | Q1: Площадь в квадратных метрах | R1: Категория земель | S1: Наличие газоснабжения | T1: Наличие отопления | U1: Наличие электроснабжения | V1: Наличие водоотведения | W1: Номер заявления | X1: Тип заявления | Y1: Статус заявления | Z1: флажок | AA1: Дата пакета | AB1: Статус расчета | AC1: Дата комиссии | AD1: Решение комиссии | AE1: Флаг кода НП | AF1: Флаг ВРИ по документу | AG1: Флаг площади | AH1: Флаг ВРИ старый спр | AI1: Флаг ВРИ новый спр | AJ1: Флаг Категории ЗУ | AK1: Правило | AL1: Группа для XML | AM1: Особый контроль | AN1: Новоя модель | AO1: ВРИ по документу новое | AP1: Код расчета вида использования новый | AQ1: Код расчета вида использования текущий | AR1: ВРИ по документу старое | AS1: Суд | AT1: Дата заседания Суда | AU1: Повтор расчета по данным предудыщего расчета | BG1: Обязательная проверка | BK1: Расчет стоимости в рамках 16 статьи и факторы для загрузки в базу | CF1: Обновляем или формируем поле "Старое ВРИ" | CG1: Анализ | CQ1: 13. СЕГМЕНТ "Садоводство и огородничество, малоэтажная жилая застройка" | CR1: 2. СЕГМЕНТ "Жилая застройка (среднеэтажная и многоэтажная)"
A2: ID | B2: CadastralNumber | C2: CadastralBlock | D2: loc_factor_807 | E2: loc_factor_822 | F2: loc_factor_804 | G2: loc_factor_803 | H2: loc_factor_802 | I2: loc_factor_838 | J2: loc_factor_835 | K2: loc_factor_836 | L2: LocalityCode | M2: OldLocalityCode | N2: Specific_CadastralCost | O2: CadastralCost | P2: CadastralCostDesc | Q2: Area | R2: ParcelCategory | S2: PresenceGas | T2: PresenceHeating | U2: PresencePower | V2: PresenceWaterDisposal | W2: Statement | X2: Type_Statement | Y2: Status_Statement | Z2: Sp_flag | AA2: inputpacket_date | AB2: Status_kc | AC2: Date_comm | AD2: Sol_comm | AE2: FlagLocalityCode | AF2: Flag_VRI | AG2: FlagParam | AH2: Flag_VRIoldspr | AI2: Flag_VRInewspr | AJ2: Flag_Category | AK2: PraviloVRI | AL2: ID_Group | AM2: ControlSP | AN2: New_id_group | AO2: UtilizationByDoc | AP2: VRICode_NEW | AQ2: loc_VICode | AR2: Old_Utlbydoc | AS2: Court | AT2: Date_Court | BI2: CadastralNumber | BJ2: loc_factor_807 | BL2: loc_Factor_838 | BM2: loc_Factor_836 | BP2: loc_Factor_835 | BQ2: loc_Factor_802 | BS2: loc_Factor_804 | BU2: loc_Factor_803 | BW2: Specific_CadastralCost | BX2: CadastralCost | BY2: id_group | BZ2: CadastralCostDesc | CA2: Status_kc | CB2: loc_VICode | CC2: Segment | CD2: loc_SgCode | CE2: loc_GroupName | CF2: Old_Utlbydoc | CI2: Контроль текущего диапазона УПКС от 866 руб. до 17 260 руб. за 1 кв. м и значительного изменения стоимости (50 млн. руб) | CM2: Площадь не является ценообразующим фактором,но при ее изменении объект может попасть на перегруппировку | CQ2: 13 | CR2: 2
A3: Parcels | B3: Parcels | C3: Parcels | D3: Parcels | E3: Parcels | F3: Parcels | G3: Parcels | H3: Parcels | I3: Parcels | J3: Parcels | K3: Parcels | L3: Parcels | M3: Parcels | N3: Parcels | O3: Parcels | P3: Parcels | Q3: Parcels | R3: Parcels | S3: Parcels | T3: Parcels | U3: Parcels | V3: Parcels | W3: Parcels | X3: Parcels | Y3: Parcels | Z3: Parcels | AA3: Parcels | AB3: Parcels | AC3: Parcels | AD3: Parcels | AE3: Parcels | AF3: Parcels | AG3: Parcels | AH3: Parcels | AI3: Parcels | AJ3: Parcels | AK3: Parcels | AL3: Parcels | AM3: Parcels | AN3: Parcels | AO3: Parcels | AP3: Parcels | AQ3: Parcels | AR3: Parcels | AS3: Parcels | AT3: Parcels | AU3: УПКС рыночной стоимости квартиры | AV3: Коэффициент типовых характеристик | AW3: Поправка на Коэффициент типовых характеристик | AX3: Коэффициент плотности | AY3: Теплоснабжение | AZ3: Теплоснабжение | BA3: Электроснабжение | BB3: Электроснабжение | BC3: Водоотведение | BD3: Водоотведение | BE3: УПКС, руб. за 1 кв. М | BF3: КС, рублей | BG3: Верно, если расходждение менее 1,00 руб. Если расхождение более 1,00 -ценовые факторы подобраны неверно. Требуется анализ | BH3: Участие объекта на комиссии, в заявлениях, в судах и прочее | BI3: Кадастровый номер | BJ3: Площадь | BK3: Район,исходя из которого считается УПКС | BL3: УПКС рыночной стоимости квартиры | BM3: Коэффициент типовых характеристик | BN3: Поправка на Коэффициент типовых характеристик | BO3: Этажность в расчет (если ЦФ "Коэ-т плотности" не сформирован ранее) | BP3: Коэффициент плотности | BQ3: Теплоснабжение | BR3: Теплоснабжение | BS3: Электроснабжение | BT3: Электроснабжение | BU3: Водоотведение | BV3: Водоотведение | BW3: УПКС, руб. за 1 кв. М | BX3: КС, рублей | CA3: Статус расчета | CB3: ВРИ | CC3: Сегмент | CD3: Код сегмента | CE3: Расшифровка расчетной подгруппы | CF3: Ври по документу старое | CG3: Сравнение текущей стоимости от предыдущего расчета | CH3: Сравнение УПКС от предыдущего расчета | CI3: Проверка отклонения УПКС от текущего диапазона и контроль значительного изменения КС | CJ3: УПКС рыночной стоимости квартиры | CK3: Электроснабжение | CL3: Теплоснабжение | CM3: Площадь | CN3: Коэффициент плотности | CO3: Коэффициент типовых характеристик | CP3: Вид разрешенного использования | CQ3: Переход от РС квартиры к району (ВНИМАНИЕ, есть совпадения по РС квартиры!) | CR3: Проверка района
AU4: =I4 -> 0 | AV4: =K4 -> 0 | AW4: =VLOOKUP(AV4,коэф.модели!$F$6:$G$11,2,0) -> #N/A | AX4: =J4 -> 0 | AY4: =H4 -> 0 | AZ4: =IF(AY4="","ОШИБКА",VLOOKUP(AY4,коэф.модели!$F$12:$G$17,2,0)) -> #N/A | BA4: =F4 -> 0 | BB4: =IF(BA4="","ОШИБКА",VLOOKUP(BA4,коэф.модели!$F$12:$G$17,2,0)) -> #N/A | BC4: =G4 -> 0 | BD4: =IF(BC4="","ОШИБКА",VLOOKUP(BC4,коэф.модели!$F$12:$G$17,2,0)) -> #N/A | BE4: =ROUND(PRODUCT(AU4,AW4,AX4,AZ4,BD4,BB4),2) -> #N/A | BF4: =MROUND(BE4*D4,2) -> #N/A | BG4: =IF(N4="","Новый объект",IF(AN4=AL4,BF4-O4,"Объект пришел из другой модели")) -> Новый объект | BH4: =IF(AM4="",IF(AC4<>"","ОСПАРИВАНИЕ",IF(AS4<>"","СУД",IF(W4="","",W4))),AM4) | BI4: =B4 -> 0 | BJ4: =Q4 -> 0 | BK4: =IFERROR(IF(AP4="02:060",VLOOKUP(C4,'КК и удельник'!$A$3:$E$6521,2,0),IF(расчеты!AP4="02:050",VLOOKUP(расчеты!C4,'КК и удельник'!$A$3:$E$6521,2,0),IF(расчеты!AP4="02:014",VLOOKUP(расчеты!C4,'КК и удельник'!$A$3:$E$6521,2,0)))),IF(AP4="02:060",IF(M4="",VLOOKUP(L4,'КК и удельник'!$AG$3:$AK$1928,2,0),VLOOKUP(M4,'КК и удельник'!$AG$3:$AK$1928,2,0)),IF(расчеты!AP4="02:050",IF(M4="",VLOOKUP(расчеты!L4,'КК и удельник'!$AG$3:$AK$1928,2,0),VLOOKUP(расчеты!M4,'КК и удельник'!$AG$3:$AK$1928,2,0)),IF(расчеты!AP4="02:014",IF(M4="",VLOOKUP(расчеты!L4,'КК и удельник'!$AG$3:$AK$1928,2,0),VLOOKUP(расчеты!M4,'КК и удельник'!$AG$3:$AK$1928,2,0)),"ОШИБКА")))) -> FALSE | BL4: =IF(AQ4=AP4,I4,IFERROR(IF(AP4="02:060",VLOOKUP(C4,'КК и удельник'!$A$3:$E$6521,4,0),IF(расчеты!AP4="02:050",VLOOKUP(расчеты!C4,'КК и удельник'!$A$3:$E$6521,3,0),IF(расчеты!AP4="02:014",VLOOKUP(расчеты!C4,'КК и удельник'!$A$3:$E$6521,5,0)))),IF(AP4="02:060",IF(M4="",VLOOKUP(L4,'КК и удельник'!$AG$3:$AK$1928,4,0),VLOOKUP(M4,'КК и удельник'!$AG$3:$AK$1928,4,0)),IF(расчеты!AP4="02:050",IF(M4="",VLOOKUP(расчеты!L4,'КК и удельник'!$AG$3:$AK$1928,3,0),VLOOKUP(расчеты!M4,'КК и удельник'!$AG$3:$AK$1928,3,0)),IF(расчеты!AP4="02:014",IF(M4="",VLOOKUP(расчеты!L4,'КК и удельник'!$AG$3:$AK$1928,5,0),VLOOKUP(расчеты!M4,'КК и удельник'!$AG$3:$AK$1928,5,0))))))) -> 0 | BM4: =VLOOKUP(AP4,коэф.модели!$J$5:$K$7,2,0) -> #N/A | BN4: =VLOOKUP(BM4,коэф.модели!$F$6:$G$11,2,0) -> #N/A | BO4: =IF(M4="",IF(L4="47:004:1:1:1",IF(BM4="многоэтажный",9,VLOOKUP(BM4,коэф.модели!$K$5:$L$7,2,0)),VLOOKUP(BM4,коэф.модели!$K$5:$L$7,2,0)),IF(M4="47:004:1:1:1",IF(BM4="многоэтажный",9,VLOOKUP(BM4,коэф.модели!$K$5:$L$7,2,0)),VLOOKUP(BM4,коэф.модели!$K$5:$L$7,2,0))) -> #N/A | BP4: =IF(AQ4=AP4,J4,ROUND(0.6329*LN(BO4)+0.0442,4)) -> 0 | BQ4: =IF(AN4=AL4,IF(H4="отсутствие теплоснабжения","отсутствие теплоснабжения","наличие теплоснабжения"),"наличие теплоснабжения") -> наличие теплоснабжения | BR4: =VLOOKUP(BQ4,коэф.модели!$F$12:$G$17,2,0) -> 1 | BS4: =IF(AN4=AL4,IF(F4="отсутствие электроснабжения","отсутствие электроснабжения","наличие электроснабжения"),"наличие электроснабжения") -> наличие электроснабжения | BT4: =VLOOKUP(BS4,коэф.модели!$F$12:$G$17,2,0) -> 1 | BU4: =IF(AN4=AL4,IF(G4="отсутствие водоотведения","отсутствие водоотведения","наличие водоотведения"),"наличие водоотведения") -> наличие водоотведения | BV4: =VLOOKUP(BU4,коэф.модели!$F$12:$G$17,2,0) -> 1 | BW4: =ROUND(PRODUCT(BL4,BN4,BP4,BR4,BT4,BV4),2) -> #N/A | BX4: =ROUND(BW4*Q4,2) -> #N/A | BY4: =8002 -> 8002 | BZ4: СТ16_Ф1_М2_18052021_Бунаков | CA4: =IF(OR(BX4<0,BX4=0),"ОТРИЦАТЕЛЬНОЕ ЗНАЧЕНИЕ",IF(OR(CG4=0,CG4<1),"Пересчет не требуется","Готов")) -> #N/A | CB4: =AP4 -> 0 | CC4: =IF(CB4="02:014",$CQ$1,$CR$1) -> 2. СЕГМЕНТ "Жилая застройка (среднеэтажная и многоэтажная)" | CD4: =IF(CB4="02:014",$CQ$2,$CR$2) -> 2 | CE4: =VLOOKUP(CB4,'справочник ВРИ'!$A$3:$B$271,2,0) -> #N/A | CF4: =AO4 -> 0 | CG4: =IF(ISBLANK(N4),"Новый объект",IF(AL4=AN4,ABS(BX4-O4),"Объект из другой модели")) -> Новый объект | CH4: =IF(AN4=AL4,BW4-N4,IF(OR(BW4<866,BW4>17260),"Отклонение УПКС","УПКС объекта в допустимом интервале")) -> #N/A | CI4: =IF(CG4="Объект из другой модели",CG4,IF(CG4="Новый объект",CG4,IF(CG4>50000000,"Внимание!Изменение стоимости","Изменение менее 50 млн"))) -> Новый объект | CJ4: =IF(I4="","Новое значение",IF(I4=BL4,"Осталось предыдущее значение ЦФ","ИЗМЕНЕНИЕ")) -> Новое значение | CK4: =IF(F4="","Новое значение",IF(BS4=F4,"Осталось предыдущее значение ЦФ","ИЗМЕНЕНИЕ")) -> Новое значение | CL4: =IF(H4="","Новое значение",IF(BQ4=H4,"Осталось предыдущее значение ЦФ","ИЗМЕНЕНИЕ")) -> Новое значение | CM4: =IF(N4="","Объект новый",IF(AG4="не готов","ИЗМЕНЕНИЕ","Осталось предыдущее значение ЦФ")) -> Объект новый | CN4: =IF(J4="","Новое значение",IF(BP4=J4,"Осталось предыдущее значение ЦФ","ИЗМЕНЕНИЕ")) -> Новое значение | CO4: =IF(K4="","Новое значение",IF(BM4=K4,"Осталось предыдущее значение ЦФ","ИЗМЕНЕНИЕ")) -> Новое значение | CP4: =IF(AP4=AQ4,"Осталось предыдущее значение ЦФ","ИЗМЕНЕНИЕ") -> Осталось предыдущее значение ЦФ | CQ4: =IFERROR(IFERROR(IFERROR(VLOOKUP(BL4,'КК и удельник'!$E$3:$G$6521,3,0),VLOOKUP(BL4,'КК и удельник'!$D$3:$G$6521,4,0)),VLOOKUP(BL4,'КК и удельник'!$AI$3:$AL$1928,4,0)),VLOOKUP(BL4,'КК и удельник'!$AK$3:$AL$1928,2,0)) -> #N/A | CR4: =CQ4=BK4 -> #N/A
A5: 1644014 | B5: 66:41:0704041:7 | C5: 66:41:0000000 | D5: 4191 | F5: наличие электроснабжения | G5: наличие водоотведения | H5: наличие теплоснабжения | I5: 77071.443 | J5: 1.0628 | K5: среднеэтажный | L5: 47:004:1:1:1 | N5: 6806.85 | O5: 28527508 | P5: ППЗ_M2_Осипов | Q5: 3296 | R5: Земли населенных пунктов | S5: наличие | T5: наличие | U5: наличие | V5: наличие | Z5: 10 | AA5: 12.05.2021 | AB5: НЕ ГОТОВ | AE5: не готов | AF5: ГОТОВ | AG5: не готов | AH5: ГОТОВ | AI5: ГОТОВ | AJ5: ГОТОВ | AK5: Правило6 | AL5: 8002 | AN5: 8002 | AO5: земли жилой застройки (для жилищных нужд) | AP5: 02:050 | AQ5: 02:050 | AR5: земли жилой застройки (для жилищных нужд) | AU5: =I5 -> 77071.443 | AV5: =K5 -> среднеэтажный | AW5: =VLOOKUP(AV5,коэф.модели!$F$6:$G$11,2,0) -> 0.0831 | AX5: =J5 -> 1.0628 | AY5: =H5 -> наличие теплоснабжения | AZ5: =IF(AY5="","ОШИБКА",VLOOKUP(AY5,коэф.модели!$F$12:$G$17,2,0)) -> 1 | BA5: =F5 -> наличие электроснабжения | BB5: =IF(BA5="","ОШИБКА",VLOOKUP(BA5,коэф.модели!$F$12:$G$17,2,0)) -> 1 | BC5: =G5 -> наличие водоотведения | BD5: =IF(BC5="","ОШИБКА",VLOOKUP(BC5,коэф.модели!$F$12:$G$17,2,0)) -> 1 | BE5: =ROUND(PRODUCT(AU5,AW5,AX5,AZ5,BD5,BB5),2) -> 6806.85 | BF5: =MROUND(BE5*D5,2) -> 28527508 | BG5: =IF(N5="","Новый объект",IF(AN5=AL5,BF5-O5,"Объект пришел из другой модели")) -> 0 | BH5: =IF(AM5="",IF(AC5<>"","ОСПАРИВАНИЕ",IF(AS5<>"","СУД",IF(W5="","",W5))),AM5) | BI5: =B5 -> 66:41:0704041:7 | BJ5: =Q5 -> 3296 | BK5: =IFERROR(IF(AP5="02:060",VLOOKUP(C5,'КК и удельник'!$A$3:$E$6521,2,0),IF(расчеты!AP5="02:050",VLOOKUP(расчеты!C5,'КК и удельник'!$A$3:$E$6521,2,0),IF(расчеты!AP5="02:014",VLOOKUP(расчеты!C5,'КК и удельник'!$A$3:$E$6521,2,0)))),IF(AP5="02:060",IF(M5="",VLOOKUP(L5,'КК и удельник'!$AG$3:$AK$1928,2,0),VLOOKUP(M5,'КК и удельник'!$AG$3:$AK$1928,2,0)),IF(расчеты!AP5="02:050",IF(M5="",VLOOKUP(расчеты!L5,'КК и удельник'!$AG$3:$AK$1928,2,0),VLOOKUP(расчеты!M5,'КК и удельник'!$AG$3:$AK$1928,2,0)),IF(расчеты!AP5="02:014",IF(M5="",VLOOKUP(расчеты!L5,'КК и удельник'!$AG$3:$AK$1928,2,0),VLOOKUP(расчеты!M5,'КК и удельник'!$AG$3:$AK$1928,2,0)),"ОШИБКА")))) -> АКАДЕМИЧЕСКИЙ | BL5: =IF(AQ5=AP5,I5,IFERROR(IF(AP5="02:060",VLOOKUP(C5,'КК и удельник'!$A$3:$E$6521,4,0),IF(расчеты!AP5="02:050",VLOOKUP(расчеты!C5,'КК и удельник'!$A$3:$E$6521,3,0),IF(расчеты!AP5="02:014",VLOOKUP(расчеты!C5,'КК и удельник'!$A$3:$E$6521,5,0)))),IF(AP5="02:060",IF(M5="",VLOOKUP(L5,'КК и удельник'!$AG$3:$AK$1928,4,0),VLOOKUP(M5,'КК и удельник'!$AG$3:$AK$1928,4,0)),IF(расчеты!AP5="02:050",IF(M5="",VLOOKUP(расчеты!L5,'КК и удельник'!$AG$3:$AK$1928,3,0),VLOOKUP(расчеты!M5,'КК и удельник'!$AG$3:$AK$1928,3,0)),IF(расчеты!AP5="02:014",IF(M5="",VLOOKUP(расчеты!L5,'КК и удельник'!$AG$3:$AK$1928,5,0),VLOOKUP(расчеты!M5,'КК и удельник'!$AG$3:$AK$1928,5,0))))))) -> 77071.443 | BM5: =VLOOKUP(AP5,коэф.модели!$J$5:$K$7,2,0) -> среднеэтажный | BN5: =VLOOKUP(BM5,коэф.модели!$F$6:$G$11,2,0) -> 0.0831 | BO5: =IF(M5="",IF(L5="47:004:1:1:1",IF(BM5="многоэтажный",9,VLOOKUP(BM5,коэф.модели!$K$5:$L$7,2,0)),VLOOKUP(BM5,коэф.модели!$K$5:$L$7,2,0)),IF(M5="47:004:1:1:1",IF(BM5="многоэтажный",9,VLOOKUP(BM5,коэф.модели!$K$5:$L$7,2,0)),VLOOKUP(BM5,коэф.модели!$K$5:$L$7,2,0))) -> 5 | BP5: =IF(AQ5=AP5,J5,ROUND(0.6329*LN(BO5)+0.0442,4)) -> 1.0628 | BQ5: =IF(AN5=AL5,IF(H5="отсутствие теплоснабжения","отсутствие теплоснабжения","наличие теплоснабжения"),"наличие теплоснабжения") -> наличие теплоснабжения | BR5: =VLOOKUP(BQ5,коэф.модели!$F$12:$G$17,2,0) -> 1 | BS5: =IF(AN5=AL5,IF(F5="отсутствие электроснабжения","отсутствие электроснабжения","наличие электроснабжения"),"наличие электроснабжения") -> наличие электроснабжения | BT5: =VLOOKUP(BS5,коэф.модели!$F$12:$G$17,2,0) -> 1 | BU5: =IF(AN5=AL5,IF(G5="отсутствие водоотведения","отсутствие водоотведения","наличие водоотведения"),"наличие водоотведения") -> наличие водоотведения | BV5: =VLOOKUP(BU5,коэф.модели!$F$12:$G$17,2,0) -> 1 | BW5: =ROUND(PRODUCT(BL5,BN5,BP5,BR5,BT5,BV5),2) -> 6806.85 | BX5: =ROUND(BW5*Q5,2) -> 22435378 | BY5: =8002 -> 8002 | BZ5: СТ16_Ф1_М2_18052021_Бунаков | CA5: =IF(OR(BX5<0,BX5=0),"ОТРИЦАТЕЛЬНОЕ ЗНАЧЕНИЕ",IF(OR(CG5=0,CG5<1),"Пересчет не требуется","Готов")) -> Готов | CB5: =AP5 -> 02:050 | CC5: =IF(CB5="02:014",$CQ$1,$CR$1) -> 2. СЕГМЕНТ "Жилая застройка (среднеэтажная и многоэтажная)" | CD5: =IF(CB5="02:014",$CQ$2,$CR$2) -> 2 | CE5: =VLOOKUP(CB5,'справочник ВРИ'!$A$3:$B$271,2,0) -> Среднеэтажная жилая застройка в целом | CF5: =AO5 -> земли жилой застройки (для жилищных нужд) | CG5: =IF(ISBLANK(N5),"Новый объект",IF(AL5=AN5,ABS(BX5-O5),"Объект из другой модели")) -> 6092130.4 | CH5: =IF(AN5=AL5,BW5-N5,IF(OR(BW5<866,BW5>17260),"Отклонение УПКС","УПКС объекта в допустимом интервале")) -> 0 | CI5: =IF(CG5="Объект из другой модели",CG5,IF(CG5="Новый объект",CG5,IF(CG5>50000000,"Внимание!Изменение стоимости","Изменение менее 50 млн"))) -> Изменение менее 50 млн | CJ5: =IF(I5="","Новое значение",IF(I5=BL5,"Осталось предыдущее значение ЦФ","ИЗМЕНЕНИЕ")) -> Осталось предыдущее значение ЦФ | CK5: =IF(F5="","Новое значение",IF(BS5=F5,"Осталось предыдущее значение ЦФ","ИЗМЕНЕНИЕ")) -> Осталось предыдущее значение ЦФ | CL5: =IF(H5="","Новое значение",IF(BQ5=H5,"Осталось предыдущее значение ЦФ","ИЗМЕНЕНИЕ")) -> Осталось предыдущее значение ЦФ | CM5: =IF(N5="","Объект новый",IF(AG5="не готов","ИЗМЕНЕНИЕ","Осталось предыдущее значение ЦФ")) -> ИЗМЕНЕНИЕ | CN5: =IF(J5="","Новое значение",IF(BP5=J5,"Осталось предыдущее значение ЦФ","ИЗМЕНЕНИЕ")) -> Осталось предыдущее значение ЦФ | CO5: =IF(K5="","Новое значение",IF(BM5=K5,"Осталось предыдущее значение ЦФ","ИЗМЕНЕНИЕ")) -> Осталось предыдущее значение ЦФ | CP5: =IF(AP5=AQ5,"Осталось предыдущее значение ЦФ","ИЗМЕНЕНИЕ") -> Осталось предыдущее значение ЦФ | CQ5: =IFERROR(IFERROR(IFERROR(VLOOKUP(BL5,'КК и удельник'!$E$3:$G$6521,3,0),VLOOKUP(BL5,'КК и удельник'!$D$3:$G$6521,4,0)),VLOOKUP(BL5,'КК и удельник'!$AI$3:$AL$1928,4,0)),VLOOKUP(BL5,'КК и удельник'!$AK$3:$AL$1928,2,0)) -> ВТУЗГОРОДОК | CR5: =CQ5=BK5 -> FALSE
A6: Select ID,Source_ID,CadastralNumber,DateCreated,CadastralBlock,Name,ObjectType,Area,AreaUnit,AreaInaccuracy,LocationinBounds,LocationPlaced,ElaborationReferenceMark,ElaborationDistance,ElaborationDirection,AddressOrLocation,FIAS,OKATO,KLADR,OKTMO,PostalCode,AddressRF,Region,DistrictName,DistrictType,CityName,CityType,UrbanDistrictName,UrbanDistrictType,SovietVillageName,SovietVillageType,LocalityName,LocalityType,PlanningElementName,PlanningElementType,StreetName,StreetType,Level1Type,Level1Value,Level2Type,Level2Value,Level3Type,Level3Value,ApartmentType,ApartmentValue,AddressOther,AddressNote,ParcelCategory,Utilization,UtilizationByDoc,UtilizationLandUse,UtilizationТхт,CostValue,CostUnit,CostDateValuation,CostDateEntering,CostDateApproval,CostDocNumber,CostDocDate,CostApplicationDate,CostRevisalStatementDate,CostApplicationLastDate,CostDocName,FacilityKN,FacilityKNPurpose,SurveyProjectNum,DecisionCodeDocument,DecisionName,DecisionSeries,DecisionNumber,DecisionDate,DecisionIssueOrgan,DecisionDesc,HiredHouseUse,HouseActBuilding,HouseActDevelopment,BuildingContractName,DevelopContractName,OwnerDecision,SupportContractName,CodeDocument,DocHiredHouseName,DocHiredHouseSeries,DocHiredHouseNumber,DocHiredHouseDate,DocHiredHouseIssueOrgan,DocHiredHouseDesc,LimitedRightNumber,CREATEOPERATORNAME,CREATEDATE,OPERATORNAME,MODIFYDATE,MI_STYLE,Specific_CadastralCost,CadastralCost,CadastralCostDesc,MO_Name,ID_Group,LocalityCode,locTypeUse2,loc_VICode,loc_GroupName,loc_VRICode,Sourse_loc_VICode,locTypeUse,inputpacket_id,loc_SgCode,VIP_Sp,Quant_Kontur,Quant_Point,Sum_Square,Sum_Perim,Proc_Diff_Square,Pr_Diff,Source_Sum_Square,SourceLocalityCode,Upload_Scroll,Date_KC,Segment,FlagLocalityCode,DistanceToRoad,DistanceToCMO,СМО,PresenceGas,SourcePresenceGas,PresenceHeating,SourcePresenceHeating,PresencePower,SourcePresencePower,PresenceWaterDisposal,SourcePresenceWaterDisposal,PresenceWaterSupply,SourcePresenceWaterSupply,DistanceToEKB,DistanceToRoadEKB,CCoordX,CCoordY,DistanceToMetro,DistanceToStationEKB,CostZone,DistanceToRRStation,costzone2,Textloc_VICode,act_sign,MaxFloor,Enc_squre,Enc_proc,Adm_rn_EKB,forestry,InfluenceZone_IGS,loc_factor_801,loc_factor_802,loc_factor_803,loc_factor_804,loc_factor_806,loc_factor_807,loc_factor_8071,loc_factor_809,loc_factor_8091,loc_factor_810,loc_factor_8101,loc_factor_811,loc_factor_8111,loc_factor_812,loc_factor_8121,loc_factor_813,loc_factor_814,loc_factor_815,loc_factor_816,loc_factor_8161,loc_factor_817,loc_factor_818,loc_factor_819,loc_factor_820,loc_factor_8201,loc_factor_821,loc_factor_822,loc_factor_823,loc_factor_8231,loc_factor_824,loc_factor_825,loc_factor_826,loc_factor_827,loc_factor_828,loc_factor_829,loc_factor_830,loc_factor_831,loc_factor_832,loc_factor_833,loc_factor_8331,loc_factor_835,loc_factor_836,loc_factor_837,loc_factor_838,Statement,Type_Statement,Status_Statement,DistanceToVZC,VRI_IGS,Cot_name,DistanceToZTB,PowerLines,loc_factor_839,KodMO,loc_factor_840,loc_factor_841,presence_entrance,loc_factor_8371,ControlSP,Sp_flag,loc_VRICode540,Status_kc,Date_comm,Sol_comm,Flag_LocalityCode,Flag_VRI,Flag_Location,FlagParam,Flag_VRIoldspr,Flag_VRInewspr,Flag_Category,OldLocalityCode,Flag_VRI_All,VRICode_NEW,PraviloVRI,New_id_group,New_loc_SgCode,New_Segment,Old_Utlbydoc,VRICode_OLD,PraviloVRI_old,Court,Date_Court,Sol_Court,(select (case count(*) when 0 then 0 else 1 end) from GEO.docboxes b where b.obj_id=PARCELS.ID and b.table_id=265) Attachment,(select sign(Count(*)) from PARCELS g where (not GEOM_OBJ is null) and (PARCELS.ID = g.ID)) GeometryExists,((select DatePacket from inputpacket where id=Parcels.inputpacket_id) ) [inputpacket_date] From PARCELS WHERE status_kc = 'НЕ ГОТОВ' AND New_id_group=8002 | AU6: =I6 -> 0 | AV6: =K6 -> 0 | AW6: =VLOOKUP(AV6,коэф.модели!$F$6:$G$11,2,0) -> #N/A | AX6: =J6 -> 0 | AY6: =H6 -> 0 | AZ6: =IF(AY6="","ОШИБКА",VLOOKUP(AY6,коэф.модели!$F$12:$G$17,2,0)) -> #N/A | BA6: =F6 -> 0 | BB6: =IF(BA6="","ОШИБКА",VLOOKUP(BA6,коэф.модели!$F$12:$G$17,2,0)) -> #N/A | BC6: =G6 -> 0 | BD6: =IF(BC6="","ОШИБКА",VLOOKUP(BC6,коэф.модели!$F$12:$G$17,2,0)) -> #N/A | BE6: =ROUND(PRODUCT(AU6,AW6,AX6,AZ6,BD6,BB6),2) -> #N/A | BF6: =MROUND(BE6*D6,2) -> #N/A | BG6: =IF(N6="","Новый объект",IF(AN6=AL6,BF6-O6,"Объект пришел из другой модели")) -> Новый объект | BH6: =IF(AM6="",IF(AC6<>"","ОСПАРИВАНИЕ",IF(AS6<>"","СУД",IF(W6="","",W6))),AM6) | BI6: =B6 -> 0 | BJ6: =Q6 -> 0 | BK6: =IFERROR(IF(AP6="02:060",VLOOKUP(C6,'КК и удельник'!$A$3:$E$6521,2,0),IF(расчеты!AP6="02:050",VLOOKUP(расчеты!C6,'КК и удельник'!$A$3:$E$6521,2,0),IF(расчеты!AP6="02:014",VLOOKUP(расчеты!C6,'КК и удельник'!$A$3:$E$6521,2,0)))),IF(AP6="02:060",IF(M6="",VLOOKUP(L6,'КК и удельник'!$AG$3:$AK$1928,2,0),VLOOKUP(M6,'КК и удельник'!$AG$3:$AK$1928,2,0)),IF(расчеты!AP6="02:050",IF(M6="",VLOOKUP(расчеты!L6,'КК и удельник'!$AG$3:$AK$1928,2,0),VLOOKUP(расчеты!M6,'КК и удельник'!$AG$3:$AK$1928,2,0)),IF(расчеты!AP6="02:014",IF(M6="",VLOOKUP(расчеты!L6,'КК и удельник'!$AG$3:$AK$1928,2,0),VLOOKUP(расчеты!M6,'КК и удельник'!$AG$3:$AK$1928,2,0)),"ОШИБКА")))) -> FALSE | BL6: =IF(AQ6=AP6,I6,IFERROR(IF(AP6="02:060",VLOOKUP(C6,'КК и удельник'!$A$3:$E$6521,4,0),IF(расчеты!AP6="02:050",VLOOKUP(расчеты!C6,'КК и удельник'!$A$3:$E$6521,3,0),IF(расчеты!AP6="02:014",VLOOKUP(расчеты!C6,'КК и удельник'!$A$3:$E$6521,5,0)))),IF(AP6="02:060",IF(M6="",VLOOKUP(L6,'КК и удельник'!$AG$3:$AK$1928,4,0),VLOOKUP(M6,'КК и удельник'!$AG$3:$AK$1928,4,0)),IF(расчеты!AP6="02:050",IF(M6="",VLOOKUP(расчеты!L6,'КК и удельник'!$AG$3:$AK$1928,3,0),VLOOKUP(расчеты!M6,'КК и удельник'!$AG$3:$AK$1928,3,0)),IF(расчеты!AP6="02:014",IF(M6="",VLOOKUP(расчеты!L6,'КК и удельник'!$AG$3:$AK$1928,5,0),VLOOKUP(расчеты!M6,'КК и удельник'!$AG$3:$AK$1928,5,0))))))) -> 0 | BM6: =VLOOKUP(AP6,коэф.модели!$J$5:$K$7,2,0) -> #N/A | BN6: =VLOOKUP(BM6,коэф.модели!$F$6:$G$11,2,0) -> #N/A | BO6: =IF(M6="",IF(L6="47:004:1:1:1",IF(BM6="многоэтажный",9,VLOOKUP(BM6,коэф.модели!$K$5:$L$7,2,0)),VLOOKUP(BM6,коэф.модели!$K$5:$L$7,2,0)),IF(M6="47:004:1:1:1",IF(BM6="многоэтажный",9,VLOOKUP(BM6,коэф.модели!$K$5:$L$7,2,0)),VLOOKUP(BM6,коэф.модели!$K$5:$L$7,2,0))) -> #N/A | BP6: =IF(AQ6=AP6,J6,ROUND(0.6329*LN(BO6)+0.0442,4)) -> 0 | BQ6: =IF(AN6=AL6,IF(H6="отсутствие теплоснабжения","отсутствие теплоснабжения","наличие теплоснабжения"),"наличие теплоснабжения") -> наличие теплоснабжения | BR6: =VLOOKUP(BQ6,коэф.модели!$F$12:$G$17,2,0) -> 1 | BS6: =IF(AN6=AL6,IF(F6="отсутствие электроснабжения","отсутствие электроснабжения","наличие электроснабжения"),"наличие электроснабжения") -> наличие электроснабжения | BT6: =VLOOKUP(BS6,коэф.модели!$F$12:$G$17,2,0) -> 1 | BU6: =IF(AN6=AL6,IF(G6="отсутствие водоотведения","отсутствие водоотведения","наличие водоотведения"),"наличие водоотведения") -> наличие водоотведения | BV6: =VLOOKUP(BU6,коэф.модели!$F$12:$G$17,2,0) -> 1 | BW6: =ROUND(PRODUCT(BL6,BN6,BP6,BR6,BT6,BV6),2) -> #N/A | BX6: =ROUND(BW6*Q6,2) -> #N/A | BY6: =8002 -> 8002 | BZ6: СТ16_Ф1_М2_18052021_Бунаков | CA6: =IF(OR(BX6<0,BX6=0),"ОТРИЦАТЕЛЬНОЕ ЗНАЧЕНИЕ",IF(OR(CG6=0,CG6<1),"Пересчет не требуется","Готов")) -> #N/A | CB6: =AP6 -> 0 | CC6: =IF(CB6="02:014",$CQ$1,$CR$1) -> 2. СЕГМЕНТ "Жилая застройка (среднеэтажная и многоэтажная)" | CD6: =IF(CB6="02:014",$CQ$2,$CR$2) -> 2 | CE6: =VLOOKUP(CB6,'справочник ВРИ'!$A$3:$B$271,2,0) -> #N/A | CF6: =AO6 -> 0 | CG6: =IF(ISBLANK(N6),"Новый объект",IF(AL6=AN6,ABS(BX6-O6),"Объект из другой модели")) -> Новый объект | CH6: =IF(AN6=AL6,BW6-N6,IF(OR(BW6<866,BW6>17260),"Отклонение УПКС","УПКС объекта в допустимом интервале")) -> #N/A | CI6: =IF(CG6="Объект из другой модели",CG6,IF(CG6="Новый объект",CG6,IF(CG6>50000000,"Внимание!Изменение стоимости","Изменение менее 50 млн"))) -> Новый объект | CJ6: =IF(I6="","Новое значение",IF(I6=BL6,"Осталось предыдущее значение ЦФ","ИЗМЕНЕНИЕ")) -> Новое значение | CK6: =IF(F6="","Новое значение",IF(BS6=F6,"Осталось предыдущее значение ЦФ","ИЗМЕНЕНИЕ")) -> Новое значение | CL6: =IF(H6="","Новое значение",IF(BQ6=H6,"Осталось предыдущее значение ЦФ","ИЗМЕНЕНИЕ")) -> Новое значение | CM6: =IF(N6="","Объект новый",IF(AG6="не готов","ИЗМЕНЕНИЕ","Осталось предыдущее значение ЦФ")) -> Объект новый | CN6: =IF(J6="","Новое значение",IF(BP6=J6,"Осталось предыдущее значение ЦФ","ИЗМЕНЕНИЕ")) -> Новое значение | CO6: =IF(K6="","Новое значение",IF(BM6=K6,"Осталось предыдущее значение ЦФ","ИЗМЕНЕНИЕ")) -> Новое значение | CP6: =IF(AP6=AQ6,"Осталось предыдущее значение ЦФ","ИЗМЕНЕНИЕ") -> Осталось предыдущее значение ЦФ | CQ6: =IFERROR(IFERROR(IFERROR(VLOOKUP(BL6,'КК и удельник'!$E$3:$G$6521,3,0),VLOOKUP(BL6,'КК и удельник'!$D$3:$G$6521,4,0)),VLOOKUP(BL6,'КК и удельник'!$AI$3:$AL$1928,4,0)),VLOOKUP(BL6,'КК и удельник'!$AK$3:$AL$1928,2,0)) -> #N/A | CR6: =CQ6=BK6 -> #N/A
AU7: =I7 -> 0 | AV7: =K7 -> 0 | AW7: =VLOOKUP(AV7,коэф.модели!$F$6:$G$11,2,0) -> #N/A | AX7: =J7 -> 0 | AY7: =H7 -> 0 | AZ7: =IF(AY7="","ОШИБКА",VLOOKUP(AY7,коэф.модели!$F$12:$G$17,2,0)) -> #N/A | BA7: =F7 -> 0 | BB7: =IF(BA7="","ОШИБКА",VLOOKUP(BA7,коэф.модели!$F$12:$G$17,2,0)) -> #N/A | BC7: =G7 -> 0 | BD7: =IF(BC7="","ОШИБКА",VLOOKUP(BC7,коэф.модели!$F$12:$G$17,2,0)) -> #N/A | BE7: =ROUND(PRODUCT(AU7,AW7,AX7,AZ7,BD7,BB7),2) -> #N/A | BF7: =MROUND(BE7*D7,2) -> #N/A | BG7: =IF(N7="","Новый объект",IF(AN7=AL7,BF7-O7,"Объект пришел из другой модели")) -> Новый объект | BH7: =IF(AM7="",IF(AC7<>"","ОСПАРИВАНИЕ",IF(AS7<>"","СУД",IF(W7="","",W7))),AM7) | BI7: =B7 -> 0 | BJ7: =Q7 -> 0 | BK7: =IFERROR(IF(AP7="02:060",VLOOKUP(C7,'КК и удельник'!$A$3:$E$6521,2,0),IF(расчеты!AP7="02:050",VLOOKUP(расчеты!C7,'КК и удельник'!$A$3:$E$6521,2,0),IF(расчеты!AP7="02:014",VLOOKUP(расчеты!C7,'КК и удельник'!$A$3:$E$6521,2,0)))),IF(AP7="02:060",IF(M7="",VLOOKUP(L7,'КК и удельник'!$AG$3:$AK$1928,2,0),VLOOKUP(M7,'КК и удельник'!$AG$3:$AK$1928,2,0)),IF(расчеты!AP7="02:050",IF(M7="",VLOOKUP(расчеты!L7,'КК и удельник'!$AG$3:$AK$1928,2,0),VLOOKUP(расчеты!M7,'КК и удельник'!$AG$3:$AK$1928,2,0)),IF(расчеты!AP7="02:014",IF(M7="",VLOOKUP(расчеты!L7,'КК и удельник'!$AG$3:$AK$1928,2,0),VLOOKUP(расчеты!M7,'КК и удельник'!$AG$3:$AK$1928,2,0)),"ОШИБКА")))) -> FALSE | BL7: =IF(AQ7=AP7,I7,IFERROR(IF(AP7="02:060",VLOOKUP(C7,'КК и удельник'!$A$3:$E$6521,4,0),IF(расчеты!AP7="02:050",VLOOKUP(расчеты!C7,'КК и удельник'!$A$3:$E$6521,3,0),IF(расчеты!AP7="02:014",VLOOKUP(расчеты!C7,'КК и удельник'!$A$3:$E$6521,5,0)))),IF(AP7="02:060",IF(M7="",VLOOKUP(L7,'КК и удельник'!$AG$3:$AK$1928,4,0),VLOOKUP(M7,'КК и удельник'!$AG$3:$AK$1928,4,0)),IF(расчеты!AP7="02:050",IF(M7="",VLOOKUP(расчеты!L7,'КК и удельник'!$AG$3:$AK$1928,3,0),VLOOKUP(расчеты!M7,'КК и удельник'!$AG$3:$AK$1928,3,0)),IF(расчеты!AP7="02:014",IF(M7="",VLOOKUP(расчеты!L7,'КК и удельник'!$AG$3:$AK$1928,5,0),VLOOKUP(расчеты!M7,'КК и удельник'!$AG$3:$AK$1928,5,0))))))) -> 0 | BM7: =VLOOKUP(AP7,коэф.модели!$J$5:$K$7,2,0) -> #N/A | BN7: =VLOOKUP(BM7,коэф.модели!$F$6:$G$11,2,0) -> #N/A | BO7: =IF(M7="",IF(L7="47:004:1:1:1",IF(BM7="многоэтажный",9,VLOOKUP(BM7,коэф.модели!$K$5:$L$7,2,0)),VLOOKUP(BM7,коэф.модели!$K$5:$L$7,2,0)),IF(M7="47:004:1:1:1",IF(BM7="многоэтажный",9,VLOOKUP(BM7,коэф.модели!$K$5:$L$7,2,0)),VLOOKUP(BM7,коэф.модели!$K$5:$L$7,2,0))) -> #N/A | BP7: =IF(AQ7=AP7,J7,ROUND(0.6329*LN(BO7)+0.0442,4)) -> 0 | BQ7: =IF(AN7=AL7,IF(H7="отсутствие теплоснабжения","отсутствие теплоснабжения","наличие теплоснабжения"),"наличие теплоснабжения") -> наличие теплоснабжения | BR7: =VLOOKUP(BQ7,коэф.модели!$F$12:$G$17,2,0) -> 1 | BS7: =IF(AN7=AL7,IF(F7="отсутствие электроснабжения","отсутствие электроснабжения","наличие электроснабжения"),"наличие электроснабжения") -> наличие электроснабжения | BT7: =VLOOKUP(BS7,коэф.модели!$F$12:$G$17,2,0) -> 1 | BU7: =IF(AN7=AL7,IF(G7="отсутствие водоотведения","отсутствие водоотведения","наличие водоотведения"),"наличие водоотведения") -> наличие водоотведения | BV7: =VLOOKUP(BU7,коэф.модели!$F$12:$G$17,2,0) -> 1 | BW7: =ROUND(PRODUCT(BL7,BN7,BP7,BR7,BT7,BV7),2) -> #N/A | BX7: =ROUND(BW7*Q7,2) -> #N/A | BY7: =8002 -> 8002 | BZ7: СТ16_Ф1_М2_18052021_Бунаков | CA7: =IF(OR(BX7<0,BX7=0),"ОТРИЦАТЕЛЬНОЕ ЗНАЧЕНИЕ",IF(OR(CG7=0,CG7<1),"Пересчет не требуется","Готов")) -> #N/A | CB7: =AP7 -> 0 | CC7: =IF(CB7="02:014",$CQ$1,$CR$1) -> 2. СЕГМЕНТ "Жилая застройка (среднеэтажная и многоэтажная)" | CD7: =IF(CB7="02:014",$CQ$2,$CR$2) -> 2 | CE7: =VLOOKUP(CB7,'справочник ВРИ'!$A$3:$B$271,2,0) -> #N/A | CF7: =AO7 -> 0 | CG7: =IF(ISBLANK(N7),"Новый объект",IF(AL7=AN7,ABS(BX7-O7),"Объект из другой модели")) -> Новый объект | CH7: =IF(AN7=AL7,BW7-N7,IF(OR(BW7<866,BW7>17260),"Отклонение УПКС","УПКС объекта в допустимом интервале")) -> #N/A | CI7: =IF(CG7="Объект из другой модели",CG7,IF(CG7="Новый объект",CG7,IF(CG7>50000000,"Внимание!Изменение стоимости","Изменение менее 50 млн"))) -> Новый объект | CJ7: =IF(I7="","Новое значение",IF(I7=BL7,"Осталось предыдущее значение ЦФ","ИЗМЕНЕНИЕ")) -> Новое значение | CK7: =IF(F7="","Новое значение",IF(BS7=F7,"Осталось предыдущее значение ЦФ","ИЗМЕНЕНИЕ")) -> Новое значение | CL7: =IF(H7="","Новое значение",IF(BQ7=H7,"Осталось предыдущее значение ЦФ","ИЗМЕНЕНИЕ")) -> Новое значение | CM7: =IF(N7="","Объект новый",IF(AG7="не готов","ИЗМЕНЕНИЕ","Осталось предыдущее значение ЦФ")) -> Объект новый | CN7: =IF(J7="","Новое значение",IF(BP7=J7,"Осталось предыдущее значение ЦФ","ИЗМЕНЕНИЕ")) -> Новое значение | CO7: =IF(K7="","Новое значение",IF(BM7=K7,"Осталось предыдущее значение ЦФ","ИЗМЕНЕНИЕ")) -> Новое значение | CP7: =IF(AP7=AQ7,"Осталось предыдущее значение ЦФ","ИЗМЕНЕНИЕ") -> Осталось предыдущее значение ЦФ | CQ7: =IFERROR(IFERROR(IFERROR(VLOOKUP(BL7,'КК и удельник'!$E$3:$G$6521,3,0),VLOOKUP(BL7,'КК и удельник'!$D$3:$G$6521,4,0)),VLOOKUP(BL7,'КК и удельник'!$AI$3:$AL$1928,4,0)),VLOOKUP(BL7,'КК и удельник'!$AK$3:$AL$1928,2,0)) -> #N/A | CR7: =CQ7=BK7 -> #N/A
AU8: =I8 -> 0 | AV8: =K8 -> 0 | AW8: =VLOOKUP(AV8,коэф.модели!$F$6:$G$11,2,0) -> #N/A | AX8: =J8 -> 0 | AY8: =H8 -> 0 | AZ8: =IF(AY8="","ОШИБКА",VLOOKUP(AY8,коэф.модели!$F$12:$G$17,2,0)) -> #N/A | BA8: =F8 -> 0 | BB8: =IF(BA8="","ОШИБКА",VLOOKUP(BA8,коэф.модели!$F$12:$G$17,2,0)) -> #N/A | BC8: =G8 -> 0 | BD8: =IF(BC8="","ОШИБКА",VLOOKUP(BC8,коэф.модели!$F$12:$G$17,2,0)) -> #N/A | BE8: =ROUND(PRODUCT(AU8,AW8,AX8,AZ8,BD8,BB8),2) -> #N/A | BF8: =MROUND(BE8*D8,2) -> #N/A | BG8: =IF(N8="","Новый объект",IF(AN8=AL8,BF8-O8,"Объект пришел из другой модели")) -> Новый объект | BH8: =IF(AM8="",IF(AC8<>"","ОСПАРИВАНИЕ",IF(AS8<>"","СУД",IF(W8="","",W8))),AM8) | BI8: =B8 -> 0 | BJ8: =Q8 -> 0 | BK8: =IFERROR(IF(AP8="02:060",VLOOKUP(C8,'КК и удельник'!$A$3:$E$6521,2,0),IF(расчеты!AP8="02:050",VLOOKUP(расчеты!C8,'КК и удельник'!$A$3:$E$6521,2,0),IF(расчеты!AP8="02:014",VLOOKUP(расчеты!C8,'КК и удельник'!$A$3:$E$6521,2,0)))),IF(AP8="02:060",IF(M8="",VLOOKUP(L8,'КК и удельник'!$AG$3:$AK$1928,2,0),VLOOKUP(M8,'КК и удельник'!$AG$3:$AK$1928,2,0)),IF(расчеты!AP8="02:050",IF(M8="",VLOOKUP(расчеты!L8,'КК и удельник'!$AG$3:$AK$1928,2,0),VLOOKUP(расчеты!M8,'КК и удельник'!$AG$3:$AK$1928,2,0)),IF(расчеты!AP8="02:014",IF(M8="",VLOOKUP(расчеты!L8,'КК и удельник'!$AG$3:$AK$1928,2,0),VLOOKUP(расчеты!M8,'КК и удельник'!$AG$3:$AK$1928,2,0)),"ОШИБКА")))) -> FALSE | BL8: =IF(AQ8=AP8,I8,IFERROR(IF(AP8="02:060",VLOOKUP(C8,'КК и удельник'!$A$3:$E$6521,4,0),IF(расчеты!AP8="02:050",VLOOKUP(расчеты!C8,'КК и удельник'!$A$3:$E$6521,3,0),IF(расчеты!AP8="02:014",VLOOKUP(расчеты!C8,'КК и удельник'!$A$3:$E$6521,5,0)))),IF(AP8="02:060",IF(M8="",VLOOKUP(L8,'КК и удельник'!$AG$3:$AK$1928,4,0),VLOOKUP(M8,'КК и удельник'!$AG$3:$AK$1928,4,0)),IF(расчеты!AP8="02:050",IF(M8="",VLOOKUP(расчеты!L8,'КК и удельник'!$AG$3:$AK$1928,3,0),VLOOKUP(расчеты!M8,'КК и удельник'!$AG$3:$AK$1928,3,0)),IF(расчеты!AP8="02:014",IF(M8="",VLOOKUP(расчеты!L8,'КК и удельник'!$AG$3:$AK$1928,5,0),VLOOKUP(расчеты!M8,'КК и удельник'!$AG$3:$AK$1928,5,0))))))) -> 0 | BM8: =VLOOKUP(AP8,коэф.модели!$J$5:$K$7,2,0) -> #N/A | BN8: =VLOOKUP(BM8,коэф.модели!$F$6:$G$11,2,0) -> #N/A | BO8: =IF(M8="",IF(L8="47:004:1:1:1",IF(BM8="многоэтажный",9,VLOOKUP(BM8,коэф.модели!$K$5:$L$7,2,0)),VLOOKUP(BM8,коэф.модели!$K$5:$L$7,2,0)),IF(M8="47:004:1:1:1",IF(BM8="многоэтажный",9,VLOOKUP(BM8,коэф.модели!$K$5:$L$7,2,0)),VLOOKUP(BM8,коэф.модели!$K$5:$L$7,2,0))) -> #N/A | BP8: =IF(AQ8=AP8,J8,ROUND(0.6329*LN(BO8)+0.0442,4)) -> 0 | BQ8: =IF(AN8=AL8,IF(H8="отсутствие теплоснабжения","отсутствие теплоснабжения","наличие теплоснабжения"),"наличие теплоснабжения") -> наличие теплоснабжения | BR8: =VLOOKUP(BQ8,коэф.модели!$F$12:$G$17,2,0) -> 1 | BS8: =IF(AN8=AL8,IF(F8="отсутствие электроснабжения","отсутствие электроснабжения","наличие электроснабжения"),"наличие электроснабжения") -> наличие электроснабжения | BT8: =VLOOKUP(BS8,коэф.модели!$F$12:$G$17,2,0) -> 1 | BU8: =IF(AN8=AL8,IF(G8="отсутствие водоотведения","отсутствие водоотведения","наличие водоотведения"),"наличие водоотведения") -> наличие водоотведения | BV8: =VLOOKUP(BU8,коэф.модели!$F$12:$G$17,2,0) -> 1 | BW8: =ROUND(PRODUCT(BL8,BN8,BP8,BR8,BT8,BV8),2) -> #N/A | BX8: =ROUND(BW8*Q8,2) -> #N/A | BY8: =8002 -> 8002 | BZ8: СТ16_Ф1_М2_18052021_Бунаков | CA8: =IF(OR(BX8<0,BX8=0),"ОТРИЦАТЕЛЬНОЕ ЗНАЧЕНИЕ",IF(OR(CG8=0,CG8<1),"Пересчет не требуется","Готов")) -> #N/A | CB8: =AP8 -> 0 | CC8: =IF(CB8="02:014",$CQ$1,$CR$1) -> 2. СЕГМЕНТ "Жилая застройка (среднеэтажная и многоэтажная)" | CD8: =IF(CB8="02:014",$CQ$2,$CR$2) -> 2 | CE8: =VLOOKUP(CB8,'справочник ВРИ'!$A$3:$B$271,2,0) -> #N/A | CF8: =AO8 -> 0 | CG8: =IF(ISBLANK(N8),"Новый объект",IF(AL8=AN8,ABS(BX8-O8),"Объект из другой модели")) -> Новый объект | CH8: =IF(AN8=AL8,BW8-N8,IF(OR(BW8<866,BW8>17260),"Отклонение УПКС","УПКС объекта в допустимом интервале")) -> #N/A | CI8: =IF(CG8="Объект из другой модели",CG8,IF(CG8="Новый объект",CG8,IF(CG8>50000000,"Внимание!Изменение стоимости","Изменение менее 50 млн"))) -> Новый объект | CJ8: =IF(I8="","Новое значение",IF(I8=BL8,"Осталось предыдущее значение ЦФ","ИЗМЕНЕНИЕ")) -> Новое значение | CK8: =IF(F8="","Новое значение",IF(BS8=F8,"Осталось предыдущее значение ЦФ","ИЗМЕНЕНИЕ")) -> Новое значение | CL8: =IF(H8="","Новое значение",IF(BQ8=H8,"Осталось предыдущее значение ЦФ","ИЗМЕНЕНИЕ")) -> Новое значение | CM8: =IF(N8="","Объект новый",IF(AG8="не готов","ИЗМЕНЕНИЕ","Осталось предыдущее значение ЦФ")) -> Объект новый | CN8: =IF(J8="","Новое значение",IF(BP8=J8,"Осталось предыдущее значение ЦФ","ИЗМЕНЕНИЕ")) -> Новое значение | CO8: =IF(K8="","Новое значение",IF(BM8=K8,"Осталось предыдущее значение ЦФ","ИЗМЕНЕНИЕ")) -> Новое значение | CP8: =IF(AP8=AQ8,"Осталось предыдущее значение ЦФ","ИЗМЕНЕНИЕ") -> Осталось предыдущее значение ЦФ | CQ8: =IFERROR(IFERROR(IFERROR(VLOOKUP(BL8,'КК и удельник'!$E$3:$G$6521,3,0),VLOOKUP(BL8,'КК и удельник'!$D$3:$G$6521,4,0)),VLOOKUP(BL8,'КК и удельник'!$AI$3:$AL$1928,4,0)),VLOOKUP(BL8,'КК и удельник'!$AK$3:$AL$1928,2,0)) -> #N/A | CR8: =CQ8=BK8 -> #N/A
AU9: =I9 -> 0 | AV9: =K9 -> 0 | AW9: =VLOOKUP(AV9,коэф.модели!$F$6:$G$11,2,0) -> #N/A | AX9: =J9 -> 0 | AY9: =H9 -> 0 | AZ9: =IF(AY9="","ОШИБКА",VLOOKUP(AY9,коэф.модели!$F$12:$G$17,2,0)) -> #N/A | BA9: =F9 -> 0 | BB9: =IF(BA9="","ОШИБКА",VLOOKUP(BA9,коэф.модели!$F$12:$G$17,2,0)) -> #N/A | BC9: =G9 -> 0 | BD9: =IF(BC9="","ОШИБКА",VLOOKUP(BC9,коэф.модели!$F$12:$G$17,2,0)) -> #N/A | BE9: =ROUND(PRODUCT(AU9,AW9,AX9,AZ9,BD9,BB9),2) -> #N/A | BF9: =MROUND(BE9*D9,2) -> #N/A | BG9: =IF(N9="","Новый объект",IF(AN9=AL9,BF9-O9,"Объект пришел из другой модели")) -> Новый объект | BH9: =IF(AM9="",IF(AC9<>"","ОСПАРИВАНИЕ",IF(AS9<>"","СУД",IF(W9="","",W9))),AM9) | BI9: =B9 -> 0 | BJ9: =Q9 -> 0 | BK9: =IFERROR(IF(AP9="02:060",VLOOKUP(C9,'КК и удельник'!$A$3:$E$6521,2,0),IF(расчеты!AP9="02:050",VLOOKUP(расчеты!C9,'КК и удельник'!$A$3:$E$6521,2,0),IF(расчеты!AP9="02:014",VLOOKUP(расчеты!C9,'КК и удельник'!$A$3:$E$6521,2,0)))),IF(AP9="02:060",IF(M9="",VLOOKUP(L9,'КК и удельник'!$AG$3:$AK$1928,2,0),VLOOKUP(M9,'КК и удельник'!$AG$3:$AK$1928,2,0)),IF(расчеты!AP9="02:050",IF(M9="",VLOOKUP(расчеты!L9,'КК и удельник'!$AG$3:$AK$1928,2,0),VLOOKUP(расчеты!M9,'КК и удельник'!$AG$3:$AK$1928,2,0)),IF(расчеты!AP9="02:014",IF(M9="",VLOOKUP(расчеты!L9,'КК и удельник'!$AG$3:$AK$1928,2,0),VLOOKUP(расчеты!M9,'КК и удельник'!$AG$3:$AK$1928,2,0)),"ОШИБКА")))) -> FALSE | BL9: =IF(AQ9=AP9,I9,IFERROR(IF(AP9="02:060",VLOOKUP(C9,'КК и удельник'!$A$3:$E$6521,4,0),IF(расчеты!AP9="02:050",VLOOKUP(расчеты!C9,'КК и удельник'!$A$3:$E$6521,3,0),IF(расчеты!AP9="02:014",VLOOKUP(расчеты!C9,'КК и удельник'!$A$3:$E$6521,5,0)))),IF(AP9="02:060",IF(M9="",VLOOKUP(L9,'КК и удельник'!$AG$3:$AK$1928,4,0),VLOOKUP(M9,'КК и удельник'!$AG$3:$AK$1928,4,0)),IF(расчеты!AP9="02:050",IF(M9="",VLOOKUP(расчеты!L9,'КК и удельник'!$AG$3:$AK$1928,3,0),VLOOKUP(расчеты!M9,'КК и удельник'!$AG$3:$AK$1928,3,0)),IF(расчеты!AP9="02:014",IF(M9="",VLOOKUP(расчеты!L9,'КК и удельник'!$AG$3:$AK$1928,5,0),VLOOKUP(расчеты!M9,'КК и удельник'!$AG$3:$AK$1928,5,0))))))) -> 0 | BM9: =VLOOKUP(AP9,коэф.модели!$J$5:$K$7,2,0) -> #N/A | BN9: =VLOOKUP(BM9,коэф.модели!$F$6:$G$11,2,0) -> #N/A | BO9: =IF(M9="",IF(L9="47:004:1:1:1",IF(BM9="многоэтажный",9,VLOOKUP(BM9,коэф.модели!$K$5:$L$7,2,0)),VLOOKUP(BM9,коэф.модели!$K$5:$L$7,2,0)),IF(M9="47:004:1:1:1",IF(BM9="многоэтажный",9,VLOOKUP(BM9,коэф.модели!$K$5:$L$7,2,0)),VLOOKUP(BM9,коэф.модели!$K$5:$L$7,2,0))) -> #N/A | BP9: =IF(AQ9=AP9,J9,ROUND(0.6329*LN(BO9)+0.0442,4)) -> 0 | BQ9: =IF(AN9=AL9,IF(H9="отсутствие теплоснабжения","отсутствие теплоснабжения","наличие теплоснабжения"),"наличие теплоснабжения") -> наличие теплоснабжения | BR9: =VLOOKUP(BQ9,коэф.модели!$F$12:$G$17,2,0) -> 1 | BS9: =IF(AN9=AL9,IF(F9="отсутствие электроснабжения","отсутствие электроснабжения","наличие электроснабжения"),"наличие электроснабжения") -> наличие электроснабжения | BT9: =VLOOKUP(BS9,коэф.модели!$F$12:$G$17,2,0) -> 1 | BU9: =IF(AN9=AL9,IF(G9="отсутствие водоотведения","отсутствие водоотведения","наличие водоотведения"),"наличие водоотведения") -> наличие водоотведения | BV9: =VLOOKUP(BU9,коэф.модели!$F$12:$G$17,2,0) -> 1 | BW9: =ROUND(PRODUCT(BL9,BN9,BP9,BR9,BT9,BV9),2) -> #N/A | BX9: =ROUND(BW9*Q9,2) -> #N/A | BY9: =8002 -> 8002 | BZ9: СТ16_Ф1_М2_18052021_Бунаков | CA9: =IF(OR(BX9<0,BX9=0),"ОТРИЦАТЕЛЬНОЕ ЗНАЧЕНИЕ",IF(OR(CG9=0,CG9<1),"Пересчет не требуется","Готов")) -> #N/A | CB9: =AP9 -> 0 | CC9: =IF(CB9="02:014",$CQ$1,$CR$1) -> 2. СЕГМЕНТ "Жилая застройка (среднеэтажная и многоэтажная)" | CD9: =IF(CB9="02:014",$CQ$2,$CR$2) -> 2 | CE9: =VLOOKUP(CB9,'справочник ВРИ'!$A$3:$B$271,2,0) -> #N/A | CF9: =AO9 -> 0 | CG9: =IF(ISBLANK(N9),"Новый объект",IF(AL9=AN9,ABS(BX9-O9),"Объект из другой модели")) -> Новый объект | CH9: =IF(AN9=AL9,BW9-N9,IF(OR(BW9<866,BW9>17260),"Отклонение УПКС","УПКС объекта в допустимом интервале")) -> #N/A | CI9: =IF(CG9="Объект из другой модели",CG9,IF(CG9="Новый объект",CG9,IF(CG9>50000000,"Внимание!Изменение стоимости","Изменение менее 50 млн"))) -> Новый объект | CJ9: =IF(I9="","Новое значение",IF(I9=BL9,"Осталось предыдущее значение ЦФ","ИЗМЕНЕНИЕ")) -> Новое значение | CK9: =IF(F9="","Новое значение",IF(BS9=F9,"Осталось предыдущее значение ЦФ","ИЗМЕНЕНИЕ")) -> Новое значение | CL9: =IF(H9="","Новое значение",IF(BQ9=H9,"Осталось предыдущее значение ЦФ","ИЗМЕНЕНИЕ")) -> Новое значение | CM9: =IF(N9="","Объект новый",IF(AG9="не готов","ИЗМЕНЕНИЕ","Осталось предыдущее значение ЦФ")) -> Объект новый | CN9: =IF(J9="","Новое значение",IF(BP9=J9,"Осталось предыдущее значение ЦФ","ИЗМЕНЕНИЕ")) -> Новое значение | CO9: =IF(K9="","Новое значение",IF(BM9=K9,"Осталось предыдущее значение ЦФ","ИЗМЕНЕНИЕ")) -> Новое значение | CP9: =IF(AP9=AQ9,"Осталось предыдущее значение ЦФ","ИЗМЕНЕНИЕ") -> Осталось предыдущее значение ЦФ | CQ9: =IFERROR(IFERROR(IFERROR(VLOOKUP(BL9,'КК и удельник'!$E$3:$G$6521,3,0),VLOOKUP(BL9,'КК и удельник'!$D$3:$G$6521,4,0)),VLOOKUP(BL9,'КК и удельник'!$AI$3:$AL$1928,4,0)),VLOOKUP(BL9,'КК и удельник'!$AK$3:$AL$1928,2,0)) -> #N/A | CR9: =CQ9=BK9 -> #N/A
AU10: =I10 -> 0 | AV10: =K10 -> 0 | AW10: =VLOOKUP(AV10,коэф.модели!$F$6:$G$11,2,0) -> #N/A | AX10: =J10 -> 0 | AY10: =H10 -> 0 | AZ10: =IF(AY10="","ОШИБКА",VLOOKUP(AY10,коэф.модели!$F$12:$G$17,2,0)) -> #N/A | BA10: =F10 -> 0 | BB10: =IF(BA10="","ОШИБКА",VLOOKUP(BA10,коэф.модели!$F$12:$G$17,2,0)) -> #N/A | BC10: =G10 -> 0 | BD10: =IF(BC10="","ОШИБКА",VLOOKUP(BC10,коэф.модели!$F$12:$G$17,2,0)) -> #N/A | BE10: =ROUND(PRODUCT(AU10,AW10,AX10,AZ10,BD10,BB10),2) -> #N/A | BF10: =MROUND(BE10*D10,2) -> #N/A | BG10: =IF(N10="","Новый объект",IF(AN10=AL10,BF10-O10,"Объект пришел из другой модели")) -> Новый объект | BH10: =IF(AM10="",IF(AC10<>"","ОСПАРИВАНИЕ",IF(AS10<>"","СУД",IF(W10="","",W10))),AM10) | BI10: =B10 -> 0 | BJ10: =Q10 -> 0 | BK10: =IFERROR(IF(AP10="02:060",VLOOKUP(C10,'КК и удельник'!$A$3:$E$6521,2,0),IF(расчеты!AP10="02:050",VLOOKUP(расчеты!C10,'КК и удельник'!$A$3:$E$6521,2,0),IF(расчеты!AP10="02:014",VLOOKUP(расчеты!C10,'КК и удельник'!$A$3:$E$6521,2,0)))),IF(AP10="02:060",IF(M10="",VLOOKUP(L10,'КК и удельник'!$AG$3:$AK$1928,2,0),VLOOKUP(M10,'КК и удельник'!$AG$3:$AK$1928,2,0)),IF(расчеты!AP10="02:050",IF(M10="",VLOOKUP(расчеты!L10,'КК и удельник'!$AG$3:$AK$1928,2,0),VLOOKUP(расчеты!M10,'КК и удельник'!$AG$3:$AK$1928,2,0)),IF(расчеты!AP10="02:014",IF(M10="",VLOOKUP(расчеты!L10,'КК и удельник'!$AG$3:$AK$1928,2,0),VLOOKUP(расчеты!M10,'КК и удельник'!$AG$3:$AK$1928,2,0)),"ОШИБКА")))) -> FALSE | BL10: =IF(AQ10=AP10,I10,IFERROR(IF(AP10="02:060",VLOOKUP(C10,'КК и удельник'!$A$3:$E$6521,4,0),IF(расчеты!AP10="02:050",VLOOKUP(расчеты!C10,'КК и удельник'!$A$3:$E$6521,3,0),IF(расчеты!AP10="02:014",VLOOKUP(расчеты!C10,'КК и удельник'!$A$3:$E$6521,5,0)))),IF(AP10="02:060",IF(M10="",VLOOKUP(L10,'КК и удельник'!$AG$3:$AK$1928,4,0),VLOOKUP(M10,'КК и удельник'!$AG$3:$AK$1928,4,0)),IF(расчеты!AP10="02:050",IF(M10="",VLOOKUP(расчеты!L10,'КК и удельник'!$AG$3:$AK$1928,3,0),VLOOKUP(расчеты!M10,'КК и удельник'!$AG$3:$AK$1928,3,0)),IF(расчеты!AP10="02:014",IF(M10="",VLOOKUP(расчеты!L10,'КК и удельник'!$AG$3:$AK$1928,5,0),VLOOKUP(расчеты!M10,'КК и удельник'!$AG$3:$AK$1928,5,0))))))) -> 0 | BM10: =VLOOKUP(AP10,коэф.модели!$J$5:$K$7,2,0) -> #N/A | BN10: =VLOOKUP(BM10,коэф.модели!$F$6:$G$11,2,0) -> #N/A | BO10: =IF(M10="",IF(L10="47:004:1:1:1",IF(BM10="многоэтажный",9,VLOOKUP(BM10,коэф.модели!$K$5:$L$7,2,0)),VLOOKUP(BM10,коэф.модели!$K$5:$L$7,2,0)),IF(M10="47:004:1:1:1",IF(BM10="многоэтажный",9,VLOOKUP(BM10,коэф.модели!$K$5:$L$7,2,0)),VLOOKUP(BM10,коэф.модели!$K$5:$L$7,2,0))) -> #N/A | BP10: =IF(AQ10=AP10,J10,ROUND(0.6329*LN(BO10)+0.0442,4)) -> 0 | BQ10: =IF(AN10=AL10,IF(H10="отсутствие теплоснабжения","отсутствие теплоснабжения","наличие теплоснабжения"),"наличие теплоснабжения") -> наличие теплоснабжения | BR10: =VLOOKUP(BQ10,коэф.модели!$F$12:$G$17,2,0) -> 1 | BS10: =IF(AN10=AL10,IF(F10="отсутствие электроснабжения","отсутствие электроснабжения","наличие электроснабжения"),"наличие электроснабжения") -> наличие электроснабжения | BT10: =VLOOKUP(BS10,коэф.модели!$F$12:$G$17,2,0) -> 1 | BU10: =IF(AN10=AL10,IF(G10="отсутствие водоотведения","отсутствие водоотведения","наличие водоотведения"),"наличие водоотведения") -> наличие водоотведения | BV10: =VLOOKUP(BU10,коэф.модели!$F$12:$G$17,2,0) -> 1 | BW10: =ROUND(PRODUCT(BL10,BN10,BP10,BR10,BT10,BV10),2) -> #N/A | BX10: =ROUND(BW10*Q10,2) -> #N/A | BY10: =8002 -> 8002 | BZ10: СТ16_Ф1_М2_18052021_Бунаков | CA10: =IF(OR(BX10<0,BX10=0),"ОТРИЦАТЕЛЬНОЕ ЗНАЧЕНИЕ",IF(OR(CG10=0,CG10<1),"Пересчет не требуется","Готов")) -> #N/A | CB10: =AP10 -> 0 | CC10: =IF(CB10="02:014",$CQ$1,$CR$1) -> 2. СЕГМЕНТ "Жилая застройка (среднеэтажная и многоэтажная)" | CD10: =IF(CB10="02:014",$CQ$2,$CR$2) -> 2 | CE10: =VLOOKUP(CB10,'справочник ВРИ'!$A$3:$B$271,2,0) -> #N/A | CF10: =AO10 -> 0 | CG10: =IF(ISBLANK(N10),"Новый объект",IF(AL10=AN10,ABS(BX10-O10),"Объект из другой модели")) -> Новый объект | CH10: =IF(AN10=AL10,BW10-N10,IF(OR(BW10<866,BW10>17260),"Отклонение УПКС","УПКС объекта в допустимом интервале")) -> #N/A | CI10: =IF(CG10="Объект из другой модели",CG10,IF(CG10="Новый объект",CG10,IF(CG10>50000000,"Внимание!Изменение стоимости","Изменение менее 50 млн"))) -> Новый объект | CJ10: =IF(I10="","Новое значение",IF(I10=BL10,"Осталось предыдущее значение ЦФ","ИЗМЕНЕНИЕ")) -> Новое значение | CK10: =IF(F10="","Новое значение",IF(BS10=F10,"Осталось предыдущее значение ЦФ","ИЗМЕНЕНИЕ")) -> Новое значение | CL10: =IF(H10="","Новое значение",IF(BQ10=H10,"Осталось предыдущее значение ЦФ","ИЗМЕНЕНИЕ")) -> Новое значение | CM10: =IF(N10="","Объект новый",IF(AG10="не готов","ИЗМЕНЕНИЕ","Осталось предыдущее значение ЦФ")) -> Объект новый | CN10: =IF(J10="","Новое значение",IF(BP10=J10,"Осталось предыдущее значение ЦФ","ИЗМЕНЕНИЕ")) -> Новое значение | CO10: =IF(K10="","Новое значение",IF(BM10=K10,"Осталось предыдущее значение ЦФ","ИЗМЕНЕНИЕ")) -> Новое значение | CP10: =IF(AP10=AQ10,"Осталось предыдущее значение ЦФ","ИЗМЕНЕНИЕ") -> Осталось предыдущее значение ЦФ | CQ10: =IFERROR(IFERROR(IFERROR(VLOOKUP(BL10,'КК и удельник'!$E$3:$G$6521,3,0),VLOOKUP(BL10,'КК и удельник'!$D$3:$G$6521,4,0)),VLOOKUP(BL10,'КК и удельник'!$AI$3:$AL$1928,4,0)),VLOOKUP(BL10,'КК и удельник'!$AK$3:$AL$1928,2,0)) -> #N/A | CR10: =CQ10=BK10 -> #N/A

Sheet ГОТОВ
A1: CadastralNumber | B1: loc_factor_807 | D1: loc_Factor_838 | E1: loc_Factor_836 | H1: loc_Factor_835 | I1: loc_Factor_802 | K1: loc_Factor_804 | M1: loc_Factor_803 | O1: Specific_CadastralCost | P1: CadastralCost | Q1: id_group | R1: CadastralCostDesc | S1: Status_kc | T1: loc_VICode | U1: Segment | V1: loc_SgCode | W1: loc_GroupName | X1: Old_Utlbydoc

Sheet ПЕРЕСЧЕТ НЕ ТРЕБУЕТСЯ
A1: CadastralNumber | B1: Status_kc | C1: loc_VICode | D1: Segment | E1: loc_SgCode | F1: loc_GroupName | G1: Old_Utlbydoc

Sheet СТОПЛИСТ
A1: CadastralNumber | B1: ControlSP

Sheet справочник ВРИ
A1: loc_VICode | B1: loc_GroupName
A2: Код расчета вида использования | B2: Наименование вида использования
A3: 01:010 | B3: Растениеводство в целом. Включает коды расчета вида использования 01.020-01.060
A4: 01:020 | B4: Выращивание зерновых, бобовых, кормовых, технических, масличных, эфиромасличных и иных сельскохозяйственных культур
A5: 01:030 | B5: Овощеводство в целом, связанное с производством картофеля, листовых, плодовых, луковичных и бахчевых сельскохозяйственных культур, в том числе с использованием теплиц
A6: 01:031 | B6: Овощеводство в открытом грунте
A7: 01:032 | B7: Овощеводство тепличное
A8: 01:040 | B8: Выращивание тонизирующих, лекарственных, цветочных культур в целом
A9: 01:041 | B9: Выращивание тонизирующих, лекарственных, цветочных культур. Травы
A10: 01:042 | B10: Выращивание тонизирующих, лекарственных, цветочных культур. Кустарники
A11: 01:050 | B11: Садоводство в целом - выращивание многолетних плодовых и ягодных культур, винограда и иных многолетних культур
A12: 01:051 | B12: Садоводство плодовое
... A271: 14:000 | B271: Иное использование

Sheet коэф.модели
B2: Модель №2 | D2: y=V1*V2*V3*V4*V5*V6
B3: Фактор | C3: Обозначение фактора | D3: Номер модели | E3: Наименование ЦФ | F3: Градация (не хранится в БД как отдельное поле) | G3: Значение поправки
B4: Рыночная стоимость квартиры | C4: V1 | D4: 8002 | E4: =B4 -> Рыночная стоимость квартиры | F4: Число | G4: функция от местоположения квартиры | K4: Типовая характеристика | L4: Типовая этажность
B5: Коэффициент плотности | C5: V2 | D5: 8002 | E5: Коэффициент плотности | F5: Число | G5: функция от этажности | J5: 02:060 | K5: многоэтажный | L5: 9
B6: Коэффициент типовых характеристик | C6: V3 | D6: 8002 | E6: Коэффициент типовых характеристик | F6: малоэтажный | G6: 0.1228 | J6: 02:050 | K6: среднеэтажный | L6: 5
F7: малоэтажный | G7: 0.1228 | J7: 02:014 | K7: малоэтажный | L7: 3
F8: среднеэтажный | G8: 0.0831
F9: среднеэтажный | G9: 0.0831
F10: многоэтажный | G10: 0.0762
F11: многоэтажный | G11: 0.0762
B12: Теплоснабжение | C12: V4 | D12: 8002 | E12: Теплоснабжение | F12: наличие теплоснабжения | G12: 1
F13: отсутствие теплоснабжения | G13: 0.92
B14: Электроснабжение | C14: V5 | D14: 8002 | E14: Электроснабжение | F14: наличие электроснабжения | G14: 1
F15: отсутствие электроснабжения | G15: 0.92
B16: Водоотведение | C16: V6 | D16: 8002 | E16: Водоотведение | F16: наличие водоотведения | G16: 1
F17: отсутствие водоотведения | G17: 0.95

Sheet Лист4
A3: Названия строк | B3: Среднее по полю Удельник для Малоэтажного-02:014 | F3: Названия строк | G3: Количество по полю Удельник для Малоэтажного-02:014
A4: 66:12:1610001 | B4: 28935.146 | F4: 66:12:1610001 | G4: 1
A5: 66:12:1617001 | B5: 25951.934 | F5: 66:12:1617001 | G5: 1
A6: 66:12:5213006 | B6: 31984.905 | F6: 66:12:5213006 | G6: 1
A7: 66:12:6901001 | B7: 25946.143 | F7: 66:12:6901001 | G7: 1
A8: 66:19:0101006 | B8: 20837.465 | F8: 66:19:0101006 | G8: 1
A9: 66:19:0101017 | B9: 26241.208 | F9: 66:19:0101017 | G9: 1
A10: 66:19:0101018 | B10: 26241.208 | F10: 66:19:0101018 | G10: 1
A11: 66:19:0101019 | B11: 26241.208 | F11: 66:19:0101019 | G11: 1
A12: 66:19:0101020 | B12: 26241.208 | F12: 66:19:0101020 | G12: 1
A13: 66:19:0101022 | B13: 32052.277 | F13: 66:19:0101022 | G13: 1
A14: 66:19:0101023 | B14: 32052.277 | F14: 66:19:0101023 | G14: 1
A15: 66:19:0101024 | B15: 32052.277 | F15: 66:19:0101024 | G15: 1
... A5033: Общий итог | B5033: 49994.412 | F5033: Общий итог | G5033: 6529

Sheet КК и удельник
A1: На странице нельзя удалять строки | B1: С учетом трансформации | C1: Без учета инфляции | F1: На странице нельзя удалять строки | L1: Желтый цвет -КК в 1003 | M1: Таблица перекодировки ЕКБ | R1: Каменск | X1: Первоуральск | AC1: Тагил
A2: КК | B2: Зона | C2: Удельник для Среднеэтажного-02:050 | D2: Удельник для Многоэтажного-02:060 | E2: Удельник для Малоэтажного-02:014 | F2: Признак квартала | M2: АВТОВОКЗАЛ | N2: =M2 -> АВТОВОКЗАЛ | R2: Наименование жилого района | S2: Наименование объединенного жилого массива (зона) | T2: Сокращенное наименование для построения модели | X2: Наименование жилого района | Y2: Сокращенное наименование для построения модели | AC2: Наименование жилого района | AD2: Сокращенное наименование для построения модели | AF2: ГО | AG2: КОД НП | AH2: ГО | AI2: Удельник для Среднеэтажного-02:050 | AJ2: Удельник для Многоэтажного-02:060 | AK2: Удельник для Малоэтажного-02:014
A3: 66:41:0401041 | B3: Центр | C3: 93989.913 | D3: 93989.913 | E3: 85109.545 | F3: КК из расчетника | G3: =B3 -> Центр | M3: АКАДЕМИЧЕСКИЙ | N3: =M3 -> АКАДЕМИЧЕСКИЙ | R3: микрорайон Южный | S3: Южный | T3: Южный | X3: Совхоз Первоуральский | Y3: Совхоз_Первоур | AC3: Верхняя Черемшанка пос. | AD3: Евст_В-Черм | AF3: Арамильский городской округ | AG3: 01:000:0:0:0 | AH3: Арамильский городской округ | AI3: 39614.886 | AJ3: 39614.886 | AK3: 36792.697 | AL3: =AF3 -> Арамильский городской округ
A4: 66:41:0609023 | B4: КОМПРЕССОРНЫЙ | C4: 56392.544 | D4: 56392.544 | E4: 51064.462 | F4: КК из расчетника | G4: =B4 -> КОМПРЕССОРНЫЙ | M4: БОТАНИЧЕСКИЙ | N4: =M4 -> БОТАНИЧЕСКИЙ | R4: микрорайон Октябрьский-I | S4: Октябрьский | T4: Октябрьский | X4: Первомайский | Y4: Первомайский | AC4: СУХОЛОЖСКИЙ | AD4: Сух_Г-Кам_Н_Кушва_Н-Черм | AF4: Арамильский городской округ | AG4: 01:001:1:1:4 | AH4: Арамильский городской округ | AI4: 48945.107 | AJ4: 48945.107 | AK4: 45458.222 | AL4: =AF4 -> Арамильский городской округ
A5: 66:41:0110004 | B5: ЭЛЬМАШ | C5: 70734.024 | D5: 70734.024 | E5: 64050.921 | F5: КК из расчетника | G5: =B5 -> ЭЛЬМАШ | M5: ВИЗ | N5: =M5 -> ВИЗ | R5: микрорайон Октябрьский-II | S5: Октябрьский | T5: Октябрьский | X5: Магнитка | Y5: Магнитка | AC5: ГОЛЫЙ КАМЕНЬ | AD5: Сух_Г-Кам_Н_Кушва_Н-Черм | AF5: Арамильский городской округ | AG5: 01:002:2:3:5 | AH5: Арамильский городской округ | AI5: 40607.171 | AJ5: 40607.171 | AK5: 37714.286 | AL5: =AF5 -> Арамильский городской округ
A6: 66:41:0206014 | B6: Центр | C6: 93989.913 | D6: 93989.913 | E6: 85109.545 | F6: КК из расчетника | G6: =B6 -> Центр | M6: ВОКЗАЛЬНЫЙ | N6: =M6 -> ВОКЗАЛЬНЫЙ | R6: 49-й квартал | S6: УАЗ III – 49 квартал | T6: УАЗ-III - 49 кв. | X6: ДИНАС | Y6: ДинСанПод | AC6: НОВАЯ КУШВА | AD6: Сух_Г-Кам_Н_Кушва_Н-Черм | AF6: Арамильский городской округ | AG6: 01:003:2:3:5 | AH6: Арамильский городской округ | AI6: 40607.171 | AJ6: 40607.171 | AK6: 37714.286 | AL6: =AF6 -> Арамильский городской округ
A7: 66:41:0303094 | B7: ВИЗ | C7: 84298.205 | D7: 84298.205 | E7: 76333.533 | F7: КК из расчетника | G7: =B7 -> ВИЗ | M7: ВТУЗГОРОДОК | N7: =M7 -> ВТУЗГОРОДОК | R7: ПОС.УАЗ-III | T7: УАЗ-III - 49 кв. | X7: ПОДВОЛОШНАЯ | Y7: ДинСанПод | AC7: Нижняя Черемшанка | AD7: Сух_Г-Кам_Н_Кушва_Н-Черм | AF7: Артемовский городской округ | AG7: 02:000:0:0:0 | AH7: Артемовский городской округ | AI7: 19458.838 | AJ7: 19458.838 | AK7: 18072.573 | AL7: =AF7 -> Артемовский городской округ
A8: 66:41:0601039 | B8: Центр | C8: 93989.913 | D8: 93989.913 | E8: 85109.545 | F8: КК из расчетника | G8: =B8 -> Центр | M8: ГОРНЫЙ ЩИТ | N8: =M8 -> ГОРНЫЙ ЩИТ | R8: ПОС.УАЗ-II | S8: УАЗ-II | T8: УАЗ-II | X8: Сантехизделий | Y8: ДинСанПод | AC8: РУДНИК ИМ. III ИНТЕРНАЦИОНАЛА | AD8: Рудник_Север | AF8: Артемовский городской округ | AG8: 02:001:1:1:4 | AH8: Артемовский городской округ | AI8: 24041.837 | AJ8: 24041.837 | AK8: 22329.077 | AL8: =AF8 -> Артемовский городской округ
A9: 66:41:0702035 | B9: ПИОНЕРСКИЙ | C9: 77743.704 | D9: 77743.704 | E9: 70398.311 | F9: КК из расчетника | G9: =B9 -> ПИОНЕРСКИЙ | M9: ЕЛИЗАВЕТ | N9: =M9 -> ЕЛИЗАВЕТ | R9: посёлок Трубников | S9: Трубников | T9: Трубников | X9: Соцгород | Y9: Соцгород | AC9: СЕВЕРНЫЙ М-Н | AD9: Рудник_Север | AF9: Артемовский городской округ | AG9: 02:002:2:4:6 | AH9: Артемовский городской округ | AI9: 19458.838 | AJ9: 19458.838 | AK9: 18072.573 | AL9: =AF9 -> Артемовский городской округ
A10: 66:41:0108117 | B10: ЭЛЬМАШ | C10: 70734.024 | D10: 70734.024 | E10: 64050.921 | F10: КК из расчетника | G10: =B10 -> ЭЛЬМАШ | M10: ЖБИ | N10: =M10 -> ЖБИ | R10: посёлок Ленинский | S10: Ленинский-Олимпийский | T10: Ленин-Олимп | X10: ТАЛИЦА ПОС. | Y10: Талица | AC10: ТАГИЛСТРОЙ | AD10: Тагил_Кирп | AF10: Артемовский городской округ | AG10: 02:003:2:3:6 | AH10: Артемовский городской округ | AI10: 19458.838 | AJ10: 19458.838 | AK10: 18072.573 | AL10: =AF10 -> Артемовский городской округ
A11: 66:41:0504035 | B11: ЧЕРМЕТ | C11: 62652.94 | D11: 62652.94 | E11: 56733.356 | F11: КК из расчетника | G11: =B11 -> ЧЕРМЕТ | M11: ЗАВОКЗАЛЬНЫЙ | N11: =M11 -> ЗАВОКЗАЛЬНЫЙ | R11: посёлок Олимпийский | S11: Ленинский-Олимпийский | T11: Ленин-Олимп | X11: Шайтанка | Y11: Шайтанка | AC11: КИРПИЧНЫЙ | AD11: Тагил_Кирп | AF11: Артемовский городской округ | AG11: 02:004:2:3:6 | AH11: Артемовский городской округ | AI11: 19458.838 | AJ11: 19458.838 | AK11: 18072.573 | AL11: =AF11 -> Артемовский городской округ
A12: 66:41:0108111 | B12: ЭЛЬМАШ | C12: 70734.024 | D12: 70734.024 | E12: 64050.921 | F12: КК из расчетника | G12: =B12 -> ЭЛЬМАШ | M12: ЗАРЕЧНЫЙ | N12: =M12 -> ЗАРЕЧНЫЙ | R12: ПОС. СЕВЕРНЫЙ | S12: Северный | T12: Северный | X12: Хромпик | Y12: Хромпик | AC12: ВЫЯ | AD12: Выя_Леб_Горб_Кр-Кам | AF12: Артемовский городской округ | AG12: 02:005:2:4:6 | AH12: Артемовский городской округ | AI12: 19458.838 | AJ12: 19458.838 | AK12: 18072.573 | AL12: =AF12 -> Артемовский городской округ
A13: 66:41:0609024 | B13: КОМПРЕССОРНЫЙ | C13: 56392.544 | D13: 56392.544 | E13: 51064.462 | F13: КК из расчетника | G13: =B13 -> КОМПРЕССОРНЫЙ | M13: ИЗОПЛИТ | N13: =M13 -> ИЗОПЛИТ | R13: посёлок Чкаловский | S13: Чкаловский | T13: Чкаловский | X13: КОРАБЕЛЬНАЯ РОЩА | Y13: КорабельнаяРоща | AC13: ЛЕБЯЖКА | AD13: Выя_Леб_Горб_Кр-Кам | AF13: Артемовский городской округ | AG13: 02:006:2:4:6 | AH13: Артемовский городской округ | AI13: 19458.838 | AJ13: 19458.838 | AK13: 18072.573 | AL13: =AF13 -> Артемовский городской округ
A14: 66:41:0504008 | B14: ЧЕРМЕТ | C14: 62652.94 | D14: 62652.94 | E14: 56733.356 | F14: КК из расчетника | G14: =B14 -> ЧЕРМЕТ | M14: ИСТОК | N14: =M14 -> ИСТОК | R14: посёлок Хозспособ | S14: Хозспособ-Старый Кменск | T14: Ст.Каменск-Хозспособ | X14: Западный | Y14: Западный | AC14: Горбуново | AD14: Выя_Леб_Горб_Кр-Кам | AF14: Артемовский городской округ | AG14: 02:007:2:3:6 | AH14: Артемовский городской округ | AI14: 19458.838 | AJ14: 19458.838 | AK14: 18072.573 | AL14: =AF14 -> Артемовский городской округ
A15: 66:41:0108009 | B15: ЭЛЬМАШ | C15: 70734.024 | D15: 70734.024 | E15: 64050.921 | F15: КК из расчетника | G15: =B15 -> ЭЛЬМАШ | M15: КАЛИНОВСКИЙ | N15: =M15 -> КАЛИНОВСКИЙ | R15: Старый Каменск | S15: Хозспособ-Старый Кменск | T15: Ст.Каменск-Хозспособ | X15: Центр | Y15: ЦЕНТР-Перв | AC15: КРАСНЫЙ КАМЕНЬ | AD15: Выя_Леб_Горб_Кр-Кам | AF15: Артемовский городской округ | AG15: 02:008:2:3:6 | AH15: Артемовский городской округ | AI15: 19458.838 | AJ15: 19458.838 | AK15: 18072.573 | AL15: =AF15 -> Артемовский городской округ
A16: 66:41:0108079 | B16: ЭЛЬМАШ | C16: 70734.024 | D16: 70734.024 | E16: 64050.921 | F16: КК из расчетника | G16: =B16 -> ЭЛЬМАШ | M16: КАРАСЬЕОЗЕРСК | N16: ШИРОКАЯ РЕЧКА | R16: ПОС. УАЗ-I | S16: УАЗ-I | T16: УАЗ | X16: Веер | Y16: Веер | AC16: СТАРАТЕЛЬ М-Н | AD16: Ваг_Стар_Пихтовы-г | AF16: Артемовский городской округ | AG16: 02:009:2:5:6 | AH16: Артемовский городской округ | AI16: 19458.838 | AJ16: 19458.838 | AK16: 18072.573 | AL16: =AF16 -> Артемовский городской округ
A17: 66:41:0108096 | B17: ЭЛЬМАШ | C17: 70734.024 | D17: 70734.024 | E17: 64050.921 | F17: КК из расчетника | G17: =B17 -> ЭЛЬМАШ | M17: КОЛЬЦОВО | N17: =M17 -> КОЛЬЦОВО | X17: Техгород | Y17: Техгород | AC17: ВАГОНКА | AD17: Ваг_Стар_Пихтовы-г | AF17: Артемовский городской округ | AG17: 02:010:2:3:6 | AH17: Артемовский городской округ | AI17: 19458.838 | AJ17: 19458.838 | AK17: 18072.573 | AL17: =AF17 -> Артемовский городской округ
A18: 66:41:0106097 | B18: УРАЛМАШ | C18: 70026.76 | D18: 70026.76 | E18: 63410.482 | F18: КК из расчетника | G18: =B18 -> УРАЛМАШ | M18: КОМПРЕССОРНЫЙ | N18: =M18 -> КОМПРЕССОРНЫЙ | R18: 52:000:0:0:0 | S18: мс | T18: Каменск-Уральскиймс | X18: Севернее ЖД | Y18: ДинСанПод | AC18: ПИХТОВЫЕ ГОРЫ | AD18: Ваг_Стар_Пихтовы-г | AF18: Артемовский городской округ | AG18: 02:011:2:3:6 | AH18: Артемовский городской округ | AI18: 19458.838 | AJ18: 19458.838 | AK18: 18072.573 | AL18: =AF18 -> Артемовский городской округ
A19: 66:41:0303080 | B19: ВИЗ | C19: 84298.205 | D19: 84298.205 | E19: 76333.533 | F19: КК из расчетника | G19: =B19 -> ВИЗ | M19: ЛЕЧЕБНЫЙ | N19: =M19 -> ЛЕЧЕБНЫЙ | R19: 52:001:1:1:2 | S19: г | T19: Каменск-Уральский | X19: Южнее ЖД | Y19: Магнитка | AC19: Гальяно-горбуновский массив ж/м | AD19: Алт_Гальян_М-Кушва | AF19: Артемовский городской округ | AG19: 02:012:2:3:6 | AH19: Артемовский городской округ | AI19: 19458.838 | AJ19: 19458.838 | AK19: 18072.573 | AL19: =AF19 -> Артемовский городской округ
A20: 66:41:0106102 | B20: УРАЛМАШ | C20: 70026.76 | D20: 70026.76 | E20: 63410.482 | F20: КК из расчетника | G20: =B20 -> УРАЛМАШ | M20: МАЛЫЙ ИСТОК | N20: =M20 -> МАЛЫЙ ИСТОК | R20: 52:002:1:1:2 | S20: д | T20: Кодинка | X20: САМСТРОЙ | Y20: ДинСанПод | AC20: АЛТАЙСКИЙ | AD20: Алт_Гальян_М-Кушва | AF20: Артемовский городской округ | AG20: 02:013:2:4:6 | AH20: Артемовский городской округ | AI20: 19458.838 | AJ20: 19458.838 | AK20: 18072.573 | AL20: =AF20 -> Артемовский городской округ
A21: 66:41:0106118 | B21: УРАЛМАШ | C21: 70026.76 | D21: 70026.76 | E21: 63410.482 | F21: КК из расчетника | G21: =B21 -> УРАЛМАШ | M21: МЕДНЫЙ | N21: =M21 -> МЕДНЫЙ | R21: 52:003:2:5:6 | S21: д | T21: Малая Кодинка | X21: Ельничный | Y21: Шайтанка | AC21: МАЛАЯ КУШВА | AD21: Алт_Гальян_М-Кушва | AF21: Артемовский городской округ | AG21: 02:014:2:4:6 | AH21: Артемовский городской округ | AI21: 19458.838 | AJ21: 19458.838 | AK21: 18072.573 | AL21: =AF21 -> Артемовский городской округ
