Workbook

Sheet расчетОО 
A1: Идентификатор | B1: Кадастровый номер | C1: Номер кадастрового квартала | D1: Площадь (ЦФ) | E1: Вид разрешённого использования (ЦФ) | F1: Газоснабжение (ЦФ) | G1: Электроснабжение (ЦФ) | H1: Водоотведение (ЦФ) | I1: Водоснабжение (ЦФ) | J1: Код МО (ЦФ) | K1: ЛЭП над участком (ЦФ) | L1: Подъезд к участку(ЦФ) | M1: Зона влияния для ИЖС (ЦФ) | N1: Внутризональное расстояние(ЦФ) | O1: Внутризональное расстояние | P1: Зона вляния для ИЖС | Q1: Удельный показатель кадастровой стоимости(руб/м2) | R1: Кадастровая стоимость (руб) | S1: Кадастровая стоимость описание вых | T1: Площадь в квадратных метрах | U1: Наличие газоснабжения | V1: Наличие электроснабжения | W1: Наличие водоотведения | X1: Наличие водоснабжения | Y1: Номер заявления | Z1: Тип заявления | AA1: Статус заявления | AB1: Код Муниципального образования | AC1: флажок | AD1: Дата пакета | AE1: Статус расчета | AF1: Дата комиссии | AG1: Решение комиссии | AH1: Флаг кода НП | AI1: Флаг ВРИ по документу | AJ1: Флаг площади | AK1: Флаг ВРИ старый спр | AL1: Флаг ВРИ новый спр | AM1: Флаг Категории ЗУ | AN1: Группа для XML | AO1: ВРИ по документу старое | AP1: Код расчета вида использования текущий | AQ1: ВРИ по документу новое | AR1: Код расчета вида использования новый | AS1: Правило | AT1: Новоя модель | AU1: Особый контроль | AV1: Тип ИЖС | AW1: Наименование кот поселка/ сад тов | AX1: Категория земель | AY1: Разрешенное использование участка Вид разрешенного использования по классификатору | AZ1: Код населённого пункта | BA1: Код расчета вида использования новый с учетом КП | BD1: Вид разрешенного использования (ЦФ) | BE1: V1 | BF1: Газоснабжение (ЦФ) | BG1: V2 | BH1: Электроснабжение (ЦФ) | BI1: V3 | BJ1: Водоснабжение (ЦФ) | BK1: V4 | BL1: Водоотведение (ЦФ) | BM1: V5 | BN1: ЛЭП над участком (ЦФ) | BO1: V6 | BP1: Наличие подъезда (ЦФ) | BQ1: V7 | BR1: Вспомогательный столбец | BS1: Зона влияния для ИЖС (ЦФ) | BT1: V8 | BU1: Площадь (ЦФ) | BV1: V9 | BW1: Внутризональное расстояние(ЦФ) | BX1: V10 | CA1: Уторгование (ЦФ) | CB1: коэффициент | CC1: УПС | CD1: Общая стоимость | CE1: 8020 | CM1: Текущий диапазон УПКС от 19 руб. до 1 914 руб.
A2: ID | B2: CadastralNumber | C2: CadastralBlock | D2: loc_factor_807 | E2: loc_factor_825 | F2: loc_factor_822 | G2: loc_factor_804 | H2: loc_factor_803 | I2: loc_factor_828 | J2: loc_factor_830 | K2: loc_factor_829 | L2: loc_factor_840 | M2: loc_factor_826 | N2: loc_factor_833 | O2: DistanceToVZC | P2: InfluenceZone_IGS | Q2: Specific_CadastralCost | R2: CadastralCost | S2: CadastralCostDesc | T2: Area | U2: PresenceGas | V2: PresencePower | W2: PresenceWaterDisposal | X2: PresenceWaterSupply | Y2: Statement | Z2: Type_Statement | AA2: Status_Statement | AB2: KodMO | AC2: Sp_flag | AD2: inputpacket_date | AE2: Status_kc | AF2: Date_comm | AG2: Sol_comm | AH2: FlagLocalityCode | AI2: Flag_VRI | AJ2: FlagParam | AK2: Flag_VRIoldspr | AL2: Flag_VRInewspr | AM2: Flag_Category | AN2: ID_Group | AO2: Old_Utlbydoc | AP2: loc_VICode | AQ2: UtilizationByDoc | AR2: VRICode_NEW | AS2: PraviloVRI | AT2: New_id_group | AU2: ControlSP | AV2: VRI_IGS | AW2: Cot_name | AX2: ParcelCategory | AY2: Utilization | AZ2: LocalityCode | BA2: Итоговая группировка | BB2: Участие объекта на комиссии, в заявлениях, в судах и прочее | BC2: CadastralNumber | BD2: loc_factor_825 | BF2: loc_factor_822 | BH2: loc_factor_804 | BJ2: loc_factor_828 | BL2: loc_factor_803 | BN2: loc_factor_829 | BP2: loc_factor_840 | BS2: loc_factor_826 | BU2: loc_factor_807 | BV2: loc_factor_8071 | BW2: loc_factor_833 | CA2: loc_factor_827 | CC2: Specific_CadastralCost | CD2: CadastralCost | CE2: id_group | CF2: CadastralCostDesc | CG2: Status_kc | CH2: loc_VICode | CI2: Segment | CJ2: loc_SgCode | CK2: loc_GroupName | CL2: Old_Utlbydoc | CM2: Проверка отклонения УПКС от текущего диапазона
A3: Parcels | B3: Parcels | C3: Parcels | D3: Parcels | E3: Parcels | F3: Parcels | G3: Parcels | H3: Parcels | I3: Parcels | J3: Parcels | K3: Parcels | L3: Parcels | M3: Parcels | N3: Parcels | O3: Parcels | P3: Parcels | Q3: Parcels | R3: Parcels | S3: Parcels | T3: Parcels | U3: Parcels | V3: Parcels | W3: Parcels | X3: Parcels | Y3: Parcels | Z3: Parcels | AA3: Parcels | AB3: Parcels | AC3: Parcels | AD3: Parcels | AE3: Parcels | AF3: Parcels | AG3: Parcels | AH3: Parcels | AI3: Parcels | AJ3: Parcels | AK3: Parcels | AL3: Parcels | AM3: Parcels | AN3: Parcels | AO3: Parcels | AP3: Parcels | AQ3: Parcels | AR3: Parcels | AS3: Parcels | AT3: Parcels | AU3: Parcels | AV3: Parcels | AW3: Parcels | AX3: Parcels | AY3: Parcels | AZ3: Parcels
BA4: =IF(OR(AR4="13:021",AR4="13:011"),IF(AV4="Коттеджные_поселки","13:031",AR4),IF(OR(AR4="02:010",AR4="02:011",AR4="02:020",AR4="02:021",AR4="02:023"),IF(AV4="Коттеджные_поселки","02:019",AR4),AR4)) -> 0 | BB4: =IF(AU4="",IF(AF4<>"","ОСПАРИВАНИЕ",IF(Y4="","",Y4)),AU4) | BC4: =B4 -> 0 | BD4: =VLOOKUP(BA4,модули!$K$27:$L$37,2,0) -> #N/A | BE4: =VLOOKUP(BD4,модули!$L$27:'модули'!$M$37,2,FALSE) -> #N/A | BF4: Отсутствие газоснабжения | BG4: =VLOOKUP(BF4,модули!$B$7:'модули'!$D$18,3,FALSE) -> 1 | BH4: Наличие электроснабжения | BI4: =VLOOKUP(BH4,модули!$F$7:'модули'!$H$18,3,FALSE) -> 1.2297 | BJ4: Отсутствие водоснабжения | BK4: =VLOOKUP(BJ4,модули!$J$7:'модули'!$L$18,3,FALSE) -> 1 | BL4: Отсутствие водоотведения | BM4: =VLOOKUP(BL4,модули!$N$7:'модули'!$P$18,3,FALSE) -> 1 | BN4: Отсутствие ЛЭП | BO4: =VLOOKUP(BN4,модули!$R$7:'модули'!$T$16,3,FALSE) -> 1 | BP4: Наличие подъезда | BQ4: =VLOOKUP(BP4,модули!$V$7:'модули'!$X$17,3,FALSE) -> 1.2423 | BR4: =IFERROR(IF(P4="",VLOOKUP(C4,модули!$Q$26:$R$7017,2,0),P4),VLOOKUP(AB4,модули!$T$26:$U$39,2,0)) -> #N/A | BS4: =VLOOKUP(BR4,модули!$A$27:$B$90,2,0) -> #N/A | BT4: =VLOOKUP(BS4,модули!$B$27:'модули'!$D$90,3,FALSE) -> #N/A | BU4: =T4 -> 0 | BV4: =ROUND(IF(BU4<модули!$A$99,модули!$B$99,IF(BU4>модули!$A$100,модули!$B$100,( ( -0.00000000000000024*BU4^4 + 0.00000000001297181*BU4^3- 0.00000011794827687*BU4^2 + 0.00020947190264916*BU4 + 0.892271997522451)))),4) -> 0.8923 | BW4: =IF(O4="",VLOOKUP(BR4,модули!$F$27:$G$90,2,0),O4) -> #N/A | BX4: =ROUND(EXP(LN(IF(BW4<модули!$H$99,модули!$I$99,IF(BW4>модули!$H$100,модули!$I$100,((9.167685587011E-08*(BW4)^4+0.000015289662956704*(BW4)^3-0.00161875861673315*(BW4)^2+0.0151997782316484*(BW4)+0.962501568438211)))))*модули!$K$98),4) -> #N/A | BY4: =коэффициенты!$G$2 -> 501.259 | BZ4: =BI4*BG4*BK4*BM4*BO4*BQ4*BE4*BT4*BV4*BX4*BY4 -> #N/A | CA4: Наличие уторгования | CB4: =0.91 -> 0.91 | CC4: =ROUND(CB4*BZ4,2) -> #N/A | CD4: =ROUND(CC4*BU4,2) -> #N/A | CE4: =$CE$1 -> 8020 | CF4: СТ16_Ф1_М20_18052021_Бунаков_НовыеОбъекты | CG4: =IF(OR(CD4<0,CD4=0),"ОТРИЦАТЕЛЬНОЕ ЗНАЧЕНИЕ","Готов") -> #N/A | CH4: =BA4 -> 0 | CI4: 13. СЕГМЕНТ "Садоводство и огородничество, малоэтажная жилая застройка" | CJ4: =13 -> 13 | CK4: =VLOOKUP(CH4,'справочник ври'!$A$3:$B$271,2,0) -> #N/A | CL4: =AQ4 -> 0 | CM4: =IF(OR(CC4<19,CC4>1914),"Отклонение УПКС","УПКС в допустимом интервале") -> #N/A
BA5: =IF(OR(AR5="13:021",AR5="13:011"),IF(AV5="Коттеджные_поселки","13:031",AR5),IF(OR(AR5="02:010",AR5="02:011",AR5="02:020",AR5="02:021",AR5="02:023"),IF(AV5="Коттеджные_поселки","02:019",AR5),AR5)) -> 0 | BB5: =IF(AU5="",IF(AF5<>"","ОСПАРИВАНИЕ",IF(Y5="","",Y5)),AU5) | BC5: =B5 -> 0 | BD5: =VLOOKUP(BA5,модули!$K$27:$L$37,2,0) -> #N/A | BE5: =VLOOKUP(BD5,модули!$L$27:'модули'!$M$37,2,FALSE) -> #N/A | BF5: Отсутствие газоснабжения | BG5: =VLOOKUP(BF5,модули!$B$7:'модули'!$D$18,3,FALSE) -> 1 | BH5: Наличие электроснабжения | BI5: =VLOOKUP(BH5,модули!$F$7:'модули'!$H$18,3,FALSE) -> 1.2297 | BJ5: Отсутствие водоснабжения | BK5: =VLOOKUP(BJ5,модули!$J$7:'модули'!$L$18,3,FALSE) -> 1 | BL5: Отсутствие водоотведения | BM5: =VLOOKUP(BL5,модули!$N$7:'модули'!$P$18,3,FALSE) -> 1 | BN5: Отсутствие ЛЭП | BO5: =VLOOKUP(BN5,модули!$R$7:'модули'!$T$16,3,FALSE) -> 1 | BP5: Наличие подъезда | BQ5: =VLOOKUP(BP5,модули!$V$7:'модули'!$X$17,3,FALSE) -> 1.2423 | BR5: =IFERROR(IF(P5="",VLOOKUP(C5,модули!$Q$26:$R$7017,2,0),P5),VLOOKUP(AB5,модули!$T$26:$U$39,2,0)) -> #N/A | BS5: =VLOOKUP(BR5,модули!$A$27:$B$90,2,0) -> #N/A | BT5: =VLOOKUP(BS5,модули!$B$27:'модули'!$D$90,3,FALSE) -> #N/A | BU5: =T5 -> 0 | BV5: =ROUND(IF(BU5<модули!$A$99,модули!$B$99,IF(BU5>модули!$A$100,модули!$B$100,( ( -0.00000000000000024*BU5^4 + 0.00000000001297181*BU5^3- 0.00000011794827687*BU5^2 + 0.00020947190264916*BU5 + 0.892271997522451)))),4) -> 0.8923 | BW5: =IF(O5="",VLOOKUP(BR5,модули!$F$27:$G$90,2,0),O5) -> #N/A | BX5: =ROUND(EXP(LN(IF(BW5<модули!$H$99,модули!$I$99,IF(BW5>модули!$H$100,модули!$I$100,((9.167685587011E-08*(BW5)^4+0.000015289662956704*(BW5)^3-0.00161875861673315*(BW5)^2+0.0151997782316484*(BW5)+0.962501568438211)))))*модули!$K$98),4) -> #N/A | BY5: =коэффициенты!$G$2 -> 501.259 | BZ5: =BI5*BG5*BK5*BM5*BO5*BQ5*BE5*BT5*BV5*BX5*BY5 -> #N/A | CA5: Наличие уторгования | CB5: =0.91 -> 0.91 | CC5: =ROUND(CB5*BZ5,2) -> #N/A | CD5: =ROUND(CC5*BU5,2) -> #N/A | CE5: =$CE$1 -> 8020 | CF5: СТ16_Ф1_М20_18052021_Бунаков_НовыеОбъекты | CG5: =IF(OR(CD5<0,CD5=0),"ОТРИЦАТЕЛЬНОЕ ЗНАЧЕНИЕ","Готов") -> #N/A | CH5: =BA5 -> 0 | CI5: 13. СЕГМЕНТ "Садоводство и огородничество, малоэтажная жилая застройка" | CJ5: =13 -> 13 | CK5: =VLOOKUP(CH5,'справочник ври'!$A$3:$B$271,2,0) -> #N/A | CL5: =AQ5 -> 0 | CM5: =IF(OR(CC5<19,CC5>1914),"Отклонение УПКС","УПКС в допустимом интервале") -> #N/A
A6: Select ID,Source_ID,CadastralNumber,DateCreated,CadastralBlock,Name,ObjectType,Area,AreaUnit,AreaInaccuracy,LocationinBounds,LocationPlaced,ElaborationReferenceMark,ElaborationDistance,ElaborationDirection,AddressOrLocation,FIAS,OKATO,KLADR,OKTMO,PostalCode,AddressRF,Region,DistrictName,DistrictType,CityName,CityType,UrbanDistrictName,UrbanDistrictType,SovietVillageName,SovietVillageType,LocalityName,LocalityType,PlanningElementName,PlanningElementType,StreetName,StreetType,Level1Type,Level1Value,Level2Type,Level2Value,Level3Type,Level3Value,ApartmentType,ApartmentValue,AddressOther,AddressNote,ParcelCategory,Utilization,UtilizationByDoc,UtilizationLandUse,UtilizationТхт,CostValue,CostUnit,CostDateValuation,CostDateEntering,CostDateApproval,CostDocNumber,CostDocDate,CostApplicationDate,CostRevisalStatementDate,CostApplicationLastDate,CostDocName,FacilityKN,FacilityKNPurpose,SurveyProjectNum,DecisionCodeDocument,DecisionName,DecisionSeries,DecisionNumber,DecisionDate,DecisionIssueOrgan,DecisionDesc,HiredHouseUse,HouseActBuilding,HouseActDevelopment,BuildingContractName,DevelopContractName,OwnerDecision,SupportContractName,CodeDocument,DocHiredHouseName,DocHiredHouseSeries,DocHiredHouseNumber,DocHiredHouseDate,DocHiredHouseIssueOrgan,DocHiredHouseDesc,LimitedRightNumber,CREATEOPERATORNAME,CREATEDATE,OPERATORNAME,MODIFYDATE,MI_STYLE,Specific_CadastralCost,CadastralCost,CadastralCostDesc,MO_Name,ID_Group,LocalityCode,locTypeUse2,loc_VICode,loc_GroupName,loc_VRICode,Sourse_loc_VICode,locTypeUse,inputpacket_id,loc_SgCode,VIP_Sp,Quant_Kontur,Quant_Point,Sum_Square,Sum_Perim,Proc_Diff_Square,Pr_Diff,Source_Sum_Square,SourceLocalityCode,Upload_Scroll,Date_KC,Segment,FlagLocalityCode,DistanceToRoad,DistanceToCMO,СМО,PresenceGas,SourcePresenceGas,PresenceHeating,SourcePresenceHeating,PresencePower,SourcePresencePower,PresenceWaterDisposal,SourcePresenceWaterDisposal,PresenceWaterSupply,SourcePresenceWaterSupply,DistanceToEKB,DistanceToRoadEKB,CCoordX,CCoordY,DistanceToMetro,DistanceToStationEKB,CostZone,DistanceToRRStation,costzone2,Textloc_VICode,act_sign,MaxFloor,Enc_squre,Enc_proc,Adm_rn_EKB,forestry,InfluenceZone_IGS,loc_factor_801,loc_factor_802,loc_factor_803,loc_factor_804,loc_factor_806,loc_factor_807,loc_factor_8071,loc_factor_809,loc_factor_8091,loc_factor_810,loc_factor_8101,loc_factor_811,loc_factor_8111,loc_factor_812,loc_factor_8121,loc_factor_813,loc_factor_814,loc_factor_815,loc_factor_816,loc_factor_8161,loc_factor_817,loc_factor_818,loc_factor_819,loc_factor_820,loc_factor_8201,loc_factor_821,loc_factor_822,loc_factor_823,loc_factor_8231,loc_factor_824,loc_factor_825,loc_factor_826,loc_factor_827,loc_factor_828,loc_factor_829,loc_factor_830,loc_factor_831,loc_factor_832,loc_factor_833,loc_factor_8331,loc_factor_835,loc_factor_836,loc_factor_837,loc_factor_838,Statement,Type_Statement,Status_Statement,DistanceToVZC,VRI_IGS,Cot_name,DistanceToZTB,PowerLines,loc_factor_839,KodMO,loc_factor_840,loc_factor_841,presence_entrance,loc_factor_8371,ControlSP,Sp_flag,loc_VRICode540,Status_kc,Date_comm,Sol_comm,Flag_LocalityCode,Flag_VRI,Flag_Location,FlagParam,Flag_VRIoldspr,Flag_VRInewspr,Flag_Category,OldLocalityCode,Flag_VRI_All,VRICode_NEW,PraviloVRI,New_id_group,New_loc_SgCode,New_Segment,Old_Utlbydoc,VRICode_OLD,PraviloVRI_old,Court,Date_Court,Sol_Court,(select (case count(*) when 0 then 0 else 1 end) from GEO.docboxes b where b.obj_id=PARCELS.ID and b.table_id=265) Attachment,(select sign(Count(*)) from PARCELS g where (not GEOM_OBJ is null) and (PARCELS.ID = g.ID)) GeometryExists,((select DatePacket from inputpacket where id=Parcels.inputpacket_id) ) [inputpacket_date] From PARCELS where status_kc='НЕ ГОТОВ' AND (CadastralCost='' OR CadastralCost is Null) AND New_id_group=8020 | BA6: =IF(OR(AR6="13:021",AR6="13:011"),IF(AV6="Коттеджные_поселки","13:031",AR6),IF(OR(AR6="02:010",AR6="02:011",AR6="02:020",AR6="02:021",AR6="02:023"),IF(AV6="Коттеджные_поселки","02:019",AR6),AR6)) -> 0 | BB6: =IF(AU6="",IF(AF6<>"","ОСПАРИВАНИЕ",IF(Y6="","",Y6)),AU6) | BC6: =B6 -> 0 | BD6: =VLOOKUP(BA6,модули!$K$27:$L$37,2,0) -> #N/A | BE6: =VLOOKUP(BD6,модули!$L$27:'модули'!$M$37,2,FALSE) -> #N/A | BF6: Отсутствие газоснабжения | BG6: =VLOOKUP(BF6,модули!$B$7:'модули'!$D$18,3,FALSE) -> 1 | BH6: Наличие электроснабжения | BI6: =VLOOKUP(BH6,модули!$F$7:'модули'!$H$18,3,FALSE) -> 1.2297 | BJ6: Отсутствие водоснабжения | BK6: =VLOOKUP(BJ6,модули!$J$7:'модули'!$L$18,3,FALSE) -> 1 | BL6: Отсутствие водоотведения | BM6: =VLOOKUP(BL6,модули!$N$7:'модули'!$P$18,3,FALSE) -> 1 | BN6: Отсутствие ЛЭП | BO6: =VLOOKUP(BN6,модули!$R$7:'модули'!$T$16,3,FALSE) -> 1 | BP6: Наличие подъезда | BQ6: =VLOOKUP(BP6,модули!$V$7:'модули'!$X$17,3,FALSE) -> 1.2423 | BR6: =IFERROR(IF(P6="",VLOOKUP(C6,модули!$Q$26:$R$7017,2,0),P6),VLOOKUP(AB6,модули!$T$26:$U$39,2,0)) -> #N/A | BS6: =VLOOKUP(BR6,модули!$A$27:$B$90,2,0) -> #N/A | BT6: =VLOOKUP(BS6,модули!$B$27:'модули'!$D$90,3,FALSE) -> #N/A | BU6: =T6 -> 0 | BV6: =ROUND(IF(BU6<модули!$A$99,модули!$B$99,IF(BU6>модули!$A$100,модули!$B$100,( ( -0.00000000000000024*BU6^4 + 0.00000000001297181*BU6^3- 0.00000011794827687*BU6^2 + 0.00020947190264916*BU6 + 0.892271997522451)))),4) -> 0.8923 | BW6: =IF(O6="",VLOOKUP(BR6,модули!$F$27:$G$90,2,0),O6) -> #N/A | BX6: =ROUND(EXP(LN(IF(BW6<модули!$H$99,модули!$I$99,IF(BW6>модули!$H$100,модули!$I$100,((9.167685587011E-08*(BW6)^4+0.000015289662956704*(BW6)^3-0.00161875861673315*(BW6)^2+0.0151997782316484*(BW6)+0.962501568438211)))))*модули!$K$98),4) -> #N/A | BY6: =коэффициенты!$G$2 -> 501.259 | BZ6: =BI6*BG6*BK6*BM6*BO6*BQ6*BE6*BT6*BV6*BX6*BY6 -> #N/A | CA6: Наличие уторгования | CB6: =0.91 -> 0.91 | CC6: =ROUND(CB6*BZ6,2) -> #N/A | CD6: =ROUND(CC6*BU6,2) -> #N/A | CE6: =$CE$1 -> 8020 | CF6: СТ16_Ф1_М20_18052021_Бунаков_НовыеОбъекты | CG6: =IF(OR(CD6<0,CD6=0),"ОТРИЦАТЕЛЬНОЕ ЗНАЧЕНИЕ","Готов") -> #N/A | CH6: =BA6 -> 0 | CI6: 13. СЕГМЕНТ "Садоводство и огородничество, малоэтажная жилая застройка" | CJ6: =13 -> 13 | CK6: =VLOOKUP(CH6,'справочник ври'!$A$3:$B$271,2,0) -> #N/A | CL6: =AQ6 -> 0 | CM6: =IF(OR(CC6<19,CC6>1914),"Отклонение УПКС","УПКС в допустимом интервале") -> #N/A

Sheet коэффициенты
A1: Номер модели | B1: Фактор | C1: Тип фактора | D1: Градации (код) | E1: Возможные градации (описание) | F1: Значение коэффициента регрессора в мультипликативной модели | G1: Значение градации | H1: Признак типовой зоны | I1: Коэффициент регрессора | J1: Минимальное значение числовой переменной | K1: Максимальное значение числовой переменной | L1: Максимальное значение фактора | M1: Миниимальное значение фактора | O1: № Фактора в модели | P1: Не знаю что это такое
F2: 6.2171229 | G2: =ROUND(EXP(F2),4) -> 501.259
A3: 8020 | B3: Вид разрешенного использования | C3: Качественный | D3: gr1 | E3: Садовые объединения | F3: 0 | G3: =ROUND(EXP(F3),4) -> 1 | O3: V1 | P3: =F3 -> 0
A4: 8020 | D4: gr3 | E4: Дачные и коттеджные объединения | F4: 0.09846646 | G4: =ROUND(EXP(F4),4) -> 1.1035 | P4: =F4 -> 0.09846646
A5: 8020 | D5: gr4 | E5: Индивидуальные поселения | F5: 0.33946031 | G5: =ROUND(EXP(F5),4) -> 1.4042 | P5: =F5 -> 0.33946031
A6: 8020 | B6: Газоснабжение | C6: Качественный | D6: YS | E6: Наличие газоснабжения | F6: 0.35394829 | G6: =ROUND(EXP(F6),4) -> 1.4247 | O6: V2 | P6: =F6 -> 0.35394829
A7: 8020 | D7: VZ | E7: Возможность подключения газоснабжения | F7: 0.31727087 | G7: =ROUND(EXP(F7),4) -> 1.3734 | P7: =F7 -> 0.31727087
A8: 8020 | D8: NO | E8: Отсутствие газоснабжения | F8: =ROUND(P8,4) -> 0 | G8: =ROUND(EXP(F8),4) -> 1
A9: 8020 | B9: Электроснабжение | C9: Качественный | D9: YS | E9: Наличие электроснабжения | F9: 0.20679468 | G9: =ROUND(EXP(F9),4) -> 1.2297 | O9: V3 | P9: =F9 -> 0.20679468
A10: 8020 | D10: VZ | E10: Возможность подключения электроснабжения | F10: 0.095905143 | G10: =ROUND(EXP(F10),4) -> 1.1007 | P10: =F10 -> 0.095905143
A11: 8020 | D11: NO | E11: Отсутствие электроснабжения | F11: 0 | G11: =ROUND(EXP(F11),4) -> 1 | P11: =F11 -> 0
A12: 8020 | B12: Водоснабжение | C12: Качественный | D12: YS | E12: Наличие водоснабжения | F12: 0.15520984 | G12: =ROUND(EXP(F12),4) -> 1.1679 | O12: V4 | P12: =F12 -> 0.15520984
A13: 8020 | D13: NO | E13: Отсутствие водоснабжения | F13: 0 | G13: =ROUND(EXP(F13),4) -> 1 | P13: =F13 -> 0
A14: 8020 | B14: Водоотведение | C14: Качественный | D14: YS | E14: Наличие водоотведения | F14: 0.095564568 | G14: =ROUND(EXP(F14),4) -> 1.1003 | O14: V5 | P14: =F14 -> 0.095564568
A15: 8020 | D15: NO | E15: Отсутствие водоотведения | F15: 0 | G15: =ROUND(EXP(F15),4) -> 1 | P15: =F15 -> 0
A16: 8020 | B16: ЛЭП над участком | C16: Качественный | D16: YS | E16: Наличие ЛЭП | F16: -1.2283471 | G16: =ROUND(EXP(F16),4) -> 0.2928 | O16: V6 | P16: =F16 -> -1.2283471
A17: 8020 | D17: NO | E17: Отсутствие ЛЭП | F17: 0 | G17: =ROUND(EXP(F17),4) -> 1 | P17: =F17 -> 0
A18: 8020 | B18: Подъезд к участку | C18: Качественный | D18: YS | E18: Наличие подъезда | F18: 0.21695849 | G18: =ROUND(EXP(F18),4) -> 1.2423 | O18: V7 | P18: =F18 -> 0.21695849
A19: 8020 | D19: NO | E19: Отсутствие подъезда | F19: 0 | G19: =ROUND(EXP(F19),4) -> 1 | P19: =F19 -> 0
A20: 8020 | B20: Зона влияния ИЖС | C20: Качественный | D20: aram_1 | E20: Арамильский_1 | F20: 0 | G20: =ROUND(EXP(F20),4) -> 1 | O20: V8 | P20: =F20 -> 0
A21: 8020 | D21: aram_2 | E21: Арамильский_2 | F21: -0.45266681 | G21: =ROUND(EXP(F21),4) -> 0.6359 | P21: =F21 -> -0.45266681
A22: 8020 | D22: Belo_1 | E22: Белоярский_1 | F22: -0.41739421 | G22: =ROUND(EXP(F22),4) -> 0.6588 | P22: =F22 -> -0.41739421
A23: 8020 | D23: Belo_10 | E23: Белоярский_10 | F23: -1.4929498 | G23: =ROUND(EXP(F23),4) -> 0.2247 | P23: =F23 -> -1.4929498
A24: 8020 | D24: Belo_11 | E24: Белоярский_11 | F24: -1.555925 | G24: =ROUND(EXP(F24),4) -> 0.211
A25: 8020 | D25: Belo_12 | E25: Белоярский_12 | F25: -0.93615192 | G25: =ROUND(EXP(F25),4) -> 0.3921
A26: 8020 | D26: Belo_2 | E26: Белоярский_2 | F26: -0.88111085 | G26: =ROUND(EXP(F26),4) -> 0.4143
A27: 8020 | D27: Belo_3 | E27: Белоярский_3 | F27: -0.98013797 | G27: =ROUND(EXP(F27),4) -> 0.3753
A28: 8020 | D28: Belo_4 | E28: Белоярский_4 | F28: -1.1774925 | G28: =ROUND(EXP(F28),4) -> 0.3081
A29: 8020 | D29: Belo_5 | E29: Белоярский_5 | F29: -1.0831564 | G29: =ROUND(EXP(F29),4) -> 0.3385
A30: 8020 | D30: Belo_6 | E30: Белоярский_6 | F30: -1.4544216 | G30: =ROUND(EXP(F30),4) -> 0.2335
A31: 8020 | D31: Belo_7 | E31: Белоярский_7 | F31: -1.408049 | G31: =ROUND(EXP(F31),4) -> 0.2446
A32: 8020 | D32: Belo_8 | E32: Белоярский_8 | F32: -1.470316 | G32: =ROUND(EXP(F32),4) -> 0.2299
A33: 8020 | D33: Belo_9 | E33: Белоярский_9 | F33: -1.6546605 | G33: =ROUND(EXP(F33),4) -> 0.1912
A34: 8020 | D34: berz_1 | E34: Березовский_1 | F34: -0.1964732 | G34: =ROUND(EXP(F34),4) -> 0.8216
A35: 8020 | D35: bezr_2 | E35: Березовский_2 | F35: -0.88179076 | G35: =ROUND(EXP(F35),4) -> 0.414
... A65: 8020 | D65: sysr_22 | E65: Сысертский_22 | F65: -1.166783 | G65: =ROUND(EXP(F65),4) -> 0.3114
A66: 8020 | D66: sysr_23 | E66: Сысертский_23 | F66: =F69 -> -0.75060315 | G66: =ROUND(EXP(F66),4) -> 0.4721
A67: 8020 | D67: sysr_24 | E67: Сысертский_24 | F67: =F69 -> -0.75060315 | G67: =ROUND(EXP(F67),4) -> 0.4721
A68: 8020 | D68: sysr_25 | E68: Сысертский_25 | F68: =F65 -> -1.166783 | G68: =ROUND(EXP(F68),4) -> 0.3114
A69: 8020 | D69: sysr_26 | E69: Сысертский_26 | F69: -0.75060315 | G69: =ROUND(EXP(F69),4) -> 0.4721
...

Sheet справочник ври
A1: loc_VICode | B1: loc_GroupName
A2: Код расчета вида использования | B2: Наименование вида использования
A3: 01:010 | B3: Растениеводство в целом. Включает коды расчета вида использования 01.020-01.060
A4: 01:020 | B4: Выращивание зерновых, бобовых, кормовых, технических, масличных, эфиромасличных и иных сельскохозяйственных культур
A5: 01:030 | B5: Овощеводство в целом, связанное с производством картофеля, листовых, плодовых, луковичных и бахчевых сельскохозяйственных культур, в том числе с использованием теплиц
A6: 01:031 | B6: Овощеводство в открытом грунте
A7: 01:032 | B7: Овощеводство тепличное
A8: 01:040 | B8: Выращивание тонизирующих, лекарственных, цветочных культур в целом
A9: 01:041 | B9: Выращивание тонизирующих, лекарственных, цветочных культур. Травы
A10: 01:042 | B10: Выращивание тонизирующих, лекарственных, цветочных культур. Кустарники
A11: 01:050 | B11: Садоводство в целом - выращивание многолетних плодовых и ягодных культур, винограда и иных многолетних культур
A12: 01:051 | B12: Садоводство плодовое
... A271: 14:000 | B271: Иное использование

Sheet ГОТОВ
A1: CadastralNumber | B1: loc_factor_825 | D1: loc_factor_822 | F1: loc_factor_804 | H1: loc_factor_828 | J1: loc_factor_803 | L1: loc_factor_829 | N1: loc_factor_840 | Q1: loc_factor_826 | S1: loc_factor_807 | T1: loc_factor_8071 | U1: loc_factor_833 | Y1: loc_factor_827 | AA1: Specific_CadastralCost | AB1: CadastralCost | AC1: id_group | AD1: CadastralCostDesc | AE1: Status_kc | AF1: loc_VICode | AG1: Segment | AH1: loc_SgCode | AI1: loc_GroupName | AJ1: Old_Utlbydoc

Sheet модули
A2: семантика
A4: Газоснабжение (ЦФ) | E4: Электроснабжение (ЦФ) | I4: Водоснабжение (ЦФ) | M4: Водоотведение (ЦФ) | Q4: ЛЭП над участком (ЦФ) | U4: Подъезд к участку (ЦФ)
A5: текст | B5: правило | E5: текст | F5: правило | I5: текст | J5: правило | M5: текст | N5: правило | Q5: правило | U5: текст | V5: правило
A7: иное | B7: Ошибка определения | C7: !MST! | E7: иное | F7: Ошибка определения | G7: !MST! | I7: иное | J7: Ошибка определения | K7: !MST! | M7: иное | N7: Ошибка определения | O7: !MST! | Q7: иное(возможность) | R7: Ошибка определения | S7: !MST! | U7: иное(возможность) | V7: Ошибка определения | W7: !MST!
A8: наличие | B8: Наличие газоснабжения | C8: YS | D8: =коэффициенты!G6 -> 1.4247 | E8: наличие | F8: Наличие электроснабжения | G8: YS | H8: =коэффициенты!G9 -> 1.2297 | I8: наличие | J8: Наличие водоснабжения | K8: YS | L8: =коэффициенты!G12 -> 1.1679 | M8: наличие | N8: Наличие водоотведения | O8: YS | P8: =коэффициенты!G14 -> 1.1003 | Q8: Наличие ЛЭП | R8: Наличие ЛЭП | S8: YS | T8: =коэффициенты!G16 -> 0.2928 | U8: Есть подъезд | V8: Наличие подъезда | W8: YS | X8: =коэффициенты!G18 -> 1.2423
A9: Наличие | B9: Наличие газоснабжения | C9: YS | D9: =коэффициенты!G6 -> 1.4247 | E9: Наличие | F9: Наличие электроснабжения | G9: YS | H9: =коэффициенты!G9 -> 1.2297 | I9: Наличие | J9: Наличие водоснабжения | K9: YS | L9: =коэффициенты!G12 -> 1.1679 | M9: Наличие | N9: Наличие водоотведения | O9: YS | P9: =коэффициенты!G14 -> 1.1003 | Q9: Наличие | R9: Наличие ЛЭП | S9: YS | T9: =коэффициенты!G16 -> 0.2928 | U9: отсыпанная | V9: Наличие подъезда | W9: YS | X9: =коэффициенты!G18 -> 1.2423
A10: есть | B10: Наличие газоснабжения | C10: YS | D10: =коэффициенты!G6 -> 1.4247 | E10: есть | F10: Наличие электроснабжения | G10: YS | H10: =коэффициенты!G9 -> 1.2297 | I10: есть | J10: Наличие водоснабжения | K10: YS | L10: =коэффициенты!G12 -> 1.1679 | M10: есть | N10: Наличие водоотведения | O10: YS | P10: =коэффициенты!G14 -> 1.1003 | Q10: есть | R10: Наличие ЛЭП | S10: YS | T10: =коэффициенты!G16 -> 0.2928 | U10: асфальт | V10: Наличие подъезда | W10: YS | X10: =коэффициенты!G18 -> 1.2423
A11: Есть | B11: Наличие газоснабжения | C11: YS | D11: =коэффициенты!G6 -> 1.4247 | E11: Есть | F11: Наличие электроснабжения | G11: YS | H11: =коэффициенты!G9 -> 1.2297 | I11: Есть | J11: Наличие водоснабжения | K11: YS | L11: =коэффициенты!G12 -> 1.1679 | M11: Есть | N11: Наличие водоотведения | O11: YS | P11: =коэффициенты!G14 -> 1.1003 | Q11: Есть | R11: Наличие ЛЭП | S11: YS | T11: =коэффициенты!G16 -> 0.2928 | U11: грунтовая | V11: Наличие подъезда | W11: YS | X11: =коэффициенты!G18 -> 1.2423
A12: нет | B12: Отсутствие газоснабжения | C12: NO | D12: =коэффициенты!G8 -> 1 | E12: нет | F12: Отсутствие электроснабжения | G12: NO | H12: =коэффициенты!G11 -> 1 | I12: нет | J12: Отсутствие водоснабжения | K12: NO | L12: =коэффициенты!G13 -> 1 | M12: нет | N12: Отсутствие водоотведения | O12: NO | P12: =коэффициенты!G15 -> 1 | Q12: нет | R12: Отсутствие ЛЭП | S12: YS | T12: =коэффициенты!G17 -> 1 | U12: Есть | V12: Наличие подъезда | W12: YS | X12: =коэффициенты!G18 -> 1.2423
A13: Нет | B13: Отсутствие газоснабжения | C13: NO | D13: =коэффициенты!G8 -> 1 | E13: Нет | F13: Отсутствие электроснабжения | G13: NO | H13: =коэффициенты!G11 -> 1 | I13: Нет | J13: Отсутствие водоснабжения | K13: NO | L13: =коэффициенты!G13 -> 1 | M13: Нет | N13: Отсутствие водоотведения | O13: NO | P13: =коэффициенты!G15 -> 1 | Q13: Нет | R13: Отсутствие ЛЭП | S13: NO | T13: =коэффициенты!G17 -> 1 | U13: нет | V13: Отсутствие подъезда | W13: NO | X13: =коэффициенты!G19 -> 1
A14: Отсутствие | B14: Отсутствие газоснабжения | C14: NO | D14: =коэффициенты!G8 -> 1 | E14: Отсутствие | F14: Отсутствие электроснабжения | G14: NO | H14: =коэффициенты!G11 -> 1 | I14: Отсутствие | J14: Отсутствие водоснабжения | K14: NO | L14: =коэффициенты!G13 -> 1 | M14: Отсутствие | N14: Отсутствие водоотведения | O14: NO | P14: =коэффициенты!G15 -> 1 | Q14: Отсутствие ЛЭП | R14: Отсутствие ЛЭП | S14: NO | T14: =коэффициенты!G17 -> 1 | U14: Нет | V14: Отсутствие подъезда | W14: NO | X14: =коэффициенты!G19 -> 1
A15: отсутствие | B15: Отсутствие газоснабжения | C15: NO | D15: =коэффициенты!G8 -> 1 | E15: отсутствие | F15: Отсутствие электроснабжения | G15: NO | H15: =коэффициенты!G11 -> 1 | I15: отсутствие | J15: Отсутствие водоснабжения | K15: NO | L15: =коэффициенты!G13 -> 1 | M15: отсутствие | N15: Отсутствие водоотведения | O15: NO | P15: =коэффициенты!G15 -> 1 | R15: Отсутствие ЛЭП | S15: NO | T15: =коэффициенты!G17 -> 1 | U15: Отсутствие | V15: Отсутствие подъезда | W15: NO | X15: =коэффициенты!G19 -> 1
A16: пересечение | B16: Возможность подключения газоснабжения | C16: VZ | D16: =коэффициенты!G7 -> 1.3734 | E16: возможность | F16: Возможность подключения электроснабжения | G16: VZ | H16: =коэффициенты!G9 -> 1.2297 | I16: 0 | J16: Отсутствие водоснабжения | K16: NO | L16: =коэффициенты!G13 -> 1 | M16: 0 | N16: Отсутствие водоотведения | O16: NO | P16: =коэффициенты!G15 -> 1 | Q16: 0 | R16: Отсутствие ЛЭП | S16: NO | T16: =коэффициенты!G17 -> 1 | U16: отсутствие | V16: Отсутствие подъезда | W16: NO | X16: =коэффициенты!G19 -> 1
A17: Пересечение | B17: Возможность подключения газоснабжения | C17: VZ | D17: =коэффициенты!G7 -> 1.3734 | E17: рядом | F17: Возможность подключения электроснабжения | G17: VZ | H17: =коэффициенты!G9 -> 1.2297 | J17: Отсутствие водоснабжения | K17: NO | L17: =коэффициенты!G13 -> 1 | N17: Отсутствие водоотведения | O17: NO | P17: =коэффициенты!G15 -> 1 | U17: 0 | V17: Наличие подъезда | W17: YS | X17: =коэффициенты!G18 -> 1.2423
A18: 0 | B18: Отсутствие газоснабжения | C18: NO | D18: =коэффициенты!G8 -> 1 | E18: 0 | F18: Отсутствие электроснабжения | G18: NO | H18: =коэффициенты!G11 -> 1 | J18: Отсутствие водоснабжения | K18: NO | L18: =коэффициенты!G13 -> 1 | N18: Отсутствие водоотведения | O18: NO | P18: =коэффициенты!G15 -> 1 | V18: Наличие подъезда | W18: YS | X18: =коэффициенты!G18 -> 1.2423
A19: контрольный образец | B19: Модуль | E19: контрольный образец | F19: Модуль | I19: контрольный образец | J19: Модуль | M19: контрольный образец | N19: Модуль | Q19: контрольный образец | R19: Модуль | U19: контрольный образец | V19: Модуль
B20: =IF(A20=$A$17,$B$17,IF(A20=$A$16,$B$16,IF(A20=$A$8,$B$8,IF(A20=$A$9,$B$9,IF(A20=$A$10,$B$10,IF(A20=$A$11,$B$11,IF(A20=$A$12,$B$12,IF(A20=$A$13,$B$13,IF(A20=$A$14,$B$14,IF(A20=$A$15,$B$15,IF(A20=$A$18,B$18,$B$7))))))))))) -> Отсутствие газоснабжения | C20: =VLOOKUP(B20,$B$7:$C$18,2,FALSE) -> NO | D20: =VLOOKUP(B20,$B$7:$D$18,3,FALSE) -> 1 | E20: пересечение | F20: =IF(E20=$E$16,$F$17,IF(E20=$E$15,$F$16,IF(E20=$E$7,$F$8,IF(E20=$E$8,$F$9,IF(E20=$E$9,$F$10,IF(E20=$E$10,$F$11,IF(E20=$E$11,$F$12,IF(E20=$E$12,$F$13,IF(E20=$E$13,$F$14,IF(E20=$E$14,$F$15,IF(E20=$E$17,F$18,$F$7))))))))))) -> Ошибка определения | G20: =VLOOKUP(F20,$F$7:$G$18,2,FALSE) -> !MST! | H20: =VLOOKUP(F20,$F$7:$H$18,3,FALSE) -> 0 | I20: наличие | J20: =IF(I20=$I$8,$J$8,IF(I20=$I$9,$J$9,IF(I20=$I$10,$J$10,IF(I20=$I$11,$J$11,IF(I20=$I$12,$J$12,IF(I20=$I$13,$J$13,IF(I20=$I$14,$J$14,IF(I20=$I$15,$J$15,IF(I20=$I$18,J$18,$J$7))))))))) -> Наличие водоснабжения | K20: =VLOOKUP(J20,$J$7:$K$18,2,FALSE) -> YS | L20: =VLOOKUP(J20,$J$7:$L$18,3,FALSE) -> 1.1679 | M20: пересечение | N20: =IF(M20=$M$8,$N$8,IF(M20=$M$9,$N$9,IF(M20=$M$10,$N$10,IF(M20=$M$11,$N$11,IF(M20=$M$12,$N$12,IF(M20=$M$13,$N$13,IF(M20=$M$14,$N$14,IF(M20=$M$15,$N$15,IF(M20=$M$18,N$18,$N$7))))))))) -> Ошибка определения | O20: =VLOOKUP(N20,$N$7:$O$18,2,FALSE) -> !MST! | P20: =VLOOKUP(N20,$N$7:$P$18,3,FALSE) -> 0 | R20: =IF(Q20=$Q$8,$R$8,IF(Q20=$Q$9,$R$9,IF(Q20=$Q$10,$R$10,IF(Q20=$Q$11,$R$11,IF(Q20=$Q$12,$R$12,IF(Q20=$Q$13,$R$13,IF(Q20=$Q$14,$R$14,IF(Q20=$Q$15,$R$15,IF(Q20=$Q$16,R$16,$R$7))))))))) -> Отсутствие ЛЭП | S20: =VLOOKUP(R20,$R$7:$S$16,2,FALSE) -> YS | T20: =VLOOKUP(R20,$R$7:$T$16,3,FALSE) -> 1 | V20: =IF(U20=$U$7,$V$7,IF(U20=$U$8,$V$8,IF(U20=$U$9,$V$9,IF(U20=$U$10,$V$10,IF(U20=$U$11,$V$11,IF(U20=$U$12,$V$12,IF(U20=$U$13,$V$13,IF(U20=$U$14,$V$14,IF(U20=$U$15,$V$15,IF(U20=$U$16,$V$16,IF(U20=$U$17,V$17,$V$7))))))))))) -> Наличие подъезда | W20: =VLOOKUP(V20,$V$7:$W$17,2,FALSE) -> YS | X20: =VLOOKUP(V20,$V$7:$X$17,3,FALSE) -> 1.2423
A22: точное совпадение
A24: =коэффициенты!B20 -> Зона влияния ИЖС | E24: среднезональные расстояния | J24: =коэффициенты!B3 -> Вид разрешенного использования
Q25: КН | R25: Зона | T25: MO | U25: ZonaIGS
A26: =коэффициенты!D1 -> Градации (код) | B26: =коэффициенты!E1 -> Возможные градации (описание) | D26: =коэффициенты!G1 -> Значение градации | E26: avg_dst_z0 | F26: zona | G26: avg_dst_z0 | I26: расшифровка ВРИ | J26: =коэффициенты!D1 -> Градации (код) | K26: код ВРИ | L26: =коэффициенты!E1 -> Возможные градации (описание) | M26: =коэффициенты!G1 -> Значение градации | Q26: 66:06:1401001 | R26: Belo_9 | T26: 08 | U26: berz_1
A27: =коэффициенты!D20 -> aram_1 | B27: =коэффициенты!E20 -> Арамильский_1 | C27: =B27 -> Арамильский_1 | D27: =коэффициенты!G20 -> 1 | E27: 5.001692 | F27: aram_1 | G27: 5.001692 | I27: Индивидуальное жилищное строительство в целом | J27: gr4 | K27: 02:010 | L27: =коэффициенты!E5 -> Индивидуальные поселения | M27: =ROUND( коэффициенты!G5,4) -> 1.4042 | Q27: 66:06:4502001 | R27: Belo_9 | T27: 32 | U27: purl_1
A28: =коэффициенты!D21 -> aram_2 | B28: =коэффициенты!E21 -> Арамильский_2 | C28: =B28 -> Арамильский_2 | D28: =коэффициенты!G21 -> 0.6359 | E28: 5 | F28: aram_2 | G28: 5 | I28: Размещение индивидуального жилого дома (дом, пригодный для постоянного проживания, высотой не выше трех надземных этажей), размещение индивидуальных гаражей и подсобных сооружений, исходя из минимальных норм отвода земельных участков для индивидуального | J28: gr4 | K28: 02:011 | L28: =коэффициенты!E5 -> Индивидуальные поселения | M28: =ROUND( коэффициенты!G5,4) -> 1.4042 | Q28: 66:06:4503005 | R28: Belo_10 | T28: 67 | U28: sysr_19
A29: =коэффициенты!D22 -> Belo_1 | B29: =коэффициенты!E22 -> Белоярский_1 | C29: =B29 -> Белоярский_1 | D29: =коэффициенты!G22 -> 0.6588 | E29: 5.280016 | F29: Belo_1 | G29: 5.280016 | I29: Размещение индивидуального жилого дома в организованных коттеджных поселках | J29: gr4 | K29: 02:019 | L29: =коэффициенты!E5 -> Индивидуальные поселения | M29: =ROUND( коэффициенты!G5,4) -> 1.4042 | Q29: 66:06:4503008 | R29: Belo_9 | T29: 17 | U29: vdbr_1
A30: =коэффициенты!D23 -> Belo_10 | B30: =коэффициенты!E23 -> Белоярский_10 | C30: =B30 -> Белоярский_10 | D30: =коэффициенты!G23 -> 0.2247 | E30: 5.959523 | F30: Belo_10 | G30: 5.959523 | I30: Ведение личного подсобного хозяйства с правом застройки в целом | J30: gr4 | K30: 02:020 | L30: =коэффициенты!E5 -> Индивидуальные поселения | M30: =ROUND( коэффициенты!G5,4) -> 1.4042 | Q30: 66:06:2001002 | R30: Belo_10 | T30: 07 | U30: Belo_1
A31: =коэффициенты!D24 -> Belo_11 | B31: =коэффициенты!E24 -> Белоярский_11 | C31: =B31 -> Белоярский_11 | D31: =коэффициенты!G24 -> 0.211 | E31: 5.060442 | F31: Belo_11 | G31: 5.060442 | I31: Блокированная жилая застройка в целом | J31: gr4 | K31: 02:030 | L31: =коэффициенты!E5 -> Индивидуальные поселения | M31: =ROUND( коэффициенты!G5,4) -> 1.4042 | Q31: 66:06:2001001 | R31: Belo_10 | T31: 60 | U31: pole_1
A32: =коэффициенты!D25 -> Belo_12 | B32: =коэффициенты!E25 -> Белоярский_12 | C32: =B32 -> Белоярский_12 | D32: =коэффициенты!G25 -> 0.3921 | E32: 5.000808 | F32: Belo_12 | G32: 5.000808 | I32: Блокированная жилая застройка. Размещение жилого дома, не предназначенного для раздела на квартиры, имеющего одну или несколько общих стен с соседними жилыми домами (количеством этажей не более чем три, при общем количестве совмещенных домов не более дес | J32: gr4 | K32: 02:031 | L32: =коэффициенты!E5 -> Индивидуальные поселения | M32: =ROUND( коэффициенты!G5,4) -> 1.4042 | Q32: 66:06:2001003 | R32: Belo_10 | T32: 48 | U32: urls_1
A33: =коэффициенты!D26 -> Belo_2 | B33: =коэффициенты!E26 -> Белоярский_2 | C33: =B33 -> Белоярский_2 | D33: =коэффициенты!G26 -> 0.4143 | E33: 5.001222 | F33: Belo_2 | G33: 5.001222 | I33: Ведение личного подсобного хозяйства. Размещение жилого дома, не предназначенного для раздела на квартиры (дома, пригодные для постоянного проживания и высотой не выше трех надземных этажей), размещение гаража и иных вспомогательных сооружений, в том чис | J33: gr4 | K33: 02:021 | L33: =коэффициенты!E5 -> Индивидуальные поселения | M33: =ROUND( коэффициенты!G5,4) -> 1.4042 | Q33: 66:06:2001004 | R33: Belo_10 | T33: 01 | U33: aram_1
A34: =коэффициенты!D27 -> Belo_3 | B34: =коэффициенты!E27 -> Белоярский_3 | C34: =B34 -> Белоярский_3 | D34: =коэффициенты!G27 -> 0.3753 | E34: 5 | F34: Belo_3 | G34: 5 | I34: Ведение крестьянско-фермерского хозяйства. Размещение жилого дома, не предназначенного для раздела на квартиры (дома, пригодные для постоянного проживания и высотой не выше трех надземных этажей), размещение гаража и иных вспомогательных сооружений, в то | J34: gr4 | K34: 02:023 | L34: =коэффициенты!E5 -> Индивидуальные поселения | M34: =ROUND( коэффициенты!G5,4) -> 1.4042 | Q34: 66:06:2001005 | R34: Belo_10 | T34: 23 | U34: degt_1
A35: =коэффициенты!D28 -> Belo_4 | B35: =коэффициенты!E28 -> Белоярский_4 | C35: =B35 -> Белоярский_4 | D35: =коэффициенты!G28 -> 0.3081 | E35: 5 | F35: Belo_4 | G35: 5 | I35: Ведение садоводства. Осуществление отдыха и (или) деятельности, связанной с выращиванием гражданами для собственных нужд сельскохозяйственных культур; размещение садовых домов, жилых домов, размещение для собственных нужд гаражей и иных хозяйственных пос | J35: gr1 | K35: 13:021 | L35: =коэффициенты!E3 -> Садовые объединения | M35: =ROUND( коэффициенты!G3,4) -> 1 | Q35: 66:06:4503004 | R35: Belo_10 | T35: 20 | U35: vpsh_1
A36: =коэффициенты!D29 -> Belo_5 | B36: =коэффициенты!E29 -> Белоярский_5 | C36: =B36 -> Белоярский_5 | D36: =коэффициенты!G29 -> 0.3385 | E36: 5 | F36: Belo_5 | G36: 5 | I36: Ведение огородничества. Осуществление отдыха и (или) деятельности, связанной с выращиванием гражданами для собственных нужд сельскохозяйственных культур; размещение хозяйственных построек, не являющихся объектами недвижимости, предназначенных для хранени | J36: gr1 | K36: 13:011 | L36: =коэффициенты!E3 -> Садовые объединения | M36: =ROUND( коэффициенты!G3,4) -> 1 | Q36: 66:06:4503006 | R36: Belo_9 | T36: 47 | U36: sw3
A37: =коэффициенты!D30 -> Belo_6 | B37: =коэффициенты!E30 -> Белоярский_6 | C37: =B37 -> Белоярский_6 | D37: =коэффициенты!G30 -> 0.2335 | E37: 5.17841 | F37: Belo_6 | G37: 5.17841 | I37: Ведение дачного хозяйства. Размещение жилого дачного дома, не предназначенного для раздела на квартиры, пригодного для отдыха и проживания, высотой не выше трех надземных этажей | J37: gr3 | K37: 13:031 | L37: =коэффициенты!E4 -> Дачные и коттеджные объединения | M37: =ROUND( коэффициенты!G4,4) -> 1.1035 | Q37: 66:06:4503007 | R37: Belo_9 | T37: 35 | U37: surl_1
A38: =коэффициенты!D31 -> Belo_7 | B38: =коэффициенты!E31 -> Белоярский_7 | C38: =B38 -> Белоярский_7 | D38: =коэффициенты!G31 -> 0.2446 | E38: 5.579458 | F38: Belo_7 | G38: 5.579458 | K38: контрольный образец | L38: Модуль | Q38: 66:06:1801001 | R38: Belo_10 | T38: 24 | U38: zare_1
A39: =коэффициенты!D32 -> Belo_8 | B39: =коэффициенты!E32 -> Белоярский_8 | C39: =B39 -> Белоярский_8 | D39: =коэффициенты!G32 -> 0.2299 | E39: 5.30318 | F39: Belo_8 | G39: 5.30318 | K39: 13:031 | L39: =VLOOKUP(K39,$K$27:$L$37,2,FALSE) -> Дачные и коттеджные объединения | M39: =VLOOKUP(L39,$L$27:$M$37,2,FALSE) -> 1.1035 | Q39: 66:06:1901001 | R39: Belo_10 | T39: 33 | U39: revd_1
A40: =коэффициенты!D33 -> Belo_9 | B40: =коэффициенты!E33 -> Белоярский_9 | C40: =B40 -> Белоярский_9 | D40: =коэффициенты!G33 -> 0.1912 | E40: 8.489239 | F40: Belo_9 | G40: 8.489239 | K40: gr3 | L40: =VLOOKUP(K40,$J$27:$L$37,3,FALSE) -> Дачные и коттеджные объединения | M40: =VLOOKUP(K40,$J$27:$M$37,4,FALSE) -> 1.1035 | Q40: 66:06:1901002 | R40: Belo_10
A41: =коэффициенты!D34 -> berz_1 | B41: =коэффициенты!E34 -> Березовский_1 | C41: =B41 -> Березовский_1 | D41: =коэффициенты!G34 -> 0.8216 | E41: 6.682615 | F41: berz_1 | G41: 6.682615 | Q41: 66:06:1901003 | R41: Belo_10
A42: berz_2 | B42: =коэффициенты!E35 -> Березовский_2 | C42: =B42 -> Березовский_2 | D42: =коэффициенты!G35 -> 0.414 | E42: 8.001034 | F42: berz_2 | G42: 8.001034 | Q42: 66:06:1901004 | R42: Belo_10
A43: =коэффициенты!D36 -> degt_1 | B43: =коэффициенты!E36 -> Дегтярский_1 | C43: =B43 -> Дегтярский_1 | D43: =коэффициенты!G36 -> 0.2888 | E43: 5.215725 | F43: degt_1 | G43: 5.215725 | Q43: 66:06:1901005 | R43: Belo_10
A44: =коэффициенты!D37 -> pole_1 | B44: =коэффициенты!E37 -> Полевской_1 | C44: =B44 -> Полевской_1 | D44: =коэффициенты!G37 -> 0.3084 | E44: 8.099409 | F44: pole_1 | G44: 8.099409 | Q44: 66:06:1901006 | R44: Belo_10
A45: =коэффициенты!D38 -> pole_2 | B45: =коэффициенты!E38 -> Полевской_2 | C45: =B45 -> Полевской_2 | D45: =коэффициенты!G38 -> 0.4779 | E45: 6.164619 | F45: pole_2 | G45: 6.164619 | Q45: 66:06:1901007 | R45: Belo_10
...

Sheet количественные факторы
B1: расчетные коэффициенты по модели | G1: !!! Расчет функции по расстоянию до 20 знаков и соответстующие графики в файле 20_modul.xlsx !!!
B2: 0.71448643 | C2: коэффициент по расстоянию | G2: !!! В данный файл вставлены только результирующие расчетные формулы !!!
B3: 0.49564754 | C3: коэффициент по площади | G3: -0,00000000000000018x4 + 0,00000000001213529x3 - 0,00000011429507157x2 + 0,00020471790205693x + 0,89389209437225900
A5: граничные значения | AE5: 9.1676856e-08 | AF5: 1.5289662e-05 | AG5: 0.0016187586 | AH5: 0.015199778 | AI5: 0.96250157
A6: 150 | B6: =(0.000000000032989*A6^3-0.000000270691185*A6^2+0.000468652420503*A6+0.726630359723856)*1.04333245461704 -> 0.82522277 | D6: =B3 -> 0.49564754 | E6: коэффициент по площади | V6: 5 | W6: =(9.167685587011E-08*(V6)^4+0.000015289662956704*(V6)^3-0.00161875861673315*(V6)^2+0.0151997782316484*(V6)+0.962501568438211) -> 1 | Y6: =B2 -> 0.71448643 | Z6: коэффициент по расстоянию
A7: 4000 | B7: =(0.000000000032989*A7^3-0.000000270691185*A7^2+0.000468652420503*A7+0.726630359723856)*1.04333245461704 -> 0.39800742 | V7: 27.5 | W7: =(9.167685587011E-08*(V7)^4+0.000015289662956704*(V7)^3-0.00161875861673315*(V7)^2+0.0151997782316484*(V7)+0.962501568438211) -> 0.52671776 | AD7: 9.1676856e-08 | AE7: 1.5289662e-05 | AF7: 0.0016187586 | AG7: 0.015199778 | AH7: 0.96250157
A8: площадь, кв.м. | B8: исходная функция (желтая) | C8: экспонированная функция (синяя) | E8: аппроксимирующая функция (серая) | G8: контроьные значения аппроксимирующей
A9: 50 | B9: =(IF(A9<$A$6,$B$6,IF(A9>$A$7,$B$7,((0.000000000032989*A9^3-0.000000270691185*A9^2+0.000468652420503*A9+0.726630359723856)*1.04333245461704)))) -> 0.82522277 | C9: =EXP(LN(IF(A9<$A$6,$B$6,IF(A9>$A$7,$B$7,((0.000000000032989*A9^3-0.000000270691185*A9^2+0.000468652420503*A9+0.726630359723856)*1.04333245461704))))*$D$6) -> 0.90917759 | E9: 50 | F9: =C9 -> 0.90917759 | G9: =( -0.00000000000000018*E9^4 + 0.00000000001213529*E9^3- 0.00000011429507157*E9^2 + 0.00020471790205693*E9 + 0.893892094372259) -> 0.90384377 | U9: 1 | V9: =IF(U9<$V$6,$W$6,IF(U9>$V$7,$W$7,((0.00000009*(U9)^4+0.00001501*(U9)^3-0.00158915*(U9)^2+0.01492176*(U9)+0.94489651)*1.0186317318901))) -> 1 | W9: =(EXP(LN(IF(U9<$V$6,$W$6,IF(U9>$V$7,$W$7,((0.00000009*(U9)^4+0.00001501*(U9)^3-0.00158915*(U9)^2+0.01492176*(U9)+0.94489651)*1.0186317318901))))*$Y$6)) -> 1 | X9: =(EXP(LN(IF(U9<$V$6,$W$6,IF(U9>$V$7,$W$7,(($AD$7*(U9)^4+$AE$7*(U9)^3-$AF$7*(U9)^2+$AG$7*(U9)+$AH$7)))))*$Y$6)) -> 1 | Y9: =(EXP(LN(IF(U9<$V$6,$W$6,IF(U9>$V$7,$W$7,((9.167685587011E-08*(U9)^4+0.000015289662956704*(U9)^3-0.00161875861673315*(U9)^2+0.0151997782316484*(U9)+0.962501568438211)))))*$Y$6)) -> 1
A10: 100 | B10: =(IF(A10<$A$6,$B$6,IF(A10>$A$7,$B$7,((0.000000000032989*A10^3-0.000000270691185*A10^2+0.000468652420503*A10+0.726630359723856)*1.04333245461704)))) -> 0.82522277 | C10: =EXP(LN(IF(A10<$A$6,$B$6,IF(A10>$A$7,$B$7,((0.000000000032989*A10^3-0.000000270691185*A10^2+0.000468652420503*A10+0.726630359723856)*1.04333245461704))))*$D$6) -> 0.90917759 | E10: 100 | F10: =C10 -> 0.90917759 | G10: =( -0.00000000000000018*E10^4 + 0.00000000001213529*E10^3- 0.00000011429507157*E10^2 + 0.00020471790205693*E10 + 0.893892094372259) -> 0.91323305 | U10: 2 | V10: =IF(U10<$V$6,$W$6,IF(U10>$V$7,$W$7,((0.00000009*(U10)^4+0.00001501*(U10)^3-0.00158915*(U10)^2+0.01492176*(U10)+0.94489651)*1.0186317318901))) -> 1 | W10: =(EXP(LN(IF(U10<$V$6,$W$6,IF(U10>$V$7,$W$7,((0.00000009*(U10)^4+0.00001501*(U10)^3-0.00158915*(U10)^2+0.01492176*(U10)+0.94489651)*1.0186317318901))))*$Y$6)) -> 1 | X10: =(EXP(LN(IF(U10<$V$6,$W$6,IF(U10>$V$7,$W$7,(($AD$7*(U10)^4+$AE$7*(U10)^3-$AF$7*(U10)^2+$AG$7*(U10)+$AH$7)))))*$Y$6)) -> 1 | Y10: =(EXP(LN(IF(U10<$V$6,$W$6,IF(U10>$V$7,$W$7,((9.167685587011E-08*(U10)^4+0.000015289662956704*(U10)^3-0.00161875861673315*(U10)^2+0.0151997782316484*(U10)+0.962501568438211)))))*$Y$6)) -> 1
A11: 150 | B11: =(IF(A11<$A$6,$B$6,IF(A11>$A$7,$B$7,((0.000000000032989*A11^3-0.000000270691185*A11^2+0.000468652420503*A11+0.726630359723856)*1.04333245461704)))) -> 0.82522277 | C11: =EXP(LN(IF(A11<$A$6,$B$6,IF(A11>$A$7,$B$7,((0.000000000032989*A11^3-0.000000270691185*A11^2+0.000468652420503*A11+0.726630359723856)*1.04333245461704))))*$D$6) -> 0.90917759 | E11: 250 | F11: =C13 -> 0.92970391 | G11: =( -0.00000000000000018*E11^4 + 0.00000000001213529*E11^3- 0.00000011429507157*E11^2 + 0.00020471790205693*E11 + 0.893892094372259) -> 0.93811704 | U11: 3 | V11: =IF(U11<$V$6,$W$6,IF(U11>$V$7,$W$7,((0.00000009*(U11)^4+0.00001501*(U11)^3-0.00158915*(U11)^2+0.01492176*(U11)+0.94489651)*1.0186317318901))) -> 1 | W11: =(EXP(LN(IF(U11<$V$6,$W$6,IF(U11>$V$7,$W$7,((0.00000009*(U11)^4+0.00001501*(U11)^3-0.00158915*(U11)^2+0.01492176*(U11)+0.94489651)*1.0186317318901))))*$Y$6)) -> 1 | X11: =(EXP(LN(IF(U11<$V$6,$W$6,IF(U11>$V$7,$W$7,(($AD$7*(U11)^4+$AE$7*(U11)^3-$AF$7*(U11)^2+$AG$7*(U11)+$AH$7)))))*$Y$6)) -> 1 | Y11: =(EXP(LN(IF(U11<$V$6,$W$6,IF(U11>$V$7,$W$7,((9.167685587011E-08*(U11)^4+0.000015289662956704*(U11)^3-0.00161875861673315*(U11)^2+0.0151997782316484*(U11)+0.962501568438211)))))*$Y$6)) -> 1
A12: 200 | B12: =(IF(A12<$A$6,$B$6,IF(A12>$A$7,$B$7,((0.000000000032989*A12^3-0.000000270691185*A12^2+0.000468652420503*A12+0.726630359723856)*1.04333245461704)))) -> 0.8448876 | C12: =EXP(LN(IF(A12<$A$6,$B$6,IF(A12>$A$7,$B$7,((0.000000000032989*A12^3-0.000000270691185*A12^2+0.000468652420503*A12+0.726630359723856)*1.04333245461704))))*$D$6) -> 0.91985225 | E12: 500 | F12: =C18 -> 0.96790026 | G12: =( -0.00000000000000018*E12^4 + 0.00000000001213529*E12^3- 0.00000011429507157*E12^2 + 0.00020471790205693*E12 + 0.893892094372259) -> 0.96918294 | U12: 4 | V12: =IF(U12<$V$6,$W$6,IF(U12>$V$7,$W$7,((0.00000009*(U12)^4+0.00001501*(U12)^3-0.00158915*(U12)^2+0.01492176*(U12)+0.94489651)*1.0186317318901))) -> 1 | W12: =(EXP(LN(IF(U12<$V$6,$W$6,IF(U12>$V$7,$W$7,((0.00000009*(U12)^4+0.00001501*(U12)^3-0.00158915*(U12)^2+0.01492176*(U12)+0.94489651)*1.0186317318901))))*$Y$6)) -> 1 | X12: =(EXP(LN(IF(U12<$V$6,$W$6,IF(U12>$V$7,$W$7,(($AD$7*(U12)^4+$AE$7*(U12)^3-$AF$7*(U12)^2+$AG$7*(U12)+$AH$7)))))*$Y$6)) -> 1 | Y12: =(EXP(LN(IF(U12<$V$6,$W$6,IF(U12>$V$7,$W$7,((9.167685587011E-08*(U12)^4+0.000015289662956704*(U12)^3-0.00161875861673315*(U12)^2+0.0151997782316484*(U12)+0.962501568438211)))))*$Y$6)) -> 1
A13: 250 | B13: =(IF(A13<$A$6,$B$6,IF(A13>$A$7,$B$7,((0.000000000032989*A13^3-0.000000270691185*A13^2+0.000468652420503*A13+0.726630359723856)*1.04333245461704)))) -> 0.86324359 | C13: =EXP(LN(IF(A13<$A$6,$B$6,IF(A13>$A$7,$B$7,((0.000000000032989*A13^3-0.000000270691185*A13^2+0.000468652420503*A13+0.726630359723856)*1.04333245461704))))*$D$6) -> 0.92970391 | E13: 750 | F13: =C23 -> 0.99028477 | G13: =( -0.00000000000000018*E13^4 + 0.00000000001213529*E13^3- 0.00000011429507157*E13^2 + 0.00020471790205693*E13 + 0.893892094372259) -> 0.98820217 | U13: 5 | V13: =IF(U13<$V$6,$W$6,IF(U13>$V$7,$W$7,((0.00000009*(U13)^4+0.00001501*(U13)^3-0.00158915*(U13)^2+0.01492176*(U13)+0.94489651)*1.0186317318901))) -> 1 | W13: =(EXP(LN(IF(U13<$V$6,$W$6,IF(U13>$V$7,$W$7,((0.00000009*(U13)^4+0.00001501*(U13)^3-0.00158915*(U13)^2+0.01492176*(U13)+0.94489651)*1.0186317318901))))*$Y$6)) -> 1 | X13: =(EXP(LN(IF(U13<$V$6,$W$6,IF(U13>$V$7,$W$7,(($AD$7*(U13)^4+$AE$7*(U13)^3-$AF$7*(U13)^2+$AG$7*(U13)+$AH$7)))))*$Y$6)) -> 1 | Y13: =(EXP(LN(IF(U13<$V$6,$W$6,IF(U13>$V$7,$W$7,((9.167685587011E-08*(U13)^4+0.000015289662956704*(U13)^3-0.00161875861673315*(U13)^2+0.0151997782316484*(U13)+0.962501568438211)))))*$Y$6)) -> 1
A14: 300 | B14: =(IF(A14<$A$6,$B$6,IF(A14>$A$7,$B$7,((0.000000000032989*A14^3-0.000000270691185*A14^2+0.000468652420503*A14+0.726630359723856)*1.04333245461704)))) -> 0.88031654 | C14: =EXP(LN(IF(A14<$A$6,$B$6,IF(A14>$A$7,$B$7,((0.000000000032989*A14^3-0.000000270691185*A14^2+0.000468652420503*A14+0.726630359723856)*1.04333245461704))))*$D$6) -> 0.93877256 | E14: 1000 | F14: =C28 -> 0.99954138 | G14: =( -0.00000000000000018*E14^4 + 0.00000000001213529*E14^3- 0.00000011429507157*E14^2 + 0.00020471790205693*E14 + 0.893892094372259) -> 0.99627021 | U14: 6 | V14: =IF(U14<$V$6,$W$6,IF(U14>$V$7,$W$7,((0.00000009*(U14)^4+0.00001501*(U14)^3-0.00158915*(U14)^2+0.01492176*(U14)+0.94489651)*1.0186317318901))) -> 0.99884631 | W14: =(EXP(LN(IF(U14<$V$6,$W$6,IF(U14>$V$7,$W$7,((0.00000009*(U14)^4+0.00001501*(U14)^3-0.00158915*(U14)^2+0.01492176*(U14)+0.94489651)*1.0186317318901))))*$Y$6)) -> 0.99917557 | X14: =(EXP(LN(IF(U14<$V$6,$W$6,IF(U14>$V$7,$W$7,(($AD$7*(U14)^4+$AE$7*(U14)^3-$AF$7*(U14)^2+$AG$7*(U14)+$AH$7)))))*$Y$6)) -> 0.99917557 | Y14: =(EXP(LN(IF(U14<$V$6,$W$6,IF(U14>$V$7,$W$7,((9.167685587011E-08*(U14)^4+0.000015289662956704*(U14)^3-0.00161875861673315*(U14)^2+0.0151997782316484*(U14)+0.962501568438211)))))*$Y$6)) -> 0.99917557
A15: 350 | B15: =(IF(A15<$A$6,$B$6,IF(A15>$A$7,$B$7,((0.000000000032989*A15^3-0.000000270691185*A15^2+0.000468652420503*A15+0.726630359723856)*1.04333245461704)))) -> 0.89613227 | C15: =EXP(LN(IF(A15<$A$6,$B$6,IF(A15>$A$7,$B$7,((0.000000000032989*A15^3-0.000000270691185*A15^2+0.000468652420503*A15+0.726630359723856)*1.04333245461704))))*$D$6) -> 0.94709459 | E15: 1250 | F15: =C33 -> 0.997647 | G15: =( -0.00000000000000018*E15^4 + 0.00000000001213529*E15^3- 0.00000011429507157*E15^2 + 0.00020471790205693*E15 + 0.893892094372259) -> 0.99446571 | U15: 7 | V15: =IF(U15<$V$6,$W$6,IF(U15>$V$7,$W$7,((0.00000009*(U15)^4+0.00001501*(U15)^3-0.00158915*(U15)^2+0.01492176*(U15)+0.94489651)*1.0186317318901))) -> 0.99504531 | W15: =(EXP(LN(IF(U15<$V$6,$W$6,IF(U15>$V$7,$W$7,((0.00000009*(U15)^4+0.00001501*(U15)^3-0.00158915*(U15)^2+0.01492176*(U15)+0.94489651)*1.0186317318901))))*$Y$6)) -> 0.99645743 | X15: =(EXP(LN(IF(U15<$V$6,$W$6,IF(U15>$V$7,$W$7,(($AD$7*(U15)^4+$AE$7*(U15)^3-$AF$7*(U15)^2+$AG$7*(U15)+$AH$7)))))*$Y$6)) -> 0.99645743 | Y15: =(EXP(LN(IF(U15<$V$6,$W$6,IF(U15>$V$7,$W$7,((9.167685587011E-08*(U15)^4+0.000015289662956704*(U15)^3-0.00161875861673315*(U15)^2+0.0151997782316484*(U15)+0.962501568438211)))))*$Y$6)) -> 0.99645744
A16: 400 | B16: =(IF(A16<$A$6,$B$6,IF(A16>$A$7,$B$7,((0.000000000032989*A16^3-0.000000270691185*A16^2+0.000468652420503*A16+0.726630359723856)*1.04333245461704)))) -> 0.91071659 | C16: =EXP(LN(IF(A16<$A$6,$B$6,IF(A16>$A$7,$B$7,((0.000000000032989*A16^3-0.000000270691185*A16^2+0.000468652420503*A16+0.726630359723856)*1.04333245461704))))*$D$6) -> 0.95470326 | E16: 1500 | F16: =C38 -> 0.98615966 | G16: =( -0.00000000000000018*E16^4 + 0.00000000001213529*E16^3- 0.00000011429507157*E16^2 + 0.00020471790205693*E16 + 0.893892094372259) -> 0.98385039 | U16: 8 | V16: =IF(U16<$V$6,$W$6,IF(U16>$V$7,$W$7,((0.00000009*(U16)^4+0.00001501*(U16)^3-0.00158915*(U16)^2+0.01492176*(U16)+0.94489651)*1.0186317318901))) -> 0.98870306 | W16: =(EXP(LN(IF(U16<$V$6,$W$6,IF(U16>$V$7,$W$7,((0.00000009*(U16)^4+0.00001501*(U16)^3-0.00158915*(U16)^2+0.01492176*(U16)+0.94489651)*1.0186317318901))))*$Y$6)) -> 0.99191541 | X16: =(EXP(LN(IF(U16<$V$6,$W$6,IF(U16>$V$7,$W$7,(($AD$7*(U16)^4+$AE$7*(U16)^3-$AF$7*(U16)^2+$AG$7*(U16)+$AH$7)))))*$Y$6)) -> 0.99191541 | Y16: =(EXP(LN(IF(U16<$V$6,$W$6,IF(U16>$V$7,$W$7,((9.167685587011E-08*(U16)^4+0.000015289662956704*(U16)^3-0.00161875861673315*(U16)^2+0.0151997782316484*(U16)+0.962501568438211)))))*$Y$6)) -> 0.99191541
A17: 450 | B17: =(IF(A17<$A$6,$B$6,IF(A17>$A$7,$B$7,((0.000000000032989*A17^3-0.000000270691185*A17^2+0.000468652420503*A17+0.726630359723856)*1.04333245461704)))) -> 0.92409532 | C17: =EXP(LN(IF(A17<$A$6,$B$6,IF(A17>$A$7,$B$7,((0.000000000032989*A17^3-0.000000270691185*A17^2+0.000468652420503*A17+0.726630359723856)*1.04333245461704))))*$D$6) -> 0.96162911 | E17: 1750 | F17: =C43 -> 0.96638799 | G17: =( -0.00000000000000018*E17^4 + 0.00000000001213529*E17^3- 0.00000011429507157*E17^2 + 0.00020471790205693*E17 + 0.893892094372259) -> 0.96546913 | U17: 9 | V17: =IF(U17<$V$6,$W$6,IF(U17>$V$7,$W$7,((0.00000009*(U17)^4+0.00001501*(U17)^3-0.00158915*(U17)^2+0.01492176*(U17)+0.94489651)*1.0186317318901))) -> 0.97992778 | W17: =(EXP(LN(IF(U17<$V$6,$W$6,IF(U17>$V$7,$W$7,((0.00000009*(U17)^4+0.00001501*(U17)^3-0.00158915*(U17)^2+0.01492176*(U17)+0.94489651)*1.0186317318901))))*$Y$6)) -> 0.98561722 | X17: =(EXP(LN(IF(U17<$V$6,$W$6,IF(U17>$V$7,$W$7,(($AD$7*(U17)^4+$AE$7*(U17)^3-$AF$7*(U17)^2+$AG$7*(U17)+$AH$7)))))*$Y$6)) -> 0.98561722 | Y17: =(EXP(LN(IF(U17<$V$6,$W$6,IF(U17>$V$7,$W$7,((9.167685587011E-08*(U17)^4+0.000015289662956704*(U17)^3-0.00161875861673315*(U17)^2+0.0151997782316484*(U17)+0.962501568438211)))))*$Y$6)) -> 0.98561722
A18: 500 | B18: =(IF(A18<$A$6,$B$6,IF(A18>$A$7,$B$7,((0.000000000032989*A18^3-0.000000270691185*A18^2+0.000468652420503*A18+0.726630359723856)*1.04333245461704)))) -> 0.93629426 | C18: =EXP(LN(IF(A18<$A$6,$B$6,IF(A18>$A$7,$B$7,((0.000000000032989*A18^3-0.000000270691185*A18^2+0.000468652420503*A18+0.726630359723856)*1.04333245461704))))*$D$6) -> 0.96790026 | E18: 2000 | F18: =C48 -> 0.93950455 | G18: =( -0.00000000000000018*E18^4 + 0.00000000001213529*E18^3- 0.00000011429507157*E18^2 + 0.00020471790205693*E18 + 0.893892094372259) -> 0.94034993 | U18: 10 | V18: =IF(U18<$V$6,$W$6,IF(U18>$V$7,$W$7,((0.00000009*(U18)^4+0.00001501*(U18)^3-0.00158915*(U18)^2+0.01492176*(U18)+0.94489651)*1.0186317318901))) -> 0.96882992 | W18: =(EXP(LN(IF(U18<$V$6,$W$6,IF(U18>$V$7,$W$7,((0.00000009*(U18)^4+0.00001501*(U18)^3-0.00158915*(U18)^2+0.01492176*(U18)+0.94489651)*1.0186317318901))))*$Y$6)) -> 0.97762895 | X18: =(EXP(LN(IF(U18<$V$6,$W$6,IF(U18>$V$7,$W$7,(($AD$7*(U18)^4+$AE$7*(U18)^3-$AF$7*(U18)^2+$AG$7*(U18)+$AH$7)))))*$Y$6)) -> 0.97762895 | Y18: =(EXP(LN(IF(U18<$V$6,$W$6,IF(U18>$V$7,$W$7,((9.167685587011E-08*(U18)^4+0.000015289662956704*(U18)^3-0.00161875861673315*(U18)^2+0.0151997782316484*(U18)+0.962501568438211)))))*$Y$6)) -> 0.97762896
A19: 550 | B19: =(IF(A19<$A$6,$B$6,IF(A19>$A$7,$B$7,((0.000000000032989*A19^3-0.000000270691185*A19^2+0.000468652420503*A19+0.726630359723856)*1.04333245461704)))) -> 0.94733925 | C19: =EXP(LN(IF(A19<$A$6,$B$6,IF(A19>$A$7,$B$7,((0.000000000032989*A19^3-0.000000270691185*A19^2+0.000468652420503*A19+0.726630359723856)*1.04333245461704))))*$D$6) -> 0.97354274 | E19: 2250 | F19: =C53 -> 0.90663323 | G19: =( -0.00000000000000018*E19^4 + 0.00000000001213529*E19^3- 0.00000011429507157*E19^2 + 0.00020471790205693*E19 + 0.893892094372259) -> 0.90950391 | U19: 11 | V19: =IF(U19<$V$6,$W$6,IF(U19>$V$7,$W$7,((0.00000009*(U19)^4+0.00001501*(U19)^3-0.00158915*(U19)^2+0.01492176*(U19)+0.94489651)*1.0186317318901))) -> 0.95552212 | W19: =(EXP(LN(IF(U19<$V$6,$W$6,IF(U19>$V$7,$W$7,((0.00000009*(U19)^4+0.00001501*(U19)^3-0.00158915*(U19)^2+0.01492176*(U19)+0.94489651)*1.0186317318901))))*$Y$6)) -> 0.96801543 | X19: =(EXP(LN(IF(U19<$V$6,$W$6,IF(U19>$V$7,$W$7,(($AD$7*(U19)^4+$AE$7*(U19)^3-$AF$7*(U19)^2+$AG$7*(U19)+$AH$7)))))*$Y$6)) -> 0.96801543 | Y19: =(EXP(LN(IF(U19<$V$6,$W$6,IF(U19>$V$7,$W$7,((9.167685587011E-08*(U19)^4+0.000015289662956704*(U19)^3-0.00161875861673315*(U19)^2+0.0151997782316484*(U19)+0.962501568438211)))))*$Y$6)) -> 0.96801543
A20: 600 | B20: =(IF(A20<$A$6,$B$6,IF(A20>$A$7,$B$7,((0.000000000032989*A20^3-0.000000270691185*A20^2+0.000468652420503*A20+0.726630359723856)*1.04333245461704)))) -> 0.95725608 | C20: =EXP(LN(IF(A20<$A$6,$B$6,IF(A20>$A$7,$B$7,((0.000000000032989*A20^3-0.000000270691185*A20^2+0.000468652420503*A20+0.726630359723856)*1.04333245461704))))*$D$6) -> 0.97858069 | E20: 2500 | F20: =C58 -> 0.86892855 | G20: =( -0.00000000000000018*E20^4 + 0.00000000001213529*E20^3- 0.00000011429507157*E20^2 + 0.00020471790205693*E20 + 0.893892094372259) -> 0.87392531 | U20: 12 | V20: =IF(U20<$V$6,$W$6,IF(U20>$V$7,$W$7,((0.00000009*(U20)^4+0.00001501*(U20)^3-0.00158915*(U20)^2+0.01492176*(U20)+0.94489651)*1.0186317318901))) -> 0.94011921 | W20: =(EXP(LN(IF(U20<$V$6,$W$6,IF(U20>$V$7,$W$7,((0.00000009*(U20)^4+0.00001501*(U20)^3-0.00158915*(U20)^2+0.01492176*(U20)+0.94489651)*1.0186317318901))))*$Y$6)) -> 0.95684054 | X20: =(EXP(LN(IF(U20<$V$6,$W$6,IF(U20>$V$7,$W$7,(($AD$7*(U20)^4+$AE$7*(U20)^3-$AF$7*(U20)^2+$AG$7*(U20)+$AH$7)))))*$Y$6)) -> 0.95684054 | Y20: =(EXP(LN(IF(U20<$V$6,$W$6,IF(U20>$V$7,$W$7,((9.167685587011E-08*(U20)^4+0.000015289662956704*(U20)^3-0.00161875861673315*(U20)^2+0.0151997782316484*(U20)+0.962501568438211)))))*$Y$6)) -> 0.95684054
A21: 650 | B21: =(IF(A21<$A$6,$B$6,IF(A21>$A$7,$B$7,((0.000000000032989*A21^3-0.000000270691185*A21^2+0.000468652420503*A21+0.726630359723856)*1.04333245461704)))) -> 0.96607057 | C21: =EXP(LN(IF(A21<$A$6,$B$6,IF(A21>$A$7,$B$7,((0.000000000032989*A21^3-0.000000270691185*A21^2+0.000468652420503*A21+0.726630359723856)*1.04333245461704))))*$D$6) -> 0.98303657 | E21: 2750 | F21: =C63 -> 0.82765862 | G21: =( -0.00000000000000018*E21^4 + 0.00000000001213529*E21^3- 0.00000011429507157*E21^2 + 0.00020471790205693*E21 + 0.893892094372259) -> 0.8345915 | U21: 13 | V21: =IF(U21<$V$6,$W$6,IF(U21>$V$7,$W$7,((0.00000009*(U21)^4+0.00001501*(U21)^3-0.00158915*(U21)^2+0.01492176*(U21)+0.94489651)*1.0186317318901))) -> 0.92273825 | W21: =(EXP(LN(IF(U21<$V$6,$W$6,IF(U21>$V$7,$W$7,((0.00000009*(U21)^4+0.00001501*(U21)^3-0.00158915*(U21)^2+0.01492176*(U21)+0.94489651)*1.0186317318901))))*$Y$6)) -> 0.94416757 | X21: =(EXP(LN(IF(U21<$V$6,$W$6,IF(U21>$V$7,$W$7,(($AD$7*(U21)^4+$AE$7*(U21)^3-$AF$7*(U21)^2+$AG$7*(U21)+$AH$7)))))*$Y$6)) -> 0.94416757 | Y21: =(EXP(LN(IF(U21<$V$6,$W$6,IF(U21>$V$7,$W$7,((9.167685587011E-08*(U21)^4+0.000015289662956704*(U21)^3-0.00161875861673315*(U21)^2+0.0151997782316484*(U21)+0.962501568438211)))))*$Y$6)) -> 0.94416757
A22: 700 | B22: =(IF(A22<$A$6,$B$6,IF(A22>$A$7,$B$7,((0.000000000032989*A22^3-0.000000270691185*A22^2+0.000468652420503*A22+0.726630359723856)*1.04333245461704)))) -> 0.97380854 | C22: =EXP(LN(IF(A22<$A$6,$B$6,IF(A22>$A$7,$B$7,((0.000000000032989*A22^3-0.000000270691185*A22^2+0.000468652420503*A22+0.726630359723856)*1.04333245461704))))*$D$6) -> 0.98693138 | E22: 3000 | F22: =C68 -> 0.78430118 | G22: =( -0.00000000000000018*E22^4 + 0.00000000001213529*E22^3- 0.00000011429507157*E22^2 + 0.00020471790205693*E22 + 0.893892094372259) -> 0.79246299 | U22: 14 | V22: =IF(U22<$V$6,$W$6,IF(U22>$V$7,$W$7,((0.00000009*(U22)^4+0.00001501*(U22)^3-0.00158915*(U22)^2+0.01492176*(U22)+0.94489651)*1.0186317318901))) -> 0.90349847 | W22: =(EXP(LN(IF(U22<$V$6,$W$6,IF(U22>$V$7,$W$7,((0.00000009*(U22)^4+0.00001501*(U22)^3-0.00158915*(U22)^2+0.01492176*(U22)+0.94489651)*1.0186317318901))))*$Y$6)) -> 0.93005951 | X22: =(EXP(LN(IF(U22<$V$6,$W$6,IF(U22>$V$7,$W$7,(($AD$7*(U22)^4+$AE$7*(U22)^3-$AF$7*(U22)^2+$AG$7*(U22)+$AH$7)))))*$Y$6)) -> 0.93005951 | Y22: =(EXP(LN(IF(U22<$V$6,$W$6,IF(U22>$V$7,$W$7,((9.167685587011E-08*(U22)^4+0.000015289662956704*(U22)^3-0.00161875861673315*(U22)^2+0.0151997782316484*(U22)+0.962501568438211)))))*$Y$6)) -> 0.93005951
A23: 750 | B23: =(IF(A23<$A$6,$B$6,IF(A23>$A$7,$B$7,((0.000000000032989*A23^3-0.000000270691185*A23^2+0.000468652420503*A23+0.726630359723856)*1.04333245461704)))) -> 0.98049579 | C23: =EXP(LN(IF(A23<$A$6,$B$6,IF(A23>$A$7,$B$7,((0.000000000032989*A23^3-0.000000270691185*A23^2+0.000468652420503*A23+0.726630359723856)*1.04333245461704))))*$D$6) -> 0.99028477 | E23: 3250 | F23: =C73 -> 0.74065808 | G23: =( -0.00000000000000018*E23^4 + 0.00000000001213529*E23^3- 0.00000011429507157*E23^2 + 0.00020471790205693*E23 + 0.893892094372259) -> 0.74848338 | U23: 15 | V23: =IF(U23<$V$6,$W$6,IF(U23>$V$7,$W$7,((0.00000009*(U23)^4+0.00001501*(U23)^3-0.00158915*(U23)^2+0.01492176*(U23)+0.94489651)*1.0186317318901))) -> 0.8825213 | W23: =(EXP(LN(IF(U23<$V$6,$W$6,IF(U23>$V$7,$W$7,((0.00000009*(U23)^4+0.00001501*(U23)^3-0.00158915*(U23)^2+0.01492176*(U23)+0.94489651)*1.0186317318901))))*$Y$6)) -> 0.91457935 | X23: =(EXP(LN(IF(U23<$V$6,$W$6,IF(U23>$V$7,$W$7,(($AD$7*(U23)^4+$AE$7*(U23)^3-$AF$7*(U23)^2+$AG$7*(U23)+$AH$7)))))*$Y$6)) -> 0.91457935 | Y23: =(EXP(LN(IF(U23<$V$6,$W$6,IF(U23>$V$7,$W$7,((9.167685587011E-08*(U23)^4+0.000015289662956704*(U23)^3-0.00161875861673315*(U23)^2+0.0151997782316484*(U23)+0.962501568438211)))))*$Y$6)) -> 0.91457935
