Workbook

Sheet Объекты оценки
A1: Идентификатор | B1: Кадастровый номер | C1: Площадь в квадратных метрах | D1: Категория земель | E1: Разрешенное использование участка Вид разрешенного использования по классификатору | F1: Вид использования участка по документу | G1: Разрешенное использование участка | H1: Разрешенное использование (текстовое описание) | I1: Кадастровая стоимость | J1: Дата определения кадастровой стоимости | K1: Удельный показатель кадастровой стоимости(руб/м2) | L1: Кадастровая стоимость (руб) | M1: Кадастровая стоимость описание вых | N1: Группа для XML | O1: Код населённого пункта | P1: Код расчета вида использования | Q1: Расшифровка расчетной подгруппы | R1: Дата оценки | S1: Сегмент | T1: Признак актуальности | U1: Код МО (ЦФ) | V1: Номер заявления | W1: Тип заявления | X1: Статус заявления | Y1: Особый контроль | Z1: Дата комиссии | AA1: Решение комиссии | AB1: Статус расчета | AC1: НЕ Используется | AD1: Флаг ВРИ по документу | AE1: Флаг Местоположения (координат) | AF1: Флаг площади | AG1: Флаг ВРИ старый спр | AH1: Флаг ВРИ новый спр | AI1: Флаг Категории ЗУ | AJ1: Старый код НП | AK1: Флаг переопределения ФРИ | AL1: ВРИ по правилам | AM1: Правило | AN1: Новоя модель | AO1: Новый сегмент | AY1: 8008 | BB1: СРАВНЕНИЕ РЕЗУЛЬТАТОВ 16СТ С ДАННЫМИ НА 01012020 | BH1: Ф5 | BI1: =CONCATENATE("М",RIGHT(AY1,1)) -> М8 | BJ1: 02032021 | BK1: Фомин | BM1: ДАННЫЕ ДЛЯ ЗАГРУЗКИ В БАЗУ | CF1: КОНТРОЛЬНАЯ ПРОВЕРКА | CG1: ГОТОВО | CH1: ПЕРЕСЧЕТ НЕ ТРЕБУЕТСЯ | CI1: СТОПЛИСТ
A2: ID | B2: CadastralNumber | C2: Area | D2: ParcelCategory | E2: Utilization | F2: UtilizationByDoc | G2: UtilizationLandUse | H2: UtilizationТхт | I2: CostValue | J2: CostDateValuation | K2: Specific_CadastralCost | L2: CadastralCost | M2: CadastralCostDesc | N2: ID_Group | O2: LocalityCode | P2: loc_VICode | Q2: loc_GroupName | R2: Date_KC | S2: Segment | T2: act_sign | U2: loc_factor_830 | V2: Statement | W2: Type_Statement | X2: Status_Statement | Y2: ControlSP | Z2: Date_comm | AA2: Sol_comm | AB2: Status_kc | AC2: Flag_LocalityCode | AD2: Flag_VRI | AE2: Flag_Location | AF2: FlagParam | AG2: Flag_VRIoldspr | AH2: Flag_VRInewspr | AI2: Flag_Category | AJ2: OldLocalityCode | AK2: Flag_VRI_All | AL2: VRICode_NEW | AM2: PraviloVRI | AN2: New_id_group | AO2: New_Segment | AP2: loc_factor_807 | AQ2: loc_factor_830 | AT2: loc_factor_8071 | AU2: Specific_CadastralCost | AV2: CadastralCost | AW2: CadastralCostDesc | AX2: CadastralNumber | AY2: id_group | AZ2: мин | BA2: макс | BH2: ОПИСАНИЕ КС | BM2: Кадастровый номер | BN2: Площадь в квадратных метрах | BO2: Код МО (ЦФ) | BP2: Значение затрат для ЕКБ, руб/м2 | BQ2: УПКС | BR2: КС | BS2: Описание КС | BT2: Группа хмл | BU2: Статус расчета | BV2: Сегмент | BW2: Код сегмента | BX2: ВРИ | BY2: Расшифровка расчетной подгруппы | BZ2: Вид использования учтенный при ТЕКУЩЕМ расчете в рамках 16 статьи для загрузки в базу (в базе название колонки "ВРИ по документу старое") | CA2: ИЗМЕНЕНИЕ КС | CB2: ИЗМЕНЕНИЕ, руб. | CC2: Старый/Новый | CG2: =IF(CG3="ОТСУТСТВУЮТ","-",CG3=ГОТОВО!P1) -> - | CH2: =IF(CH3="ОТСУТСТВУЮТ","-",CH3='ПЕРЕСЧЕТ НЕ ТРЕБУЕТСЯ'!I1) -> - | CI2: =IF(CI3="ОТСУТСТВУЮТ","-",CI3=СТОПЛИСТ!D1) -> -
A3: parcels | B3: parcels | C3: parcels | D3: parcels | E3: parcels | F3: parcels | G3: parcels | H3: parcels | I3: parcels | J3: parcels | K3: parcels | L3: parcels | M3: parcels | N3: parcels | O3: parcels | P3: parcels | Q3: parcels | R3: parcels | S3: parcels | T3: parcels | U3: parcels | V3: parcels | W3: parcels | X3: parcels | Y3: parcels | Z3: parcels | AA3: parcels | AB3: parcels | AC3: parcels | AD3: parcels | AE3: parcels | AF3: parcels | AG3: parcels | AH3: parcels | AI3: parcels | AJ3: parcels | AK3: parcels | AL3: parcels | AM3: parcels | AN3: parcels | AO3: parcels | AP3: Площадь в квадратных метрах | AQ3: Код МО (ЦФ) | AR3: МО | AS3: Поправочный коэффициент для МО | AT3: Значение затрат для ЕКБ, руб/м2 | AU3: УПКС, руб/м2 (значение затрат для ЕКБ*поправочный коэффициент для МО) | AV3: Кадастровая стоимость, руб. | AW3: Описание КС | AX3: КН | AY3: Группа xml | AZ3: 0.12 | BA3: 13117.78 | BB3: Код расчета вида использования | BC3: Модель | BD3: Площадь | BE3: УПКС | BF3: КС | BG3: ОБЯЗАТЕЛЬНАЯ ПРОВЕРКА | BH3: Файл | BI3: Модель | BJ3: Дата | BK3: Ответственный | BL3: Графика | BM3: CadastralNumber | BN3: loc_factor_807 | BO3: loc_factor_830 | BP3: loc_factor_8071 | BQ3: Specific_CadastralCost | BR3: CadastralCost | BS3: CadastralCostDesc | BT3: id_group | BU3: Status_kc | BV3: Segment | BW3: loc_SgCode | BX3: loc_VICode | BY3: loc_GroupName | BZ3: Old_Utlbydoc | CG3: =IF(AND(ГОТОВО!P1=1,COUNTIF(BU:BU,"ГОТОВ")=0),"ОТСУТСТВУЮТ",COUNTIF(BU:BU,"ГОТОВ")+1) -> ОТСУТСТВУЮТ | CH3: =IF(AND('ПЕРЕСЧЕТ НЕ ТРЕБУЕТСЯ'!I1=1,COUNTIF(BU:BU,"ПЕРЕСЧЕТ НЕ ТРЕБУЕТСЯ")=0),"ОТСУТСТВУЮТ",COUNTIF(BU:BU,"ПЕРЕСЧЕТ НЕ ТРЕБУЕТСЯ")+1) -> ОТСУТСТВУЮТ | CI3: =IF(AND(СТОПЛИСТ!D1=1,COUNTIF(BU:BU,"СТОПЛИСТ")=0),"ОТСУТСТВУЮТ",COUNTIF(BU:BU,"СТОПЛИСТ")+1) -> ОТСУТСТВУЮТ
D4: spr | E4: spr | AP4: =IF(B4="","",C4) | AQ4: =IF(B4="","",LEFT(O4,2)) | AR4: =IF(B4="","",VLOOKUP(O4,'Населённые пункты 2019'!$H:$P,9,FALSE)) | AS4: =IF(B4="","",VLOOKUP(AR4,'Поправки для МО'!$A:$C,3,FALSE)) | AT4: =IF(B4="","",IF(51178*C4^-0.982<$AZ$3,$AZ$3,IF(51178*C4^-0.982>$BA$3,$BA$3,51178*C4^-0.982))) | AU4: =IF(B4="","",ROUND(AT4*AS4,2)) | AV4: =IF(B4="","",ROUND(AU4*C4,2)) | AW4: =IF(B4="","",CONCATENATE("СТ16_",BH4,"_",BI4,"_",BJ4,"_",BK4,"_",BL4,"_",CC4)) | AX4: =IF(B4="","",B4) | AY4: =IF(B4="","",$AY$1) | BB4: =IF(B4="","",IF(MID(AL4,3,1)<>":","ОШИБКА В ФОРМАТЕ КОДА НП",IF(K4="","Отсутствуют предыдущие значения",AL4=P4))) | BC4: =IF(B4="","",IF(K4="","Отсутствуют предыдущие значения",AY4=N4)) | BD4: =IF(B4="","",IF(K4="","Отсутствуют предыдущие значения",AP4=C4)) | BE4: =IF(B4="","",IF(K4="","Отсутствуют предыдущие значения",AU4=K4)) | BF4: =IF(B4="","",IF(L4="","Отсутствуют предыдущие значения",AV4=L4)) | BG4: =IF(AA4<>"","ОСПАРИВАНИЕ",IF(V4="","",V4)) | BH4: =IF(B4="","",$BH$1) | BI4: =IF(B4="","",$BI$1) | BJ4: =IF(B4="","",$BJ$1) | BK4: =IF(B4="","",$BK$1) | BL4: =IF(B4="","",IF(K4="","Графика по ПКК","Графика на 01012020")) | BM4: =IF(B4="","",B4) | BN4: =IF(B4="","",AP4) | BO4: =IF(B4="","",AQ4) | BP4: =IF(B4="","",AT4) | BQ4: =IF(B4="","",AU4) | BR4: =IF(B4="","",AV4) | BS4: =IF(B4="","",AW4) | BT4: =IF(B4="","",AY4) | BU4: =IF(B4="","",IF(OR(Y4<>"",AA4<>"",BR4<0),"СТОПЛИСТ",IF(W4=21,"СТОПЛИСТ",IF(AND(BB4=TRUE,BD4=TRUE),"ПЕРЕСЧЕТ НЕ ТРЕБУЕТСЯ",IF(OR(CA4="Отсутствует значения предыдущих расчетов",CA4="Осуществлен пересчет"),"ГОТОВ","ПЕРЕСЧЕТ НЕ ТРЕБУЕТСЯ"))))) | BV4: =IF(B4="","",AO4) | BW4: =IF(B4="","",VLOOKUP(BV4,Справочник_ВРИ_Сегментов!$A:$D,4,)) | BX4: =IF(B4="","",AL4) | BY4: =IF(B4="","",VLOOKUP('Объекты оценки'!BX4,Справочник_ВРИ_Сегментов!$B:$C,2,FALSE)) | BZ4: =IF(B4="","",IF(OR(F4="",F4="-",F4="."),G4,F4)) | CA4: =IF(B4="","",IF(L4="","Отсутствует значения предыдущих расчетов",IF(L4=AV4,"Значения КС не изменилось","Осуществлен пересчет"))) | CB4: =IF(B4="","",L4-W4) | CC4: =IF(B4="","",IF(K4="","Новый","Измененный"))
AP5: =IF(B5="","",C5) | AQ5: =IF(B5="","",LEFT(O5,2)) | AR5: =IF(B5="","",VLOOKUP(O5,'Населённые пункты 2019'!$H:$P,9,FALSE)) | AS5: =IF(B5="","",VLOOKUP(AR5,'Поправки для МО'!$A:$C,3,FALSE)) | AT5: =IF(B5="","",IF(51178*C5^-0.982<$AZ$3,$AZ$3,IF(51178*C5^-0.982>$BA$3,$BA$3,51178*C5^-0.982))) | AU5: =IF(B5="","",ROUND(AT5*AS5,2)) | AV5: =IF(B5="","",ROUND(AU5*C5,2)) | AW5: =IF(B5="","",CONCATENATE("СТ16_",BH5,"_",BI5,"_",BJ5,"_",BK5,"_",BL5,"_",CC5)) | AX5: =IF(B5="","",B5) | AY5: =IF(B5="","",$AY$1) | BB5: =IF(B5="","",IF(MID(AL5,3,1)<>":","ОШИБКА В ФОРМАТЕ КОДА НП",IF(K5="","Отсутствуют предыдущие значения",AL5=P5))) | BC5: =IF(B5="","",IF(K5="","Отсутствуют предыдущие значения",AY5=N5)) | BD5: =IF(B5="","",IF(K5="","Отсутствуют предыдущие значения",AP5=C5)) | BE5: =IF(B5="","",IF(K5="","Отсутствуют предыдущие значения",AU5=K5)) | BF5: =IF(B5="","",IF(L5="","Отсутствуют предыдущие значения",AV5=L5)) | BG5: =IF(AA5<>"","ОСПАРИВАНИЕ",IF(V5="","",V5)) | BH5: =IF(B5="","",$BH$1) | BI5: =IF(B5="","",$BI$1) | BJ5: =IF(B5="","",$BJ$1) | BK5: =IF(B5="","",$BK$1) | BL5: =IF(B5="","",IF(K5="","Графика по ПКК","Графика на 01012020")) | BM5: =IF(B5="","",B5) | BN5: =IF(B5="","",AP5) | BO5: =IF(B5="","",AQ5) | BP5: =IF(B5="","",AT5) | BQ5: =IF(B5="","",AU5) | BR5: =IF(B5="","",AV5) | BS5: =IF(B5="","",AW5) | BT5: =IF(B5="","",AY5) | BU5: =IF(B5="","",IF(OR(Y5<>"",AA5<>"",BR5<0),"СТОПЛИСТ",IF(W5=21,"СТОПЛИСТ",IF(AND(BB5=TRUE,BD5=TRUE),"ПЕРЕСЧЕТ НЕ ТРЕБУЕТСЯ",IF(OR(CA5="Отсутствует значения предыдущих расчетов",CA5="Осуществлен пересчет"),"ГОТОВ","ПЕРЕСЧЕТ НЕ ТРЕБУЕТСЯ"))))) | BV5: =IF(B5="","",AO5) | BW5: =IF(B5="","",VLOOKUP(BV5,Справочник_ВРИ_Сегментов!$A:$D,4,)) | BX5: =IF(B5="","",AL5) | BY5: =IF(B5="","",VLOOKUP('Объекты оценки'!BX5,Справочник_ВРИ_Сегментов!$B:$C,2,FALSE)) | BZ5: =IF(B5="","",IF(OR(F5="",F5="-",F5="."),G5,F5)) | CA5: =IF(B5="","",IF(L5="","Отсутствует значения предыдущих расчетов",IF(L5=AV5,"Значения КС не изменилось","Осуществлен пересчет"))) | CB5: =IF(B5="","",L5-W5) | CC5: =IF(B5="","",IF(K5="","Новый","Измененный"))
A6: Select ID,Source_ID,CadastralNumber,DateCreated,CadastralBlock,Name,ObjectType,Area,AreaUnit,AreaInaccuracy,LocationinBounds,LocationPlaced,ElaborationReferenceMark,ElaborationDistance,ElaborationDirection,AddressOrLocation,FIAS,OKATO,KLADR,OKTMO,PostalCode,AddressRF,Region,DistrictName,DistrictType,CityName,CityType,UrbanDistrictName,UrbanDistrictType,SovietVillageName,SovietVillageType,LocalityName,LocalityType,PlanningElementName,PlanningElementType,StreetName,StreetType,Level1Type,Level1Value,Level2Type,Level2Value,Level3Type,Level3Value,ApartmentType,ApartmentValue,AddressOther,AddressNote,ParcelCategory,Utilization,UtilizationByDoc,UtilizationLandUse,UtilizationТхт,CostValue,CostUnit,CostDateValuation,CostDateEntering,CostDateApproval,CostDocNumber,CostDocDate,CostApplicationDate,CostRevisalStatementDate,CostApplicationLastDate,CostDocName,FacilityKN,FacilityKNPurpose,SurveyProjectNum,DecisionCodeDocument,DecisionName,DecisionSeries,DecisionNumber,DecisionDate,DecisionIssueOrgan,DecisionDesc,HiredHouseUse,HouseActBuilding,HouseActDevelopment,BuildingContractName,DevelopContractName,OwnerDecision,SupportContractName,CodeDocument,DocHiredHouseName,DocHiredHouseSeries,DocHiredHouseNumber,DocHiredHouseDate,DocHiredHouseIssueOrgan,DocHiredHouseDesc,LimitedRightNumber,CREATEOPERATORNAME,CREATEDATE,OPERATORNAME,MODIFYDATE,MI_STYLE,Specific_CadastralCost,CadastralCost,CadastralCostDesc,MO_Name,ID_Group,LocalityCode,locTypeUse2,loc_VICode,loc_GroupName,loc_VRICode,Sourse_loc_VICode,locTypeUse,inputpacket_id,loc_SgCode,VIP_Sp,Quant_Kontur,Quant_Point,Sum_Square,Sum_Perim,Proc_Diff_Square,Pr_Diff,Source_Sum_Square,SourceLocalityCode,Upload_Scroll,Date_KC,Segment,FlagLocalityCode,DistanceToRoad,DistanceToCMO,СМО,PresenceGas,SourcePresenceGas,PresenceHeating,SourcePresenceHeating,PresencePower,SourcePresencePower,PresenceWaterDisposal,SourcePresenceWaterDisposal,PresenceWaterSupply,SourcePresenceWaterSupply,DistanceToEKB,DistanceToRoadEKB,CCoordX,CCoordY,DistanceToMetro,DistanceToStationEKB,CostZone,DistanceToRRStation,costzone2,Textloc_VICode,act_sign,MaxFloor,Enc_squre,Enc_proc,Adm_rn_EKB,forestry,InfluenceZone_IGS,loc_factor_801,loc_factor_802,loc_factor_803,loc_factor_804,loc_factor_806,loc_factor_807,loc_factor_8071,loc_factor_809,loc_factor_8091,loc_factor_810,loc_factor_8101,loc_factor_811,loc_factor_8111,loc_factor_812,loc_factor_8121,loc_factor_813,loc_factor_814,loc_factor_815,loc_factor_816,loc_factor_8161,loc_factor_817,loc_factor_818,loc_factor_819,loc_factor_820,loc_factor_8201,loc_factor_821,loc_factor_822,loc_factor_823,loc_factor_8231,loc_factor_824,loc_factor_825,loc_factor_826,loc_factor_827,loc_factor_828,loc_factor_829,loc_factor_830,loc_factor_831,loc_factor_832,loc_factor_833,loc_factor_8331,loc_factor_835,loc_factor_836,loc_factor_837,loc_factor_838,Statement,Type_Statement,Status_Statement,DistanceToVZC,VRI_IGS,Cot_name,DistanceToZTB,PowerLines,loc_factor_839,KodMO,loc_factor_840,loc_factor_841,presence_entrance,loc_factor_8371,ControlSP,Sp_flag,loc_VRICode540,Status_kc,Date_comm,Sol_comm,Flag_LocalityCode,Flag_VRI,Flag_Location,FlagParam,Flag_VRIoldspr,Flag_VRInewspr,Flag_Category,OldLocalityCode,Flag_VRI_All,VRICode_NEW,PraviloVRI,New_id_group,New_loc_SgCode,New_Segment,Old_Utlbydoc,VRICode_OLD,PraviloVRI_old,Court,Date_Court,Sol_Court,(select (case count(*) when 0 then 0 else 1 end) from GEO.docboxes b where b.obj_id=PARCELS.ID and b.table_id=265) Attachment,(select sign(Count(*)) from PARCELS g where (not GEOM_OBJ is null) and (PARCELS.ID = g.ID)) GeometryExists,((select DatePacket from inputpacket where id=Parcels.inputpacket_id) ) [inputpacket_date] From PARCELS where status_kc='НЕ ГОТОВ' AND (CadastralCost='' OR CadastralCost is Null) AND New_id_group=8008 | AP6: =IF(B6="","",C6) | AQ6: =IF(B6="","",LEFT(O6,2)) | AR6: =IF(B6="","",VLOOKUP(O6,'Населённые пункты 2019'!$H:$P,9,FALSE)) | AS6: =IF(B6="","",VLOOKUP(AR6,'Поправки для МО'!$A:$C,3,FALSE)) | AT6: =IF(B6="","",IF(51178*C6^-0.982<$AZ$3,$AZ$3,IF(51178*C6^-0.982>$BA$3,$BA$3,51178*C6^-0.982))) | AU6: =IF(B6="","",ROUND(AT6*AS6,2)) | AV6: =IF(B6="","",ROUND(AU6*C6,2)) | AW6: =IF(B6="","",CONCATENATE("СТ16_",BH6,"_",BI6,"_",BJ6,"_",BK6,"_",BL6,"_",CC6)) | AX6: =IF(B6="","",B6) | AY6: =IF(B6="","",$AY$1) | BB6: =IF(B6="","",IF(MID(AL6,3,1)<>":","ОШИБКА В ФОРМАТЕ КОДА НП",IF(K6="","Отсутствуют предыдущие значения",AL6=P6))) | BC6: =IF(B6="","",IF(K6="","Отсутствуют предыдущие значения",AY6=N6)) | BD6: =IF(B6="","",IF(K6="","Отсутствуют предыдущие значения",AP6=C6)) | BE6: =IF(B6="","",IF(K6="","Отсутствуют предыдущие значения",AU6=K6)) | BF6: =IF(B6="","",IF(L6="","Отсутствуют предыдущие значения",AV6=L6)) | BG6: =IF(AA6<>"","ОСПАРИВАНИЕ",IF(V6="","",V6)) | BH6: =IF(B6="","",$BH$1) | BI6: =IF(B6="","",$BI$1) | BJ6: =IF(B6="","",$BJ$1) | BK6: =IF(B6="","",$BK$1) | BL6: =IF(B6="","",IF(K6="","Графика по ПКК","Графика на 01012020")) | BM6: =IF(B6="","",B6) | BN6: =IF(B6="","",AP6) | BO6: =IF(B6="","",AQ6) | BP6: =IF(B6="","",AT6) | BQ6: =IF(B6="","",AU6) | BR6: =IF(B6="","",AV6) | BS6: =IF(B6="","",AW6) | BT6: =IF(B6="","",AY6) | BU6: =IF(B6="","",IF(OR(Y6<>"",AA6<>"",BR6<0),"СТОПЛИСТ",IF(W6=21,"СТОПЛИСТ",IF(AND(BB6=TRUE,BD6=TRUE),"ПЕРЕСЧЕТ НЕ ТРЕБУЕТСЯ",IF(OR(CA6="Отсутствует значения предыдущих расчетов",CA6="Осуществлен пересчет"),"ГОТОВ","ПЕРЕСЧЕТ НЕ ТРЕБУЕТСЯ"))))) | BV6: =IF(B6="","",AO6) | BW6: =IF(B6="","",VLOOKUP(BV6,Справочник_ВРИ_Сегментов!$A:$D,4,)) | BX6: =IF(B6="","",AL6) | BY6: =IF(B6="","",VLOOKUP('Объекты оценки'!BX6,Справочник_ВРИ_Сегментов!$B:$C,2,FALSE)) | BZ6: =IF(B6="","",IF(OR(F6="",F6="-",F6="."),G6,F6)) | CA6: =IF(B6="","",IF(L6="","Отсутствует значения предыдущих расчетов",IF(L6=AV6,"Значения КС не изменилось","Осуществлен пересчет"))) | CB6: =IF(B6="","",L6-W6) | CC6: =IF(B6="","",IF(K6="","Новый","Измененный"))
AP7: =IF(B7="","",C7) | AQ7: =IF(B7="","",LEFT(O7,2)) | AR7: =IF(B7="","",VLOOKUP(O7,'Населённые пункты 2019'!$H:$P,9,FALSE)) | AS7: =IF(B7="","",VLOOKUP(AR7,'Поправки для МО'!$A:$C,3,FALSE)) | AT7: =IF(B7="","",IF(51178*C7^-0.982<$AZ$3,$AZ$3,IF(51178*C7^-0.982>$BA$3,$BA$3,51178*C7^-0.982))) | AU7: =IF(B7="","",ROUND(AT7*AS7,2)) | AV7: =IF(B7="","",ROUND(AU7*C7,2)) | AW7: =IF(B7="","",CONCATENATE("СТ16_",BH7,"_",BI7,"_",BJ7,"_",BK7,"_",BL7,"_",CC7)) | AX7: =IF(B7="","",B7) | AY7: =IF(B7="","",$AY$1) | BB7: =IF(B7="","",IF(MID(AL7,3,1)<>":","ОШИБКА В ФОРМАТЕ КОДА НП",IF(K7="","Отсутствуют предыдущие значения",AL7=P7))) | BC7: =IF(B7="","",IF(K7="","Отсутствуют предыдущие значения",AY7=N7)) | BD7: =IF(B7="","",IF(K7="","Отсутствуют предыдущие значения",AP7=C7)) | BE7: =IF(B7="","",IF(K7="","Отсутствуют предыдущие значения",AU7=K7)) | BF7: =IF(B7="","",IF(L7="","Отсутствуют предыдущие значения",AV7=L7)) | BG7: =IF(AA7<>"","ОСПАРИВАНИЕ",IF(V7="","",V7)) | BH7: =IF(B7="","",$BH$1) | BI7: =IF(B7="","",$BI$1) | BJ7: =IF(B7="","",$BJ$1) | BK7: =IF(B7="","",$BK$1) | BL7: =IF(B7="","",IF(K7="","Графика по ПКК","Графика на 01012020")) | BM7: =IF(B7="","",B7) | BN7: =IF(B7="","",AP7) | BO7: =IF(B7="","",AQ7) | BP7: =IF(B7="","",AT7) | BQ7: =IF(B7="","",AU7) | BR7: =IF(B7="","",AV7) | BS7: =IF(B7="","",AW7) | BT7: =IF(B7="","",AY7) | BU7: =IF(B7="","",IF(OR(Y7<>"",AA7<>"",BR7<0),"СТОПЛИСТ",IF(W7=21,"СТОПЛИСТ",IF(AND(BB7=TRUE,BD7=TRUE),"ПЕРЕСЧЕТ НЕ ТРЕБУЕТСЯ",IF(OR(CA7="Отсутствует значения предыдущих расчетов",CA7="Осуществлен пересчет"),"ГОТОВ","ПЕРЕСЧЕТ НЕ ТРЕБУЕТСЯ"))))) | BV7: =IF(B7="","",AO7) | BW7: =IF(B7="","",VLOOKUP(BV7,Справочник_ВРИ_Сегментов!$A:$D,4,)) | BX7: =IF(B7="","",AL7) | BY7: =IF(B7="","",VLOOKUP('Объекты оценки'!BX7,Справочник_ВРИ_Сегментов!$B:$C,2,FALSE)) | BZ7: =IF(B7="","",IF(OR(F7="",F7="-",F7="."),G7,F7)) | CA7: =IF(B7="","",IF(L7="","Отсутствует значения предыдущих расчетов",IF(L7=AV7,"Значения КС не изменилось","Осуществлен пересчет"))) | CB7: =IF(B7="","",L7-W7) | CC7: =IF(B7="","",IF(K7="","Новый","Измененный"))
AP8: =IF(B8="","",C8) | AQ8: =IF(B8="","",LEFT(O8,2)) | AR8: =IF(B8="","",VLOOKUP(O8,'Населённые пункты 2019'!$H:$P,9,FALSE)) | AS8: =IF(B8="","",VLOOKUP(AR8,'Поправки для МО'!$A:$C,3,FALSE)) | AT8: =IF(B8="","",IF(51178*C8^-0.982<$AZ$3,$AZ$3,IF(51178*C8^-0.982>$BA$3,$BA$3,51178*C8^-0.982))) | AU8: =IF(B8="","",ROUND(AT8*AS8,2)) | AV8: =IF(B8="","",ROUND(AU8*C8,2)) | AW8: =IF(B8="","",CONCATENATE("СТ16_",BH8,"_",BI8,"_",BJ8,"_",BK8,"_",BL8,"_",CC8)) | AX8: =IF(B8="","",B8) | AY8: =IF(B8="","",$AY$1) | BB8: =IF(B8="","",IF(MID(AL8,3,1)<>":","ОШИБКА В ФОРМАТЕ КОДА НП",IF(K8="","Отсутствуют предыдущие значения",AL8=P8))) | BC8: =IF(B8="","",IF(K8="","Отсутствуют предыдущие значения",AY8=N8)) | BD8: =IF(B8="","",IF(K8="","Отсутствуют предыдущие значения",AP8=C8)) | BE8: =IF(B8="","",IF(K8="","Отсутствуют предыдущие значения",AU8=K8)) | BF8: =IF(B8="","",IF(L8="","Отсутствуют предыдущие значения",AV8=L8)) | BG8: =IF(AA8<>"","ОСПАРИВАНИЕ",IF(V8="","",V8)) | BH8: =IF(B8="","",$BH$1) | BI8: =IF(B8="","",$BI$1) | BJ8: =IF(B8="","",$BJ$1) | BK8: =IF(B8="","",$BK$1) | BL8: =IF(B8="","",IF(K8="","Графика по ПКК","Графика на 01012020")) | BM8: =IF(B8="","",B8) | BN8: =IF(B8="","",AP8) | BO8: =IF(B8="","",AQ8) | BP8: =IF(B8="","",AT8) | BQ8: =IF(B8="","",AU8) | BR8: =IF(B8="","",AV8) | BS8: =IF(B8="","",AW8) | BT8: =IF(B8="","",AY8) | BU8: =IF(B8="","",IF(OR(Y8<>"",AA8<>"",BR8<0),"СТОПЛИСТ",IF(W8=21,"СТОПЛИСТ",IF(AND(BB8=TRUE,BD8=TRUE),"ПЕРЕСЧЕТ НЕ ТРЕБУЕТСЯ",IF(OR(CA8="Отсутствует значения предыдущих расчетов",CA8="Осуществлен пересчет"),"ГОТОВ","ПЕРЕСЧЕТ НЕ ТРЕБУЕТСЯ"))))) | BV8: =IF(B8="","",AO8) | BW8: =IF(B8="","",VLOOKUP(BV8,Справочник_ВРИ_Сегментов!$A:$D,4,)) | BX8: =IF(B8="","",AL8) | BY8: =IF(B8="","",VLOOKUP('Объекты оценки'!BX8,Справочник_ВРИ_Сегментов!$B:$C,2,FALSE)) | BZ8: =IF(B8="","",IF(OR(F8="",F8="-",F8="."),G8,F8)) | CA8: =IF(B8="","",IF(L8="","Отсутствует значения предыдущих расчетов",IF(L8=AV8,"Значения КС не изменилось","Осуществлен пересчет"))) | CB8: =IF(B8="","",L8-W8) | CC8: =IF(B8="","",IF(K8="","Новый","Измененный"))
AP9: =IF(B9="","",C9) | AQ9: =IF(B9="","",LEFT(O9,2)) | AR9: =IF(B9="","",VLOOKUP(O9,'Населённые пункты 2019'!$H:$P,9,FALSE)) | AS9: =IF(B9="","",VLOOKUP(AR9,'Поправки для МО'!$A:$C,3,FALSE)) | AT9: =IF(B9="","",IF(51178*C9^-0.982<$AZ$3,$AZ$3,IF(51178*C9^-0.982>$BA$3,$BA$3,51178*C9^-0.982))) | AU9: =IF(B9="","",ROUND(AT9*AS9,2)) | AV9: =IF(B9="","",ROUND(AU9*C9,2)) | AW9: =IF(B9="","",CONCATENATE("СТ16_",BH9,"_",BI9,"_",BJ9,"_",BK9,"_",BL9,"_",CC9)) | AX9: =IF(B9="","",B9) | AY9: =IF(B9="","",$AY$1) | BB9: =IF(B9="","",IF(MID(AL9,3,1)<>":","ОШИБКА В ФОРМАТЕ КОДА НП",IF(K9="","Отсутствуют предыдущие значения",AL9=P9))) | BC9: =IF(B9="","",IF(K9="","Отсутствуют предыдущие значения",AY9=N9)) | BD9: =IF(B9="","",IF(K9="","Отсутствуют предыдущие значения",AP9=C9)) | BE9: =IF(B9="","",IF(K9="","Отсутствуют предыдущие значения",AU9=K9)) | BF9: =IF(B9="","",IF(L9="","Отсутствуют предыдущие значения",AV9=L9)) | BG9: =IF(AA9<>"","ОСПАРИВАНИЕ",IF(V9="","",V9)) | BH9: =IF(B9="","",$BH$1) | BI9: =IF(B9="","",$BI$1) | BJ9: =IF(B9="","",$BJ$1) | BK9: =IF(B9="","",$BK$1) | BL9: =IF(B9="","",IF(K9="","Графика по ПКК","Графика на 01012020")) | BM9: =IF(B9="","",B9) | BN9: =IF(B9="","",AP9) | BO9: =IF(B9="","",AQ9) | BP9: =IF(B9="","",AT9) | BQ9: =IF(B9="","",AU9) | BR9: =IF(B9="","",AV9) | BS9: =IF(B9="","",AW9) | BT9: =IF(B9="","",AY9) | BU9: =IF(B9="","",IF(OR(Y9<>"",AA9<>"",BR9<0),"СТОПЛИСТ",IF(W9=21,"СТОПЛИСТ",IF(AND(BB9=TRUE,BD9=TRUE),"ПЕРЕСЧЕТ НЕ ТРЕБУЕТСЯ",IF(OR(CA9="Отсутствует значения предыдущих расчетов",CA9="Осуществлен пересчет"),"ГОТОВ","ПЕРЕСЧЕТ НЕ ТРЕБУЕТСЯ"))))) | BV9: =IF(B9="","",AO9) | BW9: =IF(B9="","",VLOOKUP(BV9,Справочник_ВРИ_Сегментов!$A:$D,4,)) | BX9: =IF(B9="","",AL9) | BY9: =IF(B9="","",VLOOKUP('Объекты оценки'!BX9,Справочник_ВРИ_Сегментов!$B:$C,2,FALSE)) | BZ9: =IF(B9="","",IF(OR(F9="",F9="-",F9="."),G9,F9)) | CA9: =IF(B9="","",IF(L9="","Отсутствует значения предыдущих расчетов",IF(L9=AV9,"Значения КС не изменилось","Осуществлен пересчет"))) | CB9: =IF(B9="","",L9-W9) | CC9: =IF(B9="","",IF(K9="","Новый","Измененный"))
AP10: =IF(B10="","",C10) | AQ10: =IF(B10="","",LEFT(O10,2)) | AR10: =IF(B10="","",VLOOKUP(O10,'Населённые пункты 2019'!$H:$P,9,FALSE)) | AS10: =IF(B10="","",VLOOKUP(AR10,'Поправки для МО'!$A:$C,3,FALSE)) | AT10: =IF(B10="","",IF(51178*C10^-0.982<$AZ$3,$AZ$3,IF(51178*C10^-0.982>$BA$3,$BA$3,51178*C10^-0.982))) | AU10: =IF(B10="","",ROUND(AT10*AS10,2)) | AV10: =IF(B10="","",ROUND(AU10*C10,2)) | AW10: =IF(B10="","",CONCATENATE("СТ16_",BH10,"_",BI10,"_",BJ10,"_",BK10,"_",BL10,"_",CC10)) | AX10: =IF(B10="","",B10) | AY10: =IF(B10="","",$AY$1) | BB10: =IF(B10="","",IF(MID(AL10,3,1)<>":","ОШИБКА В ФОРМАТЕ КОДА НП",IF(K10="","Отсутствуют предыдущие значения",AL10=P10))) | BC10: =IF(B10="","",IF(K10="","Отсутствуют предыдущие значения",AY10=N10)) | BD10: =IF(B10="","",IF(K10="","Отсутствуют предыдущие значения",AP10=C10)) | BE10: =IF(B10="","",IF(K10="","Отсутствуют предыдущие значения",AU10=K10)) | BF10: =IF(B10="","",IF(L10="","Отсутствуют предыдущие значения",AV10=L10)) | BG10: =IF(AA10<>"","ОСПАРИВАНИЕ",IF(V10="","",V10)) | BH10: =IF(B10="","",$BH$1) | BI10: =IF(B10="","",$BI$1) | BJ10: =IF(B10="","",$BJ$1) | BK10: =IF(B10="","",$BK$1) | BL10: =IF(B10="","",IF(K10="","Графика по ПКК","Графика на 01012020")) | BM10: =IF(B10="","",B10) | BN10: =IF(B10="","",AP10) | BO10: =IF(B10="","",AQ10) | BP10: =IF(B10="","",AT10) | BQ10: =IF(B10="","",AU10) | BR10: =IF(B10="","",AV10) | BS10: =IF(B10="","",AW10) | BT10: =IF(B10="","",AY10) | BU10: =IF(B10="","",IF(OR(Y10<>"",AA10<>"",BR10<0),"СТОПЛИСТ",IF(W10=21,"СТОПЛИСТ",IF(AND(BB10=TRUE,BD10=TRUE),"ПЕРЕСЧЕТ НЕ ТРЕБУЕТСЯ",IF(OR(CA10="Отсутствует значения предыдущих расчетов",CA10="Осуществлен пересчет"),"ГОТОВ","ПЕРЕСЧЕТ НЕ ТРЕБУЕТСЯ"))))) | BV10: =IF(B10="","",AO10) | BW10: =IF(B10="","",VLOOKUP(BV10,Справочник_ВРИ_Сегментов!$A:$D,4,)) | BX10: =IF(B10="","",AL10) | BY10: =IF(B10="","",VLOOKUP('Объекты оценки'!BX10,Справочник_ВРИ_Сегментов!$B:$C,2,FALSE)) | BZ10: =IF(B10="","",IF(OR(F10="",F10="-",F10="."),G10,F10)) | CA10: =IF(B10="","",IF(L10="","Отсутствует значения предыдущих расчетов",IF(L10=AV10,"Значения КС не изменилось","Осуществлен пересчет"))) | CB10: =IF(B10="","",L10-W10) | CC10: =IF(B10="","",IF(K10="","Новый","Измененный"))
AP11: =IF(B11="","",C11) | AQ11: =IF(B11="","",LEFT(O11,2)) | AR11: =IF(B11="","",VLOOKUP(O11,'Населённые пункты 2019'!$H:$P,9,FALSE)) | AS11: =IF(B11="","",VLOOKUP(AR11,'Поправки для МО'!$A:$C,3,FALSE)) | AT11: =IF(B11="","",IF(51178*C11^-0.982<$AZ$3,$AZ$3,IF(51178*C11^-0.982>$BA$3,$BA$3,51178*C11^-0.982))) | AU11: =IF(B11="","",ROUND(AT11*AS11,2)) | AV11: =IF(B11="","",ROUND(AU11*C11,2)) | AW11: =IF(B11="","",CONCATENATE("СТ16_",BH11,"_",BI11,"_",BJ11,"_",BK11,"_",BL11,"_",CC11)) | AX11: =IF(B11="","",B11) | AY11: =IF(B11="","",$AY$1) | BB11: =IF(B11="","",IF(MID(AL11,3,1)<>":","ОШИБКА В ФОРМАТЕ КОДА НП",IF(K11="","Отсутствуют предыдущие значения",AL11=P11))) | BC11: =IF(B11="","",IF(K11="","Отсутствуют предыдущие значения",AY11=N11)) | BD11: =IF(B11="","",IF(K11="","Отсутствуют предыдущие значения",AP11=C11)) | BE11: =IF(B11="","",IF(K11="","Отсутствуют предыдущие значения",AU11=K11)) | BF11: =IF(B11="","",IF(L11="","Отсутствуют предыдущие значения",AV11=L11)) | BG11: =IF(AA11<>"","ОСПАРИВАНИЕ",IF(V11="","",V11)) | BH11: =IF(B11="","",$BH$1) | BI11: =IF(B11="","",$BI$1) | BJ11: =IF(B11="","",$BJ$1) | BK11: =IF(B11="","",$BK$1) | BL11: =IF(B11="","",IF(K11="","Графика по ПКК","Графика на 01012020")) | BM11: =IF(B11="","",B11) | BN11: =IF(B11="","",AP11) | BO11: =IF(B11="","",AQ11) | BP11: =IF(B11="","",AT11) | BQ11: =IF(B11="","",AU11) | BR11: =IF(B11="","",AV11) | BS11: =IF(B11="","",AW11) | BT11: =IF(B11="","",AY11) | BU11: =IF(B11="","",IF(OR(Y11<>"",AA11<>"",BR11<0),"СТОПЛИСТ",IF(W11=21,"СТОПЛИСТ",IF(AND(BB11=TRUE,BD11=TRUE),"ПЕРЕСЧЕТ НЕ ТРЕБУЕТСЯ",IF(OR(CA11="Отсутствует значения предыдущих расчетов",CA11="Осуществлен пересчет"),"ГОТОВ","ПЕРЕСЧЕТ НЕ ТРЕБУЕТСЯ"))))) | BV11: =IF(B11="","",AO11) | BW11: =IF(B11="","",VLOOKUP(BV11,Справочник_ВРИ_Сегментов!$A:$D,4,)) | BX11: =IF(B11="","",AL11) | BY11: =IF(B11="","",VLOOKUP('Объекты оценки'!BX11,Справочник_ВРИ_Сегментов!$B:$C,2,FALSE)) | BZ11: =IF(B11="","",IF(OR(F11="",F11="-",F11="."),G11,F11)) | CA11: =IF(B11="","",IF(L11="","Отсутствует значения предыдущих расчетов",IF(L11=AV11,"Значения КС не изменилось","Осуществлен пересчет"))) | CB11: =IF(B11="","",L11-W11) | CC11: =IF(B11="","",IF(K11="","Новый","Измененный"))
AP12: =IF(B12="","",C12) | AQ12: =IF(B12="","",LEFT(O12,2)) | AR12: =IF(B12="","",VLOOKUP(O12,'Населённые пункты 2019'!$H:$P,9,FALSE)) | AS12: =IF(B12="","",VLOOKUP(AR12,'Поправки для МО'!$A:$C,3,FALSE)) | AT12: =IF(B12="","",IF(51178*C12^-0.982<$AZ$3,$AZ$3,IF(51178*C12^-0.982>$BA$3,$BA$3,51178*C12^-0.982))) | AU12: =IF(B12="","",ROUND(AT12*AS12,2)) | AV12: =IF(B12="","",ROUND(AU12*C12,2)) | AW12: =IF(B12="","",CONCATENATE("СТ16_",BH12,"_",BI12,"_",BJ12,"_",BK12,"_",BL12,"_",CC12)) | AX12: =IF(B12="","",B12) | AY12: =IF(B12="","",$AY$1) | BB12: =IF(B12="","",IF(MID(AL12,3,1)<>":","ОШИБКА В ФОРМАТЕ КОДА НП",IF(K12="","Отсутствуют предыдущие значения",AL12=P12))) | BC12: =IF(B12="","",IF(K12="","Отсутствуют предыдущие значения",AY12=N12)) | BD12: =IF(B12="","",IF(K12="","Отсутствуют предыдущие значения",AP12=C12)) | BE12: =IF(B12="","",IF(K12="","Отсутствуют предыдущие значения",AU12=K12)) | BF12: =IF(B12="","",IF(L12="","Отсутствуют предыдущие значения",AV12=L12)) | BG12: =IF(AA12<>"","ОСПАРИВАНИЕ",IF(V12="","",V12)) | BH12: =IF(B12="","",$BH$1) | BI12: =IF(B12="","",$BI$1) | BJ12: =IF(B12="","",$BJ$1) | BK12: =IF(B12="","",$BK$1) | BL12: =IF(B12="","",IF(K12="","Графика по ПКК","Графика на 01012020")) | BM12: =IF(B12="","",B12) | BN12: =IF(B12="","",AP12) | BO12: =IF(B12="","",AQ12) | BP12: =IF(B12="","",AT12) | BQ12: =IF(B12="","",AU12) | BR12: =IF(B12="","",AV12) | BS12: =IF(B12="","",AW12) | BT12: =IF(B12="","",AY12) | BU12: =IF(B12="","",IF(OR(Y12<>"",AA12<>"",BR12<0),"СТОПЛИСТ",IF(W12=21,"СТОПЛИСТ",IF(AND(BB12=TRUE,BD12=TRUE),"ПЕРЕСЧЕТ НЕ ТРЕБУЕТСЯ",IF(OR(CA12="Отсутствует значения предыдущих расчетов",CA12="Осуществлен пересчет"),"ГОТОВ","ПЕРЕСЧЕТ НЕ ТРЕБУЕТСЯ"))))) | BV12: =IF(B12="","",AO12) | BW12: =IF(B12="","",VLOOKUP(BV12,Справочник_ВРИ_Сегментов!$A:$D,4,)) | BX12: =IF(B12="","",AL12) | BY12: =IF(B12="","",VLOOKUP('Объекты оценки'!BX12,Справочник_ВРИ_Сегментов!$B:$C,2,FALSE)) | BZ12: =IF(B12="","",IF(OR(F12="",F12="-",F12="."),G12,F12)) | CA12: =IF(B12="","",IF(L12="","Отсутствует значения предыдущих расчетов",IF(L12=AV12,"Значения КС не изменилось","Осуществлен пересчет"))) | CB12: =IF(B12="","",L12-W12) | CC12: =IF(B12="","",IF(K12="","Новый","Измененный"))
AP13: =IF(B13="","",C13) | AQ13: =IF(B13="","",LEFT(O13,2)) | AR13: =IF(B13="","",VLOOKUP(O13,'Населённые пункты 2019'!$H:$P,9,FALSE)) | AS13: =IF(B13="","",VLOOKUP(AR13,'Поправки для МО'!$A:$C,3,FALSE)) | AT13: =IF(B13="","",IF(51178*C13^-0.982<$AZ$3,$AZ$3,IF(51178*C13^-0.982>$BA$3,$BA$3,51178*C13^-0.982))) | AU13: =IF(B13="","",ROUND(AT13*AS13,2)) | AV13: =IF(B13="","",ROUND(AU13*C13,2)) | AW13: =IF(B13="","",CONCATENATE("СТ16_",BH13,"_",BI13,"_",BJ13,"_",BK13,"_",BL13,"_",CC13)) | AX13: =IF(B13="","",B13) | AY13: =IF(B13="","",$AY$1) | BB13: =IF(B13="","",IF(MID(AL13,3,1)<>":","ОШИБКА В ФОРМАТЕ КОДА НП",IF(K13="","Отсутствуют предыдущие значения",AL13=P13))) | BC13: =IF(B13="","",IF(K13="","Отсутствуют предыдущие значения",AY13=N13)) | BD13: =IF(B13="","",IF(K13="","Отсутствуют предыдущие значения",AP13=C13)) | BE13: =IF(B13="","",IF(K13="","Отсутствуют предыдущие значения",AU13=K13)) | BF13: =IF(B13="","",IF(L13="","Отсутствуют предыдущие значения",AV13=L13)) | BG13: =IF(AA13<>"","ОСПАРИВАНИЕ",IF(V13="","",V13)) | BH13: =IF(B13="","",$BH$1) | BI13: =IF(B13="","",$BI$1) | BJ13: =IF(B13="","",$BJ$1) | BK13: =IF(B13="","",$BK$1) | BL13: =IF(B13="","",IF(K13="","Графика по ПКК","Графика на 01012020")) | BM13: =IF(B13="","",B13) | BN13: =IF(B13="","",AP13) | BO13: =IF(B13="","",AQ13) | BP13: =IF(B13="","",AT13) | BQ13: =IF(B13="","",AU13) | BR13: =IF(B13="","",AV13) | BS13: =IF(B13="","",AW13) | BT13: =IF(B13="","",AY13) | BU13: =IF(B13="","",IF(OR(Y13<>"",AA13<>"",BR13<0),"СТОПЛИСТ",IF(W13=21,"СТОПЛИСТ",IF(AND(BB13=TRUE,BD13=TRUE),"ПЕРЕСЧЕТ НЕ ТРЕБУЕТСЯ",IF(OR(CA13="Отсутствует значения предыдущих расчетов",CA13="Осуществлен пересчет"),"ГОТОВ","ПЕРЕСЧЕТ НЕ ТРЕБУЕТСЯ"))))) | BV13: =IF(B13="","",AO13) | BW13: =IF(B13="","",VLOOKUP(BV13,Справочник_ВРИ_Сегментов!$A:$D,4,)) | BX13: =IF(B13="","",AL13) | BY13: =IF(B13="","",VLOOKUP('Объекты оценки'!BX13,Справочник_ВРИ_Сегментов!$B:$C,2,FALSE)) | BZ13: =IF(B13="","",IF(OR(F13="",F13="-",F13="."),G13,F13)) | CA13: =IF(B13="","",IF(L13="","Отсутствует значения предыдущих расчетов",IF(L13=AV13,"Значения КС не изменилось","Осуществлен пересчет"))) | CB13: =IF(B13="","",L13-W13) | CC13: =IF(B13="","",IF(K13="","Новый","Измененный"))
AP14: =IF(B14="","",C14) | AQ14: =IF(B14="","",LEFT(O14,2)) | AR14: =IF(B14="","",VLOOKUP(O14,'Населённые пункты 2019'!$H:$P,9,FALSE)) | AS14: =IF(B14="","",VLOOKUP(AR14,'Поправки для МО'!$A:$C,3,FALSE)) | AT14: =IF(B14="","",IF(51178*C14^-0.982<$AZ$3,$AZ$3,IF(51178*C14^-0.982>$BA$3,$BA$3,51178*C14^-0.982))) | AU14: =IF(B14="","",ROUND(AT14*AS14,2)) | AV14: =IF(B14="","",ROUND(AU14*C14,2)) | AW14: =IF(B14="","",CONCATENATE("СТ16_",BH14,"_",BI14,"_",BJ14,"_",BK14,"_",BL14,"_",CC14)) | AX14: =IF(B14="","",B14) | AY14: =IF(B14="","",$AY$1) | BB14: =IF(B14="","",IF(MID(AL14,3,1)<>":","ОШИБКА В ФОРМАТЕ КОДА НП",IF(K14="","Отсутствуют предыдущие значения",AL14=P14))) | BC14: =IF(B14="","",IF(K14="","Отсутствуют предыдущие значения",AY14=N14)) | BD14: =IF(B14="","",IF(K14="","Отсутствуют предыдущие значения",AP14=C14)) | BE14: =IF(B14="","",IF(K14="","Отсутствуют предыдущие значения",AU14=K14)) | BF14: =IF(B14="","",IF(L14="","Отсутствуют предыдущие значения",AV14=L14)) | BG14: =IF(AA14<>"","ОСПАРИВАНИЕ",IF(V14="","",V14)) | BH14: =IF(B14="","",$BH$1) | BI14: =IF(B14="","",$BI$1) | BJ14: =IF(B14="","",$BJ$1) | BK14: =IF(B14="","",$BK$1) | BL14: =IF(B14="","",IF(K14="","Графика по ПКК","Графика на 01012020")) | BM14: =IF(B14="","",B14) | BN14: =IF(B14="","",AP14) | BO14: =IF(B14="","",AQ14) | BP14: =IF(B14="","",AT14) | BQ14: =IF(B14="","",AU14) | BR14: =IF(B14="","",AV14) | BS14: =IF(B14="","",AW14) | BT14: =IF(B14="","",AY14) | BU14: =IF(B14="","",IF(OR(Y14<>"",AA14<>"",BR14<0),"СТОПЛИСТ",IF(W14=21,"СТОПЛИСТ",IF(AND(BB14=TRUE,BD14=TRUE),"ПЕРЕСЧЕТ НЕ ТРЕБУЕТСЯ",IF(OR(CA14="Отсутствует значения предыдущих расчетов",CA14="Осуществлен пересчет"),"ГОТОВ","ПЕРЕСЧЕТ НЕ ТРЕБУЕТСЯ"))))) | BV14: =IF(B14="","",AO14) | BW14: =IF(B14="","",VLOOKUP(BV14,Справочник_ВРИ_Сегментов!$A:$D,4,)) | BX14: =IF(B14="","",AL14) | BY14: =IF(B14="","",VLOOKUP('Объекты оценки'!BX14,Справочник_ВРИ_Сегментов!$B:$C,2,FALSE)) | BZ14: =IF(B14="","",IF(OR(F14="",F14="-",F14="."),G14,F14)) | CA14: =IF(B14="","",IF(L14="","Отсутствует значения предыдущих расчетов",IF(L14=AV14,"Значения КС не изменилось","Осуществлен пересчет"))) | CB14: =IF(B14="","",L14-W14) | CC14: =IF(B14="","",IF(K14="","Новый","Измененный"))
AP15: =IF(B15="","",C15) | AQ15: =IF(B15="","",LEFT(O15,2)) | AR15: =IF(B15="","",VLOOKUP(O15,'Населённые пункты 2019'!$H:$P,9,FALSE)) | AS15: =IF(B15="","",VLOOKUP(AR15,'Поправки для МО'!$A:$C,3,FALSE)) | AT15: =IF(B15="","",IF(51178*C15^-0.982<$AZ$3,$AZ$3,IF(51178*C15^-0.982>$BA$3,$BA$3,51178*C15^-0.982))) | AU15: =IF(B15="","",ROUND(AT15*AS15,2)) | AV15: =IF(B15="","",ROUND(AU15*C15,2)) | AW15: =IF(B15="","",CONCATENATE("СТ16_",BH15,"_",BI15,"_",BJ15,"_",BK15,"_",BL15,"_",CC15)) | AX15: =IF(B15="","",B15) | AY15: =IF(B15="","",$AY$1) | BB15: =IF(B15="","",IF(MID(AL15,3,1)<>":","ОШИБКА В ФОРМАТЕ КОДА НП",IF(K15="","Отсутствуют предыдущие значения",AL15=P15))) | BC15: =IF(B15="","",IF(K15="","Отсутствуют предыдущие значения",AY15=N15)) | BD15: =IF(B15="","",IF(K15="","Отсутствуют предыдущие значения",AP15=C15)) | BE15: =IF(B15="","",IF(K15="","Отсутствуют предыдущие значения",AU15=K15)) | BF15: =IF(B15="","",IF(L15="","Отсутствуют предыдущие значения",AV15=L15)) | BG15: =IF(AA15<>"","ОСПАРИВАНИЕ",IF(V15="","",V15)) | BH15: =IF(B15="","",$BH$1) | BI15: =IF(B15="","",$BI$1) | BJ15: =IF(B15="","",$BJ$1) | BK15: =IF(B15="","",$BK$1) | BL15: =IF(B15="","",IF(K15="","Графика по ПКК","Графика на 01012020")) | BM15: =IF(B15="","",B15) | BN15: =IF(B15="","",AP15) | BO15: =IF(B15="","",AQ15) | BP15: =IF(B15="","",AT15) | BQ15: =IF(B15="","",AU15) | BR15: =IF(B15="","",AV15) | BS15: =IF(B15="","",AW15) | BT15: =IF(B15="","",AY15) | BU15: =IF(B15="","",IF(OR(Y15<>"",AA15<>"",BR15<0),"СТОПЛИСТ",IF(W15=21,"СТОПЛИСТ",IF(AND(BB15=TRUE,BD15=TRUE),"ПЕРЕСЧЕТ НЕ ТРЕБУЕТСЯ",IF(OR(CA15="Отсутствует значения предыдущих расчетов",CA15="Осуществлен пересчет"),"ГОТОВ","ПЕРЕСЧЕТ НЕ ТРЕБУЕТСЯ"))))) | BV15: =IF(B15="","",AO15) | BW15: =IF(B15="","",VLOOKUP(BV15,Справочник_ВРИ_Сегментов!$A:$D,4,)) | BX15: =IF(B15="","",AL15) | BY15: =IF(B15="","",VLOOKUP('Объекты оценки'!BX15,Справочник_ВРИ_Сегментов!$B:$C,2,FALSE)) | BZ15: =IF(B15="","",IF(OR(F15="",F15="-",F15="."),G15,F15)) | CA15: =IF(B15="","",IF(L15="","Отсутствует значения предыдущих расчетов",IF(L15=AV15,"Значения КС не изменилось","Осуществлен пересчет"))) | CB15: =IF(B15="","",L15-W15) | CC15: =IF(B15="","",IF(K15="","Новый","Измененный"))
AP16: =IF(B16="","",C16) | AQ16: =IF(B16="","",LEFT(O16,2)) | AR16: =IF(B16="","",VLOOKUP(O16,'Населённые пункты 2019'!$H:$P,9,FALSE)) | AS16: =IF(B16="","",VLOOKUP(AR16,'Поправки для МО'!$A:$C,3,FALSE)) | AT16: =IF(B16="","",IF(51178*C16^-0.982<$AZ$3,$AZ$3,IF(51178*C16^-0.982>$BA$3,$BA$3,51178*C16^-0.982))) | AU16: =IF(B16="","",ROUND(AT16*AS16,2)) | AV16: =IF(B16="","",ROUND(AU16*C16,2)) | AW16: =IF(B16="","",CONCATENATE("СТ16_",BH16,"_",BI16,"_",BJ16,"_",BK16,"_",BL16,"_",CC16)) | AX16: =IF(B16="","",B16) | AY16: =IF(B16="","",$AY$1) | BB16: =IF(B16="","",IF(MID(AL16,3,1)<>":","ОШИБКА В ФОРМАТЕ КОДА НП",IF(K16="","Отсутствуют предыдущие значения",AL16=P16))) | BC16: =IF(B16="","",IF(K16="","Отсутствуют предыдущие значения",AY16=N16)) | BD16: =IF(B16="","",IF(K16="","Отсутствуют предыдущие значения",AP16=C16)) | BE16: =IF(B16="","",IF(K16="","Отсутствуют предыдущие значения",AU16=K16)) | BF16: =IF(B16="","",IF(L16="","Отсутствуют предыдущие значения",AV16=L16)) | BG16: =IF(AA16<>"","ОСПАРИВАНИЕ",IF(V16="","",V16)) | BH16: =IF(B16="","",$BH$1) | BI16: =IF(B16="","",$BI$1) | BJ16: =IF(B16="","",$BJ$1) | BK16: =IF(B16="","",$BK$1) | BL16: =IF(B16="","",IF(K16="","Графика по ПКК","Графика на 01012020")) | BM16: =IF(B16="","",B16) | BN16: =IF(B16="","",AP16) | BO16: =IF(B16="","",AQ16) | BP16: =IF(B16="","",AT16) | BQ16: =IF(B16="","",AU16) | BR16: =IF(B16="","",AV16) | BS16: =IF(B16="","",AW16) | BT16: =IF(B16="","",AY16) | BU16: =IF(B16="","",IF(OR(Y16<>"",AA16<>"",BR16<0),"СТОПЛИСТ",IF(W16=21,"СТОПЛИСТ",IF(AND(BB16=TRUE,BD16=TRUE),"ПЕРЕСЧЕТ НЕ ТРЕБУЕТСЯ",IF(OR(CA16="Отсутствует значения предыдущих расчетов",CA16="Осуществлен пересчет"),"ГОТОВ","ПЕРЕСЧЕТ НЕ ТРЕБУЕТСЯ"))))) | BV16: =IF(B16="","",AO16) | BW16: =IF(B16="","",VLOOKUP(BV16,Справочник_ВРИ_Сегментов!$A:$D,4,)) | BX16: =IF(B16="","",AL16) | BY16: =IF(B16="","",VLOOKUP('Объекты оценки'!BX16,Справочник_ВРИ_Сегментов!$B:$C,2,FALSE)) | BZ16: =IF(B16="","",IF(OR(F16="",F16="-",F16="."),G16,F16)) | CA16: =IF(B16="","",IF(L16="","Отсутствует значения предыдущих расчетов",IF(L16=AV16,"Значения КС не изменилось","Осуществлен пересчет"))) | CB16: =IF(B16="","",L16-W16) | CC16: =IF(B16="","",IF(K16="","Новый","Измененный"))
AP17: =IF(B17="","",C17) | AQ17: =IF(B17="","",LEFT(O17,2)) | AR17: =IF(B17="","",VLOOKUP(O17,'Населённые пункты 2019'!$H:$P,9,FALSE)) | AS17: =IF(B17="","",VLOOKUP(AR17,'Поправки для МО'!$A:$C,3,FALSE)) | AT17: =IF(B17="","",IF(51178*C17^-0.982<$AZ$3,$AZ$3,IF(51178*C17^-0.982>$BA$3,$BA$3,51178*C17^-0.982))) | AU17: =IF(B17="","",ROUND(AT17*AS17,2)) | AV17: =IF(B17="","",ROUND(AU17*C17,2)) | AW17: =IF(B17="","",CONCATENATE("СТ16_",BH17,"_",BI17,"_",BJ17,"_",BK17,"_",BL17,"_",CC17)) | AX17: =IF(B17="","",B17) | AY17: =IF(B17="","",$AY$1) | BB17: =IF(B17="","",IF(MID(AL17,3,1)<>":","ОШИБКА В ФОРМАТЕ КОДА НП",IF(K17="","Отсутствуют предыдущие значения",AL17=P17))) | BC17: =IF(B17="","",IF(K17="","Отсутствуют предыдущие значения",AY17=N17)) | BD17: =IF(B17="","",IF(K17="","Отсутствуют предыдущие значения",AP17=C17)) | BE17: =IF(B17="","",IF(K17="","Отсутствуют предыдущие значения",AU17=K17)) | BF17: =IF(B17="","",IF(L17="","Отсутствуют предыдущие значения",AV17=L17)) | BG17: =IF(AA17<>"","ОСПАРИВАНИЕ",IF(V17="","",V17)) | BH17: =IF(B17="","",$BH$1) | BI17: =IF(B17="","",$BI$1) | BJ17: =IF(B17="","",$BJ$1) | BK17: =IF(B17="","",$BK$1) | BL17: =IF(B17="","",IF(K17="","Графика по ПКК","Графика на 01012020")) | BM17: =IF(B17="","",B17) | BN17: =IF(B17="","",AP17) | BO17: =IF(B17="","",AQ17) | BP17: =IF(B17="","",AT17) | BQ17: =IF(B17="","",AU17) | BR17: =IF(B17="","",AV17) | BS17: =IF(B17="","",AW17) | BT17: =IF(B17="","",AY17) | BU17: =IF(B17="","",IF(OR(Y17<>"",AA17<>"",BR17<0),"СТОПЛИСТ",IF(W17=21,"СТОПЛИСТ",IF(AND(BB17=TRUE,BD17=TRUE),"ПЕРЕСЧЕТ НЕ ТРЕБУЕТСЯ",IF(OR(CA17="Отсутствует значения предыдущих расчетов",CA17="Осуществлен пересчет"),"ГОТОВ","ПЕРЕСЧЕТ НЕ ТРЕБУЕТСЯ"))))) | BV17: =IF(B17="","",AO17) | BW17: =IF(B17="","",VLOOKUP(BV17,Справочник_ВРИ_Сегментов!$A:$D,4,)) | BX17: =IF(B17="","",AL17) | BY17: =IF(B17="","",VLOOKUP('Объекты оценки'!BX17,Справочник_ВРИ_Сегментов!$B:$C,2,FALSE)) | BZ17: =IF(B17="","",IF(OR(F17="",F17="-",F17="."),G17,F17)) | CA17: =IF(B17="","",IF(L17="","Отсутствует значения предыдущих расчетов",IF(L17=AV17,"Значения КС не изменилось","Осуществлен пересчет"))) | CB17: =IF(B17="","",L17-W17) | CC17: =IF(B17="","",IF(K17="","Новый","Измененный"))
AP18: =IF(B18="","",C18) | AQ18: =IF(B18="","",LEFT(O18,2)) | AR18: =IF(B18="","",VLOOKUP(O18,'Населённые пункты 2019'!$H:$P,9,FALSE)) | AS18: =IF(B18="","",VLOOKUP(AR18,'Поправки для МО'!$A:$C,3,FALSE)) | AT18: =IF(B18="","",IF(51178*C18^-0.982<$AZ$3,$AZ$3,IF(51178*C18^-0.982>$BA$3,$BA$3,51178*C18^-0.982))) | AU18: =IF(B18="","",ROUND(AT18*AS18,2)) | AV18: =IF(B18="","",ROUND(AU18*C18,2)) | AW18: =IF(B18="","",CONCATENATE("СТ16_",BH18,"_",BI18,"_",BJ18,"_",BK18,"_",BL18,"_",CC18)) | AX18: =IF(B18="","",B18) | AY18: =IF(B18="","",$AY$1) | BB18: =IF(B18="","",IF(MID(AL18,3,1)<>":","ОШИБКА В ФОРМАТЕ КОДА НП",IF(K18="","Отсутствуют предыдущие значения",AL18=P18))) | BC18: =IF(B18="","",IF(K18="","Отсутствуют предыдущие значения",AY18=N18)) | BD18: =IF(B18="","",IF(K18="","Отсутствуют предыдущие значения",AP18=C18)) | BE18: =IF(B18="","",IF(K18="","Отсутствуют предыдущие значения",AU18=K18)) | BF18: =IF(B18="","",IF(L18="","Отсутствуют предыдущие значения",AV18=L18)) | BG18: =IF(AA18<>"","ОСПАРИВАНИЕ",IF(V18="","",V18)) | BH18: =IF(B18="","",$BH$1) | BI18: =IF(B18="","",$BI$1) | BJ18: =IF(B18="","",$BJ$1) | BK18: =IF(B18="","",$BK$1) | BL18: =IF(B18="","",IF(K18="","Графика по ПКК","Графика на 01012020")) | BM18: =IF(B18="","",B18) | BN18: =IF(B18="","",AP18) | BO18: =IF(B18="","",AQ18) | BP18: =IF(B18="","",AT18) | BQ18: =IF(B18="","",AU18) | BR18: =IF(B18="","",AV18) | BS18: =IF(B18="","",AW18) | BT18: =IF(B18="","",AY18) | BU18: =IF(B18="","",IF(OR(Y18<>"",AA18<>"",BR18<0),"СТОПЛИСТ",IF(W18=21,"СТОПЛИСТ",IF(AND(BB18=TRUE,BD18=TRUE),"ПЕРЕСЧЕТ НЕ ТРЕБУЕТСЯ",IF(OR(CA18="Отсутствует значения предыдущих расчетов",CA18="Осуществлен пересчет"),"ГОТОВ","ПЕРЕСЧЕТ НЕ ТРЕБУЕТСЯ"))))) | BV18: =IF(B18="","",AO18) | BW18: =IF(B18="","",VLOOKUP(BV18,Справочник_ВРИ_Сегментов!$A:$D,4,)) | BX18: =IF(B18="","",AL18) | BY18: =IF(B18="","",VLOOKUP('Объекты оценки'!BX18,Справочник_ВРИ_Сегментов!$B:$C,2,FALSE)) | BZ18: =IF(B18="","",IF(OR(F18="",F18="-",F18="."),G18,F18)) | CA18: =IF(B18="","",IF(L18="","Отсутствует значения предыдущих расчетов",IF(L18=AV18,"Значения КС не изменилось","Осуществлен пересчет"))) | CB18: =IF(B18="","",L18-W18) | CC18: =IF(B18="","",IF(K18="","Новый","Измененный"))
... AP2000: =IF(B2000="","",C2000) | AQ2000: =IF(B2000="","",LEFT(O2000,2)) | AR2000: =IF(B2000="","",VLOOKUP(O2000,'Населённые пункты 2019'!$H:$P,9,FALSE)) | AS2000: =IF(B2000="","",VLOOKUP(AR2000,'Поправки для МО'!$A:$C,3,FALSE)) | AT2000: =IF(B2000="","",IF(51178*C2000^-0.982<$AZ$3,$AZ$3,IF(51178*C2000^-0.982>$BA$3,$BA$3,51178*C2000^-0.982))) | AU2000: =IF(B2000="","",ROUND(AT2000*AS2000,2)) | AV2000: =IF(B2000="","",ROUND(AU2000*C2000,2)) | AW2000: =IF(B2000="","",CONCATENATE("СТ16_",BH2000,"_",BI2000,"_",BJ2000,"_",BK2000,"_",BL2000,"_",CC2000)) | AX2000: =IF(B2000="","",B2000) | AY2000: =IF(B2000="","",$AY$1) | BB2000: =IF(B2000="","",IF(MID(AL2000,3,1)<>":","ОШИБКА В ФОРМАТЕ КОДА НП",IF(K2000="","Отсутствуют предыдущие значения",AL2000=P2000))) | BC2000: =IF(B2000="","",IF(K2000="","Отсутствуют предыдущие значения",AY2000=N2000)) | BD2000: =IF(B2000="","",IF(K2000="","Отсутствуют предыдущие значения",AP2000=C2000)) | BE2000: =IF(B2000="","",IF(K2000="","Отсутствуют предыдущие значения",AU2000=K2000)) | BF2000: =IF(B2000="","",IF(L2000="","Отсутствуют предыдущие значения",AV2000=L2000)) | BG2000: =IF(AA2000<>"","ОСПАРИВАНИЕ",IF(V2000="","",V2000)) | BH2000: =IF(B2000="","",$BH$1) | BI2000: =IF(B2000="","",$BI$1) | BJ2000: =IF(B2000="","",$BJ$1) | BK2000: =IF(B2000="","",$BK$1) | BL2000: =IF(B2000="","",IF(K2000="","Графика по ПКК","Графика на 01012020")) | BM2000: =IF(B2000="","",B2000) | BN2000: =IF(B2000="","",AP2000) | BO2000: =IF(B2000="","",AQ2000) | BP2000: =IF(B2000="","",AT2000) | BQ2000: =IF(B2000="","",AU2000) | BR2000: =IF(B2000="","",AV2000) | BS2000: =IF(B2000="","",AW2000) | BT2000: =IF(B2000="","",AY2000) | BU2000: =IF(B2000="","",IF(OR(Y2000<>"",AA2000<>"",BR2000<0),"СТОПЛИСТ",IF(W2000=21,"СТОПЛИСТ",IF(AND(BB2000=TRUE,BD2000=TRUE),"ПЕРЕСЧЕТ НЕ ТРЕБУЕТСЯ",IF(OR(CA2000="Отсутствует значения предыдущих расчетов",CA2000="Осуществлен пересчет"),"ГОТОВ","ПЕРЕСЧЕТ НЕ ТРЕБУЕТСЯ"))))) | BV2000: =IF(B2000="","",AO2000) | BW2000: =IF(B2000="","",VLOOKUP(BV2000,Справочник_ВРИ_Сегментов!$A:$D,4,)) | BX2000: =IF(B2000="","",AL2000) | BY2000: =IF(B2000="","",VLOOKUP('Объекты оценки'!BX2000,Справочник_ВРИ_Сегментов!$B:$C,2,FALSE)) | BZ2000: =IF(B2000="","",IF(OR(F2000="",F2000="-",F2000="."),G2000,F2000)) | CA2000: =IF(B2000="","",IF(L2000="","Отсутствует значения предыдущих расчетов",IF(L2000=AV2000,"Значения КС не изменилось","Осуществлен пересчет"))) | CB2000: =IF(B2000="","",L2000-W2000) | CC2000: =IF(B2000="","",IF(K2000="","Новый","Измененный"))

Sheet ГОТОВО
A1: CadastralNumber | B1: loc_factor_807 | C1: loc_factor_830 | D1: loc_factor_8071 | E1: Specific_CadastralCost | F1: CadastralCost | G1: CadastralCostDesc | H1: id_group | I1: Status_kc | J1: Segment | K1: loc_SgCode | L1: loc_VICode | M1: loc_GroupName | N1: Old_Utlbydoc | P1: =COUNTA(A:A) -> 1

Sheet ПЕРЕСЧЕТ НЕ ТРЕБУЕТСЯ
A1: CadastralNumber | B1: Status_kc | C1: Segment | D1: loc_SgCode | E1: loc_VICode | F1: loc_GroupName | G1: Old_Utlbydoc | I1: =COUNTA(A:A) -> 1

Sheet СТОПЛИСТ
A1: CadastralNumber | B1: Status_kc | D1: =COUNTA(A:A) -> 1

Sheet Инструкция
B1: Пошаговая инструкция расчета объектов в рамках статьи 16 для модели №8 | C1: Ссылки на папки
A2: 1 | B2: Открываем рабочую область модели №8 | C2: W:\ЦГКО\Отдел массовой оценки\19. 16 Статья\8. Земельные участки
A3: 2 | B3: В рабочей области стоят фильтры - новая модель 8008, статус расчета - не готов. Фильтры не трогаем
A4: 3 | B4: Выгружаем рабочую область через "Экспорт…", английские заголовки не нужны
A5: 4 | B5: Копируем объекты построчно без шапки, вставляем в данный файл на лист "объекты оценки". Должны быть заполнены ячейки от A3 до AO3 и ниже
A6: 5 | B6: Меняем формат вставленных данных в стилях ячеек на обычный
A7: 6 | B7: Все расчетные формулы работают автоматически, ячейки защищены и не редактируются (колонки AP - BA)
A8: 7 | B8: Анализируем колонки BB- BG, в случае, если значение не изменилось ячейка останется не закрашеной. Изменений в рамках расчета по 16 статье у объектов без графики быть не должно, за исключением смены модели, кода ВРИ, значения площади
A9: 8 | B9: Проверяем колонку "ОБЯЗАТЕЛЬНАЯ ПРОВЕРКА", в ней отражены наличия замечаний по объекту, обращений по статье 21, оспаривание
A10: 9 | B10: В случае наличия обращений по статье 21 или оспаривания ЗУ или особого контроля в колонке "статус расчета" будет указано СТОПЛИСТ | D10: уточню про стоплист
A11: 10 | B11: В случае наличия замечаний по объекту заходим в папку замечаний и проверяем корректно ли учтены данные при расчете по статье 16 | C11: W:\ЦГКО\Отдел по работе с обращениями\Замечания к ПОД-2020\ЗАМЕЧАНИЯ
A12: 11 | B12: Заполняем ячейки BF - BJ ТОЛЬКО В ПЕРВОЙ СТРОКЕ. Пишем номер файла который указан в названии файла, номер модели - М8, дата - без точек, например 22012021 (формат ячейки с точками некорректно сцепляется), фамилия исполнителя, наличие графики - с графикой или без графики
A13: 12 | B13: Проверяем колонку "Статус расчета" и изменение КС. Если в колонке "Изменение, руб." значение меньше 1 руб. необходимо проверить расчеты
A14: 13 | B14: По колонке "статус расчета" BU разносим файлы по листам. Если "пересчет не требуется" то - кадастровый номер, ври, сегмент, статус расчета, если "стоплист" то только кадастровый номер и статус расчета, если "готов" то все данные на загрузку в базу. В шапке только английские заголовки!
A15: 14 | B15: ГОТОВО, отправляем на загрузку в базу
A16: 15 | B16: Важно: формулы растянуты на 2000строк, если объектов оценки больше необходимо рассчитать их двумя файлами или растянуть ячейки
B18: Ячейки в строках 1-3 выделены цветом для удобства:
B19: Ячейки для заполнения
B20: Ячейки для анализа
B21: Ячейки не требующие редактирования

Sheet Населённые пункты 2019
A1: Идентификатор | B1: CadastralNumber | C1: MO_Type | D1: MO_Locality | E1: Road | F1: Road_Distance | G1: Descript | H1: Code_City | I1: MO_City_Name | J1: Pref_MO | K1: MO | L1: Change_zak | M1: Old_Code | N1: New_Code | O1: Управленческий округ | P1: Полное наименование МО | Q1: Внешнее устаревание для нежилых зданий | R1: Внешнее устаревание для подгруппы 0202 | S1: Код МО | T1: Модель для квартир | U1: Местоположение для моделей №5 и №6 | V1: Численность НП по справочнику
A2: 1433 | B2: 66:33:0101001 | C2: Район | D2: Сысертский | E2: Да | F2: 0 | H2: 01:001:1:1:4 | I2: Арамиль | J2: г | K2: Арамиль | O2: Южный управленческий округ | P2: Арамильский городской округ | Q2: 0.2359 | R2: 0.24 | S2: =MID(H2,1,2) -> 01 | T2: 1002 | U2: Арамильский городской округ | V2: городские населенные пункты с численностью населения менее 50 000 человек;
A3: 1811 | C3: Район | D3: Сысертский | F3: 0 | H3: 01:002:2:3:5 | I3: Арамиль | J3: п | K3: Арамиль | O3: Южный управленческий округ | P3: Арамильский городской округ | Q3: 0.3496 | R3: 0.35 | S3: =MID(H3,1,2) -> 01 | T3: 1002 | U3: Арамильский городской округ | V3: сельские населенные пункты с численностью населения более 1 000 человек;
A4: 1812 | C4: Район | D4: Сысертский | F4: 0 | H4: 01:003:2:3:5 | I4: Светлый | J4: п | K4: Арамиль | O4: Южный управленческий округ | P4: Арамильский городской округ | Q4: 0.3496 | R4: 0.35 | S4: =MID(H4,1,2) -> 01 | T4: 1002 | U4: Арамильский городской округ | V4: сельские населенные пункты с численностью населения более 1 000 человек;
A5: 1931 | C5: район | D5: Сысертский | F5: 0 | H5: 01:000:0:0:0 | I5: Арамильский городской округ | J5: б.н.п. | K5: Арамиль | O5: Южный управленческий округ | P5: Арамильский городской округ | Q5: 0.36548319 | R5: 0.37 | S5: =MID(H5,1,2) -> 01 | T5: 1002 | U5: Арамильский городской округ | V5: межселенная территория
A6: 165 | B6: 66:02:0102002 | C6: Район | D6: Артемовский | E6: Да | F6: 0 | H6: 02:009:2:5:6 | I6: Бучино | J6: д | K6: Артемовский | O6: Восточный управленческий округ | P6: Артемовский городской округ | Q6: 0.6883 | R6: 0.33 | S6: =MID(H6,1,2) -> 02 | T6: 1002 | U6: Артемовский городской округ | V6: сельские населенные пункты с численностью населения менее 1 000 человек.
A7: 166 | B7: 66:02:0201001 | C7: Район | D7: Артемовский | E7: Да | F7: 0 | H7: 02:005:2:4:6 | I7: Бичур | J7: с | K7: Артемовский | O7: Восточный управленческий округ | P7: Артемовский городской округ | Q7: 0.6883 | R7: 0.33 | S7: =MID(H7,1,2) -> 02 | T7: 1002 | U7: Артемовский городской округ | V7: сельские населенные пункты с численностью населения менее 1 000 человек.
A8: 167 | B8: 66:02:0501001 | C8: Район | D8: Артемовский | E8: Да | F8: 0 | H8: 02:025:2:4:6 | I8: Сарафаново | J8: с | K8: Артемовский | O8: Восточный управленческий округ | P8: Артемовский городской округ | Q8: 0.6883 | R8: 0.33 | S8: =MID(H8,1,2) -> 02 | T8: 1002 | U8: Артемовский городской округ | V8: сельские населенные пункты с численностью населения менее 1 000 человек.
A9: 168 | B9: 66:02:0601001 | C9: Район | D9: Артемовский | E9: Да | F9: 0 | H9: 02:021:2:3:6 | I9: Незевай | J9: п | K9: Артемовский | O9: Восточный управленческий округ | P9: Артемовский городской округ | Q9: 0.6883 | R9: 0.33 | S9: =MID(H9,1,2) -> 02 | T9: 1002 | U9: Артемовский городской округ | V9: сельские населенные пункты с численностью населения менее 1 000 человек.
A10: 169 | B10: 66:02:0801001 | C10: Район | D10: Артемовский | E10: Да | F10: 0 | H10: 02:024:2:5:6 | I10: Родники | J10: д | K10: Артемовский | O10: Восточный управленческий округ | P10: Артемовский городской округ | Q10: 0.6883 | R10: 0.33 | S10: =MID(H10,1,2) -> 02 | T10: 1002 | U10: Артемовский городской округ | V10: сельские населенные пункты с численностью населения менее 1 000 человек.
A11: 170 | B11: 66:02:1101001 | C11: Район | D11: Артемовский | E11: Да | F11: 0 | H11: 02:010:2:3:6 | I11: Заболотье | J11: п | K11: Артемовский | O11: Восточный управленческий округ | P11: Артемовский городской округ | Q11: 0.6883 | R11: 0.33 | S11: =MID(H11,1,2) -> 02 | T11: 1002 | U11: Артемовский городской округ | V11: сельские населенные пункты с численностью населения менее 1 000 человек.
A12: 171 | B12: 66:02:1201001 | C12: Район | D12: Артемовский | E12: Да | F12: 0 | H12: 02:015:2:5:6 | I12: Лисава | J12: д | K12: Артемовский | O12: Восточный управленческий округ | P12: Артемовский городской округ | Q12: 0.6883 | R12: 0.33 | S12: =MID(H12,1,2) -> 02 | T12: 1002 | U12: Артемовский городской округ | V12: сельские населенные пункты с численностью населения менее 1 000 человек.
A13: 172 | B13: 66:02:1501001 | C13: Район | D13: Артемовский | E13: Да | F13: 0 | H13: 02:017:2:5:6 | I13: Малое Трифоново | J13: д | K13: Артемовский | O13: Восточный управленческий округ | P13: Артемовский городской округ | Q13: 0.6883 | R13: 0.33 | S13: =MID(H13,1,2) -> 02 | T13: 1002 | U13: Артемовский городской округ | V13: сельские населенные пункты с численностью населения менее 1 000 человек.
A14: 173 | B14: 66:02:1901001 | C14: Район | D14: Артемовский | E14: Да | F14: 0 | H14: 02:020:2:5:6 | I14: Налимово | J14: д | K14: Артемовский | O14: Восточный управленческий округ | P14: Артемовский городской округ | Q14: 0.6883 | R14: 0.33 | S14: =MID(H14,1,2) -> 02 | T14: 1002 | U14: Артемовский городской округ | V14: сельские населенные пункты с численностью населения менее 1 000 человек.
A15: 174 | B15: 66:02:2101001 | C15: Район | D15: Артемовский | E15: Да | F15: 0 | H15: 02:022:2:4:6 | I15: Писанец | J15: с | K15: Артемовский | O15: Восточный управленческий округ | P15: Артемовский городской округ | Q15: 0.6883 | R15: 0.33 | S15: =MID(H15,1,2) -> 02 | T15: 1002 | U15: Артемовский городской округ | V15: сельские населенные пункты с численностью населения менее 1 000 человек.
A16: 175 | B16: 66:02:2501002 | C16: Район | D16: Артемовский | F16: 0.63 | H16: 02:011:2:3:6 | I16: Кислянка | J16: п | K16: Артемовский | O16: Восточный управленческий округ | P16: Артемовский городской округ | Q16: 0.6883 | R16: 0.33 | S16: =MID(H16,1,2) -> 02 | T16: 1002 | U16: Артемовский городской округ | V16: сельские населенные пункты с численностью населения менее 1 000 человек.
A17: 176 | B17: 66:02:2501005 | C17: Район | D17: Артемовский | E17: Да | F17: 0 | H17: 02:004:2:3:6 | I17: Березники | J17: п | K17: Артемовский | O17: Восточный управленческий округ | P17: Артемовский городской округ | Q17: 0.6883 | R17: 0.33 | S17: =MID(H17,1,2) -> 02 | T17: 1002 | U17: Артемовский городской округ | V17: сельские населенные пункты с численностью населения менее 1 000 человек.
A18: 177 | B18: 66:02:2502004 | C18: Район | D18: Артемовский | E18: Да | F18: 0 | H18: 02:003:2:3:6 | I18: Белый Яр | J18: п | K18: Артемовский | O18: Восточный управленческий округ | P18: Артемовский городской округ | Q18: 0.6883 | R18: 0.33 | S18: =MID(H18,1,2) -> 02 | T18: 1002 | U18: Артемовский городской округ | V18: сельские населенные пункты с численностью населения менее 1 000 человек.
A19: 1096 | B19: 66:02:0301001 | C19: Район | D19: Артемовский | E19: Да | F19: 0 | H19: 02:013:2:4:6 | I19: Лебедкино | J19: с | K19: Артемовский | O19: Восточный управленческий округ | P19: Артемовский городской округ | Q19: 0.6883 | R19: 0.33 | S19: =MID(H19,1,2) -> 02 | T19: 1002 | U19: Артемовский городской округ | V19: сельские населенные пункты с численностью населения менее 1 000 человек.
A20: 1097 | B20: 66:02:0401001 | C20: Район | D20: Артемовский | E20: Да | F20: 0 | H20: 02:002:2:4:6 | I20: Антоново | J20: с | K20: Артемовский | O20: Восточный управленческий округ | P20: Артемовский городской округ | Q20: 0.6883 | R20: 0.33 | S20: =MID(H20,1,2) -> 02 | T20: 1002 | U20: Артемовский городской округ | V20: сельские населенные пункты с численностью населения менее 1 000 человек.
A21: 1098 | B21: 66:02:0701001 | C21: Район | D21: Артемовский | E21: Да | F21: 0 | H21: 02:018:2:4:6 | I21: Мироново | J21: с | K21: Артемовский | O21: Восточный управленческий округ | P21: Артемовский городской округ | Q21: 0.6883 | R21: 0.33 | S21: =MID(H21,1,2) -> 02 | T21: 1002 | U21: Артемовский городской округ | V21: сельские населенные пункты с численностью населения менее 1 000 человек.
A22: 1099 | B22: 66:02:1401001 | C22: Район | D22: Артемовский | E22: Да | F22: 0 | H22: 02:023:2:4:6 | I22: Покровское | J22: с | K22: Артемовский | O22: Восточный управленческий округ | P22: Артемовский городской округ | Q22: 0.6883 | R22: 0.33 | S22: =MID(H22,1,2) -> 02 | T22: 1002 | U22: Артемовский городской округ | V22: сельские населенные пункты с численностью населения менее 1 000 человек.
A23: 1100 | B23: 66:02:1601001 | C23: Район | D23: Артемовский | E23: Да | F23: 0 | H23: 02:006:2:4:6 | I23: Большое Трифоново | J23: с | K23: Артемовский | O23: Восточный управленческий округ | P23: Артемовский городской округ | Q23: 0.6883 | R23: 0.33 | S23: =MID(H23,1,2) -> 02 | T23: 1002 | U23: Артемовский городской округ | V23: сельские населенные пункты с численностью населения менее 1 000 человек.
A24: 1101 | B24: 66:02:1801001 | C24: Район | D24: Артемовский | E24: Да | F24: 0 | H24: 02:028:2:4:6 | I24: Шогринское | J24: с | K24: Артемовский | O24: Восточный управленческий округ | P24: Артемовский городской округ | Q24: 0.6883 | R24: 0.33 | S24: =MID(H24,1,2) -> 02 | T24: 1002 | U24: Артемовский городской округ | V24: сельские населенные пункты с численностью населения менее 1 000 человек.
A25: 1102 | B25: 66:02:2001001 | C25: Район | D25: Артемовский | E25: Да | F25: 0 | H25: 02:019:2:4:6 | I25: Мостовское | J25: с | K25: Артемовский | O25: Восточный управленческий округ | P25: Артемовский городской округ | Q25: 0.6883 | R25: 0.33 | S25: =MID(H25,1,2) -> 02 | T25: 1002 | U25: Артемовский городской округ | V25: сельские населенные пункты с численностью населения менее 1 000 человек.
A26: 1103 | B26: 66:02:2201001 | C26: Район | D26: Артемовский | E26: Да | F26: 0 | H26: 02:026:2:3:6 | I26: Сосновый Бор | J26: п | K26: Артемовский | O26: Восточный управленческий округ | P26: Артемовский городской округ | Q26: 0.6883 | R26: 0.33 | S26: =MID(H26,1,2) -> 02 | T26: 1002 | U26: Артемовский городской округ | V26: сельские населенные пункты с численностью населения менее 1 000 человек.
A27: 1104 | B27: 66:02:2301001 | C27: Район | D27: Артемовский | E27: Да | F27: 0 | H27: 02:012:2:3:6 | I27: Красногвардейский | J27: п | K27: Артемовский | O27: Восточный управленческий округ | P27: Артемовский городской округ | Q27: 0.6883 | R27: 0.33 | S27: =MID(H27,1,2) -> 02 | T27: 1002 | U27: Артемовский городской округ | V27: сельские населенные пункты с численностью населения менее 1 000 человек.
A28: 1105 | B28: 66:02:2401001 | C28: Район | D28: Артемовский | E28: Да | F28: 0 | H28: 02:008:2:3:6 | I28: Буланаш | J28: п | K28: Артемовский | O28: Восточный управленческий округ | P28: Артемовский городской округ | Q28: 0.6883 | R28: 0.33 | S28: =MID(H28,1,2) -> 02 | T28: 1002 | U28: Артемовский городской округ | V28: сельские населенные пункты с численностью населения менее 1 000 человек.
A29: 1574 | B29: 66:02:2502002 | C29: Район | D29: Артемовский | E29: Да | F29: 0 | H29: 02:001:1:1:4 | I29: Артемовский | J29: г | K29: Артемовский | O29: Восточный управленческий округ | P29: Артемовский городской округ | Q29: 0.6247 | R29: 0.33 | S29: =MID(H29,1,2) -> 02 | T29: 1002 | U29: Артемовский городской округ | V29: городские населенные пункты с численностью населения менее 50 000 человек;
A30: 1731 | B30: 66:02:1001001 | C30: Район | D30: Артемовский | F30: 3.09 | H30: 02:014:2:4:6 | I30: Липино | J30: с | K30: Артемовский | O30: Восточный управленческий округ | P30: Артемовский городской округ | Q30: 0.6883 | R30: 0.33 | S30: =MID(H30,1,2) -> 02 | T30: 1002 | U30: Артемовский городской округ | V30: сельские населенные пункты с численностью населения менее 1 000 человек.
A31: 1786 | B31: 66:02:0901001 | C31: Район | D31: Артемовский | F31: 3.48 | H31: 02:016:2:5:6 | I31: Луговая | J31: д | K31: Артемовский | O31: Восточный управленческий округ | P31: Артемовский городской округ | Q31: 0.6883 | R31: 0.33 | S31: =MID(H31,1,2) -> 02 | T31: 1002 | U31: Артемовский городской округ | V31: сельские населенные пункты с численностью населения менее 1 000 человек.
A32: 1813 | C32: Район | D32: Артемовский | F32: 0 | H32: 02:007:2:3:6 | I32: Боровской | J32: п | K32: Артемовский | O32: Восточный управленческий округ | P32: Артемовский городской округ | Q32: 0.6883 | R32: 0.33 | S32: =MID(H32,1,2) -> 02 | T32: 1002 | U32: Артемовский городской округ | V32: сельские населенные пункты с численностью населения менее 1 000 человек.
A33: 1901 | C33: район | D33: Артемовский | F33: 0 | H33: 02:000:0:0:0 | I33: Артемовский городской округ | J33: б.н.п. | K33: Артемовский | O33: Восточный управленческий округ | P33: Артемовский городской округ | Q33: 0.6883 | R33: 0.33 | S33: =MID(H33,1,2) -> 02 | T33: 1002 | U33: Артемовский городской округ | V33: межселенная территория
A34: 178 | B34: 66:03:0101001 | C34: Район | D34: Артинский | E34: Да | F34: 0 | H34: 03:008:2:5:6 | I34: Бакийково | J34: д | K34: Артинский | O34: Западный управленческий округ | P34: Артинский городской округ | Q34: 0.6315 | R34: 0.33 | S34: =MID(H34,1,2) -> 03 | T34: 1002 | U34: Артинский городской округ | V34: сельские населенные пункты с численностью населения менее 1 000 человек.
