Workbook

Sheet расчетОО 
A1: Идентификатор | B1: Кадастровый номер | C1: Номер кадастрового квартала | D1: Площадь (ЦФ) | E1: Вид разрешённого использования (ЦФ) | F1: Газоснабжение (ЦФ) | G1: Электроснабжение (ЦФ) | H1: Водоотведение (ЦФ) | I1: Водоснабжение (ЦФ) | J1: Код МО (ЦФ) | K1: ЛЭП над участком (ЦФ) | L1: Подъезд к участку(ЦФ) | M1: Расстояние до зон транспотного безразличия (ЦФ) | N1: Расстояние до зон транспотного безразличия | O1: Зона влияния для ИЖС (ЦФ) | P1: Зона вляния для ИЖС | Q1: Удельный показатель кадастровой стоимости(руб/м2) | R1: Кадастровая стоимость (руб) | S1: Кадастровая стоимость описание вых | T1: Площадь в квадратных метрах | U1: Наличие газоснабжения | V1: Наличие электроснабжения | W1: Наличие водоотведения | X1: Наличие водоснабжения | Y1: Номер заявления | Z1: Тип заявления | AA1: Статус заявления | AB1: Код Муниципального образования | AC1: флажок | AD1: Дата пакета | AE1: Статус расчета | AF1: Дата комиссии | AG1: Решение комиссии | AH1: Флаг кода НП | AI1: Флаг ВРИ по документу | AJ1: Флаг площади | AK1: Флаг ВРИ старый спр | AL1: Флаг ВРИ новый спр | AM1: Флаг Категории ЗУ | AN1: Группа для XML | AO1: ВРИ по документу старое | AP1: Код расчета вида использования текущий (старый) | AQ1: ВРИ по документу новое | AR1: Код расчета вида использования новый | AS1: Правило | AT1: Новоя модель | AU1: Особый контроль | AV1: Тип ИЖС | AW1: Наименование кот поселка/ сад тов | AX1: Суд | AY1: Дата заседания | AZ1: Код расчета вида использования новый с учетом КП | CD1: CadastralNumber | CE1: loc_factor_825 | CG1: loc_factor_822 | CI1: loc_factor_804 | CK1: loc_factor_828 | CM1: loc_factor_803 | CO1: loc_factor_829 | CQ1: loc_factor_840 | CT1: loc_factor_826 | CV1: loc_factor_807 | CW1: loc_factor_8071 | CX1: loc_factor_837 | DB1: loc_factor_827 | DD1: Specific_CadastralCost | DE1: CadastralCost | DF1: id_group | DG1: CadastralCostDesc | DH1: Status_kc | DI1: loc_VICode | DJ1: Segment | DK1: loc_SgCode | DL1: loc_GroupName | DM1: Old_Utlbydoc
A2: ID | B2: CadastralNumber | C2: CadastralBlock | D2: loc_factor_807 | E2: loc_factor_825 | F2: loc_factor_822 | G2: loc_factor_804 | H2: loc_factor_803 | I2: loc_factor_828 | J2: loc_factor_830 | K2: loc_factor_829 | L2: loc_factor_840 | M2: loc_factor_837 | N2: DistanceToZTB | O2: loc_factor_826 | P2: InfluenceZone_IGS | Q2: Specific_CadastralCost | R2: CadastralCost | S2: CadastralCostDesc | T2: Area | U2: PresenceGas | V2: PresencePower | W2: PresenceWaterDisposal | X2: PresenceWaterSupply | Y2: Statement | Z2: Type_Statement | AA2: Status_Statement | AB2: KodMO | AC2: Sp_flag | AD2: inputpacket_date | AE2: Status_kc | AF2: Date_comm | AG2: Sol_comm | AH2: FlagLocalityCode | AI2: Flag_VRI | AJ2: FlagParam | AK2: Flag_VRIoldspr | AL2: Flag_VRInewspr | AM2: Flag_Category | AN2: ID_Group | AO2: Old_Utlbydoc | AP2: loc_VICode | AQ2: UtilizationByDoc | AR2: VRICode_NEW | AS2: PraviloVRI | AT2: New_id_group | AU2: ControlSP | AV2: VRI_IGS | AW2: Cot_name | AX2: Court | AY2: Date_Court | BA2: Кадастровый номер | BR2: Общая площадь | BV2: константа | BW2: итог | BX2: с коэфф утргования = | BZ2: 0.8 | CB2: Обязательная проверка | CD2: Кадастровый номер | CV2: Общая площадь | CZ2: константа | DA2: итог | DB2: с коэфф утргования = | DD2: 0.8 | DF2: id_group | DG2: Идентификатор стоимости | DO2: Текущий диапазон УПКС от 85 руб. до 8 560 руб. | DU2: Возможно изменение кода расчета, но при этом ЦФ может не меняться, например: 02:010 стал 02:011- все ИЖС
A3: Parcels | B3: Parcels | C3: Parcels | D3: Parcels | E3: Parcels | F3: Parcels | G3: Parcels | H3: Parcels | I3: Parcels | J3: Parcels | K3: Parcels | L3: Parcels | M3: Parcels | N3: Parcels | O3: Parcels | P3: Parcels | Q3: Parcels | R3: Parcels | S3: Parcels | T3: Parcels | U3: Parcels | V3: Parcels | W3: Parcels | X3: Parcels | Y3: Parcels | Z3: Parcels | AA3: Parcels | AB3: Parcels | AC3: Parcels | AD3: Parcels | AE3: Parcels | AF3: Parcels | AG3: Parcels | AH3: Parcels | AI3: Parcels | AJ3: Parcels | AK3: Parcels | AL3: Parcels | AM3: Parcels | AN3: Parcels | AO3: Parcels | AP3: Parcels | AQ3: Parcels | AR3: Parcels | AS3: Parcels | AT3: Parcels | AU3: Parcels | AV3: Parcels | AW3: Parcels | AX3: Parcels | AY3: Parcels | AZ3: Итоговая группировка | BB3: Вид разрешенного использования | BC3: V1 | BD3: Газоснабжение (ЦФ) | BE3: V2 | BF3: Электроснабжение (ЦФ) | BG3: V3 | BH3: Водоснабжение (ЦФ) | BI3: V4 | BJ3: Водоотведение (ЦФ) | BK3: V5 | BL3: ЛЭП над участком (ЦФ) | BM3: V6 | BN3: Наличие подъезда (ЦФ) | BO3: V7 | BP3: Зона влияния для ИЖС (ЦФ) | BQ3: V8 | BR3: Площадь (ЦФ) | BS3: V9 | BT3: Расстояние до зон транспотного безразличия (ЦФ) | BU3: V10 | BX3: Уторгование (ЦФ) | BY3: коэффициент | BZ3: УПС | CA3: Общая стоимость | CB3: Вверно, если расходждение составляет 0,00 руб. Если расхождение составляет более 0,01 -ценовые факторы подобраны неверно.Требуется анализ | CC3: Участие объекта на комиссии, в заявлениях, в судах и прочее | CE3: Вид разрешенного использования | CF3: V1 | CG3: Газоснабжение (ЦФ) | CH3: V2 | CI3: Электроснабжение (ЦФ) | CJ3: V3 | CK3: Водоснабжение (ЦФ) | CL3: V4 | CM3: Водоотведение (ЦФ) | CN3: V5 | CO3: ЛЭП над участком (ЦФ) | CP3: V6 | CQ3: Наличие подъезда (ЦФ) | CR3: V7 | CS3: Зона влияния для ИЖС (Вспомогательный столбец) | CT3: Зона влияния для ИЖС (ЦФ) | CU3: V8 | CV3: Площадь (ЦФ) | CW3: V9 | CX3: Расстояние до зон транспотного безразличия (ЦФ) | CY3: V10 | DB3: Уторгование (ЦФ) | DC3: коэффициент | DD3: УПС | DE3: Общая стоимость | DF3: 8019 | DG3: Идентификатор стоимости | DH3: Статус расчета | DI3: ВРИ | DJ3: Сегмент | DK3: Код сегмента | DL3: Расшифровка расчетной подгруппы | DM3: ВРИ по документу старое(обновление поля) | DN3: Сравнение с предыдущим расчетом | DO3: Проверка отклонения УПКС от текущего диапазона и контроль значительного изменения КС | DP3: Зона для ИЖС | DQ3: Электроснабжение | DR3: Газоснабжение | DS3: Площадь | DT3: Расстояние до зон транспотного безразличия | DU3: Ценовой фактор ВРИ в модели | DV3: Изменение Кода расчета | DW3: Водоснабжение | DX3: Водоотведение | DY3: ЛЭП над участком | DZ3: Наличие подъезда
AZ4: =IF(OR(AR4="13:021",AR4="13:011"),IF(AV4="Коттеджные_поселки","13:031",AR4),IF(OR(AR4="02:010",AR4="02:011",AR4="02:020",AR4="02:021",AR4="02:023"),IF(AV4="Коттеджные_поселки","02:019",AR4),AR4)) -> 0 | BA4: =B4 -> 0 | BB4: =E4 -> 0 | BC4: =VLOOKUP(BB4,модули!$L$27:'модули'!$M$37,2,FALSE) -> #N/A | BD4: =F4 -> 0 | BE4: =VLOOKUP(BD4,модули!$B$7:'модули'!$D$18,3,FALSE) -> #N/A | BF4: =G4 -> 0 | BG4: =VLOOKUP(BF4,модули!$F$7:'модули'!$H$18,3,FALSE) -> #N/A | BH4: =I4 -> 0 | BI4: =VLOOKUP(BH4,модули!$J$7:'модули'!$L$18,3,FALSE) -> #N/A | BJ4: =H4 -> 0 | BK4: =VLOOKUP(BJ4,модули!$N$7:'модули'!$P$18,3,FALSE) -> #N/A | BL4: =K4 -> 0 | BM4: =VLOOKUP(BL4,модули!$R$7:'модули'!$T$16,3,FALSE) -> #N/A | BN4: =L4 -> 0 | BO4: =VLOOKUP(BN4,модули!$V$7:'модули'!$X$17,3,FALSE) -> #N/A | BP4: =O4 -> 0 | BQ4: =VLOOKUP(BP4,модули!$B$27:$D$41,3,FALSE) -> #N/A | BR4: =D4 -> 0 | BS4: =ROUND(IF(BR4<модули!$A$97,модули!$E$97,IF(BR4>модули!$A$98,модули!$E$98,( 3.13069866989796E-15*BR4^4 + 6.1338708204768E-12*BR4^3- 1.95954236270195E-07*BR4^2 + 0.000387905519741556*BR4 + 0.798784147038265))),4) -> 0.7988 | BT4: =M4 -> 0 | BU4: =ROUND(EXP(LN(IF(BT4<модули!$H$99,модули!$I$99,IF(BT4>модули!$H$100,модули!$I$100,((9.167685587011E-08*(BT4)^4+0.000015289662956704*(BT4)^3-0.00161875861673315*(BT4)^2+0.0151997782316484*(BT4)+0.962501568438211)))))*модули!$K$98),4) -> 1 | BV4: =коэффициенты!$G$2 -> 638.4032 | BW4: =BG4*BE4*BI4*BK4*BM4*BO4*BC4*BQ4*BS4*BU4*BV4 -> #N/A | BX4: Наличие уторгования | BY4: =$BZ$2 -> 0.8 | BZ4: =ROUND(BY4*BW4,2) -> #N/A | CA4: =ROUND(BZ4*BR4,2) -> #N/A | CB4: =IF(Q4="","Новый объект",IF(AN4=AT4,CA4-R4,"Объект пришел из другой модели")) -> Новый объект | CC4: =IF(AU4="",IF(AF4<>"","ОСПАРИВАНИЕ",IF(AX4<>"","СУД",IF(Y4="","",Y4))),AU4) | CD4: =B4 -> 0 | CE4: =IF(AI4="ГОТОВ",E4,IF(AP4=AZ4,E4,IF(OR(AP4="02:010",AP4="02:011",AP4="02:020",AP4="02:021",AP4="02:023",AP4="02:030",AP4="02:031",AP4="02:019"),IF(OR(AZ4="02:010",AZ4="02:011",AZ4="02:020",AZ4="02:021",AZ4="02:023",AZ4="02:030",AZ4="02:031",AZ4="02:019"),E4,VLOOKUP(AZ4,модули!$K$27:$L$37,2,0)),IF(OR(AP4="13:021",AP4="13:011"),IF(OR(AZ4="13:021",AZ4="13:011"),E4,VLOOKUP(AZ4,модули!$K$27:$L$37,2,0)),VLOOKUP('расчетОО '!AZ4,модули!$K$27:$L$37,2,0))))) -> 0 | CF4: =VLOOKUP(CE4,модули!$L$27:'модули'!$M$37,2,FALSE) -> #N/A | CG4: =IF(F4="",IF(AZ4="13:011","Отсутствие газоснабжения",IF(AZ4="13:021","Отсутствие газоснабжения",IF(U4="наличие","Наличие газоснабжения",IF(U4="пересечение","Возможность подключения газоснабжения","Отсутствие газоснабжения")))),F4) -> Отсутствие газоснабжения | CH4: =VLOOKUP(CG4,модули!$B$7:'модули'!$D$18,3,FALSE) -> 1 | CI4: =IF(G4="",IF(V4="отсутствие","Отсутствие электроснабжения","Наличие электроснабжения"),G4) -> Наличие электроснабжения | CJ4: =VLOOKUP(CI4,модули!$F$7:'модули'!$H$18,3,FALSE) -> 4.2359 | CK4: Отсутствие водоснабжения | CL4: =VLOOKUP(CK4,модули!$J$7:'модули'!$L$18,3,FALSE) -> 1 | CM4: Отсутствие водоотведения | CN4: =VLOOKUP(CM4,модули!$N$7:'модули'!$P$18,3,FALSE) -> 1 | CO4: =IF(K4="Наличие ЛЭП","Наличие ЛЭП","Отсутствие ЛЭП") -> Отсутствие ЛЭП | CP4: =VLOOKUP(CO4,модули!$R$7:'модули'!$T$16,3,FALSE) -> 1 | CQ4: =IF(L4="Отсутствие подъезда","Отсутствие подъезда","Наличие подъезда") -> Наличие подъезда | CR4: =VLOOKUP(CQ4,модули!$V$7:'модули'!$X$17,3,FALSE) -> 1.1229 | CS4: =IFERROR(IF(O4="",IF(P4="",VLOOKUP(C4,модули!$F$48:$G$7038,2,0),P4),O4),VLOOKUP(AB4,модули!$I$48:$J$61,2,0)) -> #N/A | CT4: =IFERROR(VLOOKUP(CS4,модули!$A$27:$B$41,2,0),CS4) -> #N/A | CU4: =VLOOKUP(CT4,модули!$B$27:$D$41,3,FALSE) -> #N/A | CV4: =T4 -> 0 | CW4: =ROUND(IF(CV4<модули!$A$97,модули!$E$97,IF(CV4>модули!$A$98,модули!$E$98,( 3.13069866989796E-15*CV4^4 + 6.1338708204768E-12*CV4^3- 1.95954236270195E-07*CV4^2 + 0.000387905519741556*CV4 + 0.798784147038265))),4) -> 0.7988 | CX4: =IF(M4="",IF(N4="",VLOOKUP(CT4,модули!$F$27:$G$41,2,0),N4),M4) -> #N/A | CY4: =ROUND(EXP(LN(IF(CX4<модули!$H$99,модули!$I$99,IF(CX4>модули!$H$100,модули!$I$100,((9.167685587011E-08*(CX4)^4+0.000015289662956704*(CX4)^3-0.00161875861673315*(CX4)^2+0.0151997782316484*(CX4)+0.962501568438211)))))*модули!$K$98),4) -> #N/A | CZ4: =коэффициенты!$G$2 -> 638.4032 | DA4: =CJ4*CH4*CL4*CN4*CP4*CR4*CF4*CU4*CW4*CY4*CZ4 -> #N/A | DB4: Наличие уторгования | DC4: =$BZ$2 -> 0.8 | DD4: =ROUND(DC4*DA4,2) -> #N/A | DE4: =ROUND(DD4*CV4,2) -> #N/A | DF4: =8019 -> 8019 | DG4: СТ16_Ф1_М19_18052021_Бунаков_Измененные | DH4: =IF(OR(DE4<0,DE4=0),"ОТРИЦАТЕЛЬНОЕ ЗНАЧЕНИЕ",IF(DN4=0,"Пересчет не требуется","Готов")) -> #N/A | DI4: =IF(AI4="ГОТОВ",AR4,AZ4) -> 0 | DJ4: 13. СЕГМЕНТ "Садоводство и огородничество, малоэтажная жилая застройка" | DK4: =13 -> 13 | DL4: =VLOOKUP(DI4,'справочник ври'!$A$3:$B$271,2,0) -> #N/A | DM4: =AQ4 -> 0 | DN4: =IF(ISBLANK(Q4),"Новый объект",IF(DF4=AN4,ABS(DE4-R4),"Объект из другой модели")) -> Новый объект | DO4: =IF(DN4="Объект из другой модели",IF(OR(DD4<85,DD4>8560),"Отклонение УПКС","УПКС в допустимом интервале"),IF(DN4<1000000,"Изменение менее 1 млн","Внимание!Изменение более 1млн")) -> Внимание!Изменение более 1млн | DP4: =IF(O4="","Новое значение",IF(O4=CT4,"Осталось предыдущее значение ЦФ","ИЗМЕНЕНИЕ")) -> Новое значение | DQ4: =IF(G4="","Новое значение",IF(CI4=G4,"Осталось предыдущее значение ЦФ","ИЗМЕНЕНИЕ")) -> Новое значение | DR4: =IF(F4="","Новое значение",IF(CG4=F4,"Осталось предыдущее значение ЦФ","ИЗМЕНЕНИЕ")) -> Новое значение | DS4: =IF(AJ4="не готов","ИЗМЕНЕНИЕ","Осталось предыдущее значение ЦФ") -> Осталось предыдущее значение ЦФ | DT4: =IF(M4="","Новое значение",IF(CX4=M4,"Осталось предыдущее значение ЦФ","ИЗМЕНЕНИЕ")) -> Новое значение | DU4: =IF(E4="","Новое значение",IF(CE4=E4,"Осталось предыдущее значение ЦФ","ИЗМЕНЕНИЕ")) -> Новое значение | DV4: =IF(AI4="ГОТОВ",IF(AP4=AR4,"Осталось предыдущее значение ЦФ","ИЗМЕНЕНИЕ"),IF(AP4=AZ4,"Осталось предыдущее значение ЦФ","ИЗМЕНЕНИЕ")) -> Осталось предыдущее значение ЦФ | DW4: =IF(I4="","Новое значение",IF(CK4=I4,"Осталось предыдущее значение ЦФ","ИЗМЕНЕНИЕ")) -> Новое значение | DX4: =IF(H4="","Новое значение",IF(CM4=H4,"Осталось предыдущее значение ЦФ","ИЗМЕНЕНИЕ")) -> Новое значение | DY4: =IF(K4="","Новое значение",IF(CO4=K4,"Осталось предыдущее значение ЦФ","ИЗМЕНЕНИЕ")) -> Новое значение | DZ4: =IF(L4="","Новое значение",IF(CQ4=L4,"Осталось предыдущее значение ЦФ","ИЗМЕНЕНИЕ")) -> Новое значение
AZ5: =IF(OR(AR5="13:021",AR5="13:011"),IF(AV5="Коттеджные_поселки","13:031",AR5),IF(OR(AR5="02:010",AR5="02:011",AR5="02:020",AR5="02:021",AR5="02:023"),IF(AV5="Коттеджные_поселки","02:019",AR5),AR5)) -> 0 | BA5: =B5 -> 0 | BB5: =E5 -> 0 | BC5: =VLOOKUP(BB5,модули!$L$27:'модули'!$M$37,2,FALSE) -> #N/A | BD5: =F5 -> 0 | BE5: =VLOOKUP(BD5,модули!$B$7:'модули'!$D$18,3,FALSE) -> #N/A | BF5: =G5 -> 0 | BG5: =VLOOKUP(BF5,модули!$F$7:'модули'!$H$18,3,FALSE) -> #N/A | BH5: =I5 -> 0 | BI5: =VLOOKUP(BH5,модули!$J$7:'модули'!$L$18,3,FALSE) -> #N/A | BJ5: =H5 -> 0 | BK5: =VLOOKUP(BJ5,модули!$N$7:'модули'!$P$18,3,FALSE) -> #N/A | BL5: =K5 -> 0 | BM5: =VLOOKUP(BL5,модули!$R$7:'модули'!$T$16,3,FALSE) -> #N/A | BN5: =L5 -> 0 | BO5: =VLOOKUP(BN5,модули!$V$7:'модули'!$X$17,3,FALSE) -> #N/A | BP5: =O5 -> 0 | BQ5: =VLOOKUP(BP5,модули!$B$27:$D$41,3,FALSE) -> #N/A | BR5: =D5 -> 0 | BS5: =ROUND(IF(BR5<модули!$A$97,модули!$E$97,IF(BR5>модули!$A$98,модули!$E$98,( 3.13069866989796E-15*BR5^4 + 6.1338708204768E-12*BR5^3- 1.95954236270195E-07*BR5^2 + 0.000387905519741556*BR5 + 0.798784147038265))),4) -> 0.7988 | BT5: =M5 -> 0 | BU5: =ROUND(EXP(LN(IF(BT5<модули!$H$99,модули!$I$99,IF(BT5>модули!$H$100,модули!$I$100,((9.167685587011E-08*(BT5)^4+0.000015289662956704*(BT5)^3-0.00161875861673315*(BT5)^2+0.0151997782316484*(BT5)+0.962501568438211)))))*модули!$K$98),4) -> 1 | BV5: =коэффициенты!$G$2 -> 638.4032 | BW5: =BG5*BE5*BI5*BK5*BM5*BO5*BC5*BQ5*BS5*BU5*BV5 -> #N/A | BX5: Наличие уторгования | BY5: =$BZ$2 -> 0.8 | BZ5: =ROUND(BY5*BW5,2) -> #N/A | CA5: =ROUND(BZ5*BR5,2) -> #N/A | CB5: =IF(Q5="","Новый объект",IF(AN5=AT5,CA5-R5,"Объект пришел из другой модели")) -> Новый объект | CC5: =IF(AU5="",IF(AF5<>"","ОСПАРИВАНИЕ",IF(AX5<>"","СУД",IF(Y5="","",Y5))),AU5) | CD5: =B5 -> 0 | CE5: =IF(AI5="ГОТОВ",E5,IF(AP5=AZ5,E5,IF(OR(AP5="02:010",AP5="02:011",AP5="02:020",AP5="02:021",AP5="02:023",AP5="02:030",AP5="02:031",AP5="02:019"),IF(OR(AZ5="02:010",AZ5="02:011",AZ5="02:020",AZ5="02:021",AZ5="02:023",AZ5="02:030",AZ5="02:031",AZ5="02:019"),E5,VLOOKUP(AZ5,модули!$K$27:$L$37,2,0)),IF(OR(AP5="13:021",AP5="13:011"),IF(OR(AZ5="13:021",AZ5="13:011"),E5,VLOOKUP(AZ5,модули!$K$27:$L$37,2,0)),VLOOKUP('расчетОО '!AZ5,модули!$K$27:$L$37,2,0))))) -> 0 | CF5: =VLOOKUP(CE5,модули!$L$27:'модули'!$M$37,2,FALSE) -> #N/A | CG5: =IF(F5="",IF(AZ5="13:011","Отсутствие газоснабжения",IF(AZ5="13:021","Отсутствие газоснабжения",IF(U5="наличие","Наличие газоснабжения",IF(U5="пересечение","Возможность подключения газоснабжения","Отсутствие газоснабжения")))),F5) -> Отсутствие газоснабжения | CH5: =VLOOKUP(CG5,модули!$B$7:'модули'!$D$18,3,FALSE) -> 1 | CI5: =IF(G5="",IF(V5="отсутствие","Отсутствие электроснабжения","Наличие электроснабжения"),G5) -> Наличие электроснабжения | CJ5: =VLOOKUP(CI5,модули!$F$7:'модули'!$H$18,3,FALSE) -> 4.2359 | CK5: Отсутствие водоснабжения | CL5: =VLOOKUP(CK5,модули!$J$7:'модули'!$L$18,3,FALSE) -> 1 | CM5: Отсутствие водоотведения | CN5: =VLOOKUP(CM5,модули!$N$7:'модули'!$P$18,3,FALSE) -> 1 | CO5: =IF(K5="Наличие ЛЭП","Наличие ЛЭП","Отсутствие ЛЭП") -> Отсутствие ЛЭП | CP5: =VLOOKUP(CO5,модули!$R$7:'модули'!$T$16,3,FALSE) -> 1 | CQ5: =IF(L5="Отсутствие подъезда","Отсутствие подъезда","Наличие подъезда") -> Наличие подъезда | CR5: =VLOOKUP(CQ5,модули!$V$7:'модули'!$X$17,3,FALSE) -> 1.1229 | CS5: =IFERROR(IF(O5="",IF(P5="",VLOOKUP(C5,модули!$F$48:$G$7038,2,0),P5),O5),VLOOKUP(AB5,модули!$I$48:$J$61,2,0)) -> #N/A | CT5: =IFERROR(VLOOKUP(CS5,модули!$A$27:$B$41,2,0),CS5) -> #N/A | CU5: =VLOOKUP(CT5,модули!$B$27:$D$41,3,FALSE) -> #N/A | CV5: =T5 -> 0 | CW5: =ROUND(IF(CV5<модули!$A$97,модули!$E$97,IF(CV5>модули!$A$98,модули!$E$98,( 3.13069866989796E-15*CV5^4 + 6.1338708204768E-12*CV5^3- 1.95954236270195E-07*CV5^2 + 0.000387905519741556*CV5 + 0.798784147038265))),4) -> 0.7988 | CX5: =IF(M5="",IF(N5="",VLOOKUP(CT5,модули!$F$27:$G$41,2,0),N5),M5) -> #N/A | CY5: =ROUND(EXP(LN(IF(CX5<модули!$H$99,модули!$I$99,IF(CX5>модули!$H$100,модули!$I$100,((9.167685587011E-08*(CX5)^4+0.000015289662956704*(CX5)^3-0.00161875861673315*(CX5)^2+0.0151997782316484*(CX5)+0.962501568438211)))))*модули!$K$98),4) -> #N/A | CZ5: =коэффициенты!$G$2 -> 638.4032 | DA5: =CJ5*CH5*CL5*CN5*CP5*CR5*CF5*CU5*CW5*CY5*CZ5 -> #N/A | DB5: Наличие уторгования | DC5: =$BZ$2 -> 0.8 | DD5: =ROUND(DC5*DA5,2) -> #N/A | DE5: =ROUND(DD5*CV5,2) -> #N/A | DF5: =8019 -> 8019 | DG5: СТ16_Ф1_М19_18052021_Бунаков_Измененные | DH5: =IF(OR(DE5<0,DE5=0),"ОТРИЦАТЕЛЬНОЕ ЗНАЧЕНИЕ",IF(DN5=0,"Пересчет не требуется","Готов")) -> #N/A | DI5: =IF(AI5="ГОТОВ",AR5,AZ5) -> 0 | DJ5: 13. СЕГМЕНТ "Садоводство и огородничество, малоэтажная жилая застройка" | DK5: =13 -> 13 | DL5: =VLOOKUP(DI5,'справочник ври'!$A$3:$B$271,2,0) -> #N/A | DM5: =AQ5 -> 0 | DN5: =IF(ISBLANK(Q5),"Новый объект",IF(DF5=AN5,ABS(DE5-R5),"Объект из другой модели")) -> Новый объект | DO5: =IF(DN5="Объект из другой модели",IF(OR(DD5<85,DD5>8560),"Отклонение УПКС","УПКС в допустимом интервале"),IF(DN5<1000000,"Изменение менее 1 млн","Внимание!Изменение более 1млн")) -> Внимание!Изменение более 1млн | DP5: =IF(O5="","Новое значение",IF(O5=CT5,"Осталось предыдущее значение ЦФ","ИЗМЕНЕНИЕ")) -> Новое значение | DQ5: =IF(G5="","Новое значение",IF(CI5=G5,"Осталось предыдущее значение ЦФ","ИЗМЕНЕНИЕ")) -> Новое значение | DR5: =IF(F5="","Новое значение",IF(CG5=F5,"Осталось предыдущее значение ЦФ","ИЗМЕНЕНИЕ")) -> Новое значение | DS5: =IF(AJ5="не готов","ИЗМЕНЕНИЕ","Осталось предыдущее значение ЦФ") -> Осталось предыдущее значение ЦФ | DT5: =IF(M5="","Новое значение",IF(CX5=M5,"Осталось предыдущее значение ЦФ","ИЗМЕНЕНИЕ")) -> Новое значение | DU5: =IF(E5="","Новое значение",IF(CE5=E5,"Осталось предыдущее значение ЦФ","ИЗМЕНЕНИЕ")) -> Новое значение | DV5: =IF(AI5="ГОТОВ",IF(AP5=AR5,"Осталось предыдущее значение ЦФ","ИЗМЕНЕНИЕ"),IF(AP5=AZ5,"Осталось предыдущее значение ЦФ","ИЗМЕНЕНИЕ")) -> Осталось предыдущее значение ЦФ | DW5: =IF(I5="","Новое значение",IF(CK5=I5,"Осталось предыдущее значение ЦФ","ИЗМЕНЕНИЕ")) -> Новое значение | DX5: =IF(H5="","Новое значение",IF(CM5=H5,"Осталось предыдущее значение ЦФ","ИЗМЕНЕНИЕ")) -> Новое значение | DY5: =IF(K5="","Новое значение",IF(CO5=K5,"Осталось предыдущее значение ЦФ","ИЗМЕНЕНИЕ")) -> Новое значение | DZ5: =IF(L5="","Новое значение",IF(CQ5=L5,"Осталось предыдущее значение ЦФ","ИЗМЕНЕНИЕ")) -> Новое значение
A6: Select ID,Source_ID,CadastralNumber,DateCreated,CadastralBlock,Name,ObjectType,Area,AreaUnit,AreaInaccuracy,LocationinBounds,LocationPlaced,ElaborationReferenceMark,ElaborationDistance,ElaborationDirection,AddressOrLocation,FIAS,OKATO,KLADR,OKTMO,PostalCode,AddressRF,Region,DistrictName,DistrictType,CityName,CityType,UrbanDistrictName,UrbanDistrictType,SovietVillageName,SovietVillageType,LocalityName,LocalityType,PlanningElementName,PlanningElementType,StreetName,StreetType,Level1Type,Level1Value,Level2Type,Level2Value,Level3Type,Level3Value,ApartmentType,ApartmentValue,AddressOther,AddressNote,ParcelCategory,Utilization,UtilizationByDoc,UtilizationLandUse,UtilizationТхт,CostValue,CostUnit,CostDateValuation,CostDateEntering,CostDateApproval,CostDocNumber,CostDocDate,CostApplicationDate,CostRevisalStatementDate,CostApplicationLastDate,CostDocName,FacilityKN,FacilityKNPurpose,SurveyProjectNum,DecisionCodeDocument,DecisionName,DecisionSeries,DecisionNumber,DecisionDate,DecisionIssueOrgan,DecisionDesc,HiredHouseUse,HouseActBuilding,HouseActDevelopment,BuildingContractName,DevelopContractName,OwnerDecision,SupportContractName,CodeDocument,DocHiredHouseName,DocHiredHouseSeries,DocHiredHouseNumber,DocHiredHouseDate,DocHiredHouseIssueOrgan,DocHiredHouseDesc,LimitedRightNumber,CREATEOPERATORNAME,CREATEDATE,OPERATORNAME,MODIFYDATE,MI_STYLE,Specific_CadastralCost,CadastralCost,CadastralCostDesc,MO_Name,ID_Group,LocalityCode,locTypeUse2,loc_VICode,loc_GroupName,loc_VRICode,Sourse_loc_VICode,locTypeUse,inputpacket_id,loc_SgCode,VIP_Sp,Quant_Kontur,Quant_Point,Sum_Square,Sum_Perim,Proc_Diff_Square,Pr_Diff,Source_Sum_Square,SourceLocalityCode,Upload_Scroll,Date_KC,Segment,FlagLocalityCode,DistanceToRoad,DistanceToCMO,СМО,PresenceGas,SourcePresenceGas,PresenceHeating,SourcePresenceHeating,PresencePower,SourcePresencePower,PresenceWaterDisposal,SourcePresenceWaterDisposal,PresenceWaterSupply,SourcePresenceWaterSupply,DistanceToEKB,DistanceToRoadEKB,CCoordX,CCoordY,DistanceToMetro,DistanceToStationEKB,CostZone,DistanceToRRStation,costzone2,Textloc_VICode,act_sign,MaxFloor,Enc_squre,Enc_proc,Adm_rn_EKB,forestry,InfluenceZone_IGS,loc_factor_801,loc_factor_802,loc_factor_803,loc_factor_804,loc_factor_806,loc_factor_807,loc_factor_8071,loc_factor_809,loc_factor_8091,loc_factor_810,loc_factor_8101,loc_factor_811,loc_factor_8111,loc_factor_812,loc_factor_8121,loc_factor_813,loc_factor_814,loc_factor_815,loc_factor_816,loc_factor_8161,loc_factor_817,loc_factor_818,loc_factor_819,loc_factor_820,loc_factor_8201,loc_factor_821,loc_factor_822,loc_factor_823,loc_factor_8231,loc_factor_824,loc_factor_825,loc_factor_826,loc_factor_827,loc_factor_828,loc_factor_829,loc_factor_830,loc_factor_831,loc_factor_832,loc_factor_833,loc_factor_8331,loc_factor_835,loc_factor_836,loc_factor_837,loc_factor_838,Statement,Type_Statement,Status_Statement,DistanceToVZC,VRI_IGS,Cot_name,DistanceToZTB,PowerLines,loc_factor_839,KodMO,loc_factor_840,loc_factor_841,presence_entrance,loc_factor_8371,ControlSP,Sp_flag,loc_VRICode540,Status_kc,Date_comm,Sol_comm,Flag_LocalityCode,Flag_VRI,Flag_Location,FlagParam,Flag_VRIoldspr,Flag_VRInewspr,Flag_Category,OldLocalityCode,Flag_VRI_All,VRICode_NEW,PraviloVRI,New_id_group,New_loc_SgCode,New_Segment,Old_Utlbydoc,VRICode_OLD,PraviloVRI_old,Court,Date_Court,Sol_Court,(select (case count(*) when 0 then 0 else 1 end) from GEO.docboxes b where b.obj_id=PARCELS.ID and b.table_id=265) Attachment,(select sign(Count(*)) from PARCELS g where (not GEOM_OBJ is null) and (PARCELS.ID = g.ID)) GeometryExists,((select DatePacket from inputpacket where id=Parcels.inputpacket_id) ) [inputpacket_date] From PARCELS where status_kc='НЕ ГОТОВ' AND (CadastralCost is not Null) AND New_id_group=8019 | AZ6: =IF(OR(AR6="13:021",AR6="13:011"),IF(AV6="Коттеджные_поселки","13:031",AR6),IF(OR(AR6="02:010",AR6="02:011",AR6="02:020",AR6="02:021",AR6="02:023"),IF(AV6="Коттеджные_поселки","02:019",AR6),AR6)) -> 0 | BA6: =B6 -> 0 | BB6: =E6 -> 0 | BC6: =VLOOKUP(BB6,модули!$L$27:'модули'!$M$37,2,FALSE) -> #N/A | BD6: =F6 -> 0 | BE6: =VLOOKUP(BD6,модули!$B$7:'модули'!$D$18,3,FALSE) -> #N/A | BF6: =G6 -> 0 | BG6: =VLOOKUP(BF6,модули!$F$7:'модули'!$H$18,3,FALSE) -> #N/A | BH6: =I6 -> 0 | BI6: =VLOOKUP(BH6,модули!$J$7:'модули'!$L$18,3,FALSE) -> #N/A | BJ6: =H6 -> 0 | BK6: =VLOOKUP(BJ6,модули!$N$7:'модули'!$P$18,3,FALSE) -> #N/A | BL6: =K6 -> 0 | BM6: =VLOOKUP(BL6,модули!$R$7:'модули'!$T$16,3,FALSE) -> #N/A | BN6: =L6 -> 0 | BO6: =VLOOKUP(BN6,модули!$V$7:'модули'!$X$17,3,FALSE) -> #N/A | BP6: =O6 -> 0 | BQ6: =VLOOKUP(BP6,модули!$B$27:$D$41,3,FALSE) -> #N/A | BR6: =D6 -> 0 | BS6: =ROUND(IF(BR6<модули!$A$97,модули!$E$97,IF(BR6>модули!$A$98,модули!$E$98,( 3.13069866989796E-15*BR6^4 + 6.1338708204768E-12*BR6^3- 1.95954236270195E-07*BR6^2 + 0.000387905519741556*BR6 + 0.798784147038265))),4) -> 0.7988 | BT6: =M6 -> 0 | BU6: =ROUND(EXP(LN(IF(BT6<модули!$H$99,модули!$I$99,IF(BT6>модули!$H$100,модули!$I$100,((9.167685587011E-08*(BT6)^4+0.000015289662956704*(BT6)^3-0.00161875861673315*(BT6)^2+0.0151997782316484*(BT6)+0.962501568438211)))))*модули!$K$98),4) -> 1 | BV6: =коэффициенты!$G$2 -> 638.4032 | BW6: =BG6*BE6*BI6*BK6*BM6*BO6*BC6*BQ6*BS6*BU6*BV6 -> #N/A | BX6: Наличие уторгования | BY6: =$BZ$2 -> 0.8 | BZ6: =ROUND(BY6*BW6,2) -> #N/A | CA6: =ROUND(BZ6*BR6,2) -> #N/A | CB6: =IF(Q6="","Новый объект",IF(AN6=AT6,CA6-R6,"Объект пришел из другой модели")) -> Новый объект | CC6: =IF(AU6="",IF(AF6<>"","ОСПАРИВАНИЕ",IF(AX6<>"","СУД",IF(Y6="","",Y6))),AU6) | CD6: =B6 -> 0 | CE6: =IF(AI6="ГОТОВ",E6,IF(AP6=AZ6,E6,IF(OR(AP6="02:010",AP6="02:011",AP6="02:020",AP6="02:021",AP6="02:023",AP6="02:030",AP6="02:031",AP6="02:019"),IF(OR(AZ6="02:010",AZ6="02:011",AZ6="02:020",AZ6="02:021",AZ6="02:023",AZ6="02:030",AZ6="02:031",AZ6="02:019"),E6,VLOOKUP(AZ6,модули!$K$27:$L$37,2,0)),IF(OR(AP6="13:021",AP6="13:011"),IF(OR(AZ6="13:021",AZ6="13:011"),E6,VLOOKUP(AZ6,модули!$K$27:$L$37,2,0)),VLOOKUP('расчетОО '!AZ6,модули!$K$27:$L$37,2,0))))) -> 0 | CF6: =VLOOKUP(CE6,модули!$L$27:'модули'!$M$37,2,FALSE) -> #N/A | CG6: =IF(F6="",IF(AZ6="13:011","Отсутствие газоснабжения",IF(AZ6="13:021","Отсутствие газоснабжения",IF(U6="наличие","Наличие газоснабжения",IF(U6="пересечение","Возможность подключения газоснабжения","Отсутствие газоснабжения")))),F6) -> Отсутствие газоснабжения | CH6: =VLOOKUP(CG6,модули!$B$7:'модули'!$D$18,3,FALSE) -> 1 | CI6: =IF(G6="",IF(V6="отсутствие","Отсутствие электроснабжения","Наличие электроснабжения"),G6) -> Наличие электроснабжения | CJ6: =VLOOKUP(CI6,модули!$F$7:'модули'!$H$18,3,FALSE) -> 4.2359 | CK6: Отсутствие водоснабжения | CL6: =VLOOKUP(CK6,модули!$J$7:'модули'!$L$18,3,FALSE) -> 1 | CM6: Отсутствие водоотведения | CN6: =VLOOKUP(CM6,модули!$N$7:'модули'!$P$18,3,FALSE) -> 1 | CO6: =IF(K6="Наличие ЛЭП","Наличие ЛЭП","Отсутствие ЛЭП") -> Отсутствие ЛЭП | CP6: =VLOOKUP(CO6,модули!$R$7:'модули'!$T$16,3,FALSE) -> 1 | CQ6: =IF(L6="Отсутствие подъезда","Отсутствие подъезда","Наличие подъезда") -> Наличие подъезда | CR6: =VLOOKUP(CQ6,модули!$V$7:'модули'!$X$17,3,FALSE) -> 1.1229 | CS6: =IFERROR(IF(O6="",IF(P6="",VLOOKUP(C6,модули!$F$48:$G$7038,2,0),P6),O6),VLOOKUP(AB6,модули!$I$48:$J$61,2,0)) -> #N/A | CT6: =IFERROR(VLOOKUP(CS6,модули!$A$27:$B$41,2,0),CS6) -> #N/A | CU6: =VLOOKUP(CT6,модули!$B$27:$D$41,3,FALSE) -> #N/A | CV6: =T6 -> 0 | CW6: =ROUND(IF(CV6<модули!$A$97,модули!$E$97,IF(CV6>модули!$A$98,модули!$E$98,( 3.13069866989796E-15*CV6^4 + 6.1338708204768E-12*CV6^3- 1.95954236270195E-07*CV6^2 + 0.000387905519741556*CV6 + 0.798784147038265))),4) -> 0.7988 | CX6: =IF(M6="",IF(N6="",VLOOKUP(CT6,модули!$F$27:$G$41,2,0),N6),M6) -> #N/A | CY6: =ROUND(EXP(LN(IF(CX6<модули!$H$99,модули!$I$99,IF(CX6>модули!$H$100,модули!$I$100,((9.167685587011E-08*(CX6)^4+0.000015289662956704*(CX6)^3-0.00161875861673315*(CX6)^2+0.0151997782316484*(CX6)+0.962501568438211)))))*модули!$K$98),4) -> #N/A | CZ6: =коэффициенты!$G$2 -> 638.4032 | DA6: =CJ6*CH6*CL6*CN6*CP6*CR6*CF6*CU6*CW6*CY6*CZ6 -> #N/A | DB6: Наличие уторгования | DC6: =$BZ$2 -> 0.8 | DD6: =ROUND(DC6*DA6,2) -> #N/A | DE6: =ROUND(DD6*CV6,2) -> #N/A | DF6: =8019 -> 8019 | DG6: СТ16_Ф1_М19_18052021_Бунаков_Измененные | DH6: =IF(OR(DE6<0,DE6=0),"ОТРИЦАТЕЛЬНОЕ ЗНАЧЕНИЕ",IF(DN6=0,"Пересчет не требуется","Готов")) -> #N/A | DI6: =IF(AI6="ГОТОВ",AR6,AZ6) -> 0 | DJ6: 13. СЕГМЕНТ "Садоводство и огородничество, малоэтажная жилая застройка" | DK6: =13 -> 13 | DL6: =VLOOKUP(DI6,'справочник ври'!$A$3:$B$271,2,0) -> #N/A | DM6: =AQ6 -> 0 | DN6: =IF(ISBLANK(Q6),"Новый объект",IF(DF6=AN6,ABS(DE6-R6),"Объект из другой модели")) -> Новый объект | DO6: =IF(DN6="Объект из другой модели",IF(OR(DD6<85,DD6>8560),"Отклонение УПКС","УПКС в допустимом интервале"),IF(DN6<1000000,"Изменение менее 1 млн","Внимание!Изменение более 1млн")) -> Внимание!Изменение более 1млн | DP6: =IF(O6="","Новое значение",IF(O6=CT6,"Осталось предыдущее значение ЦФ","ИЗМЕНЕНИЕ")) -> Новое значение | DQ6: =IF(G6="","Новое значение",IF(CI6=G6,"Осталось предыдущее значение ЦФ","ИЗМЕНЕНИЕ")) -> Новое значение | DR6: =IF(F6="","Новое значение",IF(CG6=F6,"Осталось предыдущее значение ЦФ","ИЗМЕНЕНИЕ")) -> Новое значение | DS6: =IF(AJ6="не готов","ИЗМЕНЕНИЕ","Осталось предыдущее значение ЦФ") -> Осталось предыдущее значение ЦФ | DT6: =IF(M6="","Новое значение",IF(CX6=M6,"Осталось предыдущее значение ЦФ","ИЗМЕНЕНИЕ")) -> Новое значение | DU6: =IF(E6="","Новое значение",IF(CE6=E6,"Осталось предыдущее значение ЦФ","ИЗМЕНЕНИЕ")) -> Новое значение | DV6: =IF(AI6="ГОТОВ",IF(AP6=AR6,"Осталось предыдущее значение ЦФ","ИЗМЕНЕНИЕ"),IF(AP6=AZ6,"Осталось предыдущее значение ЦФ","ИЗМЕНЕНИЕ")) -> Осталось предыдущее значение ЦФ | DW6: =IF(I6="","Новое значение",IF(CK6=I6,"Осталось предыдущее значение ЦФ","ИЗМЕНЕНИЕ")) -> Новое значение | DX6: =IF(H6="","Новое значение",IF(CM6=H6,"Осталось предыдущее значение ЦФ","ИЗМЕНЕНИЕ")) -> Новое значение | DY6: =IF(K6="","Новое значение",IF(CO6=K6,"Осталось предыдущее значение ЦФ","ИЗМЕНЕНИЕ")) -> Новое значение | DZ6: =IF(L6="","Новое значение",IF(CQ6=L6,"Осталось предыдущее значение ЦФ","ИЗМЕНЕНИЕ")) -> Новое значение

Sheet коэффициенты
A1: Номер модели | B1: Фактор | C1: Тип фактора | D1: Градации (код) | E1: Возможные градации (описание) | F1: Значение коэффициента регрессора в мультипликативной модели | G1: Значение градации | H1: Признак типовой зоны | I1: Коэффициент регрессора | J1: Минимальное значение числовой переменной | K1: Максимальное значение числовой переменной | L1: Максимальное значение фактора | M1: Миниимальное значение фактора | O1: № Фактора в модели | P1: Не знаю что это такое
F2: 6.45897 | G2: =ROUND(EXP(F2),4) -> 638.4032
A3: 8019 | B3: Вид разрешенного использования | C3: Качественный | D3: gr1 | E3: Садовые объединения | F3: 0 | G3: =ROUND(EXP(F3),4) -> 1 | O3: V1 | P3: =F3 -> 0
A4: 8019 | D4: gr3 | E4: Дачные и коттеджные объединения | F4: 0.13279 | G4: =ROUND(EXP(F4),4) -> 1.142 | P4: =F4 -> 0.13279
A5: 8019 | D5: gr4 | E5: Индивидуальные поселения | F5: 0.46542 | G5: =ROUND(EXP(F5),4) -> 1.5927 | P5: =F5 -> 0.46542
A6: 8019 | B6: Газоснабжение | C6: Качественный | D6: YS | E6: Наличие газоснабжения | F6: 0.79251 | G6: =ROUND(EXP(F6),4) -> 2.2089 | O6: V2 | P6: =F6 -> 0.79251
A7: 8019 | D7: VZ | E7: Возможность подключения газоснабжения | F7: 0.13241 | G7: =ROUND(EXP(F7),4) -> 1.1416 | P7: =F7 -> 0.13241
A8: 8019 | D8: NO | E8: Отсутствие газоснабжения | F8: =ROUND(P8,4) -> 0 | G8: =ROUND(EXP(F8),4) -> 1
A9: 8019 | B9: Электроснабжение | C9: Качественный | D9: YS | E9: Наличие электроснабжения | F9: 1.4436 | G9: =ROUND(EXP(F9),4) -> 4.2359 | O9: V3 | P9: =F9 -> 1.4436
A10: 8019 | D10: VZ | E10: Возможность подключения электроснабжения | F10: 1.14025 | G10: =ROUND(EXP(F10),4) -> 3.1276 | P10: =F10 -> 1.14025
A11: 8019 | D11: NO | E11: Отсутствие электроснабжения | F11: 0 | G11: =ROUND(EXP(F11),4) -> 1 | P11: =F11 -> 0
A12: 8019 | B12: Водоснабжение | C12: Качественный | D12: YS | E12: Наличие водоснабжения | F12: 0.45966 | G12: =ROUND(EXP(F12),4) -> 1.5835 | O12: V4 | P12: =F12 -> 0.45966
A13: 8019 | D13: NO | E13: Отсутствие водоснабжения | F13: 0 | G13: =ROUND(EXP(F13),4) -> 1 | P13: =F13 -> 0
A14: 8019 | B14: Водоотведение | C14: Качественный | D14: YS | E14: Наличие водоотведения | F14: 0.14116 | G14: =ROUND(EXP(F14),4) -> 1.1516 | O14: V5 | P14: =F14 -> 0.14116
A15: 8019 | D15: NO | E15: Отсутствие водоотведения | F15: 0 | G15: =ROUND(EXP(F15),4) -> 1 | P15: =F15 -> 0
A16: 8019 | B16: ЛЭП над участком | C16: Качественный | D16: YS | E16: Наличие ЛЭП | F16: -0.30695 | G16: =ROUND(EXP(F16),4) -> 0.7357 | O16: V6 | P16: =F16 -> -0.30695
A17: 8019 | D17: NO | E17: Отсутствие ЛЭП | F17: 0 | G17: =ROUND(EXP(F17),4) -> 1 | P17: =F17 -> 0
A18: 8019 | B18: Подъезд к участку | C18: Качественный | D18: YS | E18: Наличие подъезда | F18: 0.11591 | G18: =ROUND(EXP(F18),4) -> 1.1229 | O18: V7 | P18: =F18 -> 0.11591
A19: 8019 | D19: NO | E19: Отсутствие подъезда | F19: 0 | G19: =ROUND(EXP(F19),4) -> 1 | P19: =F19 -> 0
A20: 8019 | B20: Зона влияния ИЖС | C20: Качественный | D20: ee | E20: Восток | F20: -0.78651 | G20: =ROUND(EXP(F20),4) -> 0.4554 | O20: V8 | P20: =F20 -> -0.78651
A21: 8019 | D21: ne1 | E21: Северо-Восток_1 | F21: -1.39413 | G21: =ROUND(EXP(F21),4) -> 0.248 | P21: =F21 -> -1.39413
A22: 8019 | D22: ne2 | E22: Северо-Восток_2 | F22: -0.95815 | G22: =ROUND(EXP(F22),4) -> 0.3836 | P22: =F22 -> -0.95815
A23: 8019 | D23: nw | E23: Северо-Запад | F23: -1.52398 | G23: =ROUND(EXP(F23),4) -> 0.2178 | P23: =F23 -> -1.52398
A24: 8019 | D24: nn | E24: Север | F24: -1.39413 | G24: =ROUND(EXP(F24),4) -> 0.248
A25: 8019 | D25: se1 | E25: Юго-Восток_1 | F25: -1.38094 | G25: =ROUND(EXP(F25),4) -> 0.2513
A26: 8019 | D26: se2 | E26: Юго-Восток_2 | F26: -1.53773 | G26: =ROUND(EXP(F26),4) -> 0.2149
A27: 8019 | D27: ss | E27: Юг | F27: -1.48756 | G27: =ROUND(EXP(F27),4) -> 0.2259
A28: 8019 | D28: sw1 | E28: Юго-Запад_1 | F28: -1.51944 | G28: =ROUND(EXP(F28),4) -> 0.2188
A29: 8019 | D29: sw2 | E29: Юго-Запад_2 | F29: -1.69646 | G29: =ROUND(EXP(F29),4) -> 0.1833
A30: 8019 | D30: sw3 | E30: Юго-Запад_3 | F30: -1.76113 | G30: =ROUND(EXP(F30),4) -> 0.1719
A31: 8019 | D31: sw4 | E31: Юго-Запад_4 | F31: -0.98576 | G31: =ROUND(EXP(F31),4) -> 0.3732
A32: 8019 | D32: ww1 | E32: Запад_1 | F32: -1.69003 | G32: =ROUND(EXP(F32),4) -> 0.1845
A33: 8019 | D33: ww2 | E33: Запад_2 | F33: -1.02326 | G33: =ROUND(EXP(F33),4) -> 0.3594
A34: 8019 | D34: cc | E34: Центр | F34: 0 | G34: =ROUND(EXP(F34),4) -> 1
A35: 8019 | B35: Общая площадь | C35: количественный | E35: ЕСЛИ(Общая площадь>4200;0,4000;(-0.0000000000000031307*Общая площадь^4 + 0.000000000063387082*Общая площадь^3- 0.0000001959542362702*Общая площадь^2 +0.000387905519741556*Общая площадь + 0.798784147038265000)) | I35: Это аппрокисимирующая функция, учитывет коэффициент регрессора | J35: нет ограничения | K35: 4200 | L35: 1 | M35: 0.4 | O35: V9
A36: 8019 | B36: Расстояние до зон транспортного безразличия | C36: количественный | E36: (EXP(LN(ЕСЛИ(Расстояние до зон транспортного безразличия <5;1;ЕСЛИ(Расстояние до зон транспортного безразличия >27,5;0,6638;((0,00000009167685587011*( Расстояние до зон транспортного безразличия)^4+0,0000152896622956704*( Расстояние до зон транспортного безразличия)^3-0,00161875861673315*( Расстояние до зон транспортного безразличия)^2+0,0151997782316484*( Расстояние до зон транспортного безразличия)+0,962501568438211)))))*0,6392) | I36: 0.63922 | J36: 5 | K36: 27.5 | L36: 1 | M36: 0.6638 | O36: V10
A37: 8019 | B37: Уторгование | C37: коэффициент вне модели | E37: Наличие уторгования | G37: 0.8 | O37: V11
A38: 8019 | E38: Отсутствие уторгования | G38: 1
B40: площадь
B41: 3.1306987e-15
...

Sheet ГОТОВ
A1: CadastralNumber | B1: loc_factor_825 | D1: loc_factor_822 | F1: loc_factor_804 | H1: loc_factor_828 | J1: loc_factor_803 | L1: loc_factor_829 | N1: loc_factor_840 | Q1: loc_factor_826 | S1: loc_factor_807 | T1: loc_factor_8071 | U1: loc_factor_837 | V1: loc_factor_8371 | Y1: loc_factor_827 | AA1: Specific_CadastralCost | AB1: CadastralCost | AC1: id_group | AD1: CadastralCostDesc | AE1: Status_kc | AF1: loc_VICode | AG1: Segment | AH1: loc_SgCode | AI1: loc_GroupName | AJ1: Old_Utlbydoc

Sheet СТОПЛИСТ
A1: CadastralNumber | B1: ControlSP

Sheet ПЕРЕСЧЕТ НЕ ТРЕБУЕТСЯ
A1: CadastralNumber | B1: Status_kc | C1: loc_VICode | D1: Segment | E1: loc_SgCode | F1: loc_GroupName | G1: Old_Utlbydoc

Sheet справочник ври
A1: loc_VICode | B1: loc_GroupName
A2: Код расчета вида использования | B2: Наименование вида использования
A3: 01:010 | B3: Растениеводство в целом. Включает коды расчета вида использования 01.020-01.060
A4: 01:020 | B4: Выращивание зерновых, бобовых, кормовых, технических, масличных, эфиромасличных и иных сельскохозяйственных культур
A5: 01:030 | B5: Овощеводство в целом, связанное с производством картофеля, листовых, плодовых, луковичных и бахчевых сельскохозяйственных культур, в том числе с использованием теплиц
A6: 01:031 | B6: Овощеводство в открытом грунте
A7: 01:032 | B7: Овощеводство тепличное
A8: 01:040 | B8: Выращивание тонизирующих, лекарственных, цветочных культур в целом
A9: 01:041 | B9: Выращивание тонизирующих, лекарственных, цветочных культур. Травы
A10: 01:042 | B10: Выращивание тонизирующих, лекарственных, цветочных культур. Кустарники
A11: 01:050 | B11: Садоводство в целом - выращивание многолетних плодовых и ягодных культур, винограда и иных многолетних культур
A12: 01:051 | B12: Садоводство плодовое
... A271: 14:000 | B271: Иное использование

Sheet модули
A2: семантика
A4: Газоснабжение (ЦФ) | E4: Электроснабжение (ЦФ) | I4: Водоснабжение (ЦФ) | M4: Водоотведение (ЦФ) | Q4: ЛЭП над участком (ЦФ) | U4: Подъезд к участку (ЦФ)
A5: текст | B5: правило | E5: текст | F5: правило | I5: текст | J5: правило | M5: текст | N5: правило | Q5: правило | U5: текст | V5: правило
A7: иное | B7: Ошибка определения | C7: !MST! | E7: иное | F7: Ошибка определения | G7: !MST! | I7: иное | J7: Ошибка определения | K7: !MST! | M7: иное | N7: Ошибка определения | O7: !MST! | Q7: иное(возможность) | R7: Ошибка определения | S7: !MST! | U7: иное(возможность) | V7: Ошибка определения | W7: !MST!
A8: наличие | B8: Наличие газоснабжения | C8: YS | D8: =коэффициенты!G6 -> 2.2089 | E8: наличие | F8: Наличие электроснабжения | G8: YS | H8: =коэффициенты!G9 -> 4.2359 | I8: наличие | J8: Наличие водоснабжения | K8: YS | L8: =коэффициенты!G12 -> 1.5835 | M8: наличие | N8: Наличие водоотведения | O8: YS | P8: =коэффициенты!G14 -> 1.1516 | Q8: Наличие ЛЭП | R8: Наличие ЛЭП | S8: YS | T8: =коэффициенты!G16 -> 0.7357 | U8: Есть подъезд | V8: Наличие подъезда | W8: YS | X8: =коэффициенты!G18 -> 1.1229
A9: Наличие | B9: Наличие газоснабжения | C9: YS | D9: =коэффициенты!G6 -> 2.2089 | E9: Наличие | F9: Наличие электроснабжения | G9: YS | H9: =коэффициенты!G9 -> 4.2359 | I9: Наличие | J9: Наличие водоснабжения | K9: YS | L9: =коэффициенты!G12 -> 1.5835 | M9: Наличие | N9: Наличие водоотведения | O9: YS | P9: =коэффициенты!G14 -> 1.1516 | Q9: Наличие | R9: Наличие ЛЭП | S9: YS | T9: =коэффициенты!G16 -> 0.7357 | U9: отсыпанная | V9: Наличие подъезда | W9: YS | X9: =коэффициенты!G18 -> 1.1229
A10: есть | B10: Наличие газоснабжения | C10: YS | D10: =коэффициенты!G6 -> 2.2089 | E10: есть | F10: Наличие электроснабжения | G10: YS | H10: =коэффициенты!G9 -> 4.2359 | I10: есть | J10: Наличие водоснабжения | K10: YS | L10: =коэффициенты!G12 -> 1.5835 | M10: есть | N10: Наличие водоотведения | O10: YS | P10: =коэффициенты!G14 -> 1.1516 | Q10: есть | R10: Наличие ЛЭП | S10: YS | T10: =коэффициенты!G16 -> 0.7357 | U10: асфальт | V10: Наличие подъезда | W10: YS | X10: =коэффициенты!G18 -> 1.1229
A11: Есть | B11: Наличие газоснабжения | C11: YS | D11: =коэффициенты!G6 -> 2.2089 | E11: Есть | F11: Наличие электроснабжения | G11: YS | H11: =коэффициенты!G9 -> 4.2359 | I11: Есть | J11: Наличие водоснабжения | K11: YS | L11: =коэффициенты!G12 -> 1.5835 | M11: Есть | N11: Наличие водоотведения | O11: YS | P11: =коэффициенты!G14 -> 1.1516 | Q11: Есть | R11: Наличие ЛЭП | S11: YS | T11: =коэффициенты!G16 -> 0.7357 | U11: грунтовая | V11: Наличие подъезда | W11: YS | X11: =коэффициенты!G18 -> 1.1229
A12: нет | B12: Отсутствие газоснабжения | C12: NO | D12: =коэффициенты!G8 -> 1 | E12: нет | F12: Отсутствие электроснабжения | G12: NO | H12: =коэффициенты!G11 -> 1 | I12: нет | J12: Отсутствие водоснабжения | K12: NO | L12: =коэффициенты!G13 -> 1 | M12: нет | N12: Отсутствие водоотведения | O12: NO | P12: =коэффициенты!G15 -> 1 | Q12: нет | R12: Отсутствие ЛЭП | S12: YS | T12: =коэффициенты!G17 -> 1 | U12: Есть | V12: Наличие подъезда | W12: YS | X12: =коэффициенты!G18 -> 1.1229
A13: Нет | B13: Отсутствие газоснабжения | C13: NO | D13: =коэффициенты!G8 -> 1 | E13: Нет | F13: Отсутствие электроснабжения | G13: NO | H13: =коэффициенты!G11 -> 1 | I13: Нет | J13: Отсутствие водоснабжения | K13: NO | L13: =коэффициенты!G13 -> 1 | M13: Нет | N13: Отсутствие водоотведения | O13: NO | P13: =коэффициенты!G15 -> 1 | Q13: Нет | R13: Отсутствие ЛЭП | S13: NO | T13: =коэффициенты!G17 -> 1 | U13: нет | V13: Отсутствие подъезда | W13: NO | X13: =коэффициенты!G19 -> 1
A14: Отсутствие | B14: Отсутствие газоснабжения | C14: NO | D14: =коэффициенты!G8 -> 1 | E14: Отсутствие | F14: Отсутствие электроснабжения | G14: NO | H14: =коэффициенты!G11 -> 1 | I14: Отсутствие | J14: Отсутствие водоснабжения | K14: NO | L14: =коэффициенты!G13 -> 1 | M14: Отсутствие | N14: Отсутствие водоотведения | O14: NO | P14: =коэффициенты!G15 -> 1 | Q14: Отсутствие ЛЭП | R14: Отсутствие ЛЭП | S14: NO | T14: =коэффициенты!G17 -> 1 | U14: Нет | V14: Отсутствие подъезда | W14: NO | X14: =коэффициенты!G19 -> 1
A15: отсутствие | B15: Отсутствие газоснабжения | C15: NO | D15: =коэффициенты!G8 -> 1 | E15: отсутствие | F15: Отсутствие электроснабжения | G15: NO | H15: =коэффициенты!G11 -> 1 | I15: отсутствие | J15: Отсутствие водоснабжения | K15: NO | L15: =коэффициенты!G13 -> 1 | M15: отсутствие | N15: Отсутствие водоотведения | O15: NO | P15: =коэффициенты!G15 -> 1 | R15: Отсутствие ЛЭП | S15: NO | T15: =коэффициенты!G17 -> 1 | U15: Отсутствие | V15: Отсутствие подъезда | W15: NO | X15: =коэффициенты!G19 -> 1
A16: пересечение | B16: Возможность подключения газоснабжения | C16: VZ | D16: =коэффициенты!G7 -> 1.1416 | E16: возможность | F16: Возможность подключения электроснабжения | G16: VZ | H16: =коэффициенты!G9 -> 4.2359 | I16: 0 | J16: Отсутствие водоснабжения | K16: NO | L16: =коэффициенты!G13 -> 1 | M16: 0 | N16: Отсутствие водоотведения | O16: NO | P16: =коэффициенты!G15 -> 1 | Q16: 0 | R16: Отсутствие ЛЭП | S16: NO | T16: =коэффициенты!G17 -> 1 | U16: отсутствие | V16: Отсутствие подъезда | W16: NO | X16: =коэффициенты!G19 -> 1
A17: Пересечение | B17: Возможность подключения газоснабжения | C17: VZ | D17: =коэффициенты!G7 -> 1.1416 | E17: рядом | F17: Возможность подключения электроснабжения | G17: VZ | H17: =коэффициенты!G9 -> 4.2359 | J17: Отсутствие водоснабжения | K17: NO | L17: =коэффициенты!G13 -> 1 | N17: Отсутствие водоотведения | O17: NO | P17: =коэффициенты!G15 -> 1 | U17: 0 | V17: Наличие подъезда | W17: YS | X17: =коэффициенты!G18 -> 1.1229
A18: 0 | B18: Отсутствие газоснабжения | C18: NO | D18: =коэффициенты!G8 -> 1 | E18: 0 | F18: Отсутствие электроснабжения | G18: NO | H18: =коэффициенты!G11 -> 1 | J18: Отсутствие водоснабжения | K18: NO | L18: =коэффициенты!G13 -> 1 | N18: Отсутствие водоотведения | O18: NO | P18: =коэффициенты!G15 -> 1 | V18: Наличие подъезда | W18: YS | X18: =коэффициенты!G18 -> 1.1229
A19: контрольный образец | B19: Модуль | E19: контрольный образец | F19: Модуль | I19: контрольный образец | J19: Модуль | M19: контрольный образец | N19: Модуль | Q19: контрольный образец | R19: Модуль | U19: контрольный образец | V19: Модуль
B20: =IF(A20=$A$17,$B$17,IF(A20=$A$16,$B$16,IF(A20=$A$8,$B$8,IF(A20=$A$9,$B$9,IF(A20=$A$10,$B$10,IF(A20=$A$11,$B$11,IF(A20=$A$12,$B$12,IF(A20=$A$13,$B$13,IF(A20=$A$14,$B$14,IF(A20=$A$15,$B$15,IF(A20=$A$18,B$18,$B$7))))))))))) -> Отсутствие газоснабжения | C20: =VLOOKUP(B20,$B$7:$C$18,2,FALSE) -> NO | D20: =VLOOKUP(B20,$B$7:$D$18,3,FALSE) -> 1 | E20: пересечение | F20: =IF(E20=$E$16,$F$17,IF(E20=$E$15,$F$16,IF(E20=$E$7,$F$8,IF(E20=$E$8,$F$9,IF(E20=$E$9,$F$10,IF(E20=$E$10,$F$11,IF(E20=$E$11,$F$12,IF(E20=$E$12,$F$13,IF(E20=$E$13,$F$14,IF(E20=$E$14,$F$15,IF(E20=$E$17,F$18,$F$7))))))))))) -> Ошибка определения | G20: =VLOOKUP(F20,$F$7:$G$18,2,FALSE) -> !MST! | H20: =VLOOKUP(F20,$F$7:$H$18,3,FALSE) -> 0 | I20: наличие | J20: =IF(I20=$I$8,$J$8,IF(I20=$I$9,$J$9,IF(I20=$I$10,$J$10,IF(I20=$I$11,$J$11,IF(I20=$I$12,$J$12,IF(I20=$I$13,$J$13,IF(I20=$I$14,$J$14,IF(I20=$I$15,$J$15,IF(I20=$I$18,J$18,$J$7))))))))) -> Наличие водоснабжения | K20: =VLOOKUP(J20,$J$7:$K$18,2,FALSE) -> YS | L20: =VLOOKUP(J20,$J$7:$L$18,3,FALSE) -> 1.5835 | M20: пересечение | N20: =IF(M20=$M$8,$N$8,IF(M20=$M$9,$N$9,IF(M20=$M$10,$N$10,IF(M20=$M$11,$N$11,IF(M20=$M$12,$N$12,IF(M20=$M$13,$N$13,IF(M20=$M$14,$N$14,IF(M20=$M$15,$N$15,IF(M20=$M$18,N$18,$N$7))))))))) -> Ошибка определения | O20: =VLOOKUP(N20,$N$7:$O$18,2,FALSE) -> !MST! | P20: =VLOOKUP(N20,$N$7:$P$18,3,FALSE) -> 0 | R20: =IF(Q20=$Q$8,$R$8,IF(Q20=$Q$9,$R$9,IF(Q20=$Q$10,$R$10,IF(Q20=$Q$11,$R$11,IF(Q20=$Q$12,$R$12,IF(Q20=$Q$13,$R$13,IF(Q20=$Q$14,$R$14,IF(Q20=$Q$15,$R$15,IF(Q20=$Q$16,R$16,$R$7))))))))) -> Отсутствие ЛЭП | S20: =VLOOKUP(R20,$R$7:$S$16,2,FALSE) -> YS | T20: =VLOOKUP(R20,$R$7:$T$16,3,FALSE) -> 1 | V20: =IF(U20=$U$7,$V$7,IF(U20=$U$8,$V$8,IF(U20=$U$9,$V$9,IF(U20=$U$10,$V$10,IF(U20=$U$11,$V$11,IF(U20=$U$12,$V$12,IF(U20=$U$13,$V$13,IF(U20=$U$14,$V$14,IF(U20=$U$15,$V$15,IF(U20=$U$16,$V$16,IF(U20=$U$17,V$17,$V$7))))))))))) -> Наличие подъезда | W20: =VLOOKUP(V20,$V$7:$W$17,2,FALSE) -> YS | X20: =VLOOKUP(V20,$V$7:$X$17,3,FALSE) -> 1.1229
A22: точное совпадение
A24: =коэффициенты!B20 -> Зона влияния ИЖС | F24: среднезональные расстояния | J24: =коэффициенты!B3 -> Вид разрешенного использования
A26: =коэффициенты!D1 -> Градации (код) | B26: =коэффициенты!E1 -> Возможные градации (описание) | D26: =коэффициенты!G1 -> Значение градации | F26: zona | G26: avg_dst_z0 | I26: расшифровка ВРИ | J26: =коэффициенты!D1 -> Градации (код) | K26: код ВРИ | L26: =коэффициенты!E1 -> Возможные градации (описание) | M26: =коэффициенты!G1 -> Значение градации
A27: =коэффициенты!D20 -> ee | B27: =коэффициенты!E20 -> Восток | C27: =B27 -> Восток | D27: =коэффициенты!G20 -> 0.4554 | F27: Центр | G27: 7.801 | I27: Индивидуальное жилищное строительство в целом | J27: gr4 | K27: 02:010 | L27: =коэффициенты!E5 -> Индивидуальные поселения | M27: =ROUND( коэффициенты!G5,4) -> 1.5927
A28: =коэффициенты!D21 -> ne1 | B28: =коэффициенты!E21 -> Северо-Восток_1 | C28: =B28 -> Северо-Восток_1 | D28: =коэффициенты!G21 -> 0.248 | F28: Восток | G28: 7.0774 | I28: Размещение индивидуального жилого дома (дом, пригодный для постоянного проживания, высотой не выше трех надземных этажей), размещение индивидуальных гаражей и подсобных сооружений, исходя из минимальных норм отвода земельных участков для индивидуального | J28: gr4 | K28: 02:011 | L28: =коэффициенты!E5 -> Индивидуальные поселения | M28: =ROUND( коэффициенты!G5,4) -> 1.5927
A29: =коэффициенты!D22 -> ne2 | B29: =коэффициенты!E22 -> Северо-Восток_2 | C29: =B29 -> Северо-Восток_2 | D29: =коэффициенты!G22 -> 0.3836 | F29: Северо-Восток_1 | G29: 4.8953 | I29: Размещение индивидуального жилого дома в организованных коттеджных поселках | J29: gr4 | K29: 02:019 | L29: =коэффициенты!E5 -> Индивидуальные поселения | M29: =ROUND( коэффициенты!G5,4) -> 1.5927
A30: =коэффициенты!D23 -> nw | B30: =коэффициенты!E23 -> Северо-Запад | C30: =B30 -> Северо-Запад | D30: =коэффициенты!G23 -> 0.2178 | F30: Северо-Восток_2 | G30: 7.1043 | I30: Ведение личного подсобного хозяйства с правом застройки в целом | J30: gr4 | K30: 02:020 | L30: =коэффициенты!E5 -> Индивидуальные поселения | M30: =ROUND( коэффициенты!G5,4) -> 1.5927
A31: =коэффициенты!D24 -> nn | B31: =коэффициенты!E24 -> Север | C31: =B31 -> Север | D31: =коэффициенты!G24 -> 0.248 | F31: Север | G31: 5.4484 | I31: Блокированная жилая застройка в целом | J31: gr4 | K31: 02:030 | L31: =коэффициенты!E5 -> Индивидуальные поселения | M31: =ROUND( коэффициенты!G5,4) -> 1.5927
A32: =коэффициенты!D25 -> se1 | B32: =коэффициенты!E25 -> Юго-Восток_1 | C32: =B32 -> Юго-Восток_1 | D32: =коэффициенты!G25 -> 0.2513 | F32: Северо-Запад | G32: 8.6543 | I32: Блокированная жилая застройка. Размещение жилого дома, не предназначенного для раздела на квартиры, имеющего одну или несколько общих стен с соседними жилыми домами (количеством этажей не более чем три, при общем количестве совмещенных домов не более дес | J32: gr4 | K32: 02:031 | L32: =коэффициенты!E5 -> Индивидуальные поселения | M32: =ROUND( коэффициенты!G5,4) -> 1.5927
A33: =коэффициенты!D26 -> se2 | B33: =коэффициенты!E26 -> Юго-Восток_2 | C33: =B33 -> Юго-Восток_2 | D33: =коэффициенты!G26 -> 0.2149 | F33: Юго-Восток_1 | G33: 7.088 | I33: Ведение личного подсобного хозяйства. Размещение жилого дома, не предназначенного для раздела на квартиры (дома, пригодные для постоянного проживания и высотой не выше трех надземных этажей), размещение гаража и иных вспомогательных сооружений, в том чис | J33: gr4 | K33: 02:021 | L33: =коэффициенты!E5 -> Индивидуальные поселения | M33: =ROUND( коэффициенты!G5,4) -> 1.5927
A34: =коэффициенты!D27 -> ss | B34: =коэффициенты!E27 -> Юг | C34: =B34 -> Юг | D34: =коэффициенты!G27 -> 0.2259 | F34: Юго-Восток_2 | G34: 9.069 | I34: Ведение крестьянско-фермерского хозяйства. Размещение жилого дома, не предназначенного для раздела на квартиры (дома, пригодные для постоянного проживания и высотой не выше трех надземных этажей), размещение гаража и иных вспомогательных сооружений, в то | J34: gr4 | K34: 02:023 | L34: =коэффициенты!E5 -> Индивидуальные поселения | M34: =ROUND( коэффициенты!G5,4) -> 1.5927
A35: =коэффициенты!D28 -> sw1 | B35: =коэффициенты!E28 -> Юго-Запад_1 | C35: =B35 -> Юго-Запад_1 | D35: =коэффициенты!G28 -> 0.2188 | F35: Юг | G35: 5.483 | I35: Ведение садоводства. Осуществление отдыха и (или) деятельности, связанной с выращиванием гражданами для собственных нужд сельскохозяйственных культур; размещение садовых домов, жилых домов, размещение для собственных нужд гаражей и иных хозяйственных пос | J35: gr1 | K35: 13:021 | L35: =коэффициенты!E3 -> Садовые объединения | M35: =ROUND( коэффициенты!G3,4) -> 1
A36: =коэффициенты!D29 -> sw2 | B36: =коэффициенты!E29 -> Юго-Запад_2 | C36: =B36 -> Юго-Запад_2 | D36: =коэффициенты!G29 -> 0.1833 | F36: Юго-Запад_1 | G36: 17.7922 | I36: Ведение огородничества. Осуществление отдыха и (или) деятельности, связанной с выращиванием гражданами для собственных нужд сельскохозяйственных культур; размещение хозяйственных построек, не являющихся объектами недвижимости, предназначенных для хранени | J36: gr1 | K36: 13:011 | L36: =коэффициенты!E3 -> Садовые объединения | M36: =ROUND( коэффициенты!G3,4) -> 1
A37: =коэффициенты!D30 -> sw3 | B37: =коэффициенты!E30 -> Юго-Запад_3 | C37: =B37 -> Юго-Запад_3 | D37: =коэффициенты!G30 -> 0.1719 | F37: Юго-Запад_2 | G37: 22.8126 | I37: Ведение дачного хозяйства. Размещение жилого дачного дома, не предназначенного для раздела на квартиры, пригодного для отдыха и проживания, высотой не выше трех надземных этажей | J37: gr3 | K37: 13:031 | L37: =коэффициенты!E4 -> Дачные и коттеджные объединения | M37: =ROUND( коэффициенты!G4,4) -> 1.142
A38: =коэффициенты!D31 -> sw4 | B38: =коэффициенты!E31 -> Юго-Запад_4 | C38: =B38 -> Юго-Запад_4 | D38: =коэффициенты!G31 -> 0.3732 | F38: Юго-Запад_3 | G38: 7.7827 | K38: контрольный образец | L38: Модуль
A39: =коэффициенты!D32 -> ww1 | B39: =коэффициенты!E32 -> Запад_1 | C39: =B39 -> Запад_1 | D39: =коэффициенты!G32 -> 0.1845 | F39: Юго-Запад_4 | G39: 14.9373 | K39: 13:031 | L39: =VLOOKUP(K39,$K$27:$L$37,2,FALSE) -> Дачные и коттеджные объединения | M39: =VLOOKUP(L39,$L$27:$M$37,2,FALSE) -> 1.142
A40: =коэффициенты!D33 -> ww2 | B40: =коэффициенты!E33 -> Запад_2 | C40: =B40 -> Запад_2 | D40: =коэффициенты!G33 -> 0.3594 | F40: Запад_1 | G40: 8.9429 | K40: gr3 | L40: =VLOOKUP(K40,$J$27:$L$37,3,FALSE) -> Дачные и коттеджные объединения | M40: =VLOOKUP(K40,$J$27:$M$37,4,FALSE) -> 1.142
A41: =коэффициенты!D34 -> cc | B41: =коэффициенты!E34 -> Центр | C41: =B41 -> Центр | D41: =коэффициенты!G34 -> 1 | F41: Запад_2 | G41: 14.5624
F42: контрольный образец | G42: Модуль
B43: принятые решения | F43: Запад_2 | G43: =VLOOKUP(F43,$F$27:$G$41,2,FALSE) -> 14.5624
A44: sysert_1 | B44: Сысерть_1 | C44: Юг
A45: контрольный образец | B45: Модуль
A46: ss | B46: =VLOOKUP(A46,$A$27:$B$44,2,FALSE) -> Юг | C46: =VLOOKUP(B46,$B$27:$C$44,2,FALSE) -> Юг | D46: =VLOOKUP(C46,$C$27:$D$41,2,FALSE) -> 0.2259 | F46: Справочник квартал-зона, при отсутствии КК в списке зона назначается по МО
...

Sheet количественные факторы
B1: расчетные коэффициенты по модели | G1: 0.00000000000000311x4 + 0.00000000000610051x3 - 0.00000019488839112x2 + 0.00038579560251740x + 0.79443935598877000
B2: 0.63922 | C2: коэффициент по расстоянию | G2: !!! Правильный лист с точностью до 20 знаков в файле 19_modul0.xlsx | W2: 1.0186317
B3: 0.98966 | C3: коэффициент по площади | Z3: y=(EXP(LN(ЕСЛИ(x<5;1;ЕСЛИ(x>27,5;0,5237;((0,00000009*(x)^4+0,00001501*(x)^3-0,00158915*(x)^2+0,01492176*(x)+0,94489651)*1,0186317318901))))*0,6174))
A5: граничные значения | AD5: 9e-08 | AE5: 1.501e-05 | AF5: 0.00158915 | AG5: 0.01492176 | AH5: 0.94489651
A6: 150 | B6: =(0.000000000032989*A6^3-0.000000270691185*A6^2+0.000468652420503*A6+0.726630359723856)*1.04333245461704 -> 0.82522277 | D6: =B3 -> 0.98966 | E6: коэффициент по площади | V6: 5 | W6: =(0.00000009*(V6)^4+0.00001501*(V6)^3-0.00158915*(V6)^2+0.01492176*(V6)+0.94489651)*1.0186317318901 -> 1 | Y6: =B2 -> 0.63922 | Z6: коэффициент по расстоянию | AD6: =AD5*1.0186317318901 -> 9.1676856e-08 | AE6: =AE5*1.0186317318901 -> 1.5289662e-05 | AF6: =AF5*1.0186317318901 -> 0.0016187586 | AG6: =AG5*1.0186317318901 -> 0.015199778 | AH6: =AH5*1.0186317318901 -> 0.96250157
A7: 4000 | B7: =(0.000000000032989*A7^3-0.000000270691185*A7^2+0.000468652420503*A7+0.726630359723856)*1.04333245461704 -> 0.39800742 | V7: 27.5 | W7: =(0.00000009*(V7)^4+0.00001501*(V7)^3-0.00158915*(V7)^2+0.01492176*(V7)+0.94489651)*1.0186317318901 -> 0.52671774
A8: площадь, кв.м. | B8: исходная функция (желтая) | C8: экспонированная функция (синяя) | E8: аппроксимирующая функция (серая) | G8: контроьные значения аппроксимирующей
A9: 50 | B9: =(IF(A9<$A$6,$B$6,IF(A9>$A$7,$B$7,((0.000000000032989*A9^3-0.000000270691185*A9^2+0.000468652420503*A9+0.726630359723856)*1.04333245461704)))) -> 0.82522277 | C9: =EXP(LN(IF(A9<$A$6,$B$6,IF(A9>$A$7,$B$7,((0.000000000032989*A9^3-0.000000270691185*A9^2+0.000468652420503*A9+0.726630359723856)*1.04333245461704))))*$D$6) -> 0.82686357 | E9: 50 | F9: =C9 -> 0.82686357 | G9: =3.11367E-15*E9^4*$H$14+6.10050713E-12*E9^3*$H$14- 1.9488839111664E-07*E9^2*$H$14+0.000385795602517395*E9*$H$14+0.79443935598877*$H$14 -> 0.81769032 | U9: 1 | V9: =IF(U9<$V$6,$W$6,IF(U9>$V$7,$W$7,((0.00000009*(U9)^4+0.00001501*(U9)^3-0.00158915*(U9)^2+0.01492176*(U9)+0.94489651)*1.0186317318901))) -> 1 | W9: =(EXP(LN(IF(U9<$V$6,$W$6,IF(U9>$V$7,$W$7,((0.00000009*(U9)^4+0.00001501*(U9)^3-0.00158915*(U9)^2+0.01492176*(U9)+0.94489651)*1.0186317318901))))*$Y$6)) -> 1 | X9: =(EXP(LN(IF(U9<$V$6,$W$6,IF(U9>$V$7,$W$7,((0.00000009*(U9)^4+0.00001501*(U9)^3-0.00158915*(U9)^2+0.01492176*(U9)+0.94489651)*1.0186317318901))))*$Y$6)) -> 1
A10: 100 | B10: =(IF(A10<$A$6,$B$6,IF(A10>$A$7,$B$7,((0.000000000032989*A10^3-0.000000270691185*A10^2+0.000468652420503*A10+0.726630359723856)*1.04333245461704)))) -> 0.82522277 | C10: =EXP(LN(IF(A10<$A$6,$B$6,IF(A10>$A$7,$B$7,((0.000000000032989*A10^3-0.000000270691185*A10^2+0.000468652420503*A10+0.726630359723856)*1.04333245461704))))*$D$6) -> 0.82686357 | E10: 100 | F10: =C10 -> 0.82686357 | G10: =3.11367E-15*E10^4*$H$14+6.10050713E-12*E10^3*$H$14- 1.9488839111664E-07*E10^2*$H$14+0.000385795602517395*E10*$H$14+0.79443935598877*$H$14 -> 0.8356216 | U10: 2 | V10: =IF(U10<$V$6,$W$6,IF(U10>$V$7,$W$7,((0.00000009*(U10)^4+0.00001501*(U10)^3-0.00158915*(U10)^2+0.01492176*(U10)+0.94489651)*1.0186317318901))) -> 1 | W10: =(EXP(LN(IF(U10<$V$6,$W$6,IF(U10>$V$7,$W$7,((0.00000009*(U10)^4+0.00001501*(U10)^3-0.00158915*(U10)^2+0.01492176*(U10)+0.94489651)*1.0186317318901))))*$Y$6)) -> 1
A11: 150 | B11: =(IF(A11<$A$6,$B$6,IF(A11>$A$7,$B$7,((0.000000000032989*A11^3-0.000000270691185*A11^2+0.000468652420503*A11+0.726630359723856)*1.04333245461704)))) -> 0.82522277 | C11: =EXP(LN(IF(A11<$A$6,$B$6,IF(A11>$A$7,$B$7,((0.000000000032989*A11^3-0.000000270691185*A11^2+0.000468652420503*A11+0.726630359723856)*1.04333245461704))))*$D$6) -> 0.82686357 | E11: 250 | F11: =C13 -> 0.86455722 | G11: =3.11367E-15*E11^4*$H$14+6.10050713E-12*E11^3*$H$14- 1.9488839111664E-07*E11^2*$H$14+0.000385795602517395*E11*$H$14+0.79443935598877*$H$14 -> 0.88362146 | U11: 3 | V11: =IF(U11<$V$6,$W$6,IF(U11>$V$7,$W$7,((0.00000009*(U11)^4+0.00001501*(U11)^3-0.00158915*(U11)^2+0.01492176*(U11)+0.94489651)*1.0186317318901))) -> 1 | W11: =(EXP(LN(IF(U11<$V$6,$W$6,IF(U11>$V$7,$W$7,((0.00000009*(U11)^4+0.00001501*(U11)^3-0.00158915*(U11)^2+0.01492176*(U11)+0.94489651)*1.0186317318901))))*$Y$6)) -> 1
A12: 200 | B12: =(IF(A12<$A$6,$B$6,IF(A12>$A$7,$B$7,((0.000000000032989*A12^3-0.000000270691185*A12^2+0.000468652420503*A12+0.726630359723856)*1.04333245461704)))) -> 0.8448876 | C12: =EXP(LN(IF(A12<$A$6,$B$6,IF(A12>$A$7,$B$7,((0.000000000032989*A12^3-0.000000270691185*A12^2+0.000468652420503*A12+0.726630359723856)*1.04333245461704))))*$D$6) -> 0.84636138 | E12: 500 | F12: =C18 -> 0.93693176 | G12: =3.11367E-15*E12^4*$H$14+6.10050713E-12*E12^3*$H$14- 1.9488839111664E-07*E12^2*$H$14+0.000385795602517395*E12*$H$14+0.79443935598877*$H$14 -> 0.94471075 | U12: 4 | V12: =IF(U12<$V$6,$W$6,IF(U12>$V$7,$W$7,((0.00000009*(U12)^4+0.00001501*(U12)^3-0.00158915*(U12)^2+0.01492176*(U12)+0.94489651)*1.0186317318901))) -> 1 | W12: =(EXP(LN(IF(U12<$V$6,$W$6,IF(U12>$V$7,$W$7,((0.00000009*(U12)^4+0.00001501*(U12)^3-0.00158915*(U12)^2+0.01492176*(U12)+0.94489651)*1.0186317318901))))*$Y$6)) -> 1
A13: 250 | B13: =(IF(A13<$A$6,$B$6,IF(A13>$A$7,$B$7,((0.000000000032989*A13^3-0.000000270691185*A13^2+0.000468652420503*A13+0.726630359723856)*1.04333245461704)))) -> 0.86324359 | C13: =EXP(LN(IF(A13<$A$6,$B$6,IF(A13>$A$7,$B$7,((0.000000000032989*A13^3-0.000000270691185*A13^2+0.000468652420503*A13+0.726630359723856)*1.04333245461704))))*$D$6) -> 0.86455722 | E13: 750 | F13: =C23 -> 0.98069551 | G13: =3.11367E-15*E13^4*$H$14+6.10050713E-12*E13^3*$H$14- 1.9488839111664E-07*E13^2*$H$14+0.000385795602517395*E13*$H$14+0.79443935598877*$H$14 -> 0.98306733 | U13: 5 | V13: =IF(U13<$V$6,$W$6,IF(U13>$V$7,$W$7,((0.00000009*(U13)^4+0.00001501*(U13)^3-0.00158915*(U13)^2+0.01492176*(U13)+0.94489651)*1.0186317318901))) -> 1 | W13: =(EXP(LN(IF(U13<$V$6,$W$6,IF(U13>$V$7,$W$7,((0.00000009*(U13)^4+0.00001501*(U13)^3-0.00158915*(U13)^2+0.01492176*(U13)+0.94489651)*1.0186317318901))))*$Y$6)) -> 1
A14: 300 | B14: =(IF(A14<$A$6,$B$6,IF(A14>$A$7,$B$7,((0.000000000032989*A14^3-0.000000270691185*A14^2+0.000468652420503*A14+0.726630359723856)*1.04333245461704)))) -> 0.88031654 | C14: =EXP(LN(IF(A14<$A$6,$B$6,IF(A14>$A$7,$B$7,((0.000000000032989*A14^3-0.000000270691185*A14^2+0.000468652420503*A14+0.726630359723856)*1.04333245461704))))*$D$6) -> 0.88147763 | E14: 1000 | F14: =C28 -> 0.99908447 | G14: =3.11367E-15*E14^4*$H$14+6.10050713E-12*E14^3*$H$14- 1.9488839111664E-07*E14^2*$H$14+0.000385795602517395*E14*$H$14+0.79443935598877*$H$14 -> 1 | H14: 1.005469 | U14: 6 | V14: =IF(U14<$V$6,$W$6,IF(U14>$V$7,$W$7,((0.00000009*(U14)^4+0.00001501*(U14)^3-0.00158915*(U14)^2+0.01492176*(U14)+0.94489651)*1.0186317318901))) -> 0.99884631 | W14: =(EXP(LN(IF(U14<$V$6,$W$6,IF(U14>$V$7,$W$7,((0.00000009*(U14)^4+0.00001501*(U14)^3-0.00158915*(U14)^2+0.01492176*(U14)+0.94489651)*1.0186317318901))))*$Y$6)) -> 0.99926238
A15: 350 | B15: =(IF(A15<$A$6,$B$6,IF(A15>$A$7,$B$7,((0.000000000032989*A15^3-0.000000270691185*A15^2+0.000468652420503*A15+0.726630359723856)*1.04333245461704)))) -> 0.89613227 | C15: =EXP(LN(IF(A15<$A$6,$B$6,IF(A15>$A$7,$B$7,((0.000000000032989*A15^3-0.000000270691185*A15^2+0.000468652420503*A15+0.726630359723856)*1.04333245461704))))*$D$6) -> 0.89714902 | E15: 1250 | F15: =C33 -> 0.99530727 | G15: =G48*E15^4*$H$14+6.10050713E-12*E15^3*$H$14- 1.9488839111664E-07*E15^2*$H$14+0.000385795602517395*E15*$H$14+0.79443935598877*$H$14 -> 0.98946777 | U15: 7 | V15: =IF(U15<$V$6,$W$6,IF(U15>$V$7,$W$7,((0.00000009*(U15)^4+0.00001501*(U15)^3-0.00158915*(U15)^2+0.01492176*(U15)+0.94489651)*1.0186317318901))) -> 0.99504531 | W15: =(EXP(LN(IF(U15<$V$6,$W$6,IF(U15>$V$7,$W$7,((0.00000009*(U15)^4+0.00001501*(U15)^3-0.00158915*(U15)^2+0.01492176*(U15)+0.94489651)*1.0186317318901))))*$Y$6)) -> 0.99683003
