Workbook

Sheet Объекты
A1: &T0
A2: &H1 | B2: cadastralNumber | C2: prevCadastralNumbers | D2: segment | E2: additional_51410 | F2: additional_51412 | G2: additional_51413 | H2: additional_51417 | I2: additional_51414 | J2: additional_51415 | K2: additional_51416 | L2: additional_51407 | M2: additional_51409 | N2: areaObject | O2: cadastralNumber | P2: segment | Q2: additional_51410 | R2: additional_51412 | S2: additional_51413 | T2: additional_51417 | U2: additional_51414 | V2: additional_51415 | W2: additional_51416 | X2: additional_51407 | Y2: additional_51409 | Z2: areaObject
A3: &H1 | D3: segmentOfUsage | N3: areaValue | P3: segmentOfUsage | Z3: areaValue
A4: &H2 | B4: кадастровый номер объекта | C4: Кадастровые номера объектов недвижимости, из которых образован данный объект недвижимости | D4: Код расчёта вида использования | E4: Транспортная доступность до административного центра МО | F4: Транспортная доступность до центра Екатеринбурга | G4: Водоотведение итог | H4: Водоснабжение итог | I4: Газоснабжение итог | J4: Теплоснабжение итог | K4: Электроснабжение итог | L4: Обременение | M4: Подтопление | N4: значение площади | O4: кадастровый номер объекта | P4: Код расчёта вида использования | Q4: Транспортная доступность до административного центра МО | R4: Транспортная доступность до центра Екатеринбурга | S4: Водоотведение итог | T4: Водоснабжение итог | U4: Газоснабжение итог | V4: Теплоснабжение итог | W4: Электроснабжение итог | X4: Обременение | Y4: Подтопление | Z4: значение площади | AA4: KN_2022 | AB4: Теплоснабжение_2022 | AC4: Газоснабжение_2022 | AD4: Водоснабжение_2022 | AE4: Водоотведение_2022 | AF4: значение площади | AG4: Обременение | AH4: Подтопление | AI4: Наличие родителя | AJ4: КВРИ 13 Сегмент | AK4: Транспортная доступность до административного центра МО | AL4: Транспортная доступность до центра Екатеринбурга | AM4: Водоотведение итог | AN4: Водоснабжение итог | AO4: Газоснабжение итог | AP4: Теплоснабжение итог | AQ4: Электроснабжение итог | AR4: Обременение | AS4: Подтопление | AT4: ИТОГ
B5: 66:01:0202008:151 | D5: 03:070 | E5: 34 | F5: 322 | G5: Отсутствует информация | H5: Отсутствует информация | I5: Отсутствует информация | J5: Отсутствует информация | K5: Отсутствует информация | L5: 0 | M5: 0 | N5: 1195 | AI5: =IF(LEN(O5)=0,FALSE,TRUE) -> FALSE | AJ5: =AND( IFERROR(VLOOKUP(D5,КВРИ13!A$1:B$9,2,FALSE),FALSE),IFERROR(VLOOKUP(P5,КВРИ13!A$1:B$9,2,FALSE),FALSE)) -> FALSE | AK5: =E5=Q5 -> FALSE | AL5: =F5=R5 -> FALSE | AM5: =IF(AND(AI5,AJ5),VLOOKUP(G5,Градации!A$20:B$55,2,FALSE)=VLOOKUP(S5,Градации!A$20:B$55,2,FALSE),TRUE) -> TRUE | AN5: =IF(AND(AI5,AJ5),VLOOKUP(H5,Градации!A$57:B$85,2,FALSE)=VLOOKUP(T5,Градации!A$57:B$85,2,FALSE),TRUE) -> TRUE | AO5: =IF(AND(AI5,AJ5),VLOOKUP(I5,Градации!A$118:B$147,2,FALSE)=VLOOKUP(U5,Градации!A$118:B$147,2,FALSE),TRUE) -> TRUE | AP5: =IF(AND(AI5,AJ5),VLOOKUP(J5,Градации!A$87:B$117,2,FALSE)=VLOOKUP(V5,Градации!A$87:B$117,2,FALSE),TRUE) -> TRUE | AQ5: =IF(AND(AI5,AJ5),VLOOKUP(K5,Градации!A$2:B$18,2,FALSE)=VLOOKUP(W5,Градации!A$2:B$18,2,FALSE),TRUE) -> TRUE | AR5: =OR(AND(L5<0.5,X5<0.5),AND(L5>=0.5,X5>=0.5)) -> TRUE | AS5: =OR(AND(M5<0.5,Y5<0.5),AND(M5>=0.5,Y5>=0.5)) -> TRUE | AT5: =IF(AND(AI5,AJ5),IF(AND(AM5,AN5,AO5,AP5,AQ5,AR5,AS5),"ХАРАКТЕРИСТИКИ СОВПАДАЮТ","ПЕРЕНОС ХАРАКТЕРИСТИК ОТ РОДИТЕЛЯ"),"УСЛОВИЯ НЕ ВЫПОЛНЕНЫ") -> УСЛОВИЯ НЕ ВЫПОЛНЕНЫ | AU5: =E5-Q5 -> 34 | AV5: =F5-R5 -> 322 | AW5: =N5-Z5 -> 1195 | AX5: =VLOOKUP(B5,#REF!,1,FALSE) -> #REF!

Sheet Градации
A1: Электроснабжение
A2: Отсутствие электроснабжения_Электроснабжение_Оценка2020 | B2: Отсутствие электроснабжения
A3: отсутствие_Электроснабжение_Оценка2020 | B3: Отсутствие электроснабжения
A4: Отсутствие_Электроснабжения_ПОД 2022 | B4: Отсутствие электроснабжения
A5: нет информации | B5: Возможность электроснабжения
A6: Отсутствие_Электроснабжения_Ст_21 | B6: Отсутствие электроснабжения
A7: Отсутствие_Электроснабжения_Аналог 2022 | B7: Отсутствие электроснабжения
A8: Возможность_Электроснабжения_ПОД 2022 | B8: Возможность электроснабжения
A9: Возможность_Электроснабжения_Ст_21 | B9: Возможность электроснабжения
A10: Возможность_Электроснабжения_Аналог 2022 | B10: Возможность электроснабжения
A11: нет информации_Электроснабжение | B11: Возможность электроснабжения
A12: Наличие_Электроснабжения_ПОД 2022 | B12: Возможность электроснабжения
A13: Наличие электроснабжения | B13: Наличие электроснабжения
... A16: Отсутствует информация | B16: Возможность электроснабжения
A19: Водоотведение
A20: Канализация_Водоотведение_Графика2022 | B20: Возможность централизованного водоотведения
A21: Наличие водоотведения_Водоотведение_Ресурсоснабжающие2022 | B21: Наличие централизованного водоотведения
A22: наличие_Водоотведение_Оценка2020 | B22: Наличие централизованного водоотведения
A23: Наличие_централизованного_водоотведения_Аналог_М7 | B23: Наличие централизованного водоотведения
A24: нет информации | B24: Отсутствие централизованного водоотведения
A25: Отсутствие водоотведения_Водоотведение_Оценка2020 | B25: Отсутствие централизованного водоотведения
A26: Отсутствие централизованного водоотведения_ПОД 2022 | B26: Отсутствие централизованного водоотведения
A27: отсутствие_Водоотведение_Оценка2020 | B27: Отсутствие централизованного водоотведения
A28: Отсутствие_централизованного_водоотведения_Аналог_М7 | B28: Отсутствие централизованного водоотведения
A29: пересечение_Водоотведение_Оценка2020 | B29: Возможность централизованного водоотведения
A30: Потребитель канализации автономное выгребная яма_Водоотведение_Графика2022 | B30: Отсутствие централизованного водоотведения
A31: Потребитель канализации из буферной зоны_Водоотведение_Графика2022 | B31: Наличие централизованного водоотведения
... A52: Отсутствует информация | B52: Отсутствие централизованного водоотведения
A56: Водоснабжение
A57: Водопровод_Водоснабжение_Графика2022 | B57: Возможность централизованного водоснабжения
A58: Водоразборная колонка_Водоснабжение_Графика2022 | B58: Возможность централизованного водоснабжения
A59: Наличие водоснабжения_Водоснабжение_Ресурсоснабжающие2022 | B59: Наличие централизованного водоснабжения
A60: наличие_Водоснабжение_Оценка2020 | B60: Наличие централизованного водоснабжения
A61: нет информации | B61: Отсутствие централизованного водоснабжения
A62: Отсутствие водоснабжения_Водоснабжение_Ресурсоснабжающие2022 | B62: Отсутствие централизованного водоснабжения
A63: Отсутствие централизованного водоснабжения_ПОД 2022 | B63: Отсутствие централизованного водоснабжения
A64: отсутствие_Водоснабжение_Оценка2020 | B64: Отсутствие централизованного водоснабжения
A65: пересечение_Водоснабжение_Оценка2020 | B65: Возможность централизованного водоснабжения
A66: Потребитель водоснабжения автономное скважина_Водоснабжение_Графика2022 | B66: Скважина
A67: Потребитель водоснабжения из линий_Водоснабжение_Графика2022 | B67: Наличие централизованного водоснабжения
...

Sheet КВРИ13
A1: 02:011 | B1: =TRUE -> TRUE
A2: 02:019 | B2: =TRUE -> TRUE
A3: 02:021 | B3: =TRUE -> TRUE
A4: 02:023 | B4: =TRUE -> TRUE
A5: 02:031 | B5: =TRUE -> TRUE
A6: 13:011 | B6: =TRUE -> TRUE
A7: 13:021 | B7: =TRUE -> TRUE
A8: 13:021 | B8: =TRUE -> TRUE
A9: 13:031 | B9: =TRUE -> TRUE
